Workbook

Sheet Pathways
B1: Reactants Charge | C1: Products Charge | D1: Charge Balanced? | E1: rxnID | F1: rxnName [gene] | G1: rxnLB | H1: rxnUB | I1: rxnModels | J1: rxnNotes
A4: 1,3-Butanediol PW1 | B4: DONE | J4: It seems that to make (R)-1,3-butanediol, acetoacetyl-CoA must be converted to (R)-3-hydroxybutanoyl-CoA, which requires the NADP-dependent (R)-3-hydroxybutyryl-CoA dehydrogenase reaction. The (S) pathway uses an NAD-dependent (S)-3-hydroxybutyryl-CoA dehydrogenase instead. If using the NAD-dependent (S)-3-hydroxybutyryl-CoA dehydrogenase is desirable, another pathway option could be to use this reaction and then convert (S)-3-Hydroxybutanoyl-CoA to (R)-3-Hydroxybutanoyl-CoA using an isomerase/epimerase (such as the one that exists in the P.putida iJN1463 model under rxnID HBCE). I don’t believe this was employed in any of the literature paper references, but it could be an option. Note that if adding an exogenous (R)-3-hydroxybutyryl-CoA dehydrogenase to E.coli, the endogenous (S)-3-hydroxybutyryl-CoA dehydrogenase (rxnID HACD1 in iJO1366 model) might need to be knocked-out/down.
A5: 2Acetyl-CoA ---> Acetoacetyl-CoA + CoA | E5: ACACT1r | F5: Acetyl-CoA C-acetyltransferase (Acetoacetyl-CoA) | G5: -1000 | H5: 1000 | I5: iJO1366 | J5: Gene: phaA from R. Eutropha OR AtoB from E. coli
A6: Acetoacetyl-CoA + NADPH + H+ ---> (R)-3-Hydroxybutanoyl-CoA + NADP+ | E6: 3HBCOADH | F6: (R)-3-hydroxybutyryl-CoA dehydrogenase [phaB, Hbd] | G6: 0 | H6: 1000 | J6: Gene: phaB from R. Eutropha OR Hbd from C. Saccharoperbutylacetonicum
A7: (R)-3-Hydroxybutanoyl-CoA + NADH + H+ ---> (R)-3-Hydroxybutanal + CoA + NAD+ | E7: 3HBCOAR | F7: (R)-3-Hydroxybutyryl-CoA reductase (NADH) | G7: 0 | H7: 1000 | J7: Not in BiGG database. Gene: bldD from C. Saccharoperbutylacetonicum
A8: (R)-3-Hydroxybutanal + NADH + H+ --> (R)-1,3-Butanediol + NAD+ | E8: 3HBDH | F8: Alcohol dehydrogenase ((R)-1,3-butanediol forming) | G8: 0 | H8: 1000 | J8: Not in BiGG database. Gene: Adh from E. coli. OR can use NADPH-dependent aldo/keto reductase (PA1127) from P. Aeruginosa (Nemr, 2018). Used NADH-dependent reaction in model.
A9: 1,3-Butanediol_p + H+_p <=> 1,3-Butanediol_c + H+_c | E9: R13BDOt2rpp | F9: 1,3-Butanediol transport via proton symport (periplasm) | G9: -1000 | H9: 1000 | J9: Not in BiGG database.
A10: 1,3-Butanediol_e <=> 1,3-Butanediol_p | E10: R13BDOtex | F10: 1,3-Butanediol transport via diffusion (extracellular to periplasm) | G10: -1000 | H10: 1000 | J10: Not in BiGG database.
A11: 1,3-Butanediol_e <=> | E11: EX_r13bdo_e | F11: 1,3-Butanediol exchange | G11: 0 | H11: 1000 | J11: Exists in the BiGG Homo Sapiens Recon3D model.
A12: Based on boiling point >37degC, assuming proton symporter used for C <=> P, and diffusion for P <=> E. No instances of 1,3-Butanediol transport exist in BiGG database.
A13: Acetoacetyl-CoA + NADH + H+ ---> (S)-3-Hydroxybutanoyl-CoA + NAD+ | E13: HACD1 | F13: 3-hydroxyacyl-CoA dehydrogenase (acetoacetyl-CoA) | G13: -1000 | H13: 1000 | I13: iJO1366 | J13: *Reaction included for reference only (not in pathway), see pathway notes.
A14: (R)-3-Hydroxybutanoyl-CoA <=> (R)-3-Hydroxybutanoyl-CoA | E14: HBCE | F14: 3-Hydroxybutanoyl-CoA Isomerase | G14: 0 | H14: 1000 | J14: *Reaction included for reference only (not in pathway), see pathway notes. Not in iJO1366 model but exists in P. Putida iJN1463 model.
A16: Nemr (2018): https://pubmed.ncbi.nlm.nih.gov/29753069/
A17: Kataoka (2014): https://www.tandfonline.com/doi/pdf/10.1080/09168451.2014.891933?needAccess=true&
A18: Kataoka (2013): https://www.sciencedirect.com/science/article/pii/S1389172312004768?via%3Dihub
A19: MetaCyc (3-hydroxybutyryl-CoA dehydrogenase): https://metacyc.org/gene?orgid=META&id=MONOMER-13586
A20: MetaCyc (R vs S pathway options): https://metacyc.org/META/NEW-IMAGE?type=PATHWAY&object=PWY-7216
A22: 1,3-Butanediol PW2 | B22: DONE | J22: It seems that to make (R)-1,3-butanediol, acetoacetyl-CoA must be converted to (R)-3-hydroxybutanoyl-CoA, which requires the NADP-dependent (R)-3-hydroxybutyryl-CoA dehydrogenase reaction. The (S) pathway uses an NAD-dependent (S)-3-hydroxybutyryl-CoA dehydrogenase instead. If using the NAD-dependent (S)-3-hydroxybutyryl-CoA dehydrogenase is desirable, another pathway option could be to use this reaction and then convert (S)-3-Hydroxybutanoyl-CoA to (R)-3-Hydroxybutanoyl-CoA using an isomerase/epimerase (such as the one that exists in the P.putida iJN1463 model under rxnID HBCE). I don’t believe this was employed in any of the literature paper references, but it could be an option. Note that if adding an exogenous (R)-3-hydroxybutyryl-CoA dehydrogenase to E.coli, the endogenous (S)-3-hydroxybutyryl-CoA dehydrogenase (rxnID HACD1 in iJO1366 model) might need to be knocked-out/down.
A23: Pyruvate + H+ --> Acetaldehyde + CO2 | E23: PYRDC | F23: Pyruvate decarboxylase | G23: 0 | H23: 1000 | J23: Not in iJO1366 model but exists in other BiGG models, including other E. coli models. Nemr et al (2018) used PDC from Z. Mobilis.
A24: 2 Acetaldehyde ---> (R)-3-Hydroxybutanal | E24: DERA | F24: Deoxyribose-5-phosphate aldolase | G24: 0 | H24: 1000 | J24: Not in BiGG database. Nemr et al (2018) used DERA from B. Halodurans (Nemr, 2018).
A25: (R)-3-Hydroxybutanal + NADH + H+ --> (R)-1,3-Butanediol + NAD+ | E25: 3HBDH | F25: Alcohol dehydrogenase ((R)-1,3-butanediol forming) | G25: 0 | H25: 1000 | J25: Not in BiGG database. Gene: Adh from E. coli. OR can use NADPH-dependent aldo/keto reductase (PA1127) from P. Aeruginosa (Nemr, 2018). Used NADH-dependent reaction in model.
A26: 1,3-Butanediol_p + H+_p <=> 1,3-Butanediol_c + H+_c | E26: R13BDOt2rpp | F26: 1,3-Butanediol transport via proton symport (periplasm) | G26: -1000 | H26: 1000 | J26: Not in BiGG database.
A27: 1,3-Butanediol_e <=> 1,3-Butanediol_p | E27: R13BDOtex | F27: 1,3-Butanediol transport via diffusion (extracellular to periplasm) | G27: -1000 | H27: 1000 | J27: Not in BiGG database.
A28: 1,3-Butanediol_e <=> | E28: EX_r13bdo_e | F28: 1,3-Butanediol exchange | G28: 0 | H28: 1000 | J28: Exists in the BiGG Homo Sapiens Recon3D model.
A29: Based on boiling point >37degC, assuming proton symporter used for C <=> P, and diffusion for P <=> E. No instances of 1,3-Butanediol transport exist in BiGG database.
A30: Acetoacetyl-CoA + NADH + H+ ---> (S)-3-Hydroxybutanoyl-CoA + NAD+ | E30: HACD1 | F30: 3-hydroxyacyl-CoA dehydrogenase (acetoacetyl-CoA) | G30: -1000 | H30: 1000 | I30: iJO1366 | J30: *Reaction included for reference only (not in pathway), see pathway notes.
A31: (R)-3-Hydroxybutanoyl-CoA <=> (R)-3-Hydroxybutanoyl-CoA | E31: HBCE | F31: 3-Hydroxybutanoyl-CoA Isomerase | G31: 0 | H31: 1000 | J31: *Reaction included for reference only (not in pathway), see pathway notes. Not in iJO1366 model but exists in P. Putida iJN1463 model.
A33: Nemr (2018): https://pubmed.ncbi.nlm.nih.gov/29753069/
A34: Kataoka (2014): https://www.tandfonline.com/doi/pdf/10.1080/09168451.2014.891933?needAccess=true&
A35: Kataoka (2013): https://www.sciencedirect.com/science/article/pii/S1389172312004768?via%3Dihub
A36: MetaCyc (3-hydroxybutyryl-CoA dehydrogenase): https://metacyc.org/gene?orgid=META&id=MONOMER-13586
A37: MetaCyc (R vs S pathway options): https://metacyc.org/META/NEW-IMAGE?type=PATHWAY&object=PWY-7216
A39: 1,3-Diaminopropane | B39: DONE
A40: Oxaloacetate --> L-Aspartate --> L-aspartate 4-semi aldehyde // alpha-ketoglutarate --> Glutamate | J40: Native steps, for reference.
A41: L-Aspartate-4-semialdehyde + L-Glutamate <=> L-2,4-diaminobutanoate + 2-Oxoglutarate + H+ | B41: =0+-1 -> -1 | C41: =0+-2+1 -> -1 | D41: Y | E41: DABAAT2 | F41: DABA aminotransferase | G41: -1000 | H41: 1000 | J41: Not in iJO1366 model, but exists in other BiGG models under rxn ID DABAAT2 or DABAAT. DABAAT is not charge/mass balanced but DABAAT2 is (hence used here). Reverse reaction is direction needed for this pathway (as shown here).
A42: L-2,4-diaminobutanoate + 2H+ --> 1,3-Diaminopropane + CO2 | B42: =2 -> 2 | C42: =2 -> 2 | D42: Y | E42: DABDC | F42: Diaminobutyrate decarboxylase | G42: 0 | H42: 1000 | J42: Doesn’t appear to exist in any BiGG models. Based on reaction in BioCyc (EC: 4.1.1.86), only one H+ is required on reactant side, but to be charge/mass balanced based on charges assumed for metabolites, 2H+ are required.
A43: 1,3-Diaminopropane_p + H+_p <=> 1,3-Diaminopropane_c + H+_c | E43: 13DAMPPtpp | F43: 1,3-Diaminopropane transport via proton symport (periplasm) | G43: -1000 | H43: 1000 | J43: Doesn’t exist in any BiGG models.
A44: 1,3-Diaminopropane_e <=> 1,3-Diaminopropane_p | E44: 13DAMPPtex | F44: 1,3-Diaminopropane transporter via diffusion (extracellular to periplasm) | G44: -1000 | H44: 1000 | J44: Not in iJO1366 model but exists in the iJN1463 model for P. Putida.
A45: 1,3-Diaminopropane_e <=> | E45: EX_13dampp_e | F45: 1,3-Diaminopropane exchange | G45: 0 | H45: 1000 | J45: Not in iJO1366 model but exists in the iJN1463 model for P. Putida.
A46: Chae (2015) hypothesized that E.coli’s natural putrescine and cadaverine transporters might act as nonspecific transporters for 1,3-diaminopropane because of structural similarities. Overexpression of potE and cadB genes increased 1,3-DAP production in flasks, supporting this hypothesis. In iJO1366 model, putrescine transport (rxnID PTRCt2pp) occurs via a proton symport (periplams to cytoplasm), this same transporter would work in reverse for 1,3-diaminopropane export. Transport exsts in P. Putida model iJN1463 but uses ABC transporter for C <=> P. Based on boiling point >37degC, assuming proton symporter used for C <=> P, and diffusion for P <=> E.
...

Sheet Metabolites
A1: productName | B1: metName | C1: metID | D1: metFormula | E1: metCompartment | F1: metCharge | G1: metModels | H1: metNotes
A3: 1,3-Butanediol PW1 | B3: Acetyl-CoA | C3: accoa_c | D3: C23H34N7O17P3S | E3: c | F3: -4 | G3: iJO1366
A4: 1,3-Butanediol PW1 | B4: Acetoacetyl-CoA | C4: aacoa_c | D4: C25H36N7O18P3S | E4: c | F4: -4 | G4: iJO1366 | H4: Aka 3-oxobutanoyl-CoA
A5: 1,3-Butanediol PW1 | B5: (R)-3-Hydroxybutanoyl-CoA | C5: 3hbcoa__R_c | D5: C25H38N7O18P3S | E5: c | F5: -4 | H5: Not in iJO1366 model but does exist in other BiGG models. Aka (R)-3-Hydroxybutyryl-CoA.
A6: 1,3-Butanediol PW1 | B6: (R)-3-Hydroxybutanal | C6: 3hba_c | D6: C4H8O2 | E6: c | F6: 0 | H6: Not in iJO1366 or any other BiGG models. Aka (R)-3-Hydroxybutyraldehyde.
A7: 1,3-Butanediol PW1 | B7: (R)-1,3-Butanediol | C7: 13bdo__R_c | D7: C4H10O2 | E7: c | F7: 0 | H7: Not in iJO1366 or any other BiGG models.
A8: 1,3-Butanediol PW1 | B8: (R)-1,3-Butanediol | C8: 13bdo__R_e | D8: C4H10O2 | E8: e | F8: 0 | H8: Not in iJO1366 or any other BiGG models.
A11: 1,3-Butanediol PW2 | B11: Pyruvate | C11: pyr_c | D11: C3H3O3 | E11: c | F11: -1 | G11: iJO1366
A12: 1,3-Butanediol PW2 | B12: Acetaldehyde | C12: acald_c | D12: C2H4O | E12: c | F12: 0 | G12: iJO1366
A13: 1,3-Butanediol PW2 | B13: (R)-3-Hydroxybutanal | C13: 3hba_c | D13: C4H8O2 | E13: c | F13: 0 | H13: Not in iJO1366 or any other BiGG models. Aka (R)-3-Hydroxybutyraldehyde.
A14: 1,3-Butanediol PW2 | B14: (R)-1,3-Butanediol | C14: 13bdo__R_c | D14: C4H10O2 | E14: c | F14: 0 | H14: Not in iJO1366 or any other BiGG models.
A15: 1,3-Butanediol PW2 | B15: (R)-1,3-Butanediol | C15: 13bdo__R_e | D15: C4H10O2 | E15: e | F15: 0 | H15: Not in iJO1366 or any other BiGG models.
A19: 1,3-Diaminopropane | B19: L-Aspartate 4-semialdehyde | C19: aspsa_c | D19: C4H7NO3 | E19: c | F19: 0 | G19: iJO1366
A20: 1,3-Diaminopropane | B20: L-Glutamate | C20: glu__L_c | D20: C5H8NO4 | E20: c | F20: -1 | G20: iJO1366
A21: 1,3-Diaminopropane | B21: 2-Oxoglutarate | C21: akg_c | D21: C5H4O5 | E21: c | F21: -2 | G21: iJO1366
A22: 1,3-Diaminopropane | B22: L-2,4-diaminobutanoate | C22: 24dab_c | D22: C4H10N2O2 | E22: c | F22: 0 | H22: Not in iJO1366, but exists in other BiGG models. Charge of 0 reported in other models.
A23: 1,3-Diaminopropane | B23: 1,3-Diaminopropane | C23: 13dampp_c | D23: C3H12N2 | E23: c | F23: 2 | H23: Not in iJO1366, but exists in other BiGG models. Charge of 2 reported in other models. Also called Propane-1-3-Diamine.
A24: 1,3-Diaminopropane | B24: 1,3-Diaminopropane | C24: 13dampp_e | D24: C3H12N2 | E24: e | F24: 2 | H24: Not in iJO1366, but exists in other BiGG models. Charge of 2 reported in other models. Also called Propane-1-3-Diamine.
A27: 1,3-propanediol | B27: Glycerol | C27: glyc_c | D27: C3H8O3 | E27: c | F27: 0 | G27: iJO1366
A28: 1,3-propanediol | B28: 3-Hydroxypropanal | C28: 3hppnl_c | D28: C3H6O2 | E28: c | F28: 0 | H28: Not in iJO1366, but exists in other BiGG models including other E.coli models. Aka Reuterin, also present in the acrylic acid 1 pathway.
A29: 1,3-propanediol | B29: 1,3-propanediol | C29: 13ppd_c | D29: C3H8O2 | E29: c | F29: 0 | H29: Not in iJO1366, but exists in other BiGG models including other E.coli models (like iML1515)
A30: 1,3-propanediol | B30: 1,3-propanediol | C30: 13ppd_e | D30: C3H8O2 | E30: e | F30: 0 | H30: Not in iJO1366, but exists in other BiGG models including other E.coli models
A33: 1,4-Butanediol | B33: Succinyl-CoA | C33: succoa_c | D33: C25H35N7O19P3S | E33: c | F33: -5 | G33: iJO1366
A34: 1,4-Butanediol | B34: Succinyl semialdehyde | C34: sucsal_c | D34: C4H5O3 | E34: c | F34: -1 | G34: iJO1366
A35: 1,4-Butanediol | B35: Gamma-hydroxybutyrate | C35: ghb_c | D35: C4H7O3 | E35: c | F35: -1 | G35: iJO1366 | H35: Aka 4-hydroxybutyrate. Note that there are other instances of 4-hydroxybutyrate in the BiGG database under the metabolite IDs h4but_c and 4ohbut_c.
A36: 1,4-Butanediol | B36: Acetyl-CoA | C36: accoa_c | D36: C23H34N7O17P3S | E36: c | F36: -4 | G36: iJO1366
A37: 1,4-Butanediol | B37: Acetate | C37: ac_c | D37: C2H3O2 | E37: c | F37: -1 | G37: iJO1366
A38: 1,4-Butanediol | B38: 4-Hydroxybutanoyl-CoA (4-Hydroxybutyryl-CoA) | C38: 4hbutcoa_c | D38: C25H38N7O18P3S | E38: c | F38: -4 | H38: Not in iJO1366 but does exist in other BiGG models. Aka 4-Hydroxybutyryl-CoA.
A39: 1,4-Butanediol | B39: 4-Hydroxybutanal | C39: 4hba_c | D39: C4H8O2 | E39: c | F39: 0 | H39: Not in iJO1366 or any other BiGG models. Aka 4-hydroxybutyraldehyde
A40: 1,4-Butanediol | B40: 1,4-Butanediol | C40: 14bdo_c | D40: C4H10O2 | E40: c | F40: 0 | H40: Not in iJO1366 or any other BiGG models.
A41: 1,4-Butanediol | B41: 1,4-Butanediol | C41: 14bdo_e | D41: C4H10O2 | E41: e | F41: 0 | H41: Not in iJO1366 or any other BiGG models.
A44: 1-Propanol PW1 | B44: Dihydroxyacetone Phosphate | C44: dhap_c | D44: C3H5O6P | E44: c | F44: -2 | G44: iJO1366
A45: 1-Propanol PW1 | B45: Methylglyoxal | C45: mthgxl_c | D45: C3H4O2 | E45: c | F45: 0 | G45: iJO1366
A46: 1-Propanol PW1 | B46: D-Lactaldehyde | C46: lald__D_c | D46: C3H6O2 | E46: c | F46: 0 | G46: iJO1366
A47: 1-Propanol PW1 | B47: (R)-Propane-1,2-diol | C47: 12ppd__R_c | D47: C3H8O2 | E47: c | F47: 0 | G47: iJO1366
A48: 1-Propanol PW1 | B48: Propanal | C48: ppal_c | D48: C3H6O | E48: c | F48: 0 | G48: iJO1366 | H48: Aka Propionaldehyde
A49: 1-Propanol PW1 | B49: 1-Propanol | C49: ppoh_c | D49: C3H8O | E49: c | F49: 0 | H49: Not in IJO1366 model but exists in other BiGG models, including other E.coli models.
A52: 1-Propanol PW2 | B52: L-Threonine | C52: thr__L_c | D52: C4H9NO3 | E52: c | F52: 0 | G52: iJO1366
A53: 1-Propanol PW2 | B53: 2-Oxobutanoate | C53: 2obut_c | D53: C4H5O3 | E53: c | F53: -1 | G53: iJO1366 | H53: Aka 2-ketobutyrate
A54: 1-Propanol PW2 | B54: Propanal | C54: ppal_c | D54: C3H6O | E54: c | F54: 0 | G54: iJO1366 | H54: Aka Propionaldehyde
...

Sheet Products
A1: ProductName | B1: Model_Author | C1: Formula | D1: C | E1: H | F1: O | G1: N | H1: Charge | I1: Deg_Red | J1: MW_g/mol | K1: BP_degC | L1: MoleculeType | M1: CCM_Feeder | N1: Transport | O1: ExchangeRxn | P1: MetID | Q1: ProductNotes | R1: Transport (old)
A2: 1-3-Diaminopropane | B2: A | C2: C3H12N2 | D2: 3 | E2: 12 | F2: 0 | G2: 2 | H2: =Metabolites!F23 -> 2 | I2: =(D2*4+E2*1+F2*-2+G2*-3)/D2 -> 6 | J2: =D2*12.0107+E2*1.00784+F2*15.999+G2*14.0067 -> 76.13958 | K2: 139.3 | L2: Diamine | M2: Oxaloacetate + aKG | N2: =IF(K2>37,"Proton symporter", "Diffusion") -> Proton symporter | O2: EX_13dampp_e | P2: 13dampp_c | Q2: H-associated on both amino groups, giving H12 and 2+ charge | R2: Proton symporter
A3: 1-3-Propanediol | B3: A | C3: C3H8O2 | D3: 3 | E3: 8 | F3: 2 | G3: 0 | H3: =Metabolites!F29 -> 0 | I3: =(D3*4+E3*1+F3*-2+G3*-3)/D3 -> 5.3333333 | J3: =D3*12.0107+E3*1.00784+F3*15.999+G3*14.0067 -> 76.09282 | K3: 213 | L3: Diol | M3: Glyceraldehyde 3-P | N3: =IF(K3>37,"Proton symporter", "Diffusion") -> Proton symporter | O3: EX_13ppd_e | P3: 13ppd_c | R3: Diffusion
A4: 2-Methyl-1-Butanol | B4: A | C4: C5H12O | D4: 5 | E4: 12 | F4: 1 | G4: 0 | H4: =Metabolites!F60 -> 0 | I4: =(D4*4+E4*1+F4*-2+G4*-3)/D4 -> 6 | J4: =D4*12.0107+E4*1.00784+F4*15.999+G4*14.0067 -> 88.14658 | K4: 129 | L4: Alcohol | M4: PEP | N4: =IF(K4>37,"Proton symporter", "Diffusion") -> Proton symporter | O4: EX_2mbtoh_e | P4: 2mbtoh_c | Q4: 2-methyl-1-butanol transport exists in the S. cerevisiae iMM904 model as free diffusion between the extra-cellular space and the cytoplasm (rxnID 2MBTOHp). | R4: Diffusion
A5: 2-Pyrone-4-6-Dicarboxylate | B5: A | C5: C7H2O6 | D5: 7 | E5: 2 | F5: 6 | G5: 0 | H5: =Metabolites!F74 -> -2 | I5: =(D5*4+E5*1+F5*-2+G5*-3)/D5 -> 2.5714286 | J5: =D5*12.0107+E5*1.00784+F5*15.999+G5*14.0067 -> 182.08458 | K5: 355.5 | L5: Dicarboxylate | M5: Glyceraldehyde 3-P | N5: =IF(K5>37,"Proton symporter", "Diffusion") -> Proton symporter | O5: EX_2p46dc_e | P5: 2p46dc_c | R5: ExCell, transport?
A6: 3-Methyl-1-Pentanol | B6: A | C6: C6H14O | D6: 6 | E6: 14 | F6: 1 | G6: 0 | H6: =Metabolites!F85 -> 0 | I6: =(D6*4+E6*1+F6*-2+G6*-3)/D6 -> 6 | J6: =D6*12.0107+E6*1.00784+F6*15.999+G6*14.0067 -> 102.17296 | K6: 153 | L6: Alcohol | M6: Oxaloacetate | N6: =IF(K6>37,"Proton symporter", "Diffusion") -> Proton symporter | O6: EX_3mptoh_e | P6: 3mptoh_c | R6: Diffusion
A7: 5-Aminopentanoate | B7: A | C7: C5H11NO2 | D7: 5 | E7: 11 | F7: 2 | G7: 1 | H7: =Metabolites!F108 -> 0 | I7: =(D7*4+E7*1+F7*-2+G7*-3)/D7 -> 4.8 | J7: =D7*12.0107+E7*1.00784+F7*15.999+G7*14.0067 -> 117.14444 | K7: 247.5 | L7: D-Amino Acid | M7: Oxaloacetate | N7: =IF(K7>37,"Proton symporter", "Diffusion") -> Proton symporter | O7: EX_5aptn_e | P7: 5aptn_c | Q7: Both the acid and conjugate base have the same formula and charge 0 ( the base has a +1 charge on amino group and -1 charge on the carboxylate group, giving charge of 0 overall, and same number of hydrogens in both cases). The conjugate base should exist at pH ~7. | R7: Proton symporter?
A8: Acetone | B8: A | C8: C3H6O | D8: 3 | E8: 6 | F8: 1 | G8: 0 | H8: =Metabolites!F112 -> 0 | I8: =(D8*4+E8*1+F8*-2+G8*-3)/D8 -> 5.3333333 | J8: =D8*12.0107+E8*1.00784+F8*15.999+G8*14.0067 -> 58.07814 | K8: 56 | L8: Ketone | M8: Acetyl-CoA | N8: =IF(K8>37,"Proton symporter", "Diffusion") -> Proton symporter | O8: EX_acetone_e | P8: acetone_c | R8: Diffusion
A9: Acrylate-PW1 | B9: A | C9: C3H3O2 | D9: 3 | E9: 3 | F9: 2 | G9: 0 | H9: =Metabolites!F121 -> -1 | I9: =(D9*4+E9*1+F9*-2+G9*-3)/D9 -> 3.6666667 | J9: =D9*12.0107+E9*1.00784+F9*15.999+G9*14.0067 -> 71.05362 | K9: 80 | L9: Carboxylate | M9: Glyceraldehyde 3-P | N9: =IF(K9>37,"Proton symporter", "Diffusion") -> Proton symporter | O9: EX_acryl_e | P9: acryl_c | R9: Proton symporter
A10: Acrylate-PW2 | B10: A | C10: C3H3O2 | D10: 3 | E10: 3 | F10: 2 | G10: 0 | H10: =Metabolites!F129 -> -1 | I10: =(D10*4+E10*1+F10*-2+G10*-3)/D10 -> 3.6666667 | J10: =D10*12.0107+E10*1.00784+F10*15.999+G10*14.0067 -> 71.05362 | K10: 80 | L10: Carboxylate | M10: Pyruvate | N10: =IF(K10>37,"Proton symporter", "Diffusion") -> Proton symporter | O10: EX_acryl_e | P10: acryl_c | R10: Proton symporter
A11: Benzoate-PW1 | B11: A | C11: C7H5O2 | D11: 7 | E11: 5 | F11: 2 | G11: 0 | H11: =Metabolites!F146 -> -1 | I11: =(D11*4+E11*1+F11*-2+G11*-3)/D11 -> 4.1428571 | J11: =D11*12.0107+E11*1.00784+F11*15.999+G11*14.0067 -> 121.1121 | K11: 249.2 | L11: Aromatic + Carboxylate | M11: E4P + aKG | N11: =IF(K11>37,"Proton symporter", "Diffusion") -> Proton symporter | O11: EX_bz_e | P11: bz_c | R11: Proton symporter
A12: Benzoate-PW2 | B12: A | C12: C7H5O2 | D12: 7 | E12: 5 | F12: 2 | G12: 0 | H12: =Metabolites!F156 -> -1 | I12: =(D12*4+E12*1+F12*-2+G12*-3)/D12 -> 4.1428571 | J12: =D12*12.0107+E12*1.00784+F12*15.999+G12*14.0067 -> 121.1121 | K12: 249.2 | L12: Aromatic + Carboxylate | M12: E4P + aKG | N12: =IF(K12>37,"Proton symporter", "Diffusion") -> Proton symporter | O12: EX_bz_e | P12: bz_c | R12: Proton symporter
A13: BetaCarotene | B13: A | C13: C40H56 | D13: 40 | E13: 56 | F13: 0 | G13: 0 | H13: =Metabolites!F182 -> 0 | I13: =(D13*4+E13*1+F13*-2+G13*-3)/D13 -> 5.4 | J13: =D13*12.0107+E13*1.00784+F13*15.999+G13*14.0067 -> 536.86704 | K13: 633 | L13: Hydrocarbon | M13: Acetyl-CoA | N13: ABC Transporter | O13: EX_caro_e | P13: caro_c | R13: Intracellular Product OR ABC Transporter?
A14: Butyrate | B14: A | C14: C4H7O2 | D14: 4 | E14: 7 | F14: 2 | G14: 0 | H14: =Metabolites!F228 -> -1 | I14: =(D14*4+E14*1+F14*-2+G14*-3)/D14 -> 4.75 | J14: =D14*12.0107+E14*1.00784+F14*15.999+G14*14.0067 -> 87.09568 | K14: 163.5 | L14: Carboxylate | M14: Acetyl-CoA | N14: =IF(K14>37,"Proton symporter", "Diffusion") -> Proton symporter | O14: EX_but_e | P14: but_c | Q14: Product transport already exists in iJO1366 model as proton symporter. | R14: Proton symporter
A15: ciscisMuconate | B15: A | C15: C6H4O4 | D15: 6 | E15: 4 | F15: 4 | G15: 0 | H15: =Metabolites!F241 -> -2 | I15: =(D15*4+E15*1+F15*-2+G15*-3)/D15 -> 3.3333333 | J15: =D15*12.0107+E15*1.00784+F15*15.999+G15*14.0067 -> 140.09156 | K15: 345.4 | L15: Dicarboxylate | M15: Glyceraldehyde 3-P | N15: =IF(K15>37,"Proton symporter", "Diffusion") -> Proton symporter | O15: EX_ccmuac_e | P15: ccmuac_c | R15: ExCell, transport?
A16: Farnesene | B16: A | C16: C15H24 | D16: 15 | E16: 24 | F16: 0 | G16: 0 | H16: =Metabolites!F277 -> 0 | I16: =(D16*4+E16*1+F16*-2+G16*-3)/D16 -> 5.6 | J16: =D16*12.0107+E16*1.00784+F16*15.999+G16*14.0067 -> 204.34866 | K16: 260 (A)/272 (B) | L16: Isoprenoid; Hydrocarbon | M16: Acetyl-CoA | N16: =IF(K16>37,"Proton symporter", "Diffusion") -> Proton symporter | O16: EX_frene_e | P16: frene_c | Q16: Pathway for making alpha or beta farnesene is the same, except last step requires different enzyme (but carries out same reaction). | R16: Proton Symporter OR ABC Transporter?
A17: GammaButyrolactone | B17: A | C17: C4H6O2 | D17: 4 | E17: 6 | F17: 2 | G17: 0 | H17: =Metabolites!F283 -> 0 | I17: =(D17*4+E17*1+F17*-2+G17*-3)/D17 -> 4.5 | J17: =D17*12.0107+E17*1.00784+F17*15.999+G17*14.0067 -> 86.08784 | K17: 204 | L17: Lactone (cyclic ester) | M17: aKG | N17: =IF(K17>37,"Proton symporter", "Diffusion") -> Proton symporter | O17: EX_gblt_e | P17: gblt_c | R17: Proton symporter?
A18: Glutarate | B18: A | C18: C5H6O4 | D18: 5 | E18: 6 | F18: 4 | G18: 0 | H18: =Metabolites!F293 -> -2 | I18: =(D18*4+E18*1+F18*-2+G18*-3)/D18 -> 3.6 | J18: =D18*12.0107+E18*1.00784+F18*15.999+G18*14.0067 -> 130.09654 | K18: 200 | L18: Dicarboxylate | M18: Oxaloacetate + aKG | N18: =IF(K18>37,"Proton symporter", "Diffusion") -> Proton symporter | O18: EX_glutar_e | P18: glutar_c | R18: Proton symporter
A19: Isobutyrate | B19: A | C19: C4H7O2 | D19: 4 | E19: 7 | F19: 2 | G19: 0 | H19: =Metabolites!F351 -> -1 | I19: =(D19*4+E19*1+F19*-2+G19*-3)/D19 -> 4.75 | J19: =D19*12.0107+E19*1.00784+F19*15.999+G19*14.0067 -> 87.09568 | K19: 155 | L19: Carboxylate | M19: Pyruvate | N19: =IF(K19>37,"Proton symporter", "Diffusion") -> Proton symporter | O19: EX_ibt_e | P19: ibt_c | R19: Proton symporter
A20: Isopropanol | B20: A | C20: C3H8O | D20: 3 | E20: 8 | F20: 1 | G20: 0 | H20: =Metabolites!F369 -> 0 | I20: =(D20*4+E20*1+F20*-2+G20*-3)/D20 -> 6 | J20: =D20*12.0107+E20*1.00784+F20*15.999+G20*14.0067 -> 60.09382 | K20: 82.5 | L20: Alcohol | M20: Acetyl-CoA | N20: =IF(K20>37,"Proton symporter", "Diffusion") -> Proton symporter | O20: EX_2ppoh_e | P20: 2ppoh_c | R20: Diffusion
A21: Malonate | B21: A | C21: C3H2O4 | D21: 3 | E21: 2 | F21: 4 | G21: 0 | H21: =Metabolites!F398 -> -2 | I21: =(D21*4+E21*1+F21*-2+G21*-3)/D21 -> 2 | J21: =D21*12.0107+E21*1.00784+F21*15.999+G21*14.0067 -> 102.04378 | K21: 199 | L21: Dicarboxylate | M21: Oxaloacetate | N21: =IF(K21>37,"Proton symporter", "Diffusion") -> Proton symporter | O21: EX_malon_e | P21: malon_c | R21: Proton symporter (?)
A22: 1-3-butanediol-PW1 | B22: E | C22: C4H10O2 | D22: 4 | E22: 10 | F22: 2 | G22: 0 | H22: 0 | I22: =(D22*4+E22*1+F22*-2+G22*-3)/D22 -> 5.5 | J22: =D22*12.0107+E22*1.00784+F22*15.999+G22*14.0067 -> 90.1192 | K22: 207 | L22: Diol | M22: Acetyl-CoA | N22: =IF(K22>37,"Proton symporter", "Diffusion") -> Proton symporter | O22: EX_r13bdo_e | P22: 13bdo__R_c | Q22: Not in BiGG db, but 2,3-butanediol is as metID 23btdl_c and charge 0. 2,3-Butanediol transport exists in the BiGG database as diffusion (see BTDt_RR, BTDDtpp, BTDDtex). | R22: Diffusion
A23: 1-3-butanediol-PW2 | B23: E | C23: C4H10O2 | D23: 4 | E23: 10 | F23: 2 | G23: 0 | H23: 0 | I23: =(D23*4+E23*1+F23*-2+G23*-3)/D23 -> 5.5 | J23: =D23*12.0107+E23*1.00784+F23*15.999+G23*14.0067 -> 90.1192 | K23: 207 | L23: Diol | M23: Pyruvate (acetalehyde) | N23: =IF(K23>37,"Proton symporter", "Diffusion") -> Proton symporter | O23: EX_r13bdo_e | P23: 13bdo__R_c | Q23: Not in BiGG db, but 2,3-butanediol is as metID 23btdl_c and charge 0. 2,3-Butanediol transport exists in the BiGG database as diffusion (see BTDt_RR, BTDDtpp, BTDDtex). | R23: Eflux pump / Diffusion
A24: 1-4-butanediol | B24: E | C24: C4H10O2 | D24: 4 | E24: 10 | F24: 2 | G24: 0 | H24: 0 | I24: =(D24*4+E24*1+F24*-2+G24*-3)/D24 -> 5.5 | J24: =D24*12.0107+E24*1.00784+F24*15.999+G24*14.0067 -> 90.1192 | K24: 230 | L24: Diol | M24: aKG | N24: =IF(K24>37,"Proton symporter", "Diffusion") -> Proton symporter | O24: EX_14bdo_e | P24: 14bdo_c | Q24: Not in BiGG db, but 2,3-butanediol is as metID 23btdl_c and charge 0. 2,3-Butanediol transport exist in the BiGG database as diffusion (see BTDt_RR, BTDDtpp, BTDDtex). | R24: Eflux pump / Diffusion
A25: 2-3-butanediol | B25: E | C25: C4H10O2 | D25: 4 | E25: 10 | F25: 2 | G25: 0 | H25: 0 | I25: =(D25*4+E25*1+F25*-2+G25*-3)/D25 -> 5.5 | J25: =D25*12.0107+E25*1.00784+F25*15.999+G25*14.0067 -> 90.1192 | K25: 177 | L25: Diol | M25: Pyruvate | N25: =IF(K25>37,"Proton symporter", "Diffusion") -> Proton symporter | O25: EX_btd_RR_e | P25: btd_RR_c | Q25: Not in iJO1366, but exists in other BiGG models. 2,3-Butanediol transport exists in the BiGG database as diffusion (see BTDt_RR, BTDDtpp, BTDDtex). | R25: Eflux pump / Diffusion
A26: 4-Hydroxystyrene | B26: E | C26: C8H8O | D26: 8 | E26: 8 | F26: 1 | G26: 0 | H26: 0 | I26: =(D26*4+E26*1+F26*-2+G26*-3)/D26 -> 4.75 | J26: =D26*12.0107+E26*1.00784+F26*15.999+G26*14.0067 -> 120.14732 | K26: 229 | L26: Aromatic + Alcohol | M26: E4P + L-glutamate | N26: =IF(K26>37,"Proton symporter", "Diffusion") -> Proton symporter | O26: EX_hxst_e | P26: 4hxst_c | Q26: Not in BiGG db at all. | R26: Eflux pump / Diffusion
A27: Adipate | B27: E | C27: C6H8O4 | D27: 6 | E27: 8 | F27: 4 | G27: 0 | H27: -2 | I27: =(D27*4+E27*1+F27*-2+G27*-3)/D27 -> 4 | J27: =D27*12.0107+E27*1.00784+F27*15.999+G27*14.0067 -> 144.12292 | K27: 337.5 | L27: Dicarboxylate | M27: Glyceraldehyde 3-P | N27: =IF(K27>37,"Proton symporter", "Diffusion") -> Proton symporter | O27: EX_adpac_e | P27: adpac_c | Q27: Not in iJO1366, aka adipic acid. Does exist in other BiGG models but only mammal ones (Homo sapiens and Cricetulus griseus). Reported as -2 in model, adipic acid carboxylate pKas reported as 4.1 and 5.4, meaning both will be deprotonated at pH ~7. One instance of transport exists in Homo sapiens model as diffusion (rxnID ADPACtd), but given it’s charged I think it will likely need to be transported actively... | R27: Diffusion
A28: Benzyl alcohol | B28: E | C28: C7H8O | D28: 7 | E28: 8 | F28: 1 | G28: 0 | H28: 0 | I28: =(D28*4+E28*1+F28*-2+G28*-3)/D28 -> 4.8571429 | J28: =D28*12.0107+E28*1.00784+F28*15.999+G28*14.0067 -> 108.13662 | K28: 205 | L28: Aromatic + Alcohol | M28: E4P | N28: =IF(K28>37,"Proton symporter", "Diffusion") -> Proton symporter | O28: EX_bzalc_e | P28: bzalc_c | Q28: Not in iJO1366, but exists in other BiGG model (iAF987). | R28: Diffusion
A29: Butane | B29: E | C29: C4H10 | D29: 4 | E29: 10 | F29: 0 | G29: 0 | H29: =Metabolites!F197 -> 0 | I29: =(D29*4+E29*1+F29*-2+G29*-3)/D29 -> 6.5 | J29: =D29*12.0107+E29*1.00784+F29*15.999+G29*14.0067 -> 58.1212 | K29: -1 | L29: Hydrocarbon (alkane) | M29: Acetyl-CoA + Succinyl-CoA | N29: =IF(K29>37,"Proton symporter", "Diffusion") -> Diffusion | O29: EX_butane_e | P29: butn_c | R29: Diffusion
A30: Butanol-PW1 | B30: E | C30: C4H10O | D30: 4 | E30: 10 | F30: 1 | G30: 0 | H30: 0 | I30: =(D30*4+E30*1+F30*-2+G30*-3)/D30 -> 6 | J30: =D30*12.0107+E30*1.00784+F30*15.999+G30*14.0067 -> 74.1202 | K30: 117.7 | L30: Alcohol | M30: Acetyl-CoA | N30: =IF(K30>37,"Proton symporter", "Diffusion") -> Proton symporter | O30: EX_btoh_e | P30: btoh_c | Q30: Not in iJO1366. Does exist in other BiGG models, also another instance of butanol exists as 1-butanol (metID: 1btol_c ). Transport of butanol exists in the Clostridium ljungdahlii iHN637 model as free diffusion (see rxnID: BTOHt) | R30: Diffusion
A31: Butanol-PW2 | B31: E | C31: C4H10O | D31: 4 | E31: 10 | F31: 1 | G31: 0 | H31: 0 | I31: =(D31*4+E31*1+F31*-2+G31*-3)/D31 -> 6 | J31: =D31*12.0107+E31*1.00784+F31*15.999+G31*14.0067 -> 74.1202 | K31: 117.7 | L31: Alcohol | M31: Oxaloacetate | N31: =IF(K31>37,"Proton symporter", "Diffusion") -> Proton symporter | O31: EX_btoh_e | P31: btoh_c | Q31: Not in iJO1366. Does exist in other BiGG models, also another instance of butanol exists as 1-butanol (metID: 1btol_c ). Transport of butanol exists in the Clostridium ljungdahlii iHN637 model as free diffusion (see rxnID: BTOHt) | R31: Diffusion
A32: Catechol | B32: E | C32: C6H6O2 | D32: 6 | E32: 6 | F32: 2 | G32: 0 | H32: 0 | I32: =(D32*4+E32*1+F32*-2+G32*-3)/D32 -> 4.3333333 | J32: =D32*12.0107+E32*1.00784+F32*15.999+G32*14.0067 -> 110.10924 | K32: 245 | L32: Aromatic + Diol | M32: Glyceraldehyde 3-P | N32: =IF(K32>37,"Proton symporter", "Diffusion") -> Proton symporter | O32: EX_catechol_e | P32: catechol_c | Q32: Not in iJO1366. Exists in other BiGG models under same metID as shown. Aka 1,2-dihydroxybenzene or 1,2-benzenediol. Transport of catechol exists in P. Putida models (iJN1463 and iJN746) as diffusion, see rnx IDs: CATECHOLtpp & CATECHOLtex. | R32: Diffusion
A33: Coumaric acid | B33: E | C33: C9H7O3 | D33: 9 | E33: 7 | F33: 3 | G33: 0 | H33: -1 | I33: =(D33*4+E33*1+F33*-2+G33*-3)/D33 -> 4.1111111 | J33: =D33*12.0107+E33*1.00784+F33*15.999+G33*14.0067 -> 163.14818 | K33: 346 | L33: Aromatic + Alcohol + Carboxylate | M33: E4P + L-glutamate | N33: =IF(K33>37,"Proton symporter", "Diffusion") -> Proton symporter | O33: EX_T4hcinnm_e | P33: T4hcinnm_c | Q33: Not in iJO1366, but exists in other BiGG model (iJN1463). | R33: Diffusion
A34: EthylAcetate | B34: E | C34: C4H8O2 | D34: 4 | E34: 8 | F34: 2 | G34: 0 | H34: 0 | I34: =(D34*4+E34*1+F34*-2+G34*-3)/D34 -> 5 | J34: =D34*12.0107+E34*1.00784+F34*15.999+G34*14.0067 -> 88.10352 | K34: 77.1 | L34: Carboxylate Ester | M34: Acetyl-CoA | N34: =IF(K34>37,"Proton symporter", "Diffusion") -> Proton symporter | O34: EX_aces_e | P34: aces_c | Q34: Not in iJO1366 but exists in S. cerevisiae IMM904 model under name “Acetic Ester C4H8O2”. In this model, the transport of ethyl acetate is by diffusion (see rxnID ACESt). Considered a carboxylate but it’s not charged (it’s a carboxylate ester so the O group that’s usually charged in a carboxylate is not, as it has two bonds via the ester). May have similar transport to other carboxylate esters. | R34: Diffusion
A35: Heptane | B35: E | C35: C7H16 | D35: 7 | E35: 16 | F35: 0 | G35: 0 | H35: 0 | I35: =(D35*4+E35*1+F35*-2+G35*-3)/D35 -> 6.2857143 | J35: =D35*12.0107+E35*1.00784+F35*15.999+G35*14.0067 -> 100.20034 | K35: 98 | L35: Hydrocarbon (alkane) | M35: Acetyl-CoA | N35: =IF(K35>37,"Proton symporter", "Diffusion") -> Proton symporter | O35: EX_heptane | P35: hept_c | R35: ??
A36: Hexane | B36: E | C36: C6H14 | D36: 6 | E36: 14 | F36: 0 | G36: 0 | H36: 0 | I36: =(D36*4+E36*1+F36*-2+G36*-3)/D36 -> 6.3333333 | J36: =D36*12.0107+E36*1.00784+F36*15.999+G36*14.0067 -> 86.17396 | K36: 69 | L36: Hydrocarbon (alkane) | M36: Acetyl-CoA + Succinyl-CoA | N36: =IF(K36>37,"Proton symporter", "Diffusion") -> Proton symporter | O36: EX_hexane_e | P36: hex_c | R36: ??
A37: Isobutanol | B37: E | C37: C5H10O | D37: 5 | E37: 10 | F37: 1 | G37: 0 | H37: 0 | I37: =(D37*4+E37*1+F37*-2+G37*-3)/D37 -> 5.6 | J37: =D37*12.0107+E37*1.00784+F37*15.999+G37*14.0067 -> 86.1309 | K37: 108 | L37: Alcohol | M37: Pyruvate | N37: =IF(K37>37,"Proton symporter", "Diffusion") -> Proton symporter | O37: EX_ibutoh_e | P37: ibutoh_c | R37: Diffusion
A38: Isoprene | B38: E | C38: C5H8 | D38: 5 | E38: 8 | F38: 0 | G38: 0 | H38: 0 | I38: =(D38*4+E38*1+F38*-2+G38*-3)/D38 -> 5.6 | J38: =D38*12.0107+E38*1.00784+F38*15.999+G38*14.0067 -> 68.11622 | K38: 34.07 | L38: Isoprenoid; Hydrocarbon | M38: Acetyl-CoA | N38: =IF(K38>37,"Proton symporter", "Diffusion") -> Diffusion | O38: EX_iprene_e | P38: iprene_c | Q38: Not in BiGG db at all, aka isopentadiene or 2-methyl-1,3-butadiene. | R38: Diffusion(?)
A39: Itaconate | B39: E | C39: C5H4O4 | D39: 5 | E39: 4 | F39: 4 | G39: 0 | H39: -2 | I39: =(D39*4+E39*1+F39*-2+G39*-3)/D39 -> 3.2 | J39: =D39*12.0107+E39*1.00784+F39*15.999+G39*14.0067 -> 128.08086 | K39: 381 | L39: Dicarboxylate | M39: Acetyl-CoA + Oxaloacetate | N39: =IF(K39>37,"Proton symporter", "Diffusion") -> Proton symporter | O39: EX_itacon_e | P39: itacon_c | Q39: Itaconate (itaconic acid)
A40: Limonene | B40: E | C40: C10H16 | D40: 10 | E40: 16 | F40: 0 | G40: 0 | H40: 0 | I40: =(D40*4+E40*1+F40*-2+G40*-3)/D40 -> 5.6 | J40: =D40*12.0107+E40*1.00784+F40*15.999+G40*14.0067 -> 136.23244 | K40: 176 | L40: Isoprenoid; Aromatic (Cycloalkane) | M40: Acetyl-CoA | N40: =IF(K40>37,"Proton symporter", "Diffusion") -> Proton symporter | O40: EX_limnen_e | P40: limnen_c | Q40: Exists in a few BiGG models, but all mammal models. Called limnen in these models for some reason (but confident its limonene because it has the same formula and is used in the Limonene exchange reaction). Aka Dipentene. Transport in the mammal models is by diffusion (see rxnIDs LIMNENte). Not sure if applicable here.
...

Sheet Products_2
A1: ProductName | B1: Model_Author | C1: Formula | D1: C | E1: H | F1: O | G1: N | H1: Charge | I1: MoleculeType | J1: Degree_of_Reduction | K1: CCM_Feeder | L1: Transport | M1: ExchangeRxn | N1: MW_BP | O1: MetID | P1: ProductNotes
A2: 1-3-Diaminopropane | B2: A | C2: C3H12N2 | D2: 3 | E2: 12 | F2: 0 | G2: 2 | H2: =Metabolites!F23 -> 2 | I2: Diamine | J2: =(D2*4+E2*1+F2*-2+G2*-3)/D2 -> 6 | K2: Oxaloacetate + aKG | L2: Proton symporter | M2: EX_13dampp_e | N2: =D2*12.0107+E2*1.00784+F2*15.999+G2*14.0067 -> 76.13958 | P2: H-associated on both amino groups, giving H12 and 2+ charge
A3: 1-3-Propanediol | B3: A | C3: C3H8O2 | D3: 3 | E3: 8 | F3: 2 | G3: 0 | H3: =Metabolites!F29 -> 0 | I3: Diol | J3: =(D3*4+E3*1+F3*-2+G3*-3)/D3 -> 5.3333333 | K3: Glyceraldehyde 3-P | L3: Diffusion | M3: EX_13ppd_e | N3: =D3*12.0107+E3*1.00784+F3*15.999+G3*14.0067 -> 76.09282
A4: 2-Methyl-1-Butanol | B4: A | C4: C5H12O | D4: 5 | E4: 12 | F4: 1 | G4: 0 | H4: =Metabolites!F60 -> 0 | I4: Alcohol | J4: =(D4*4+E4*1+F4*-2+G4*-3)/D4 -> 6 | K4: PEP | L4: Diffusion | M4: EX_2mbtoh_e | N4: =D4*12.0107+E4*1.00784+F4*15.999+G4*14.0067 -> 88.14658
A5: 2-Pyrone-4-6-Dicarboxylate | B5: A | C5: C7H2O6 | D5: 7 | E5: 2 | F5: 6 | G5: 0 | H5: =Metabolites!F74 -> -2 | I5: Dicarboxylate | J5: =(D5*4+E5*1+F5*-2+G5*-3)/D5 -> 2.5714286 | K5: Glyceraldehyde 3-P | L5: ExCell, transport? | M5: EX_2p46dc_e | N5: =D5*12.0107+E5*1.00784+F5*15.999+G5*14.0067 -> 182.08458
A6: 3-Methyl-1-Pentanol | B6: A | C6: C6H14O | D6: 6 | E6: 14 | F6: 1 | G6: 0 | H6: =Metabolites!F85 -> 0 | I6: Alcohol | J6: =(D6*4+E6*1+F6*-2+G6*-3)/D6 -> 6 | K6: Oxaloacetate | L6: Free diffusion? | M6: EX_3mptoh_e | N6: =D6*12.0107+E6*1.00784+F6*15.999+G6*14.0067 -> 102.17296
A7: 5-Aminovalerate | B7: A | C7: C5H11NO2 | D7: 5 | E7: 11 | F7: 2 | G7: 1 | H7: =Metabolites!F108 -> 0 | I7: D-Amino Acid | J7: =(D7*4+E7*1+F7*-2+G7*-3)/D7 -> 4.8 | K7: Oxaloacetate | L7: Proton symporter? | M7: EX_5aptn_e | N7: =D7*12.0107+E7*1.00784+F7*15.999+G7*14.0067 -> 117.14444 | P7: Both the acid and conjugate base have the same formula and charge 0 ( the base has a +1 charge on amino group and -1 charge on the carboxylate group, giving charge of 0 overall, and same number of hydrogens in both cases). The conjugate base should exist at pH ~7.
A8: Acetone | B8: A | C8: C3H6O | D8: 3 | E8: 6 | F8: 1 | G8: 0 | H8: =Metabolites!F112 -> 0 | I8: Ketone | J8: =(D8*4+E8*1+F8*-2+G8*-3)/D8 -> 5.3333333 | K8: Acetyl-CoA | L8: ExCell, transport? | M8: EX_acetone_e | N8: =D8*12.0107+E8*1.00784+F8*15.999+G8*14.0067 -> 58.07814
A9: Acrylate-PW1 | B9: A | C9: C3H3O2 | D9: 3 | E9: 3 | F9: 2 | G9: 0 | H9: =Metabolites!F121 -> -1 | I9: Carboxylate | J9: =(D9*4+E9*1+F9*-2+G9*-3)/D9 -> 3.6666667 | K9: Glyceraldehyde 3-P | L9: ExCell, transport? | M9: EX_acryl_e | N9: =D9*12.0107+E9*1.00784+F9*15.999+G9*14.0067 -> 71.05362
A10: Acrylate-PW2 | B10: A | C10: C3H3O2 | D10: 3 | E10: 3 | F10: 2 | G10: 0 | H10: =Metabolites!F129 -> -1 | I10: Carboxylate | J10: =(D10*4+E10*1+F10*-2+G10*-3)/D10 -> 3.6666667 | K10: Pyruvate | L10: ExCell, transport? | M10: EX_acryl_e | N10: =D10*12.0107+E10*1.00784+F10*15.999+G10*14.0067 -> 71.05362
A11: Benzoate-PW1 | B11: A | C11: C7H5O2 | D11: 7 | E11: 5 | F11: 2 | G11: 0 | H11: =Metabolites!F146 -> -1 | I11: Cycloalkane + Carboxylate | J11: =(D11*4+E11*1+F11*-2+G11*-3)/D11 -> 4.1428571 | K11: E4P + aKG | L11: Proton symporter | M11: EX_bz_e | N11: =D11*12.0107+E11*1.00784+F11*15.999+G11*14.0067 -> 121.1121
A12: Benzoate-PW2 | B12: A | C12: C7H5O2 | D12: 7 | E12: 5 | F12: 2 | G12: 0 | H12: =Metabolites!F156 -> -1 | I12: Cycloalkane + Carboxylate | J12: =(D12*4+E12*1+F12*-2+G12*-3)/D12 -> 4.1428571 | K12: E4P + aKG | L12: Proton symporter | M12: EX_bz_e | N12: =D12*12.0107+E12*1.00784+F12*15.999+G12*14.0067 -> 121.1121
A13: BetaCarotene | B13: A | C13: C40H56 | D13: 40 | E13: 56 | F13: 0 | G13: 0 | H13: =Metabolites!F182 -> 0 | I13: Hydrocarbon | J13: =(D13*4+E13*1+F13*-2+G13*-3)/D13 -> 5.4 | K13: Acetyl-CoA | L13: Intracellular Product | M13: EX_caro_e | N13: =D13*12.0107+E13*1.00784+F13*15.999+G13*14.0067 -> 536.86704
A14: Butane | B14: E | C14: C4H10 | D14: 4 | E14: 10 | F14: 0 | G14: 0 | H14: =Metabolites!F197 -> 0 | I14: Hydrocarbon (alkane) | J14: =(D14*4+E14*1+F14*-2+G14*-3)/D14 -> 6.5 | K14: Acetyl-CoA + Succinyl-CoA | L14: Diffusion(?) | M14: EX_butane_e | N14: =D14*12.0107+E14*1.00784+F14*15.999+G14*14.0067 -> 58.1212
A15: Butyrate | B15: A | C15: C4H7O2 | D15: 4 | E15: 7 | F15: 2 | G15: 0 | H15: =Metabolites!F228 -> -1 | I15: Carboxylate | J15: =(D15*4+E15*1+F15*-2+G15*-3)/D15 -> 4.75 | K15: Acetyl-CoA | L15: Proton symporter | M15: EX_but_e | N15: =D15*12.0107+E15*1.00784+F15*15.999+G15*14.0067 -> 87.09568
A16: ciscisMuconate | B16: A | C16: C6H4O4 | D16: 6 | E16: 4 | F16: 4 | G16: 0 | H16: =Metabolites!F241 -> -2 | I16: Dicarboxylate | J16: =(D16*4+E16*1+F16*-2+G16*-3)/D16 -> 3.3333333 | K16: Glyceraldehyde 3-P | L16: ExCell, transport? | M16: EX_ccmuac_e | N16: =D16*12.0107+E16*1.00784+F16*15.999+G16*14.0067 -> 140.09156
A17: Farnesene | B17: A | C17: C15H24 | D17: 15 | E17: 24 | F17: 0 | G17: 0 | H17: =Metabolites!F277 -> 0 | I17: Hydrocarbon | J17: =(D17*4+E17*1+F17*-2+G17*-3)/D17 -> 5.6 | K17: Acetyl-CoA | L17: ExCell, transport? | M17: EX_frene_e | N17: =D17*12.0107+E17*1.00784+F17*15.999+G17*14.0067 -> 204.34866 | P17: Pathway for making alpha or beta farnesene is the same, except last step requires different enzyme (but carries out same reaction).
A18: GammaButyrolactone | B18: A | C18: C4H6O2 | D18: 4 | E18: 6 | F18: 2 | G18: 0 | H18: =Metabolites!F283 -> 0 | I18: Lactone (cyclic ester) | J18: =(D18*4+E18*1+F18*-2+G18*-3)/D18 -> 4.5 | K18: aKG | L18: ?? | M18: EX_gblt_e | N18: =D18*12.0107+E18*1.00784+F18*15.999+G18*14.0067 -> 86.08784
A19: Glutarate | B19: A | C19: C5H6O4 | D19: 5 | E19: 6 | F19: 4 | G19: 0 | H19: =Metabolites!F293 -> -2 | I19: Dicarboxylate | J19: =(D19*4+E19*1+F19*-2+G19*-3)/D19 -> 3.6 | K19: Oxaloacetate + aKG | L19: Proton symporter | M19: EX_glutar_e | N19: =D19*12.0107+E19*1.00784+F19*15.999+G19*14.0067 -> 130.09654
A20: Heptane | B20: E | C20: C7H16 | D20: 7 | E20: 16 | F20: 0 | G20: 0 | H20: 0 | I20: Hydrocarbon (alkane) | J20: =(D20*4+E20*1+F20*-2+G20*-3)/D20 -> 6.2857143 | L20: Diffusion(?) | N20: =D20*12.0107+E20*1.00784+F20*15.999+G20*14.0067 -> 100.20034 | P20: Not in BiGG db at all. Call (2016) showed that the fatty acid transporter FadL is also used to import medium-chain alkanes (ie. Octane) in E.coli. From our experiments at LMSE, we already know that butane and pentane are extracellular products. It seems likely that this transporter (or another similar) could be used for the export of alkanes as well. Can thus probably assume diffusion for the transport mechanism? Can this be assumed for all small-medium alkanes?
A21: Hexane | B21: E | C21: C6H14 | D21: 6 | E21: 14 | F21: 0 | G21: 0 | H21: 0 | I21: Hydrocarbon (alkane) | J21: =(D21*4+E21*1+F21*-2+G21*-3)/D21 -> 6.3333333 | K21: Acetyl-CoA | L21: Diffusion(?) | M21: EX_hexane_e | N21: =D21*12.0107+E21*1.00784+F21*15.999+G21*14.0067 -> 86.17396
A22: Isobutyrate | B22: A | C22: C4H7O2 | D22: 4 | E22: 7 | F22: 2 | G22: 0 | H22: =Metabolites!F351 -> -1 | I22: Carboxylate | J22: =(D22*4+E22*1+F22*-2+G22*-3)/D22 -> 4.75 | K22: Pyruvate | L22: Proton symporter (?) | M22: EX_ibt_e | N22: =D22*12.0107+E22*1.00784+F22*15.999+G22*14.0067 -> 87.09568
A23: Isopropanol | B23: A | C23: C3H8O | D23: 3 | E23: 8 | F23: 1 | G23: 0 | H23: =Metabolites!F369 -> 0 | I23: Alcohol | J23: =(D23*4+E23*1+F23*-2+G23*-3)/D23 -> 6 | K23: Acetyl-CoA | L23: Proton symporter (?) | M23: EX_ipp_e | N23: =D23*12.0107+E23*1.00784+F23*15.999+G23*14.0067 -> 60.09382
A24: Malonate | B24: A | C24: C3H2O4 | D24: 3 | E24: 2 | F24: 4 | G24: 0 | H24: =Metabolites!F398 -> -2 | I24: Dicarboxylate | J24: =(D24*4+E24*1+F24*-2+G24*-3)/D24 -> 2 | K24: Oxaloacetate | L24: Proton symporter (?) | M24: EX_malon_e | N24: =D24*12.0107+E24*1.00784+F24*15.999+G24*14.0067 -> 102.04378
A25: Nonane | B25: E | C25: C9H20 | D25: 9 | E25: 20 | F25: 0 | G25: 0 | H25: 0 | I25: Hydrocarbon (alkane) | J25: =(D25*4+E25*1+F25*-2+G25*-3)/D25 -> 6.2222222 | L25: Diffusion(?) | N25: =D25*12.0107+E25*1.00784+F25*15.999+G25*14.0067 -> 128.2531 | P25: Not in BiGG db at all. Call (2016) showed that the fatty acid transporter FadL is also used to import medium-chain alkanes (ie. Octane) in E.coli. From our experiments at LMSE, we already know that butane and pentane are extracellular products. It seems likely that this transporter (or another similar) could be used for the export of alkanes as well. Can thus probably assume diffusion for the transport mechanism? Can this be assumed for all small-medium alkanes?
A26: Octane | B26: E | C26: C8H18 | D26: 8 | E26: 18 | F26: 0 | G26: 0 | H26: 0 | I26: Hydrocarbon (alkane) | J26: =(D26*4+E26*1+F26*-2+G26*-3)/D26 -> 6.25 | K26: Acetyl-CoA | L26: Diffusion(?) | M26: EX_octane_e | N26: =D26*12.0107+E26*1.00784+F26*15.999+G26*14.0067 -> 114.22672
A27: Pentane | B27: E | C27: C5H12 | D27: 5 | E27: 12 | F27: 0 | G27: 0 | H27: =Metabolites!F461 -> 0 | I27: Hydrocarbon (alkane) | J27: =(D27*4+E27*1+F27*-2+G27*-3)/D27 -> 6.4 | K27: Acetyl-CoA | L27: Diffusion(?) | M27: EX_pentane_e | N27: =D27*12.0107+E27*1.00784+F27*15.999+G27*14.0067 -> 72.14758
A28: Propane-PW1 | B28: E | C28: C3H8O | D28: 3 | E28: 8 | F28: 0 | G28: 0 | H28: 0 | I28: Hydrocarbon | J28: =(D28*4+E28*1+F28*-2+G28*-3)/D28 -> 6.6666667 | L28: Diffusion(?) | N28: =D28*12.0107+E28*1.00784+F28*15.999+G28*14.0067 -> 44.09482 | P28: Not in BiGG db at all. Call (2016) showed that the fatty acid transporter FadL is also used to import medium-chain alkanes (ie. Octane) in E.coli. From our experiments at LMSE, we already know that butane and pentane are extracellular products. It seems likely that this transporter (or another similar) could be used for the export of alkanes as well. Can thus probably assume diffusion for the transport mechanism? Can this be assumed for all small-medium alkanes?
A29: Propane-PW2 | B29: E | C29: C3H8O | D29: 3 | E29: 8 | F29: 0 | G29: 0 | H29: 0 | I29: Hydrocarbon | J29: =(D29*4+E29*1+F29*-2+G29*-3)/D29 -> 6.6666667 | L29: Diffusion(?) | N29: =D29*12.0107+E29*1.00784+F29*15.999+G29*14.0067 -> 44.09482 | P29: Not in BiGG db at all. Call (2016) showed that the fatty acid transporter FadL is also used to import medium-chain alkanes (ie. Octane) in E.coli. From our experiments at LMSE, we already know that butane and pentane are extracellular products. It seems likely that this transporter (or another similar) could be used for the export of alkanes as well. Can thus probably assume diffusion for the transport mechanism? Can this be assumed for all small-medium alkanes?
A31: 1,3-butanediol | B31: S | C31: C4H10O2 | D31: 4 | E31: 10 | F31: 2 | G31: 0 | H31: 0 | I31: Diol | J31: =(D31*4+E31*1+F31*-2+G31*-3)/D31 -> 5.5 | L31: Diffusion | N31: =D31*12.0107+E31*1.00784+F31*15.999+G31*14.0067 -> 90.1192 | O31: 13btdl_c | P31: Not in BiGG db, but 2,3-butanediol is as metID 23btdl_c and charge 0. 2,3-Butanediol transport exists in the BiGG database as diffusion (see BTDt_RR, BTDDtpp, BTDDtex).
A32: 1,4-butanediol | B32: S | C32: C4H10O2 | D32: 4 | E32: 10 | F32: 2 | G32: 0 | H32: 0 | I32: Diol | J32: =(D32*4+E32*1+F32*-2+G32*-3)/D32 -> 5.5 | L32: Diffusion | N32: =D32*12.0107+E32*1.00784+F32*15.999+G32*14.0067 -> 90.1192 | O32: 14btdl_c | P32: Not in BiGG db, but 2,3-butanediol is as metID 23btdl_c and charge 0. 2,3-Butanediol transport exist in the BiGG database as diffusion (see BTDt_RR, BTDDtpp, BTDDtex).
A33: 1-propanol | B33: S | C33: C3H8O | D33: 3 | E33: 8 | F33: 1 | G33: 0 | H33: 0 | I33: Alcohol | J33: =(D33*4+E33*1+F33*-2+G33*-3)/D33 -> 6 | L33: Proton symporter | M33: EX_ppoh_e | N33: =D33*12.0107+E33*1.00784+F33*15.999+G33*14.0067 -> 60.09382 | O33: ppoh_c | P33: Not in iJO1366, but exists in other BiGG models. Transport exists in Geobacter metallireducens iAF987 model as proton symport (see rxnIDs PPOHt2pp, PPOHtex).
A34: 2,3-butanediol | B34: S | C34: C4H10O2 | D34: 4 | E34: 10 | F34: 2 | G34: 0 | H34: 0 | I34: Diol | J34: =(D34*4+E34*1+F34*-2+G34*-3)/D34 -> 5.5 | L34: Diffusion | M34: EX_btd_RR_e | N34: =D34*12.0107+E34*1.00784+F34*15.999+G34*14.0067 -> 90.1192 | O34: 23btdl_c | P34: Not in iJO1366, but exists in other BiGG models. 2,3-Butanediol transport exists in the BiGG database as diffusion (see BTDt_RR, BTDDtpp, BTDDtex).
A35: Adipate | B35: S | C35: C6H8O4 | D35: 6 | E35: 8 | F35: 4 | G35: 0 | H35: -2 | I35: Dicarboxylate | J35: =(D35*4+E35*1+F35*-2+G35*-3)/D35 -> 4 | L35: ?? | M35: EX_adpac_e | N35: =D35*12.0107+E35*1.00784+F35*15.999+G35*14.0067 -> 144.12292 | O35: adpac_c | P35: Not in iJO1366, aka adipic acid. Does exist in other BiGG models but only mammal ones (Homo sapiens and Cricetulus griseus). Reported as -2 in model, adipic acid carboxylate pKas reported as 4.1 and 5.4, meaning both will be deprotonated at pH ~7. One instance of transport exists in Homo sapiens model as diffusion (rxnID ADPACtd), but given it’s charged I think it will likely need to be transported actively...
A36: Butanol | B36: S | C36: C4H10O | D36: 4 | E36: 10 | F36: 1 | G36: 0 | H36: 0 | I36: Alcohol | J36: =(D36*4+E36*1+F36*-2+G36*-3)/D36 -> 6 | L36: Diffusion | M36: EX_btoh_e | N36: =D36*12.0107+E36*1.00784+F36*15.999+G36*14.0067 -> 74.1202 | O36: btoh_c | P36: Not in iJO1366. Does exist in other BiGG models, also another instance of butanol exists as 1-butanol (metID: 1btol_c ). Transport of butanol exists in the Clostridium ljungdahlii iHN637 model as free diffusion (see rxnID: BTOHt)
A37: ButylButanoate | B37: S | C37: C8H16O2 | D37: 8 | E37: 16 | F37: 2 | G37: 0 | H37: 0 | I37: Carboxylate Ester | J37: =(D37*4+E37*1+F37*-2+G37*-3)/D37 -> 5.5 | L37: Diffusion(?) | N37: =D37*12.0107+E37*1.00784+F37*15.999+G37*14.0067 -> 144.20904 | O37: butbut_c | P37: Not in BiGG db at all. Considered a carboxylate but it’s not charged (it’s a carboxylate ester so the O group that’s usually charged in a carboxylate is not, as it has two bonds via the ester). May have similar transport to other carboxylate esters.
A38: Casbene | B38: S | C38: C20H32 | D38: 20 | E38: 32 | F38: 0 | G38: 0 | H38: 0 | I38: Diterpene | J38: =(D38*4+E38*1+F38*-2+G38*-3)/D38 -> 5.6 | L38: ?? | N38: =D38*12.0107+E38*1.00784+F38*15.999+G38*14.0067 -> 272.46488 | P38: Not in BiGG db at all.
A39: Catechol | B39: S | C39: C6H6O2 | D39: 6 | E39: 6 | F39: 2 | G39: 0 | H39: 0 | I39: Cycloalkane + Diol | J39: =(D39*4+E39*1+F39*-2+G39*-3)/D39 -> 4.3333333 | L39: Diffusion | M39: EX_catechol_e | N39: =D39*12.0107+E39*1.00784+F39*15.999+G39*14.0067 -> 110.10924 | O39: catechol_c | P39: Not in iJO1366. Exists in other BiGG models under same metID as shown. Aka 1,2-dihydroxybenzene or 1,2-benzenediol. Transport of catechol exists in P. Putida models (iJN1463 and iJN746) as diffusion, see rnx IDs: CATECHOLtpp & CATECHOLtex.
A40: EthylAcetate | B40: S | C40: C4H8O2 | D40: 4 | E40: 8 | F40: 2 | G40: 0 | H40: 0 | I40: Carboxylate Ester | J40: =(D40*4+E40*1+F40*-2+G40*-3)/D40 -> 5 | L40: Diffusion(?) | M40: EX_aces_e | N40: =D40*12.0107+E40*1.00784+F40*15.999+G40*14.0067 -> 88.10352 | O40: aces_c | P40: Not in iJO1366 but exists in S. cerevisiae IMM904 model under name “Acetic Ester C4H8O2”. In this model, the transport of ethyl acetate is by diffusion (see rxnID ACESt). Considered a carboxylate but it’s not charged (it’s a carboxylate ester so the O group that’s usually charged in a carboxylate is not, as it has two bonds via the ester). May have similar transport to other carboxylate esters.
A41: EthylButanoate | B41: S | C41: C6H12O2 | D41: 6 | E41: 12 | F41: 2 | G41: 0 | H41: 0 | I41: Carboxylate Ester | J41: =(D41*4+E41*1+F41*-2+G41*-3)/D41 -> 5.3333333 | L41: Diffusion(?) | N41: =D41*12.0107+E41*1.00784+F41*15.999+G41*14.0067 -> 116.15628 | P41: Not in BiGG db at all. Considered a carboxylate but it’s not charged (it’s a carboxylate ester so the O group that’s usually charged in a carboxylate is not, as it has two bonds via the ester). May have similar transport to other carboxylate esters.
...

Sheet All Pathways
A1: 1,3-butanediol | C1: https://www.tandfonline.com/doi/pdf/10.1080/09168451.2014.891933?needAccess=true
A2: 2ACALD -> C4H8O2 (3-hydroxybutanal, HB3)
A3: HB3 + NADH + H(+) -> 1,3-BD + NAD(+)
A5: 1,4-butanediol | C5: https://www.genomatica.com/wp-content/uploads/2017/01/Metabolic-engineering-of-Escherichia-coli-for-direct-production-of-14-butanediol-Nature-Chemical-V1.pdf
A6: sucsal + NADH + H(+) -> C4H7O3(-) (4-hydroxybutyrate) + NAD(+)
A7: C4H7O3(-) (4-hydroxybutyrate) + accoa + 4H(+) -> C25H42N7O18P3S (4-hydroxybutyryl-CoA) + acetate
A8: C25H42N7O18P3S (4-hydroxybutyryl-CoA) + NADPH -> C4H8O2 (4-hydroxybutyraldehyde) + NADP(+) + CoA + 3H(+)
A9: C4H8O2 (4-hydroxybutyraldehyde) + NADPH + H(+) -> BD-1,4 NADP(+)
A11: 1-propanol | C11: https://www.sciencedirect.com/science/article/abs/pii/S1389172316300330?via%3Dihub
A12: PPDR12 (12ppd__R) -> C3H6O (propionaldehyde) + H2O
A13: C3H6O + NADH + H(+) -> C3H8O (1-propanol) + NAD(+)
A15: 2,3-butanediol | C15: https://biotechnologyforbiofuels.biomedcentral.com/track/pdf/10.1186/s13068-019-1545-1
A16: alac__S -> C4H8O2 (Acetoin) + CO2
A17: C4H8O2 (acetoin) + NADH + H(+) -> 2,3-BD + NAD(+)
A19: Adipic acid | C19: https://www.sciencedirect.com/science/article/pii/S2214030117300275
A20: 3-dehydroshikimate -> C7H5O4(-) (PCA) + H2O
A21: C7H5O4(-) (PCA) + H(+) -> C6H6O2 (catechol) + CO2
A22: C6H6O2 (catechol) + O2 -> C6H4O4(2-) (cis,cis-muconic acid) + 2H(+)
A23: C6H4O4(2-) (CCMA) + 2H(+) + 2NADH -> C6H8O4(2-) (adipic acid) + 2NAD(+)
A25: alpha-Farnesene | C25: https://academic.oup.com/femsle/article/365/10/fny079/4953741
A26: frdp -> diphosphate + C15H24 (alpha-farnesene)
A28: Butane | C28: https://www.ncbi.nlm.nih.gov/pmc/articles/PMC5270751/
A29: accoa + ppcoa -> C26H38N7O18P3S(4-) (3-oxopentanoyl-CoA) + CoA
A30: 3-oxopentanoyl-CoA + NADPH + H(+) -> C26H40N7O18P3S(4-) (3-hydroxypentanoyl-CoA) + NADP(+)
A31: 3-hydroxypentanoyl-CoA -> C26H38N7O17P3S(4-) (pentenoyl-CoA) + H2O
A32: C26H38N7O17P3S(4-) (pentenoyl-CoA) + NADH + H(+) -> C26H40N7O12P3S(4-) (pentanoyl-CoA) + NAD(+)
A33: pentanoyl-CoA + H2O -> C5H9O2(-) (pentanoate) + CoA + H(+)
A34: pentanoate + NADPH + 2H(+) -> C5H10O (pentanal) + NADP(+) + H2O
A35: pentanal + H2O -> C4H10 (butane) + formate + H(+)
A37: Butanol | C37: https://pubs.acs.org/doi/pdf/10.1021/acssynbio.9b00518
A38: 2accoa + 4NADH + 4H(+) -> 2CoA + 4NAD(+) + butanol + H2O
A40: Butyl butanoate | C40: https://pubs.acs.org/doi/pdf/10.1021/acssynbio.9b00518
A41: 4accoa + 4NADH + 6H(+) -> butyl-butanoate + 4CoA + 2H2O + 6NAD(+)
A43: Casbene | C43: https://academic.oup.com/femsle/article/365/10/fny079/4953741
A44: FRDP + IPDP -> diphosphate + C20H33O7P2(3-) (geranylgeranyl diphosphate)
A45: geranylgeranyl diphosphate -> casbene + diphosphate
A47: Catechol | C47: https://www.sciencedirect.com/science/article/pii/S2214030117300275
A48: 3-dehydroshikimate -> C7H5O4(-) (PCA) + H2O
A49: C7H5O4(-) (PCA) + H(+) -> C6H6O2 (catechol) + CO2
A51: Ethyl Acetate | C51: https://pubs.acs.org/doi/pdf/10.1021/acssynbio.9b00518
...

Sheet yields
B1: mmol/gDw.h | C1: mg/gDw.h | F1: mol/mol | G1: g/mol
A2: Product | B2: MOL FLUX | C2: MASS FLUX | D2: EX_name | E2: SBML file name | F2: YIELDS | G2: MOLAR MASS | H2: FINAL METABOLITE
A3: phenol | B3: 7.445245 | C3: =94.11*B3 -> 700.672 | D3: EX_phenol_e | E3: phenol.xml | F3: =B3/10 -> 0.7445245 | G3: =C3/B3 -> 94.11
A4: styrene | B4: 5.5072917 | C4: =104.15*B4 -> 573.58443 | D4: EX_styrene_e | E4: styrene.xml | F4: =B4/10 -> 0.55072917 | G4: =C4/B4 -> 104.15
A5: Isobutanol | B5: 10 | C5: =74.122*B5 -> 741.22 | D5: EX_ibtol_e | E5: isobutanol.xml | F5: =B5/10 -> 1 | G5: =C5/B5 -> 74.122
A6: Catechol | B6: 8.5879646 | C6: =110.1*B6 -> 945.5349 | D6: EX_catechol_e | E6: catechol.xml | F6: =B6/10 -> 0.85879646 | G6: =C6/B6 -> 110.1
A7: 1-propanol | B7: 12.749231 | C7: =60.0952*B7 -> 766.16757 | D7: EX_ppoh_e | E7: 1_propanol.xml | F7: =B7/10 -> 1.2749231 | G7: =C7/B7 -> 60.0952
A8: Adipic acid | B8: 7.4992 | C8: =144.12532*B8 -> 1080.8246 | D8: EX_adipic_e | E8: adipic_acid.xml | F8: =B8/10 -> 0.74992 | G8: =C8/B8 -> 144.12532
A9: Polylactic acid | B9: 16.462329 | C9: =90.08*B9 -> 1482.9266 | D9: EX_polylactic_e | E9: polylactic_acid.xml | F9: =B9/10 -> 1.6462329 | G9: =C9/B9 -> 90.08
A10: 1,3-butanediol | B10: 10.909091 | C10: =90.12*B10 -> 983.12727 | D10: EX_13btdl_e | E10: 1_3_butanediol.xml | F10: =B10/10 -> 1.0909091 | G10: =C10/B10 -> 90.12
A11: 2,3-butanediol | B11: 10.909091 | C11: =90.12*B11 -> 983.12727 | D11: EX_23btdl_e | E11: 2_3_butanediol.xml | F11: =B11/10 -> 1.0909091 | G11: =C11/B11 -> 90.12
A12: 1,4-butanediol | B12: 10.283333 | C12: =90.12*B12 -> 926.734 | D12: EX_14btdl_e | E12: 1_4_butanediol.xml | F12: =B12/10 -> 1.0283333 | G12: =C12/B12 -> 90.12
A13: Levulinic acid | B13: 10.206015 | C13: =115.10728*B13 -> 1174.7866 | D13: EX_levulinate_e | E13: levulinic_acid.xml | F13: =B13/10 -> 1.0206015 | G13: =C13/B13 -> 115.10728
A14: Butanol | B14: 10 | C14: =74.121*B14 -> 741.21 | D14: EX_btoh_e | E14: butanol.xml | F14: =B14/10 -> 1 | G14: =C14/B14 -> 74.121
A15: Pentanol | B15: 8 | C15: =88.15*B15 -> 705.2 | D15: EX_ptoh_e | E15: pentanol.xml | F15: =B15/10 -> 0.8 | G15: =C15/B15 -> 88.15
A16: Ethyl acetate | B16: 11.885455 | C16: =88.11*B16 -> 1047.2274 | D16: EX_ethac_e | E16: ethyl_acetate.xml | F16: =B16/10 -> 1.1885455 | G16: =C16/B16 -> 88.11
A17: Isobutyl acetate | B17: 7.5 | C17: =116.16*B17 -> 871.2 | D17: EX_ibutac_e | E17: isobutyl_acetate.xml | F17: =B17/10 -> 0.75 | G17: =C17/B17 -> 116.16
A18: Ethyl butanoate | B18: 7.5 | C18: =116.16*B18 -> 871.2 | D18: EX_ethbt_e | E18: ethyl_butanoate.xml | F18: =B18/10 -> 0.75 | G18: =C18/B18 -> 116.16
A19: Butyl butanoate | B19: 5.4545455 | C19: =144.21*B19 -> 786.6 | D19: EX_butyl_but_e | E19: butyl_butanoate.xml | F19: =B19/10 -> 0.54545455 | G19: =C19/B19 -> 144.21
A20: Isobutyl butanoate | B20: 5.4545455 | C20: =144.21*B20 -> 786.6 | D20: EX_ibutbu_e | E20: isobutyl_butanoate.xml | F20: =B20/10 -> 0.54545455 | G20: =C20/B20 -> 144.21
A21: Propyl butanoate | B21: 6.3157895 | C21: =130.18*B21 -> 822.18947 | D21: EX_propyl_but_e | E21: propyl_butanoate.xml | F21: =B21/10 -> 0.63157895 | G21: =C21/B21 -> 130.18
A22: Ethyl pentanoate | B22: 6.1588972 | C22: =130.18*B22 -> 801.76524 | D22: EX_ethpt_e | E22: ethyl_pentanoate.xml | F22: =B22/10 -> 0.61588972 | G22: =C22/B22 -> 130.18
A23: Isobutyl pentanoate | B23: 4.8 | C23: =158.24*B23 -> 759.552 | D23: EX_iso_pent_e | E23: isobutyl_pentanoate.xml | F23: =B23/10 -> 0.48 | G23: =C23/B23 -> 158.24
A24: Pentyl pentanoate | B24: 4.2826873 | C24: =172.15*B24 -> 737.26463 | D24: EX_pentyl_pent_e | E24: pentyl_pentanoate.xml | F24: =B24/10 -> 0.42826873 | G24: =C24/B24 -> 172.15
A25: Propane | B25: 9.6668831 | C25: =44.1*B25 -> 426.30955 | D25: EX_propane_e | E25: propane.xml | F25: =B25/10 -> 0.96668831 | G25: =C25/B25 -> 44.1
A26: Isoprene | B26: 8.1754098 | C26: =68.12*B26 -> 556.90892 | D26: EX_isoprene_e | E26: isoprene.xml | F26: =B26/10 -> 0.81754098 | G26: =C26/B26 -> 68.12
A27: Vanillin | B27: 3.7605585 | C27: =152.15*B27 -> 572.16897 | D27: EX_vanln_e | E27: vanillin.xml | F27: =B27/10 -> 0.37605585 | G27: =C27/B27 -> 152.15
A28: Itaconic acid | B28: 12 | C28: =130.099*B28 -> 1561.188 | D28: EX_itacon_e | E28: itaconic_acid.xml | F28: =B28/10 -> 1.2 | G28: =C28/B28 -> 130.099
A29: HMF | B29: 10 | C29: =126.11*B29 -> 1261.1 | D29: EX_HMF_e | E29: HMF.xml | F29: =B29/10 -> 1 | G29: =C29/B29 -> 126.11
A30: Ethylene | B30: 13.010337 | C30: =28.05*B30 -> 364.93996 | D30: EX_ethe_e | E30: ethylene.xml | F30: =B30/10 -> 1.3010337 | G30: =C30/B30 -> 28.05
A31: Ethylbenzene | B31: 5.2998897 | C31: =106.17*B31 -> 562.68929 | D31: EX_ethylbenzene_e | E31: ethylbenzene.xml | F31: =B31/10 -> 0.52998897 | G31: =C31/B31 -> 106.17
A32: n-Nonane | B32: 4.2529412 | C32: =128.2*B32 -> 545.22706 | D32: EX_nonane_e | E32: nonane.xml | F32: =B32/10 -> 0.42529412 | G32: =C32/B32 -> 128.2
A33: n-Heptane | B33: 5.3660156 | C33: =100.21*B33 -> 537.72843 | D33: EX_heptane_e | E33: heptane.xml | F33: =B33/10 -> 0.53660156 | G33: =C33/B33 -> 100.21
A34: n-Butane | B34: 9.0376068 | C34: =58.12*B34 -> 525.26571 | D34: EX_butane_e | E34: butane.xml | F34: =B34/10 -> 0.90376068 | G34: =C34/B34 -> 58.12
A35: n-Pentane | B35: 7.268254 | C35: =72.15*B35 -> 524.40452 | D35: EX_pentane_e | E35: pentane.xml | F35: =B35/10 -> 0.7268254 | G35: =C35/B35 -> 72.15
A36: Xylene | B36: 7.5 | C36: =106.16*B36 -> 796.2 | D36: EX_p_xyl_e | E36: xylene.xml | F36: =B36/10 -> 0.75 | G36: =C36/B36 -> 106.16
A37: Mycrene | B37: 4.0877049 | C37: =136.23*B37 -> 556.86804 | D37: EX_mycrene_e | E37: mycrene.xml | F37: =B37/10 -> 0.40877049 | G37: =C37/B37 -> 136.23
A38: Limonene | B38: =B37 -> 4.0877049 | C38: =C37 -> 556.86804 | D38: EX_limnen_e | E38: limonene.xml
A39: alpha-Pinene | B39: =B38 -> 4.0877049 | C39: =C38 -> 556.86804 | D39: -
A40: beta-Pinene | B40: =B37 -> 4.0877049 | C40: =C38 -> 556.86804 | D40: -
...

Sheet Alternative Yields
A1: Product | B1: MOL FLUX | C1: MASS FLUX | D1: YIELDS
A2: phenol | B2: 7.329078 | C2: =B2*94.11 -> 689.73953 | D2: =C2/1801.56 -> 0.38285682
A3: catechol | B3: 7.7119403 | C3: =B3*110.1 -> 849.08463 | D3: =C3/1801.56 -> 0.47130522
A4: adipic acid | B4: 6.7278646 | C4: =B4*144.12532 -> 969.65564 | D4: =C4/1801.56 -> 0.53823111
A5: levulinic acid | B5: 10.345338 | C5: =B5*115.10728 -> 1190.8237 | D5: =C5/1801.56 -> 0.66099584
