Workbook
Name dG_CO2: 'ECR General'!$B$5
Name dG_H2O: 'ECR General'!$B$6
Name F: 'ECR General'!$B$11
Name pH: 'ECR General'!$B$14

Sheet Substrates
A1: Substrate | B1: Type | C1: Formula | D1: C | E1: H | F1: O | G1: Charge | H1: Molecular Weight | I1: Degree of Reduction | J1: Transport In
A2: Glucose | B2: Sugar | C2: C6H12O6 | D2: 6 | E2: 12 | F2: 6 | G2: 0 | H2: =D2*12.0107+E2*1.00784+F2*15.999 -> 180.15228 | I2: =(D2*4+E2*1+F2*-2)/D2 -> 4 | J2: Transporter / Proton Symport
A3: Glycerol | B3: Sugar | C3: C3H8O3 | D3: 3 | E3: 8 | F3: 3 | G3: 0 | H3: =D3*12.0107+E3*1.00784+F3*15.999 -> 92.09182 | I3: =(D3*4+E3*1+F3*-2)/D3 -> 4.6666667 | J3: Channel
A4: Xylose | B4: Sugar | C4: C5H10O5 | D4: 5 | E4: 10 | F4: 5 | G4: 0 | H4: =D4*12.0107+E4*1.00784+F4*15.999 -> 150.1269 | I4: =(D4*4+E4*1+F4*-2)/D4 -> 4 | J4: Transporter / Proton Symport
A5: Formate | B5: ECR-C1a | C5: CHO2 | D5: 1 | E5: 1 | F5: 2 | G5: -1 | H5: =D5*12.0107+E5*1.00784+F5*15.999 -> 45.01654 | I5: =(D5*4+E5*1+F5*-2)/D5 -> 1 | J5: Proton Symport
A6: Formic acid | B6: ECR-C1a | C6: CH2O2 | D6: 1 | E6: 2 | F6: 2 | G6: -1 | H6: =D6*12.0107+E6*1.00784+F6*15.999 -> 46.02438 | I6: =(D6*4+E6*1+F6*-2)/D6 -> 2
A7: Methanol | B7: ECR-C1a | C7: CH4O | D7: 1 | E7: 4 | F7: 1 | G7: 0 | H7: =D7*12.0107+E7*1.00784+F7*15.999 -> 32.04106 | I7: =(D7*4+E7*1+F7*-2)/D7 -> 6 | J7: Diffusion
A8: Acetaldehyde | B8: ECR-C2a | C8: C2H4O | D8: 2 | E8: 4 | F8: 1 | G8: 0 | H8: =D8*12.0107+E8*1.00784+F8*15.999 -> 44.05176 | I8: =(D8*4+E8*1+F8*-2)/D8 -> 5 | J8: Diffusion
A9: Acetate | B9: ECR-C2a | C9: C2H3O2 | D9: 2 | E9: 3 | F9: 2 | G9: -1 | H9: =D9*12.0107+E9*1.00784+F9*15.999 -> 59.04292 | I9: =(D9*4+E9*1+F9*-2)/D9 -> 3.5 | J9: Proton Symport
A10: Acetic acid | B10: ECR-C2a | C10: C2H4O2 | D10: 2 | E10: 4 | F10: 2 | G10: -1 | H10: =D10*12.0107+E10*1.00784+F10*15.999 -> 60.05076 | I10: =(D10*4+E10*1+F10*-2)/D10 -> 4
A11: Ethanol | B11: ECR-C2a | C11: C2H6O | D11: 2 | E11: 6 | F11: 1 | G11: 0 | H11: =D11*12.0107+E11*1.00784+F11*15.999 -> 46.06744 | I11: =(D11*4+E11*1+F11*-2)/D11 -> 6 | J11: Diffusion
A12: Ethylene Glycol | B12: ECR-C2a | C12: C2H6O2 | D12: 2 | E12: 6 | F12: 2 | G12: 0 | H12: =D12*12.0107+E12*1.00784+F12*15.999 -> 62.06644 | I12: =(D12*4+E12*1+F12*-2)/D12 -> 5 | J12: Difffusion
A13: Glycolaldehyde | B13: ECR-C2a | C13: C2H4O2 | D13: 2 | E13: 4 | F13: 2 | G13: 0 | H13: =D13*12.0107+E13*1.00784+F13*15.999 -> 60.05076 | I13: =(D13*4+E13*1+F13*-2)/D13 -> 4 | J13: Diffusion
A15: Carbon Monoxide | B15: ECR-C1b | C15: CO | D15: 1 | E15: 0 | F15: 1 | G15: 0 | H15: =D15*12.0107+E15*1.00784+F15*15.999 -> 28.0097 | I15: =(D15*4+E15*1+F15*-2)/D15 -> 2 | J15: Diffusion
A16: Formate | B16: ECR-C1b | C16: CHO2 | D16: 1 | E16: 1 | F16: 2 | G16: -1 | H16: =D16*12.0107+E16*1.00784+F16*15.999 -> 45.01654 | I16: =(D16*4+E16*1+F16*-2)/D16 -> 1 | J16: Proton Symport
A17: Hydrogen | B17: ECR-H2 | C17: H2 | D17: 0 | E17: 2 | F17: 0 | G17: 0 | H17: =D17*12.0107+E17*1.00784+F17*15.999 -> 2.01568 | J17: Diffusion
A18: CO_1:H2_0 | C18: CO | D18: 1 | E18: 0 | F18: 1 | G18: 0 | H18: =$H$15*1/1+$H$17*0/1 -> 28.0097 | I18: =(D18*4+E18*1+F18*-2)/D18 -> 2 | J18: Difffusion
A19: CO_1:H2_0.5 | C19: CO+0.5(H2) | D19: 1 | E19: 0 | F19: 1 | G19: 0 | H19: =$H$15*1/1.5+$H$17*0.5/1.5 -> 19.345027 | I19: =(D19*4+E19*1+F19*-2)/D19 -> 2 | J19: Diffusion
A20: CO_1:H2_1 | C20: CO+H2 | D20: 1 | E20: 0 | F20: 1 | G20: 0 | H20: =$H$15*1/2+$H$17*1/2 -> 15.01269 | I20: =(D20*4+E20*1+F20*-2)/D20 -> 2 | J20: Diffusion
A21: CO_1:H2_2 | C21: CO+2(H2) | D21: 1 | E21: 0 | F21: 1 | G21: 0 | H21: =$H$15*1/3+$H$17*3/2 -> 12.360087 | I21: =(D21*4+E21*1+F21*-2)/D21 -> 2 | J21: Diffusion
A22: FOR_1:H2_0 | C22: CHO2 | D22: 1 | E22: 1 | F22: 2 | G22: -1 | H22: =D22*12.0107+E22*1.00784+F22*15.999 -> 45.01654 | I22: =(D22*4+E22*1+F22*-2)/D22 -> 1 | J22: Proton Symport (FOR)/ Diffusion (H2)
A23: FOR_1:H2_0.5 | C23: CHO2+0.5(H2) | D23: 1 | E23: 1 | F23: 2 | G23: -1 | H23: =$H$22*1/1.5+$H$17*0.5/1.5 -> 30.68292 | I23: =(D23*4+E23*1+F23*-2)/D23 -> 1 | J23: Proton Symport (FOR)/ Diffusion (H2)
A24: FOR_1:H2_1 | C24: CHO2+H2 | D24: 1 | E24: 1 | F24: 2 | G24: -1 | H24: =$H$22*1/2+$H$17*1/2 -> 23.51611 | I24: =(D24*4+E24*1+F24*-2)/D24 -> 1 | J24: Proton Symport (FOR)/ Diffusion (H2)
A25: FOR_1:H2_2 | C25: CHO2+2(H2) | D25: 1 | E25: 1 | F25: 2 | G25: -1 | H25: =$H$22*1/3+$H$17*3/2 -> 18.029033 | I25: =(D25*4+E25*1+F25*-2)/D25 -> 1 | J25: Proton Symport (FOR)/ Diffusion (H2)
A26: CO2 | C26: CO2 | D26: 1 | E26: 0 | F26: 2 | I26: =(D26*4+E26*1+F26*-2)/D26 -> 0
A28: Acetyl | C28: C2H3O | D28: 2 | E28: 3 | F28: 1 | G28: 0 | H28: =D28*12.0107+E28*1.00784+F28*15.999 -> 43.04392

Sheet Pathways
A1: Substrate | B1: Pathway | C1: Entry to CCM | D1: Number of Steps to CCM | E1: Number of Steps to Acetyl-CoA | F1: Overall Reaction | G1: Gibbs
A2: Glucose | B2: Native | C2: G6P | D2: 1 | E2: =D2+9 -> 10
A3: Glycerol | B3: Native | C3: G3P | D3: 3 / 3 | E3: 9 / 9
A4: Xylose | B4: Native (PPP) | C4: F6p? (Xu5P)
A5: Formate | B5: Formolase | C5: G3P | D5: 6 | E5: =D5+6 -> 12
B6: Serine Cycle | C6: Pyruvate | D6: 6 | E6: =D6+1 -> 7
B7: Reductive Glycine Pathway (RGP) | C7: Pyruvate | D7: 12 | E7: 13
A8: Methanol | B8: Formolase | C8: G3P | D8: 8 | E8: =D8+1 -> 9
B9: Serine Cycle | C9: Pyruvate | D9: 14 | E9: =D9+1 -> 15
B10: Ribulose Monophosphate (RuMP) | C10: F6P
A11: Acetaldehyde | B11: Native | C11: Acetyl-CoA | D11: 1 | E11: 1
A12: Acetate | B12: Native | C12: Acetyl-CoA | D12: 1 / 2 | E12: 1 / 2
A13: Ethanol | B13: Native (via acetaldehyde) | C13: Acetyl-CoA | D13: 2 | E13: 2
A14: Ethylene Glycol | B14: SACA | C14: Acetyl-CoA | D14: 3 | E14: 3
B15: Glycolate | C15: 2PG | D15: 6 | E15: =D15+3 -> 9
A16: Glycolaldehyde | B16: SACA | C16: Acetyl-CoA | D16: 2 | E16: 2
B17: Glycolate | C17: 2PG | D17: 5 | E17: =D17+3 -> 8

Sheet ECR General
A1: ECR Thermodynamic Half Reaction Cell Potentials
A3: Constants
A4: ΔG°_f @ 298K
A5: CO2 | B5: -394359 | C5: J/mol
A6: H2O | B6: -237129 | C6: J/mol
A7: H+ | B7: 0 | C7: J/mol
A8: O2 | B8: 0 | C8: J/mol
A9: H2 | B9: 0
A10: Other Constants
A11: Faraday (F) | B11: 96485 | C11: C/mol
A13: Variables
A14: pH | B14: 7
H15: =-361.4*10^3 -> -361400
P16: See: Nitopi (2019), Fan (2020), Garg (2020), Jouny (2018), Kuhl (2012), Lu (2016), Malkhandi (2019) [pH7], Verma (2016)
A17: Compound Data | J17: Reaction Data
A18: Substrate | B18: Formula | C18: Alt Formula | D18: C | E18: H | F18: O | H18: ΔG°_f (J/mol) | I18: State (for ΔG_f) | J18: Reaction | K18: ΔG°_rxn (J/mol) | L18: ΔG°_cell (J/mol) | M18: n_elec | N18: E° (V vs RHE) | O18: E° (V vs SHE) | P18: E° (V vs RHE) REPORTED | Q18: E°_cell (V vs SHE) | R18: E°_cell (V vs RHE)
A19: Oxygen | B19: O2 | C19: - | D19: 0 | E19: 0 | F19: 2 | G19: =B8 -> 0 | H19: =B8 -> 0 | I19: Gas | J19: 2H2O → O2 + 4H+ + 4e- | K19: =H19-dG_H2O*2 -> 474258 | L19: - | M19: =-4 -> -4 | N19: =-K19/(M19*F) -> 1.2288387 | O19: =N19-0.0591*pH -> 0.81513868 | P19: 1.23
A20: Hydrogen | B20: H2 | C20: - | D20: 0 | E20: 2 | F20: 0 | G20: =B7 -> 0 | H20: =B7 -> 0 | I20: Gas | J20: 2H+ + 2e- → H2 | K20: =H20*2-B9 -> 0 | L20: =K20-$K$19 -> -474258 | M20: 2 | N20: =-K20/(M20*F) -> 0 | O20: =N20-0.0591*pH -> -0.4137 | P20: 0 | Q20: =$N$19-N20 -> 1.2288387 | R20: =$O$19-O20 -> 1.2288387
A21: Carbon Monoxide | B21: CO | C21: - | D21: 1 | E21: 0 | F21: 1 | G21: -137168 | H21: -137168 | I21: Gas | J21: CO2 + 2H+ + 2e- → CO + H2O | K21: =SUM(H21+dG_H2O)-SUM(dG_CO2) -> 20062 | L21: =K21-$K$19 -> -454196 | M21: 2 | N21: =-K21/(M21*F) -> -0.10396435 | O21: =N21-0.0591*pH -> -0.51766435 | P21: -0.1 | Q21: =$N$19-N21 -> 1.332803 | R21: =$O$19-O21 -> 1.332803
A22: Formate | B22: C2HO2 | C22: CHOOH | D22: 2 | E22: 1 | F22: 2 | G22: =-361.4*10^3 -> -361400 | H22: =-346*10^3 -> -346000 | I22: Liquid | J22: CO2 + 2H+ + 2e − → HCOOH(aq) | K22: =H22-(dG_CO2) -> 48359 | L22: =K22-$K$19 -> -425899 | M22: 2 | N22: =-K22/(M22*F) -> -0.25060372 | O22: =N22-0.0591*pH -> -0.66430372 | P22: -0.12 | Q22: =$N$19-N22 -> 1.4794424 | R22: =$O$19-O22 -> 1.4794424
A23: Methanol | B23: CH4O | C23: CH3OH | D23: 1 | E23: 4 | F23: 1 | G23: -166270 | H23: -166270 | I23: Liquid | J23: CO2 + 6H+ + 6e − → CH3OH(aq) + H2O | K23: =(H23+ dG_H2O*1)-(dG_CO2*1) -> -9040 | L23: =K23-$K$19 -> -483298 | M23: 6 | N23: =-K23/(M23*F) -> 0.015615553 | O23: =N23-0.0591*pH -> -0.39808445 | P23: 0.03 | Q23: =$N$19-N23 -> 1.2132231 | R23: =$O$19-O23 -> 1.2132231
A24: Acetaldehyde | B24: C2H4O | C24: CH3CHO | D24: 2 | E24: 4 | F24: 1 | G24: -128860 | H24: -128860 | I24: Liquid | J24: 2CO2 + 10H+ + 10e− → CH3CHO(aq) + 3H2O | K24: =(H24+ dG_H2O*3)-(dG_CO2*2) -> -51529 | L24: =K24-$K$19 -> -525787 | M24: 10 | N24: =-K24/(M24*F) -> 0.053406229 | O24: =N24-0.0591*pH -> -0.36029377 | P24: 0.06 | Q24: =$N$19-N24 -> 1.1754325 | R24: =$O$19-O24 -> 1.1754325
A25: Acetic acid | B25: C2H3O2 | C25: CH3COOH | D25: 2 | E25: 3 | F25: 2 | G25: -389900 | H25: -389900 | I25: Liquid | J25: 2CO2 + 8H+ + 8e− → CH3COOH(aq) + 2H2O | K25: =(H25+dG_H2O*2)-(dG_CO2*2) -> -75440 | L25: =K25-$K$19 -> -549698 | M25: 8 | N25: =-K25/(M25*F) -> 0.097735399 | O25: =N25-0.0591*pH -> -0.3159646 | P25: 0.11 | Q25: =$N$19-N25 -> 1.1311033 | R25: =$O$19-O25 -> 1.1311033
A26: Ethanol | B26: C2H6O | C26: C2H5OH | D26: 2 | E26: 6 | F26: 1 | G26: -174780 | H26: -174780 | I26: Liquid | J26: 2CO2 + 12H+ + 12e− → C2H5OH(aq) + 3H2O | K26: =(H26+ dG_H2O*3)-(dG_CO2*2) -> -97449 | L26: =K26-$K$19 -> -571707 | M26: 12 | N26: =-K26/(M26*F) -> 0.084165933 | O26: =N26-0.0591*pH -> -0.32953407 | P26: 0.09 | Q26: =$N$19-N26 -> 1.1446727 | R26: =$O$19-O26 -> 1.1446727
A27: Ethylene Glycol | B27: C2H6O2 | C27: (CH2OH)2 | D27: 2 | E27: 6 | F27: 2 | J27: 2CO2 + 10H+ + 10e− → (CH2OH)2(aq) + 2H2O | K27: =(H27+ dG_H2O*2)-(dG_CO2*2) -> 314460 | L27: =K27-$K$19 -> -159798 | M27: 10 | N27: =-K27/(M27*F) -> -0.32591595 | O27: =N27-0.0591*pH -> -0.73961595 | Q27: =$N$19-N27 -> 1.5547546 | R27: =$O$19-O27 -> 1.5547546
A28: Glycolaldehyde | B28: C2H4O2 | C28: HOCH2*CHO | D28: 2 | E28: 4 | F28: 2 | J28: 2CO2 + 8H+ + 8e− → C2H4O2(aq) + 2H2O | K28: =(H28+ dG_H2O*2)-(dG_CO2*2) -> 314460 | L28: =K28-$K$19 -> -159798 | M28: 8 | N28: =-K28/(M28*F) -> -0.40739493 | O28: =N28-0.0591*pH -> -0.82109493 | Q28: =$N$19-N28 -> 1.6362336 | R28: =$O$19-O28 -> 1.6362336

Sheet THESIS-Std Cell Pot
A8: Substrate | B8: Formula | C8: C | D8: H | E8: O | F8: ΔG°f (kJ/mol)1 | G8: State | H8: Source | K8: Reaction Name | L8: Stoichiometry | M8: ΔG°rxn (kJ/mol) | N8: ΔG°cell (kJ/mol) | O8: Ne (#e-/mol P) | P8: E° (V vs RHE) | Q8: E° (V vs SHE)1 | R8: E° (V vs RHE) REPORTED | S8: E°cell (V)
A9: Oxygen | B9: O2 | C9: 0 | D9: 0 | E9: 2 | F9: 0 | G9: Gas | H9: Bard (1985) | K9: Anode
A10: Hydrogen | B10: H2 | C10: 0 | D10: 2 | E10: 0 | F10: 0 | G10: Gas | H10: Bard (1985) | K10: Water oxidation | L10: 2H2O(l) → O2(g) + 4H+(aq) + 4e- | M10: =(F9+4*F11)-F14*2 -> 474.356 | O10: =-4 -> -4 | P10: =-M10/(O10*F)*10^3 -> 1.2290926 | Q10: =P10-0.0591*pH -> 0.81539261 | R10: 1.23
A11: Hydrogen ion | B11: H+ | C11: 0 | D11: 1 | E11: 0 | F11: 0 | G11: Aqueous | H11: Bard (1985) | K11: Cathode
A12: Hydroxide ion | B12: OH- | C12: 0 | D12: 1 | E12: 1 | F12: -157.293 | G12: Aqueous | H12: Bard (1985) | K12: Hydrogen Evolution | L12: 2H+(aq) + 2e- → H2(g) | M12: =F10-2*F11 -> 0 | N12: =M12-$M$10 -> -474.356 | O12: 2 | P12: =-M12/(O12*F)*10^3 -> 0 | Q12: =P12-0.0591*pH -> -0.4137 | R12: 0 | S12: =P12-$P$10 -> -1.2290926
A13: Carbon Dioxide | B13: CO2 | C13: 1 | D13: 0 | E13: 2 | F13: -394.383 | G13: Gas | H13: Bard (1985) | K13: Carbon Monoxide | L13: CO2(g) + 2H+(aq) + 2e- → CO(g) + H2O(l) | M13: =SUM(F15,F14)-SUM(2*F11,F13) -> 19.937 | N13: =M13-$M$10 -> -454.419 | O13: 2 | P13: =-M13/(O13*F)*10^3 -> -0.10331658 | Q13: =P13-0.0591*pH -> -0.51701658 | R13: -0.1 | S13: =P13-$P$10 -> -1.3324092
A14: Water | B14: H2O | C14: 0 | D14: 2 | E14: 1 | F14: -237.178 | G14: Liquid | H14: Bard (1985) | K14: Formic Acid | L14: CO2(g) + 2H+(aq) + 2e- − → HCOOH(aq) | M14: =SUM(F16)-SUM(2*F11,F13) -> 38.383 | N14: =M14-$M$10 -> -435.973 | O14: 2 | P14: =-M14/(O14*F)*10^3 -> -0.19890657 | Q14: =P14-0.0591*pH -> -0.61260657 | R14: -0.12 | S14: =P14-$P$10 -> -1.4279992
A15: Carbon Monoxide | B15: CO | C15: 1 | D15: 0 | E15: 1 | F15: -137.268 | G15: Gas | H15: Bard (1985) | K15: Methanol | L15: CO2(g) + 6H+(aq) + 6e − → CH3OH(aq) + H2O(l) | M15: =(F19+F14)-(F13+6*F11) -> -17.295 | N15: =M15-$M$10 -> -491.651 | O15: 6 | P15: =-M15/(O15*F)*10^3 -> 0.02987511 | Q15: =P15-0.0591*pH -> -0.38382489 | R15: 0.03 | S15: =P15-$P$10 -> -1.1992175
A16: Formic acid | B16: CHOOH | C16: 2 | D16: 2 | E16: 2 | F16: -356 | G16: Aqueous | H16: Bard (1985) | K16: Acetaldehyde | L16: 2CO2(g) + 10H+(aq) + 10e− → CH3CHO(g) + 3H2O(l) | M16: =(F21+3*F14)-(2*F13+10*F11) -> -51.628 | N16: =M16-$M$10 -> -525.984 | O16: 10 | P16: =-M16/(O16*F)*10^3 -> 0.053508836 | Q16: =P16-0.0591*pH -> -0.36019116 | R16: 0.06 | S16: =P16-$P$10 -> -1.1755838
A17: Formic acid | B17: CHOOH | C17: 2 | D17: 2 | E17: 2 | F17: -346 | G17: Liquid | H17: Bard (1985) | K17: Acetic Acid | L17: 2CO2(g) + 8H+(aq) + 8e− → CH3COOH(aq) + 2H2O(l) | M17: =(F22+2*F14)-(2*F13+8*F11) -> -85.19 | N17: =M17-$M$10 -> -559.546 | O17: 8 | P17: =-M17/(O17*F)*10^3 -> 0.1103669 | Q17: =P17-0.0591*pH -> -0.3033331 | R17: 0.11 | S17: =P17-$P$10 -> -1.1187257
A18: Formate | B18: CHOO- | C18: 2 | D18: 1 | E18: 2 | F18: -351 | G18: Aqueous | H18: Bard (1985) | K18: Ethanol | L18: 2CO2(g) + 12H+(aq) + 12e− → C2H5OH(aq) + 3H2O(l) | M18: =(F25+3*F14)-(2*F13+12*F11) -> -99.768 | N18: =M18-$M$10 -> -574.124 | O18: 12 | P18: =-M18/(O18*F)*10^3 -> 0.086168835 | Q18: =P18-0.0591*pH -> -0.32753117 | R18: 0.09 | S18: =P18-$P$10 -> -1.1429238
A19: Methanol | B19: CH3OH | C19: 1 | D19: 4 | E19: 1 | F19: -174.5 | G19: Aqueous | H19: Bard (1985) | K19: Ethylene Glycol | L19: 2CO2(g) + 10H+(aq) + 10e− → (CH2OH)2(aq) + 2H2O(l) | M19: NA | N19: NA | O19: 10 | P19: NA | Q19: NA | R19: NA
A20: Methanol | B20: CH3OH | C20: 1 | D20: 4 | E20: 1 | F20: -166.3 | G20: Liquid | H20: Bard (1985) | K20: Glycolaldehyde | L20: 2CO2(g) + 8H+(aq) + 8e− → C2H4O2(aq) + 2H2O(l) | M20: NA | N20: NA | O20: 8 | P20: NA | Q20: NA | R20: NA
A21: Acetaldehyde | B21: CH3CHO | C21: 2 | D21: 4 | E21: 1 | F21: -128.86 | G21: Gas | H21: Introduction to Chemical Engineering Thermodynamics 7th Edition; Table C.4 | K21: 1 At pH 7, calculated using the Nerst equation.
A22: Acetic acid | B22: CH3COOH | C22: 2 | D22: 3 | E22: 2 | F22: -399.6 | G22: Aqueous | H22: Bard (1985)
A23: Acetic acid | B23: CH3COOH | C23: 2 | D23: 3 | E23: 2 | F23: -392 | G23: Liquid | H23: Bard (1985)
A24: Acetate | B24: CH3COO- | C24: 2 | D24: 2 | E24: 2 | F24: -369.4 | G24: Aqueous | H24: Bard (1985)
A25: Ethanol | B25: C2H5OH | C25: 2 | D25: 6 | E25: 1 | F25: -177 | G25: Aqueous | H25: Bard (1985)
A26: Ethanol | B26: C2H5OH | C26: 2 | D26: 6 | E26: 1 | F26: -174.8 | G26: Liquid | H26: Bard (1985)
A27: Ethylene Glycol2 | B27: (CH2OH)2 | C27: 2 | D27: 6 | E27: 2 | F27: NA | G27: NA | H27: NA
A28: Glycolaldehyde2 | B28: HOCH2*CHO | C28: 2 | D28: 4 | E28: 2 | F28: NA | G28: NA | H28: NA
A29: 1 I think the values are at 298.15K and 1.01325 bar, but it doesn’t explicitly say... Found in Table 1 of Chapter 8 (p. 190).
A30: 2 Values could not be found
A38: See: Nitopi (2019), Fan (2020), Garg (2020), Jouny (2018), Kuhl (2012), Lu (2016), Malkhandi (2019) [pH7], Verma (2016)

Sheet ECR - V, CD, FE Data
A1: ECR - Data from Literature
A3: Catalyst | B3: Electrolyte | C3: Product | D3: Voltage (V) | E3: V type | F3: Cell Voltage (V) | G3: CD (mA/cm^2) | H3: FE (%) | I3: EE (%) | J3: Source | K3: Notes
A4: Ag | B4: 0.1 M K2SO4 : 1.5 M KHCO3 | C4: CO | D4: 4.7 | E4: Cell | F4: =D4 -> 4.7 | G4: 300 | H4: 78 | I4: 25 | J4: DeLuna (2019), Haas (2018) | K4: Cell voltage. In Fig 3b, Haas (2018) show the system’s stability over time. Overall, the FE of CO and H2 add up to near-100% over the duration. Early on (ie. like maybe 20min in), the CO FE drops to 60-70% while the H2 FE increases accordingly. The FE measurements remain pretty consistent for the duration of the experiment (>1000h).
A5: Ag | B5: 0.5 M K2SO4 : 1 M KHCO3 | C5: CO | D5: 4 | E5: Cell | F5: =D5 -> 4 | G5: 275 | H5: 87 | J5: Dufek (2012), DeLuna (2019)* | K5: Cell voltage. Values were reported in DeLuna (2019) as well, (reported as source 109) BUT values are wrong... They seemed to have mixed up values from different temps and pressures (& not even sure where they got the 197 CD from?). Values reported here are for 60degC, 24.6 atm and 275 mA/cm^2. See Figure 3 and text underneath (right side of page).
A6: Ag-coated AEM electrodes | B6: 0.2 M K2SO4 | C6: CO | D6: -2.96 | E6: V vs. SHE | G6: 100 | H6: 52.7 | J6: Hori (2003) | K6: FE: 52.7 CO, 8.0 Formate & 35.9 H2 (totaling 96.6%) --> example of how CO2 ECR to CO can be a mix of CO, formate and H2!
A7: Ag/MWCNT (GDE) | B7: 1 M KOH | C7: CO | D7: -0.8 | E7: V vs RHE | F7: 3 | G7: 350 | H7: 100 | I7: 45.4 | J7: Ma (2016), DeLuna (2019), Hernandez (2017) | K7: Report V vs RHE and cell voltage. See Figure 4a/b ES3 (mixed, 1:4) --> at CD of 350, the FE is reported as just over 100% (but using 100% since >100 doesn’t make sense...), and the Cathode Potential (V vs RHE) is -0.8. In the abstract (& in text; see Fig 6 + text), they report an energy efficiency of 45% for the ES3 electrode with Ag/MWCNT ratio of 1:4.
A8: Sn | B8: 0.5 M KCl | C8: Formate | D8: 4 | E8: Cell | F8: =D8 -> 4 | G8: 163 | H8: 84 | I8: 32 | J8: DeLuna (2019), Whipple (2010) | K8: Cell voltage
A9: Pb | B9: 0.5 M H2SO4 | C9: Formate | D9: 2.8 | E9: Cell | F9: =D9 -> 2.8 | G9: 50 | H9: 95 | I9: 49 | J9: DeLuna (2019), Lu (2017) | K9: Cell voltage
A10: Sn | B10: 0.5 M KHCO3 + 2 M KCl | C10: Formate | D10: 4.1 | E10: Cell | F10: =D10 -> 4.1 | G10: 133 | H10: 86 | I10: 33 | J10: Li (2006), DeLuna (2019)* | K10: Cell voltage. Values were reported in DeLuna (2019) as well, BUT values they report seem to be wrong... See Li (2006) abstract and their conclusions...
A11: CC/InP CQDs) (20ug/cm^2 CQDs) | B11: 3 M KOH | C11: Formate | D11: -2.6 | E11: V vs RHE | F11: =1.23-D11 -> 3.83 | G11: 1000 | H11: 93.1 | J11: Grigioni (2021)
A12: Cu2O | B12: KHCO3 | C12: Methanol | D12: -2 | E12: V vs SHE | G12: 7.8 | H12: 47.5 | J12: Hazarika (2019) | K12: V versus SHE. Paper doesn’t mention electrolyte concentration. Note that the cathodic surface wasn’t super stable though (changes in surface resulted in slow decrease of CD over time... But used optimal values here.)
A13: Cu1.63Se(1/3) | B13: 0.5M H2SO 4 aqueous solution and [Bmim]PF6-CH3CN-H2O | C13: Methanol | D13: 2.67 | E13: Cell | F13: =D13 -> 2.67 | G13: 41.5 | H13: 77.6 | I13: 61.7 | J13: Yang (2019) | K13: *Cell voltage calculated using reported method (from -2.1V vs Ag/Ag+ as reported operating voltage).
A14: NDD/Si RA | B14: 0.5 M NaHCO3 | C14: Acetate | D14: =-1 -> -1 | E14: V vs RHE | F14: =1.23-D14 -> 2.23 | G14: -2 | H14: 77.6 | J14: Liu (2015) | K14: V vs RHE determined from Figure 6/text for NDD_L; ~-1V provided the greatest FE, so used this value. CD estimated from figure 2 for NDD_L .EE not reported.
A15: Keggin- type POM [SiW9V3O40]7 (SiW9V3) and metal indium | B15: 0.1M Na2SO4 | C15: Acetate | D15: -0.71 | E15: V vs RHE | F15: =1.23-D15 -> 1.94 | G15: -1.2 | H15: 96.5 | J15: Zha (2019) | K15: CD estimated from figures 3a and 6. V vs RHE.
A16: Cu4Zn | B16: 0.1 M KHCO3 | C16: Ethanol | D16: -1.05 | E16: V vs RHE | F16: =1.23-D16 -> 2.28 | G16: -8.2 | H16: 29.1 | J16: Ren (2016) | K16: Reported in abstract. Potential (V) vs RHE
A17: Ce(OH)x/CU/PTFE | B17: 1M KOH | C17: Ethanol | D17: -0.7 | E17: V vs RHE | F17: =1.23-D17 -> 1.93 | G17: 128 | H17: 43 | I17: 25 | J17: Luo (2019) | K17: Partial current density for ethanol, V versus RHE. Probably one of highest values reported to date
A18: Ag-G-NCF | B18: 0.1M KHCO3 | C18: Ethanol | D18: -0.5 | E18: V vs RHE | F18: =1.23-D18 -> 1.73 | G18: -0.35 | H18: 79.1 | J18: Lv (2018) | K18: CD estimated from Figure 3C. V vs RHE. Highest reported FE was ~85%, but CD was very low (looked like <-0.2), so selected to use slightly lower FE for higher CD.
A19: SAM on Au | B19: 0.5 NaHCO3 | C19: Ethylene glycol | D19: -0.58 | E19: V vs RHE | F19: =1.23-D19 -> 1.81 | G19: -0.3 | H19: 87 | J19: Tamura (2015), Na (2019) | K19: *Seems to be one of only papers that look specifically at EG production, and highest reported FE for EG. CD estimated from graph, V vs E (RHE); all potential values measured against Ag/AgCl ref electrode but then converted to RHE (therefore assuming values they report are for RHE). Note that EG as a product is typical at very low FE and CD.
A20: CuAg-NF | B20: 0.1 M KOH | C20: Acetaldehyde | D20: -0.33 | E20: V vs RHE | F20: =1.23-D20 -> 1.56 | G20: 0.95 | H20: 70 | J20: Wang (2020) | K20: *This is for CO reduction, not CO2. Not sure if I can use these values... -0.33 V vs RHE
C21: Glycolaldehyde, Acetaldehyde, Methanol, EG,Acetate | J21: Kuhl (2012), Na (2019) | K21: All reported as very minor products by Kuhl (2012) --> very low FE reported for these products (like <1%). Most (excluding methanol) reported as very minor products by Na (2019) as well (Lowest FE; <1%, lowest current density; <0.5)
C22: Nature; pair up 18 reduction reactions with 16 oxidation reactions --> pick best pair (2020)
A48: SOURCES
A49: DeLuna (2019) | B49: https://science.sciencemag.org/content/364/6438/eaav3506 | C49: What would it take for renewably powered electrosynthesis to displace petrochemical processes?
A50: Dufek (2012) | B50: https://iopscience.iop.org/article/10.1149/2.011209jes/pdf | C50: Operation of a Pressurized System for Continuous Reduction of CO2
A51: Haas (2018) | B51: https://www.nature.com/articles/s41929-017-0005-1 | C51: Technical photosynthesis involving CO2 electrolysis and fermentation
A52: Hori (2003) | B52: https://www.sciencedirect.com/science/article/pii/S0013468603003116 | C52: Silver-coated ion exchange membrane electrode applied to electrochemical reduction of carbon dioxide
A53: Hernandez (2017) | B53: https://pubs-rsc-org.myaccess.library.utoronto.ca/en/content/articlelanding/2017/GC/C7GC00398F#!divAbstract | C53: Syngas production from electrochemical reduction of CO2: current status and prospective implementation
A54: Ma (2016) | B54: https://pubs.rsc.org/en/content/articlelanding/2016/ta/c6ta00427j#!divAbstract | C54: Carbon nanotube containing Ag catalyst layers for efficient and selective reduction of carbon dioxide
A55: Whipple (2010) | B55: https://iopscience.iop.org/article/10.1149/1.3456590 | C55: Microfluidic Reactor for the Electrochemical Reduction of Carbon Dioxide: The Effect of pH ()
A56: Lu (2017) | B56: https://www.sciencedirect.com/science/article/abs/pii/S0306261916306882?via%3Dihub | C56: A high performance dual electrolyte microfluidic reactor for the utilization of CO 2 .
A57: Li (2006) | B57: https://link.springer.com/article/10.1007%2Fs10800-006-9194-z | C57: Development of a continuous reactor for the electro-reduction of carbon dioxideto formate – Part 1: Process variables.
A58: Grigioni (2021) | B58: https://pubs.acs.org/doi/10.1021/acsenergylett.0c02165?goto=supporting-info&ref=pdf | C58: CO2 electroreduction to formate at a partial current Density of 930 mA cm-2 with InP colloidal quantum dot derived catalysts
A59: Liu (2015) | B59: https://pubs.acs.org/doi/10.1021/jacs.5b02975 | C59: Efficient Electrochemical Reduction of Carbon Dioxide to Acetate on Nitrogen-Doped Nanodiamond
A60: Ren (2016) | B60: https://pubs.acs.org/doi/10.1021/acscatal.6b02162 | C60: Tuning the Selectivity of Carbon Dioxide Electroreduction toward Ethanol on Oxide-Derived CuxZn Catalysts
A61: Luo (2019) | B61: https://www.nature.com/articles/s41467-019-13833-8
A62: Hazarika (2019) | B62: https://www.sciencedirect.com/science/article/pii/S0013468619319243 | C62: Electrochemical reduction of CO2 to methanol with synthesized Cu2O nanocatalyst: Study of the selectivity
A63: Yang (2019) | B63: https://www.nature.com/articles/s41467-019-08653-9 | C63: Selective electroreduction of carbon dioxide to methanol on copper selenide nanocatalysts
A64: Wang (2020) | B64: https://www.pnas.org/content/117/23/12572 | C64: Selective reduction of CO to acetaldehyde with CuAg electrocatalysts
A65: Nitopi (2019) * | B65: https://pubs.acs.org/doi/10.1021/acs.chemrev.8b00705 | C65: Progress and Perspectives of Electrochemical CO2 Reduction on Copper in Aqueous Electrolyte
A66: Tamura (2015) | B66: https://pubs.rsc.org/en/content/articlelanding/2015/cp/c5cp03028e#!divAbstract | C66: Electrochemical reduction of CO2 to ethylene glycol on imidazolium ion-terminated self-assembly monolayer-modified Au electrodes in an aqueous solution
...

Sheet THESIS-Parameters
A3: Independent Parameters | H3: Product | I3: Cell Voltage | J3: Current Density | K3: Faradaic Efficiency | L3: By-Products | M3: By-Product Faradaic Efficiency | N3: Reference
A4: Parameter | B4: Units | C4: Case | H4: Ideal Parameters
C5: Worst | D5: Base | E5: Best | H5: All | I5: 3 | J5: 200 | K5: 80 | L5: Formic acid and/or CO | M5: 20
A6: Electricity Price | B6: cents CA/kWh | C6: 8 | D6: 5 | E6: 2.5 | H6: Realistic Parameters
A7: CO2 Price | B7: $ CA/tonne | H7: Acetic acid | I7: ='ECR - V, CD, FE Data'!F15 -> 1.94 | J7: =ABS('ECR - V, CD, FE Data'!G15) -> 1.2 | K7: ='ECR - V, CD, FE Data'!H15 -> 96.5 | L7: Formic acid | M7: =100-K7 -> 3.5 | N7: ='ECR - V, CD, FE Data'!J15 -> Zha (2019)
A8: Carbon Tax | B8: $ CA/tonne CO2 eq | C8: 170 | H8: Carbon monoxide | I8: ='ECR - V, CD, FE Data'!F7 -> 3 | J8: ='ECR - V, CD, FE Data'!G7 -> 350 | K8: ='ECR - V, CD, FE Data'!H7 -> 100 | L8: None | M8: - | N8: ='ECR - V, CD, FE Data'!J7 -> Ma (2016), DeLuna (2019), Hernandez (2017)
A9: Dependent Parameters | H9: Ethanol | I9: ='ECR - V, CD, FE Data'!F17 -> 1.93 | J9: ='ECR - V, CD, FE Data'!G17 -> 128 | K9: ='ECR - V, CD, FE Data'!H17 -> 43 | L9: Ethylene, Hydrogen, Acetic acid, Methane | M9: 34, 16, 4, 3 | N9: ='ECR - V, CD, FE Data'!J17 -> Luo (2019)
A10: CO2 Conversion | B10: % | C10: 50 | H10: Ethylene glycol | I10: ='ECR - V, CD, FE Data'!F19 -> 1.81 | J10: =ABS('ECR - V, CD, FE Data'!G19) -> 0.3 | K10: ='ECR - V, CD, FE Data'!H19 -> 87 | L10: Hydrogen | M10: =100-K10 -> 13 | N10: ='ECR - V, CD, FE Data'!J19 -> Tamura (2015), Na (2019)
A11: Bioconversion | B11: % | C11: 80 | H11: Formic acid | I11: ='ECR - V, CD, FE Data'!F10 -> 4.1 | J11: ='ECR - V, CD, FE Data'!G10 -> 133 | K11: ='ECR - V, CD, FE Data'!H10 -> 86 | L11: Carbon monoxide | M11: =100-K11 -> 14 | N11: ='ECR - V, CD, FE Data'!J10 -> Li (2006), DeLuna (2019)*
H12: Methanol | I12: ='ECR - V, CD, FE Data'!F13 -> 2.67 | J12: ='ECR - V, CD, FE Data'!G13 -> 41.5 | K12: ='ECR - V, CD, FE Data'!H13 -> 77.6 | L12: Formic acid, Carbon monoxide | M12: 20, 2.4 | N12: ='ECR - V, CD, FE Data'!J13 -> Yang (2019)
H14: For values in yellow: Authors did not report measured cell voltages, only the cathode voltage. In these cases, the cell voltages were calculated from the reported cathode potential (V vs RHE) assuming the anode potential is the standard water oxidation potential (1.23 V). Therefore, these values are likely below the true cell voltage for the system (ie. ohmic drop is not considered).

Sheet THESIS-Lit Review
A4: Product | B4: Catalyst | C4: Electrolyte | D4: Voltage (V) | E4: V type | F4: Cell Voltage (V) | G4: CD (mA/cm^2) | H4: FE (%) | I4: EE (%) | J4: Source
A5: Acetaldehyde | D5: -0.33 | E5: V vs RHE | F5: =1.23-D5 -> 1.56 | G5: 0.95 | H5: 70 | J5: Wang (2020)
A6: Acetate | B6: NDD/Si RA | C6: 0.5 M NaHCO3 | D6: =-1 -> -1 | E6: V vs RHE | F6: =1.23-D6 -> 2.23 | G6: -2 | H6: 77.6 | J6: Liu (2015)
A7: Acetate | B7: Keggin- type POM [SiW9V3O40]7 (SiW9V3) and metal indium | C7: 0.1M Na2SO4 | D7: -0.71 | E7: V vs RHE | F7: =1.23-D7 -> 1.94 | G7: -1.2 | H7: 96.5 | J7: Zha (2019)
A8: CO | B8: Ag | C8: 0.1 M K2SO4 : 1.5 M KHCO3 | D8: 4.7 | E8: Cell | F8: =D8 -> 4.7 | G8: 300 | H8: 78 | I8: 25 | J8: DeLuna (2019), Haas (2018)
A9: CO | B9: Ag | C9: 0.5 M K2SO4 : 1 M KHCO3 | D9: 4 | E9: Cell | F9: =D9 -> 4 | G9: 275 | H9: 87 | J9: Dufek (2012), DeLuna (2019)*
A10: CO | B10: Ag-coated AEM electrodes | C10: 0.2 M K2SO4 | D10: -2.96 | E10: V vs. SHE | F10: - | G10: 100 | H10: 52.7 | J10: Hori (2003)
A11: CO | B11: Ag/MWCNT (GDE) | C11: 1 M KOH | D11: -0.8 | E11: V vs RHE | F11: 3 | G11: 350 | H11: 100 | I11: 45.4 | J11: Ma (2016), DeLuna (2019), Hernandez (2017)
A12: Ethanol | B12: Cu4Zn | C12: 0.1 M KHCO3 | D12: -1.05 | E12: V vs RHE | F12: =1.23-D12 -> 2.28 | G12: -8.2 | H12: 29.1 | J12: Ren (2016)
A13: Ethanol | B13: Ce(OH)x/CU/PTFE | C13: 1M KOH | D13: -0.7 | E13: V vs RHE | F13: =1.23-D13 -> 1.93 | G13: 128 | H13: 43 | I13: 25 | J13: Luo (2019)
A14: Ethanol | B14: Ag-G-NCF | C14: 0.1M KHCO3 | D14: -0.5 | E14: V vs RHE | F14: =1.23-D14 -> 1.73 | G14: -0.35 | H14: 79.1 | J14: Lv (2018)
A15: Ethylene glycol | B15: SAM on Au | C15: 0.5 NaHCO3 | D15: -0.58 | E15: V vs RHE | F15: =1.23-D15 -> 1.81 | G15: -0.3 | H15: 87 | J15: Tamura (2015), Na (2019)
A16: Formate | B16: Sn | C16: 0.5 M KCl | D16: 4 | E16: Cell | F16: =D16 -> 4 | G16: 163 | H16: 84 | I16: 32 | J16: DeLuna (2019), Whipple (2010)
A17: Formate | B17: Pb | C17: 0.5 M H2SO4 | D17: 2.8 | E17: Cell | F17: =D17 -> 2.8 | G17: 50 | H17: 95 | I17: 49 | J17: DeLuna (2019), Lu (2017)
A18: Formate | B18: Sn | C18: 0.5 M KHCO3 + 2 M KCl | D18: 4.1 | E18: Cell | F18: =D18 -> 4.1 | G18: 133 | H18: 86 | I18: 33 | J18: Li (2006), DeLuna (2019)*
A19: Formate | B19: CC/InP CQDs) (20ug/cm^2 CQDs) | C19: 3 M KOH | D19: -2.6 | E19: V vs RHE | F19: =1.23-D19 -> 3.83 | G19: 1000 | H19: 93.1 | J19: Grigioni (2021)
A20: Methanol | B20: Cu2O | C20: KHCO3 | D20: -2 | E20: V vs SHE | F20: - | G20: 7.8 | H20: 47.5 | J20: Hazarika (2019)
A21: Methanol | B21: Cu1.63Se(1/3) | C21: 0.5M H2SO 4 aqueous solution and [Bmim]PF6-CH3CN-H2O | D21: 2.67 | E21: Cell | F21: =D21 -> 2.67 | G21: 41.5 | H21: 77.6 | I21: 61.7 | J21: Yang (2019)
A23: For values in yellow: Authors did not report measured cell voltages, only the cathode voltage. In these cases, the cell voltages were calculated from the reported cathode potential (V vs RHE) assuming the anode potential is the standard water oxidation potential (1.23 V). Therefore, these values are likely below the true cell voltage for the system (ie. ohmic drop is not considered).

Sheet C1 Comparison
A1: Pathway | B1: Substrate | C1: Mols Sub | D1: Acetyl-CoA | E1: Max Mass Yield | F1: Predicted Mass Yield | G1: %Theoretical MY | H1: Mol C/mol P used for Energetic requirements | I1: NADH | J1: NADPH | K1: FerredoxinR | L1: ATP | M1: H+ | N1: CO2 | O1: Overall RXN (FBA)
A2: Formolase | B2: Formate | C2: 3 | D2: 1 | E2: =D2/C2*Substrates!H28/Substrates!H16 -> 0.3187267 | F2: 0.13 | G2: =F2/E2 -> 0.40787295 | H2: =10/1.4-C2 -> 4.1428571 | I2: =sFormate_pwFormolase!G19 -> -1 | J2: =sFormate_pwFormolase!H19 -> 0 | L2: =sFormate_pwFormolase!J19 -> -2 | M2: =sFormate_pwFormolase!L19 -> 4 | N2: =sFormate_pwFormolase!M19 -> 1 | O2: 10Formate + 10H+_e + 2.3O2 ---> 1.4 AcCoA + 8.6H2O + 7.3CO2
A3: Serine Cycle | B3: Formate | C3: 1 | D3: 1 | E3: =D3/C3*Substrates!H28/Substrates!H16 -> 0.95618011 | F3: 0.04 | G3: =F3/E3 -> 0.041833123 | H3: =10/0.5-C3 -> 19 | I3: =sFormate_pwSerineCycle!G18 -> -2 | J3: =sFormate_pwSerineCycle!H18 -> -1 | L3: =sFormate_pwSerineCycle!J18 -> -3 | M3: =sFormate_pwSerineCycle!L18 -> 1 | N3: =sFormate_pwSerineCycle!M18 -> -1 | O3: 10Formate + 10H+_e + 4.1O2 ---> 0.5 AcCoA + 9.5H2O + 9.1CO2
A4: RGP | B4: Formate | C4: 2 | D4: 1 | E4: =D4/C4*Substrates!H28/Substrates!H16 -> 0.47809005 | F4: 0.09 | G4: =F4/E4 -> 0.18824905 | H4: =10/1-C4 -> 8 | I4: =sFormate_pwRGPviaSerine!G14 -> 0 | J4: =sFormate_pwRGPviaSerine!H14 -> -2 | L4: =sFormate_pwRGPviaSerine!J14 -> -2 | M4: =sFormate_pwRGPviaSerine!L14 -> 0 | N4: =sFormate_pwRGPviaSerine!M14 -> 0 | O4: 10Formate + 10H+_e + 3.0O2 ---> 1AcCoA + 9H2O + 8CO2
A5: Formolase | B5: Methanol | C5: 3 | D5: 1 | E5: =D5/C5*Substrates!H28/Substrates!H7 -> 0.44779958 | F5: 0.75 | G5: =F5/E5 -> 1.6748564 | H5: =10/5.6-C5 -> -1.2142857 | I5: =sMethanol_pwFormolase!G17 -> 5 | J5: =sMethanol_pwFormolase!H17 -> 0 | L5: =sMethanol_pwFormolase!J17 -> 1 | M5: =sMethanol_pwFormolase!L17 -> 4 | N5: =sMethanol_pwFormolase!M17 -> 1 | O5: 10Methanol + 3.8O2 + 1.2CO2 --> 5.6AcCoA + 14.4H2O
A6: Serine Cycle | B6: Methanol | C6: 1 | D6: 1 | E6: =D6/C6*Substrates!H28/Substrates!H7 -> 1.3433988 | F6: 0.6 | G6: =F6/E6 -> 0.44662837 | H6: =10/4.4-C6 -> 1.2727273 | I6: =sMethanol_pwSerineCycle!H19 -> 0 | J6: =sMethanol_pwSerineCycle!I19 -> -1 | L6: =sMethanol_pwSerineCycle!K19 -> -3 | M6: =sMethanol_pwSerineCycle!M19 -> 2 | N6: =sMethanol_pwSerineCycle!N19 -> -1 | O6: 10Methanol + 6.1O2 --> 4.4AcCoA +15.6H2O + 1.13CO2
A7: RuMP | B7: Methanol | C7: 3 | D7: 1 | E7: =D7/C7*Substrates!H28/Substrates!H7 -> 0.44779958 | F7: 0.75 | G7: =F7/E7 -> 1.6748564 | H7: =10/5.6-C7 -> -1.2142857 | I7: =sMethanol_pwRuMP!G17 -> 5 | J7: =sMethanol_pwRuMP!H17 -> 0 | L7: =sMethanol_pwRuMP!J17 -> 1 | M7: =sMethanol_pwRuMP!L17 -> 5 | N7: =sMethanol_pwRuMP!M17 -> 1 | O7: 10Methanol + 3.7O2 + 1.2CO2 --> 5.6AcCoA + 14.4H2O
A9: WLP | B9: CO_1:H2_0 | C9: 2 | D9: 1 | E9: =D9/C9*Substrates!H28/Substrates!H18 -> 0.76837524 | F9: 0.38418351 | G9: =F9/$E$9 -> 0.49999464 | H9: =10/2.5-C9 -> 2 | I9: ='sCO-FOR_pwWLP'!G17 -> -2 | J9: ='sCO-FOR_pwWLP'!H17 -> -1 | K9: ='sCO-FOR_pwWLP'!I17 -> 0 | L9: ='sCO-FOR_pwWLP'!J17 -> -1 | M9: ='sCO-FOR_pwWLP'!K17 -> -2 | N9: ='sCO-FOR_pwWLP'!L17 -> 0 | O9: 10CO + 2.5H2O -->2.5AcCoA + 5CO2 | T9: =2.5/10*43/28 -> 0.38392857
A10: WLP | B10: CO_1:H2_0.5 | C10: 2 | D10: 1 | F10: 0.53586106 | G10: =F10/$E$9 -> 0.697395 | H10: =10/3.6-C10 -> 0.77777778 | O10: 10CO + 5H2 --> 3.6AcCoA + 2.5CO2 + 1.1H2O + 0.14H+_e + 0.14Acetate | T10: =3.6/10*43/28 -> 0.55285714
A11: WLP | B11: CO_1:H2_1 | C11: 2 | D11: 1 | F11: 0.65226749 | G11: =F11/$E$9 -> 0.84889186 | H11: =10/4.55-C11 -> 0.1978022 | O11: 10CO + 10H2 --> 4.6AcCoA + 4.6 H2O + 0.5 H+_e + 0.5Acetate | T11: =4.55/10*43/29 -> 0.67465517
A12: WLP | B12: CO_1:H2_2 | C12: 2 | D12: 1 | F12: 0.66196938 | G12: =F12/$E$9 -> 0.86151837 | H12: =10/4.64-C12 -> 0.15517241 | O12: 10CO + 10.72H2 --> 4.64AcCoA + 5H2O + 0.36Ethanol | T12: =4.64/10*43/28 -> 0.71257143
A13: WLP | B13: FOR_1:H2_0 | C13: 2 | D13: 1 | E13: =D13/C13*Substrates!H28/Substrates!H22 -> 0.47809005 | F13: 0.23378391 | G13: =F13/$E$13 -> 0.48899556 | H13: =10/2.5-C13 -> 2 | I13: ='sCO-FOR_pwWLP'!G40 -> -2 | J13: ='sCO-FOR_pwWLP'!H40 -> -1 | K13: ='sCO-FOR_pwWLP'!I40 -> 1 | L13: ='sCO-FOR_pwWLP'!J40 -> -1 | M13: ='sCO-FOR_pwWLP'!K40 -> -1 | N13: ='sCO-FOR_pwWLP'!L40 -> 0 | O13: 10Formate + 10H+_e -->2.5AcCoA + 5CO2 + 7.5H2O | T13: =2.5/10*43/45 -> 0.23888889
A14: WLP | B14: FOR_1:H2_0.5 | C14: 2 | D14: 1 | F14: 0.33057843 | G14: =F14/$E$13 -> 0.69145641 | H14: =10/3.6-C14 -> 0.77777778 | O14: 10Formate + 5H2 + 9.9H+_e -->3.6 AcCoA + 2.5CO2 + 11.1H2O + 0.14Acetate | T14: =3.6/10*43/45 -> 0.344
A15: WLP | B15: FOR_1:H2_1 | C15: 2 | D15: 1 | F15: 0.40763324 | G15: =F15/$E$13 -> 0.85262857 | H15: =10/4.55-C15 -> 0.1978022 | O15: 10Formate + 10H2 + 9.6H+ --> 4.6AcCoA + 14.6 H2O + 0.5Acetate | T15: =4.55/10*43/45 -> 0.43477778
A16: WLP | B16: FOR_1:H2_2 | C16: 2 | D16: 1 | F16: 0.41444423 | G16: =F16/$E$13 -> 0.86687481 | H16: =10/4.64-C16 -> 0.15517241 | O16: 10Formate + 10.72H2 + 10H+--> 4.64AcCoA + 15H2O + 0.36Ethanol | T16: =4.64/10*43/45 -> 0.44337778
A19: Pathway | B19: Substrate | C19: Mols Sub | D19: Acetyl-CoA | E19: NADH | F19: NADPH | G19: ATP | H19: H+ | I19: CO2
A20: Formolase | B20: Formate | C20: =C2/$C2 -> 1 | D20: =D2/$C$2 -> 0.33333333 | E20: =I2/$C$2 -> -0.33333333 | F20: =J2/$C$2 -> 0 | G20: =L2/$C$2 -> -0.66666667 | H20: =M2/$C$2 -> 1.3333333 | I20: =N2/$C$2 -> 0.33333333
A21: Serine Cycle | B21: Formate | C21: =C3/$C3 -> 1 | D21: =D3/$C3 -> 1 | E21: =I3/$C3 -> -2 | F21: =J3/$C3 -> -1 | G21: =L3/$C3 -> -3 | H21: =M3/$C3 -> 1 | I21: =N3/$C3 -> -1
A22: RGP | B22: Formate | C22: =C4/$C4 -> 1 | D22: =D4/$C4 -> 0.5 | E22: =I4/$C4 -> 0 | F22: =J4/$C4 -> -1 | G22: =L4/$C4 -> -1 | H22: =M4/$C4 -> 0 | I22: =N4/$C4 -> 0
A23: Formolase | B23: Methanol | C23: =C5/$C5 -> 1 | D23: =D5/$C5 -> 0.33333333 | E23: =I5/$C5 -> 1.6666667 | F23: =J5/$C5 -> 0 | G23: =L5/$C5 -> 0.33333333 | H23: =M5/$C5 -> 1.3333333 | I23: =N5/$C5 -> 0.33333333
A24: Serine Cycle | B24: Methanol | C24: =C6/$C6 -> 1 | D24: =D6/$C6 -> 1 | E24: =I6/$C6 -> 0 | F24: =J6/$C6 -> -1 | G24: =L6/$C6 -> -3 | H24: =M6/$C6 -> 2 | I24: =N6/$C6 -> -1
A25: RuMP | B25: Methanol | C25: =C7/$C7 -> 1 | D25: =D7/$C7 -> 0.33333333 | E25: =I7/$C7 -> 1.6666667 | F25: =J7/$C7 -> 0 | G25: =L7/$C7 -> 0.33333333 | H25: =M7/$C7 -> 1.6666667 | I25: =N7/$C7 -> 0.33333333

Sheet sCO-FOR_pwWLP
A1: CO
A2: rxnID | B2: rxnName | C2: rxnSubsystem | D2: rxnLB | E2: rxnUB | F2: rxnAddMetabolites | G2: NADH | H2: NADPH | I2: FerredoxinR | J2: ATP | K2: H+ | L2: CO2 | M2: rxnModels | N2: rxnNotes | O2: Quinol
A3: EX_co_e | B3: EX co LPAREN e RPAREN | C3: '- | D3: 0 | E3: 1000 | F3: co_e <=> | M3: iHN637
A4: COt | B4: CO transporter via diffusion | C4: '- | D4: -1000 | E4: 1000 | F4: co_c <=> co_e | M4: iHN637
A5: Methyl Branch
A6: CODH4 | B6: Carbon monoxide dehydrogenase / acetyl-CoA synthase 2 | C6: Wood Ljungadhl Pathway | D6: 0 | E6: 1000 | F6: h2o_c + co_c + fdxo_42_c --> co2_c + 2.0 h_c + fdxr_42_c | I6: 1 | K6: 2 | L6: 1 | M6: iHN637
A7: FDH7 | B7: Formate Dehydrogenase(Ferredoxin dependent) | C7: Wood Ljungadhl Pathway | D7: -100 | E7: 1000 | F7: co2_c + h_c + fdxr_42_c <=> for_c + fdxo_42_c | I7: -1 | K7: -1 | M7: iHN637
A8: FTHFLi | B8: Formate-tetrahydrofolate ligase | C8: Wood Ljungadhl Pathway | D8: 0 | E8: 1000 | F8: atp_c + for_c + thf_c --> 10fthf_c + adp_c + pi_c | J8: -1 | M8: iHN637
A9: MTHFC | B9: Methenyltetrahydrofolate cyclohydrolase | C9: Wood Ljungadhl Pathway | D9: -1000 | E9: 1000 | F9: h2o_c + methf_c <=> 10fthf_c + h_c | K9: -1 | M9: iHN637 | N9: Reverse rxn needed
A10: MTHFD | B10: Methylenetetrahydrofolate dehydrogenase (NADP) | C10: Wood Ljungadhl Pathway | D10: -1000 | E10: 1000 | F10: mlthf_c + nadp_c <=> methf_c + nadph_c | H10: -1 | M10: iHN637 | N10: Reverse rxn needed
A11: MTHFR5 | B11: 5,10-methylenetetrahydrofolate reductase (Ferredoxin) Electron bifurcating | C11: Wood Ljungadhl Pathway | D11: -1000 | E11: 1000 | F11: h_c + mlthf_c + 2.0 nadh_c + fdxo_42_c <=> 5mthf_c + 2.0 nad_c + fdxr_42_c | G11: -2 | I11: 1 | K11: -1 | M11: iHN637
A12: METR | B12: Methyltetrahydrofolate:corrinoid/iron-sulfur protein methyltransferase (MeTr) | C12: Wood Ljungadhl Pathway | D12: -1000 | E12: 1000 | F12: 5mthf_c + cfesp_c <=> thf_c + mecfsp_c | M12: iHN637
A13: Carbonyl Branch
A14: **Model combines (i) CO2 --> CO (ii) CO +mecfsp--> accoa as single reaction (see next rxn)
A15: Combining Branches
A16: CODH_ACS | B16: CODH/Acetyl-CoA synthase (Wood-Ljundahl) | C16: Wood Ljungadhl Pathway | D16: 0 | E16: 1000 | F16: co2_c + coa_c + h_c + fdxr_42_c + mecfsp_c --> accoa_c + h2o_c + fdxo_42_c + cfesp_c | I16: -1 | K16: -1 | L16: -1 | M16: iHN637
G17: =SUM(G6:G12,G16,G3:G4) -> -2 | H17: =SUM(H6:H12,H16,H3:H4) -> -1 | I17: =SUM(I6:I12,I16,I3:I4) -> 0 | J17: =SUM(J6:J12,J16,J3:J4) -> -1 | K17: =SUM(K6:K12,K16,K3:K4) -> -2 | L17: =SUM(L6:L12,L16,L3:L4) -> 0 | O17: 0
G18: NADH | H18: NADPH | I18: FerredoxinR | J18: ATP | K18: H+ | L18: CO2 | O18: Quinol
G19: *These are values required to get 1 mol of AcCoA, which requires 2 mol CO
G20: *2 CO are fed to get 1 PEP, 1 PYR or 1 AcCoA
A24: FORMATE
A25: rxnID | B25: rxnName | C25: rxnSubsystem | D25: rxnLB | E25: rxnUB | F25: rxnAddMetabolites | G25: NADH | H25: NADPH | I25: FerredoxinR | J25: ATP | K25: H+ | L25: CO2 | M25: rxnModels | N25: rxnNotes | O25: Quinol
A26: EX_for_e | B26: Formate exchange | C26: '- | D26: 0 | E26: 1000 | F26: for_e <=> | M26: iHN637
A27: FORt2 | B27: Formate transport in via proton symport | C27: '- | D27: 0 | E27: 1000 | F27: for_e + h_e --> for_c + h_c | K27: 1 | M27: iHN637
A28: Methyl Branch
A30: FTHFLi | B30: Formate-tetrahydrofolate ligase | C30: Wood Ljungadhl Pathway | D30: 0 | E30: 1000 | F30: atp_c + for_c + thf_c --> 10fthf_c + adp_c + pi_c | J30: -1 | M30: iHN637
A31: MTHFC | B31: Methenyltetrahydrofolate cyclohydrolase | C31: Wood Ljungadhl Pathway | D31: -1000 | E31: 1000 | F31: h2o_c + methf_c <=> 10fthf_c + h_c | K31: -1 | M31: iHN637 | N31: Reverse rxn needed
A32: MTHFD | B32: Methylenetetrahydrofolate dehydrogenase (NADP) | C32: Wood Ljungadhl Pathway | D32: -1000 | E32: 1000 | F32: mlthf_c + nadp_c <=> methf_c + nadph_c | H32: -1 | M32: iHN637 | N32: Reverse rxn needed
A33: MTHFR5 | B33: 5,10-methylenetetrahydrofolate reductase (Ferredoxin) Electron bifurcating | C33: Wood Ljungadhl Pathway | D33: -1000 | E33: 1000 | F33: h_c + mlthf_c + 2.0 nadh_c + fdxo_42_c <=> 5mthf_c + 2.0 nad_c + fdxr_42_c | G33: -2 | I33: 1 | K33: -1 | M33: iHN637
A34: METR | B34: Methyltetrahydrofolate:corrinoid/iron-sulfur protein methyltransferase (MeTr) | C34: Wood Ljungadhl Pathway | D34: -1000 | E34: 1000 | F34: 5mthf_c + cfesp_c <=> thf_c + mecfsp_c | M34: iHN637
A35: Carbonyl Branch
A36: FDH7 | B36: Formate Dehydrogenase(Ferredoxin dependent) | C36: Wood Ljungadhl Pathway | D36: -100 | E36: 1000 | F36: co2_c + h_c + fdxr_42_c <=> for_c + fdxo_42_c | I36: 1 | K36: 1 | L36: 1 | M36: iHN637 | N36: Reverse rxn needed
A37: **Model combines (i) CO2 --> CO (ii) CO +mecfsp--> accoa as single reaction (see next rxn)
A38: Combining Branches
A39: CODH_ACS | B39: CODH/Acetyl-CoA synthase (Wood-Ljundahl) | C39: Wood Ljungadhl Pathway | D39: 0 | E39: 1000 | F39: co2_c + coa_c + h_c + fdxr_42_c + mecfsp_c --> accoa_c + h2o_c + fdxo_42_c + cfesp_c | I39: -1 | K39: -1 | L39: -1 | M39: iHN637
G40: =SUM(G26:G39) -> -2 | H40: =SUM(H26:H39) -> -1 | I40: =SUM(I26:I39) -> 1 | J40: =SUM(J26:J39) -> -1 | K40: =SUM(K26:K39) -> -1 | L40: =SUM(L26:L39) -> 0 | O40: 0
G41: NADH | H41: NADPH | I41: FerredoxinR | J41: ATP | K41: H+ | L41: CO2 | O41: Quinol
G42: *These are values required to get 1 mol of AcCoA, which requires 2 mol formate
G43: *2 formate are fed to get 1 PEP, 1 PYR or 1 AcCoA
A45: Energy/H2
...

Sheet sFormate_pwFormolase
A1: rxnID | B1: rxnName | C1: rxnSubsystem | D1: rxnLB | E1: rxnUB | F1: rxnAddMetabolites | G1: NADH | H1: NADPH | I1: FADH2 | J1: ATP | K1: Quinol | L1: H+ | M1: CO2 | N1: rxnModels | O1: rxnNotes
A2: EX_for_e | B2: Formate exchange | C2: Extracellular exchange | D2: 0 | E2: 1000 | F2: for_e <=> | N2: iJO1366, iHN637
A3: FORtex | B3: Formate transport via diffusion (extracellular to periplasm) | C3: Transport, Outer Membrane Porin | D3: -1000 | E3: 1000 | F3: for_e <=> for_p | N3: iJO1366 | O3: IHN637 model has one reaction from for_e to for_c (no transport though periplasm); ID FORt2.
A4: FORt2pp | B4: Formate transport via proton symport (uptake only, periplasm) | C4: Transport, Inner Membrane | D4: 0 | E4: 1000 | F4: for_p + h_p --> for_c + h_c | L4: =1*3 -> 3 | N4: iJO1366 | O4: For import only (FORtppi for export). IHN637 model has one reaction from for_e to for_c (no transport though periplasm); ID FORt2.
A5: FORtppi | B5: Formate transport via diffusion (cytoplasm to periplasm) | C5: Transport, Inner Membrane | D5: 0 | E5: 1000 | F5: for_c --> for_p | N5: iJO1366 | O5: For export only (FORt2pp for import). IHN637 model doesn’t seem to have rxn for outward transport for formate.
A6: ACSf | B6: Acetyl-CoA Synthase (formyl-CoA forming) | D6: 0 | E6: 1000 | F6: for_c + coa_c + atp_c --> forcoa_c + amp_c + ppi_c | J6: =-1*3 -> -3 | N6: None | O6: Reaction reported in Siegel (2015), doesn’t appear to exist in any BiGG model
A7: ACALDf | B7: Acetaldehyde dehydrogenase (formaldehyde forming) | D7: -1000 | E7: 1000 | F7: forcoa_c + nadh_c + h_c --> fald_c + nad_c + coa_c | G7: =-1*3 -> -3 | N7: None | O7: Reaction reported in Siegel (2015), doesn’t appear to exist in any BiGG model
A8: FLSa | B8: Formolase (Glycolaldehyde forming) | D8: 0 | E8: 1000 | F8: 2.0 fald_c --> gcald_c | N8: None | O8: Reaction catalyzed by novel, computational designed formolase enzyme from Siegel (2015), doesn’t exist in any BiGG models. May or may not be reversible, but only including forward direction in assimilation pathway.
A9: FLSb | B9: Formolase (DHA forming) | D9: 0 | E9: 1000 | F9: fald_c + gcald_c --> dha_c | N9: None | O9: Reaction catalyzed by novel, computational designed formolase enzyme from Siegel (2015), doesn’t exist in any BiGG models. May or may not be reversible, but only including forward direction in assimilation pathway.
A10: DHAK | B10: Dihydroxyacetone kinase | C10: Glycerol Metabolism | D10: 0 | E10: 1000 | F10: atp_c + dha_c --> adp_c + dhap_c + h_c | J10: -1 | N10: iHN637 | O10: Does not exist in iJO1366 model, but iJO1366 model does contain reaction below (need to determine which to use and which to knock out....). In Siegel 2015, they used this rxn.
A11: DHAPT | B11: Dihydroxyacetone phosphotransferase | C11: Alternate Carbon Metabolism | D11: 0 | E11: 1000 | F11: dha_c + pep_c --> dhap_c + pyr_c | N11: iJO1366 | O11: *Rxn above used for formolase pathway by Siegel (2015). This reaction does not exist in iHN637 model, but iHN637 model does have alternative reaction above.
A12: TPI | B12: Triose-phosphate isomerase | C12: Glycolysis/Gluconeogenesis | D12: -1000 | E12: 1000 | F12: dhap_c ⇌ g3p_c
A13: GAPD | B13: Glyceraldehyde-3-phosphate dehydrogenase | C13: Glycolysis/Gluconeogenesis | D13: -1000 | E13: 1000 | F13: g3p_c + nad_c + pi_c <=> 13dpg_c + h_c + nadh_c | G13: 1 | L13: 1
A14: PGK | B14: Phosphoglycerate kinase | C14: Glycolysis/Gluconeogenesis | D14: -1000 | E14: 1000 | F14: 3pg_c + atp_c <=> 13dpg_c + adp_c | J14: 1 | N14: Reverse rxn needed
A15: PGM | B15: Phosphoglycerate mutase | C15: Glycolysis/Gluconeogenesis | D15: -1000 | E15: 1000 | F15: 2pg_c <=> 3pg_c
A16: ENO | B16: Enolase | C16: Glycolysis/Gluconeogenesis | D16: -1000 | E16: 1000 | F16: 2pg_c <=> h2o_c + pep_c
A17: PYK | B17: Pyruvate kinase | C17: Glycolysis/Gluconeogenesis | D17: 0 | E17: 1000 | F17: adp_c + h_c + pep_c --> atp_c + pyr_c | J17: 1
A18: PDH | B18: Pyruvate dehydrogenase | C18: Glycolysis/Gluconeogenesis | D18: 0 | E18: 1000 | F18: coa_c + nad_c + pyr_c --> accoa_c + co2_c + nadh_c | G18: 1 | M18: 1
G19: =SUM(G2:G18) -> -1 | H19: =SUM(H2:H18) -> 0 | I19: =SUM(I2:I18) -> 0 | J19: =SUM(J2:J18) -> -2 | K19: =SUM(K2:K18) -> 0 | L19: =SUM(L2:L18) -> 4 | M19: =SUM(M2:M18) -> 1
G20: NADH | H20: NADPH | I20: FADH2 | J20: ATP | K20: Quinol | L20: H+ | M20: CO2
G21: *These are values required to get 1 mol of AcCoA, which requires 3 mol formate
G22: *3 formate are fed to get 1 PEP, 1 PYR or 1 AcCoA
A24: metDef | B24: metID | C24: metFormula | D24: metName | E24: metCompartment | F24: metCharge | G24: metModels | H24: metNotes
A25: NAD | B25: nad_c | C25: C21H26N7O14P2 | D25: Nicotinamide adenine dinucleotide | E25: c | F25: -1 | G25: iJO1366, iHN637
A26: NADH | B26: nadh_c | C26: C21H27N7O14P2 | D26: Nicotinamide adenine dinucleotide – reduced | E26: c | F26: -2 | G26: iJO1366, iHN637
A27: ATP | B27: atp_c | C27: C10H12N5O13P3 | D27: ATP C10H12N5O13P3 | E27: c | F27: -4 | G27: iJO1366, iHN637
A28: ADP | B28: adp_c | C28: C10H12N5O10P2 | D28: ADP C10H12N5O10P2 | E28: c | F28: -3 | G28: iJO1366, iHN637
A29: AMP | B29: amp_c | C29: C10H12N5O7P | D29: AMP C10H12N5O7P | E29: c | F29: -2 | G29: iJO1366, iHN637
A30: H_ion | B30: h_c | C30: H | D30: H+ | E30: c | F30: 1 | G30: iJO1366, iHN637
A31: H_ion_p | B31: h_p | C31: H | D31: H+ | E31: p | F31: 1 | G31: iJO1366
A32: PPi | B32: ppi_c | C32: HO7P2 | D32: Diphosphate | E32: c | F32: -3 | G32: iJO1366, iHN637
A33: CoA | B33: coa_c | C33: C21H32N7O16P3S | D33: Coenzyme A | E33: c | F33: -4 | G33: iJO1366
A34: Formate_e | B34: for_e | C34: CH1O2 | D34: Formate | E34: e | F34: -1 | G34: iJO1366, iHN637
A35: Formate_p | B35: for_p | C35: CH1O2 | D35: Formate | E35: p | F35: -1 | G35: iJO1366 | H35: Not in iHN637 model
A36: Formate_c | B36: for_c | C36: CH1O2 | D36: Formate | E36: c | F36: -1 | G36: iJO1366, iHN637
A37: Formyl_CoA | B37: forcoa_c | C37: C22H32N7O17P3S | D37: Formyl-CoA(4-) | E37: c | F37: -4 | G37: iJO1366 | H37: Not in iHN637 model
A38: Formaldehyde | B38: fald_c | C38: CH2O | D38: Formaldehyde | E38: c | F38: 0 | G38: iJO1366 | H38: Not in iHN637 model
A39: Glycolaldehyde | B39: gcald_c | C39: C2H4O2 | D39: Glycolaldehyde | E39: c | F39: 0 | G39: iJO1366, iHN637
A40: DHA | B40: dha_c | C40: C3H6O3 | D40: Dihydroxyacetone | E40: c | F40: 0 | G40: iJO1366, iHN637
A41: DHAP | B41: dhap_c | C41: C3H5O6P | D41: Dihydroxyacetone phosphate | E41: c | F41: -2 | G41: iJO1366, iHN637
...

Sheet sFormate_pwSerineCycle
A1: rxnID | B1: rxnName | C1: rxnSubsystem | D1: rxnLB | E1: rxnUB | F1: rxnAddMetabolites | G1: NADH | H1: NADPH | I1: FADH2 | J1: ATP | K1: Quinol | L1: H+ | M1: CO2 | N1: rxnModels | O1: rxnNotes
A2: EX_for_e | B2: Formate exchange | C2: Extracellular exchange | D2: 0 | E2: 1000 | F2: for_e <=> | N2: iJO1366
A3: FORtex | B3: Formate transport via diffusion (extracellular to periplasm) | C3: Transport, Outer Membrane Porin | D3: -1000 | E3: 1000 | F3: for_e <=> for_p | N3: iJO1366
A4: FORt2pp | B4: Formate transport via proton symport (uptake only, periplasm) | C4: Transport, Inner Membrane | D4: 0 | E4: 1000 | F4: for_p + h_p --> for_c + h_c | L4: 1 | N4: iJO1366 | O4: For import only (FORtppi for export)
A5: FORtppi | B5: Formate transport via diffusion (cytoplasm to periplasm) | C5: Transport, Inner Membrane | D5: 0 | E5: 1000 | F5: for_c --> for_p | N5: iJO1366 | O5: For export only (FORt2pp for import)
A6: FTHFLi | B6: Formate-tetrahydrofolate ligase | C6: Folate Metabolism | D6: 0 | E6: 1000 | F6: atp_c + for_c + thf_c --> 10fthf_c + adp_c + pi_c | J6: -1 | N6: iJO1366, iHN637
A7: MTHFC | B7: Methenyltetrahydrofolate cyclohydrolase | C7: Folate Metabolism | D7: -1000 | E7: 1000 | F7: h2o_c + methf_c <=> 10fthf_c + h_c | L7: -1 | N7: iJO1366, iHN637
A8: MTHFD | B8: Methylenetetrahydrofolate dehydrogenase (NADP) | C8: Folate Metabolism | D8: -1000 | E8: 1000 | F8: mlthf_c + nadp_c <=> methf_c + nadph_c | H8: -1 | N8: iJO1366, iHN637
A9: GHMT2r | B9: Glycine hydroxymethyltransferase, reversible | C9: Glycine and Serine Metabolism | D9: -1000 | E9: 1000 | F9: ser__L_c + thf_c <=> gly_c + h2o_c + mlthf_c | N9: iJO1366, iHN637
A10: SGATc | B10: Serine--glyoxylate aminotransferase | C10: Glycine, serine and threonine metabolism | D10: -1000 | E10: 1000 | F10: ser__L_c + glx_c <=> gly_c + hpyr_c | O10: SGAT only exists in BiGG model iRC1080 and it takes place in the mitochondrial compartment (all metabolites are _m and not _c, but changed them to cytosol for my analysis and so renamed ID SGATc
A11: HPYRRx | B11: Hydroxypyruvate reductase (NADH) | C11: Alternate Carbon Metabolism | D11: 0 | E11: 1000 | F11: h_c + hpyr_c + nadh_c --> glyc__R_c + nad_c | G11: -1 | N11: iJO1366
A12: GLYCK2 | B12: Glycerate 2-kinase | C12: unknown | D12: 0 | E12: 1000 | F12: atp_c + glyc__R_c --> 2pg_c + adp_c + h_c | J12: -1 | L12: 1 | N12: iJO1366
A13: ENO | B13: Enolase | C13: Glycolysis/Gluconeogenesis | D13: -1000 | E13: 1000 | F13: 2pg_c <=> h2o_c + pep_c | N13: iJO1366, iHN637
A14: PPC | B14: Phosphoenolpyruvate carboxylase | C14: Anaplerotic Reactions | D14: 0 | E14: 1000 | F14: co2_c + h2o_c + pep_c --> h_c + oaa_c + pi_c | L14: 1 | M14: -1 | N14: iJO1366 | O14: Only in forward direct, PPCK is reaction that exists for reverse direction (although rev not needed for serine cycle). IHN637 model only has PPCK rxn.
A15: MDH | B15: Malate dehydrogenase | C15: Citric Acid Cycle | D15: -1000 | E15: 1000 | F15: mal__L_c + nad_c <=> h_c + nadh_c + oaa_c | G15: -1 | L15: -1 | N15: iJO1366 | O15: Reverse action is needed for serine cycle. There are multiple MDH reactions that exist in iJO1366 model that use different electron carrier (ie. ubiquinone)
A16: MALlig | B16: Malate-CoA ligase | C16: NA | D16: -1000 | E16: 1000 | F16: mal__L_c + atp_c + coa_c <=> malylcoa_c + adp_c + pi_c | J16: -1 | O16: Reaction does not seem to exist in any BiGG models, but exists in MetaCyc as part of formaldehyde assimilation pathway I (serine pathway).
A17: MALlya | B17: Malyl-CoA lyase | C17: NA | D17: -1000 | E17: 1000 | F17: malylcoa_c <=> glx_c + accoa_c | O17: Reaction does not seem to exist in any BiGG models, but exists in MetaCyc as part of formaldehyde assimilation pathway I (serine pathway).
G18: =SUM(G2:G17) -> -2 | H18: =SUM(H2:H17) -> -1 | I18: =SUM(I2:I17) -> 0 | J18: =SUM(J2:J17) -> -3 | K18: =SUM(K2:K17) -> 0 | L18: =SUM(L2:L17) -> 1 | M18: =SUM(M2:M17) -> -1
G19: NADH | H19: NADPH | I19: FADH2 | J19: ATP | K19: Quinol | L19: H+ | M19: CO2
G20: *These are values required to get 1 mol of AcCoA, which requires 1 mol formate
G21: *1 formate is fed to get 1 AcCoA
A23: metID | B23: metFormula | C23: metName | D23: metCompartment | E23: metCharge | F23: metModels | G23: metNotes
A24: nad_c | B24: C21H26N7O14P2 | C24: Nicotinamide adenine dinucleotide | D24: c | E24: -1 | F24: iJO1366, iHN637
A25: nadh_c | B25: C21H27N7O14P2 | C25: Nicotinamide adenine dinucleotide – reduced | D25: c | E25: -2 | F25: iJO1366, iHN637
A26: nadp_c | B26: C21H25N7O17P3 | C26: Nicotinamide adenine dinucleotide phosphate | D26: c | E26: -3 | F26: iJO1366, iHN637
A27: nadph_c | B27: C21H26N7O17P3 | C27: Nicotinamide adenine dinucleotide phosphate – reduced | D27: c | E27: -4 | F27: iJO1366, iHN637
A28: atp_c | B28: C10H12N5O13P3 | C28: ATP C10H12N5O13P3 | D28: c | E28: -4 | F28: iJO1366, iHN637
A29: adp_c | B29: C10H12N5O10P2 | C29: ADP C10H12N5O10P2 | D29: c | E29: -3 | F29: iJO1366, iHN637
A30: amp_c | B30: C10H12N5O7P | C30: AMP C10H12N5O7P | D30: c | E30: -2 | F30: iJO1366, iHN637
A31: h2o_c | B31: H2O | C31: water | D31: c | E31: 0 | F31: iJO1366, iHN637
A32: co2_c | B32: CO2 | C32: carbon dioxide | D32: c | E32: 0 | F32: iJO1366, iHN637
A33: h_c | B33: H | C33: H+_c | D33: c | E33: 1 | F33: iJO1366, iHN637
A34: h_p | B34: H | C34: H+ | D34: p | E34: 1 | F34: iJO1366
A35: pi_c | B35: HO4P | C35: Phosphate | D35: c | E35: -2 | F35: iJO1366, iHN637
... A48: gly_c | B48: C2H5NO2 | C48: Glycine | D48: c | E48: 0 | F48: iJO1366
A49: hpyr_c | B49: C3H3O4 | C49: Hydroxypyruvate | D49: c | E49: -1 | F49: iJO1366 | G49: iHN637 model doesn’t have hydroxypyruvate
A50: glyc__R_c | B50: C3H5O4 | C50: (R)-Glycerate | D50: c | E50: -1 | F50: iJO1366
A51: 2pg_c | B51: C3H4O7P | C51: D-Glycerate 2-phosphate | D51: c | E51: -3 | F51: iJO1366
A52: pep_c | B52: C3H2O6P | C52: Phosphoenolpyruvate | D52: c | E52: -3 | F52: iJO1366
A53: oaa_c | B53: C4H2O5 | C53: Oxaloacetate | D53: c | E53: -2 | F53: iJO1366
...

Sheet sFormate_pwRGPviaSerine
A1: rxnID | B1: rxnName | C1: rxnSubsystem | D1: rxnLB | E1: rxnUB | F1: rxnAddMetabolites | G1: NADH | H1: NADPH | I1: FADH2 | J1: ATP | K1: Quinol | L1: H+ | M1: CO2 | N1: rxnModels | O1: rxnNotes
A2: EX_for_e | B2: Formate exchange | C2: Extracellular exchange | D2: 0 | E2: 1000 | F2: for_e <=> | N2: iJO1366
A3: FORtex | B3: Formate transport via diffusion (extracellular to periplasm) | C3: Transport, Outer Membrane Porin | D3: -1000 | E3: 1000 | F3: for_e <=> for_p | N3: iJO1366
A4: FORt2pp | B4: Formate transport via proton symport (uptake only, periplasm) | C4: Transport, Inner Membrane | D4: 0 | E4: 1000 | F4: for_p + h_p --> for_c + h_c | L4: =1*2 -> 2 | N4: iJO1366 | O4: For import only (FORtppi for export)
A5: FORtppi | B5: Formate transport via diffusion (cytoplasm to periplasm) | C5: Transport, Inner Membrane | D5: 0 | E5: 1000 | F5: for_c --> for_p | N5: iJO1366 | O5: For export only (FORt2pp for import)
A6: FTHFLi | B6: Formate-tetrahydrofolate ligase | C6: Folate Metabolism | D6: 0 | E6: 1000 | F6: atp_c + for_c + thf_c --> 10fthf_c + adp_c + pi_c | J6: =-1*2 -> -2 | N6: iJO1366, iHN637
A7: MTHFC | B7: Methenyltetrahydrofolate cyclohydrolase | C7: Folate Metabolism | D7: -1000 | E7: 1000 | F7: h2o_c + methf_c <=> 10fthf_c + h_c | L7: =-1*2 -> -2 | N7: iJO1366, iHN637
A8: MTHFD | B8: Methylenetetrahydrofolate dehydrogenase (NADP) | C8: Folate Metabolism | D8: -1000 | E8: 1000 | F8: mlthf_c + nadp_c <=> methf_c + nadph_c | H8: =-1*2 -> -2 | N8: iJO1366, iHN637
A9: GLYCL | B9: Glycine Cleavage System | C9: Folate Metabolism | D9: -1000 | E9: 1000 | F9: gly_c + nad_c + thf_c <=> co2_c + mlthf_c + nadh_c + nh4_c | G9: -1 | M9: -1 | N9: iJO1366, iHN637 | O9: Reaction exists in iJO1366 and iHN637 models as irreversible, must change lower bound to -1000. Has been shown to be reversible (Tashiro, 2018).
A10: GHMT2r | B10: Glycine hydroxymethyltransferase, reversible | C10: Glycine and Serine Metabolism | D10: -1000 | E10: 1000 | F10: ser__L_c + thf_c <=> gly_c + h2o_c + mlthf_c | N10: iJO1366, iHN637
A11: SERD_L | B11: L-serine deaminase | C11: Glycine and Serine Metabolism | D11: 0 | E11: 1000 | F11: ser__L_c --> nh4_c + pyr_c | N11: iJO1366, iHN637
A12: PPS | B12: Phosphoenolpyruvate synthase | C12: Glycolysis/Gluconeogenesis | D12: 0 | E12: 1000 | F12: atp_c + h2o_c + pyr_c --> amp_c + 2.0 h_c + pep_c + pi_c | N12: iJO1366 | O12: Reaction is different in iHN637 model and has rxnID PPDK.
A13: PDH | B13: Pyruvate dehydrogenase | C13: Glycolysis/Gluconeogenesis | D13: 0 | E13: 1000 | F13: coa_c + nad_c + pyr_c --> accoa_c + co2_c + nadh_c | G13: 1 | M13: 1
G14: =SUM(G2:G13) -> 0 | H14: =SUM(H2:H13) -> -2 | I14: =SUM(I2:I13) -> 0 | J14: =SUM(J2:J13) -> -2 | K14: =SUM(K2:K13) -> 0 | L14: =SUM(L2:L13) -> 0 | M14: =SUM(M2:M13) -> 0
G15: NADH | H15: NADPH | I15: FADH2 | J15: ATP | K15: Quinol | L15: H+ | M15: CO2
G16: *These are values required to get 1 mol of AcCoA, which requires 2 mol formate
G17: *1 methanol is fed to get 1 AcCoA
A19: metDef | B19: metID | C19: metFormula | D19: metName | E19: metCompartment | F19: metCharge | G19: metModels | H19: metNotes
A20: NAD | B20: nad_c | C20: C21H26N7O14P2 | D20: Nicotinamide adenine dinucleotide | E20: c | F20: -1 | G20: iJO1366, iHN637
A21: NADH | B21: nadh_c | C21: C21H27N7O14P2 | D21: Nicotinamide adenine dinucleotide – reduced | E21: c | F21: -2 | G21: iJO1366, iHN637
A22: NADP | B22: nadp_c | C22: C21H25N7O17P3 | D22: Nicotinamide adenine dinucleotide phosphate | E22: c | F22: -3 | G22: iJO1366, iHN637
A23: NADPH | B23: nadph_c | C23: C21H26N7O17P3 | D23: Nicotinamide adenine dinucleotide phosphate – reduced | E23: c | F23: -4 | G23: iJO1366, iHN637
A24: ATP | B24: atp_c | C24: C10H12N5O13P3 | D24: ATP C10H12N5O13P3 | E24: c | F24: -4 | G24: iJO1366, iHN637
A25: ADP | B25: adp_c | C25: C10H12N5O10P2 | D25: ADP C10H12N5O10P2 | E25: c | F25: -3 | G25: iJO1366, iHN637
A26: AMP | B26: amp_c | C26: C10H12N5O7P | D26: AMP C10H12N5O7P | E26: c | F26: -2 | G26: iJO1366, iHN637
A27: H2O | B27: h2o_c | C27: H2O | D27: water | E27: c | F27: 0 | G27: iJO1366, iHN637
A28: CO2 | B28: co2_c | C28: CO2 | D28: carbon dioxide | E28: c | F28: 0 | G28: iJO1366, iHN637
A29: H_ion | B29: h_c | C29: H | D29: H+_c | E29: c | F29: 1 | G29: iJO1366, iHN637
A30: H_ion_p | B30: h_p | C30: H | D30: H+ | E30: p | F30: 1 | G30: iJO1366
A31: Pi | B31: pi_c | C31: HO4P | D31: Phosphate | E31: c | F31: -2 | G31: iJO1366, iHN637
... A44: PEP | B44: pep_c | C44: C3H2O6P | D44: Phosphoenolpyruvate | E44: c | F44: -3 | G44: iJO1366

Sheet sMethanol_pwFormolase
A1: rxnID | B1: rxnName | C1: rxnSubsystem | D1: rxnLB | E1: rxnUB | F1: rxnAddMetabolites | G1: NADH | H1: NADPH | I1: FADH2 | J1: ATP | K1: Quinol | L1: H+ | M1: CO2 | N1: rxnModels | O1: rxnNotes
A2: EX_meoh_e | B2: Methanol exchange | C2: Extracellular exchange | D2: 0 | E2: 1000 | F2: meoh_e <=> | N2: iJO1366
A3: MEOHtex | B3: Methanol transport via diffusion (extracellular to periplasm) | C3: Transport, Outer Membrane Porin | D3: -1000 | E3: 1000 | F3: meoh_e <=> meoh_p | N3: iJO1366
A4: MEOHtrpp | B4: Methanol reversible transport via diffusion (periplasm) | C4: Transport, Inner Membrane | D4: -1000 | E4: 1000 | F4: meoh_p <=> meoh_c | N4: iJO1366
