Workbook

Sheet Overall-ECR-Bio
B1: Substrate | C1: Formula_S | D1: C_Sn | E1: H_Sn | F1: O_Sn | G1: MW_S | H1: N_electrons | I1: ParametersType | J1: CellVoltage | K1: CurrentDensity | L1: FaradaicEfficiency | M1: EnergyEfficiency | N1: ByProducts | O1: ByP_FE | P1: Xco2 | Q1: ElectricityPrice | R1: CO2Price | S1: CarbonTax | T1: Conversion | U1: ElectrolyzerPrice | V1: PlantLife | W1: StreamFactor | X1: ScalingFactor | Y1: ElectrodeArea | Z1: I | AA1: Power | AB1: kWh | AC1: kWh_sep | AD1: emol_curr | AE1: MaxProductionRate | AF1: ActualProductionRate | AG1: ActualProductionRate_mass | AH1: CO2rate_fed | AI1: CO2rate_conv | AJ1: Cost_elec_h | AK1: Cost_h_sep | AL1: Type_sep | AM1: Cost_CO2_h | AN1: Cost_electrolyzer_h | AO1: CT_savings_h | AP1: ProductionCost_hNOCT | AQ1: ProductionCost_h | AR1: Cost_elec_mol | AS1: Cost_elec_mass | AT1: Cost_CO2_mass | AU1: Cost_electrolyzer_mass | AV1: CT_savings_mass | AW1: ProductionCost_massNOCT | AX1: ProductionCost_mass | AY1: CO2_ECons_mass | AZ1: BioProduct_Graph | BA1: BioProduct | BB1: Formula_BP | BC1: MW_BP | BD1: Deg_RedBP | BE1: BoilP_degC | BF1: SubstratePathway | BG1: CO2_BProd_mass | BH1: YieldBP_Molar | BI1: YieldBP_Mass | BJ1: Bioconversion | BK1: BioproductionCost_massNOCT | BL1: BioproductionCost_mass1 | BM1: CO2_OverallCons_mass | BN1: CT_OverallSavings_mass | BO1: BioproductionCost_mass2
A2: 0 | B2: Acetaldehyde | C2: C2H4O | D2: 2 | E2: 4 | F2: 1 | G2: 44.05176 | H2: 10 | I2: Categories-Category_2 | J2: 1.176 | K2: 500 | L2: 100 | N2: FormicAcid/CO | O2: 0 | P2: 0.2 | Q2: 0.0325 | R2: 77.5 | S2: 170 | T2: 100 | U2: 1812.1302 | V2: 20 | W2: 0.95 | X2: 1 | Y2: 33997.862 | Z2: 1.6998931e+08 | AA2: 1.9990743e+08 | AB2: 199907.43 | AC2: 0 | AD2: 1761.815 | AE2: 634253.42 | AF2: 634253.42 | AG2: 27.939979 | AH2: 55.826986 | AI2: 55.826986 | AJ2: 6496.9915 | AK2: 854.70085 | AL2: Nanofiltration | AM2: 4326.5914 | AN2: 370.15472 | AO2: 9490.5876 | AP2: 12048.438 | AQ2: 2557.8509 | AR2: 0.010243526 | AS2: 232.53387 | AT2: 154.85306 | AU2: 13.24821 | AV2: 339.67769 | AW2: 431.22575 | AX2: 91.548059 | AY2: 1.998104 | AZ2: =VLOOKUP(BA2,Sheet1!$A$1:$B$58,2,FALSE) -> 1,3-Butanediol (PW1) | BA2: 1-3-Butanediol-PW1 | BB2: C4H10O2 | BC2: 90.1192 | BD2: 5.5 | BE2: 207 | BF2: Acetaldehyde | BG2: 0.27966661 | BH2: 0.43738095 | BI2: 0.89477518 | BJ2: 90 | BK2: 535.48615 | BL2: 113.68226 | BM2: 2.2015327 | BN2: 374.26057 | BO2: 161.22559
A3: 1 | B3: Acetaldehyde | C3: C2H4O | D3: 2 | E3: 4 | F3: 1 | G3: 44.05176 | H3: 10 | I3: Categories-Category_2 | J3: 1.176 | K3: 500 | L3: 100 | N3: FormicAcid/CO | O3: 0 | P3: 0.2 | Q3: 0.0325 | R3: 77.5 | S3: 170 | T3: 100 | U3: 1812.1302 | V3: 20 | W3: 0.95 | X3: 1 | Y3: 33429.253 | Z3: 1.6714626e+08 | AA3: 1.9656401e+08 | AB3: 196564.01 | AC3: 0 | AD3: 1732.3489 | AE3: 623645.62 | AF3: 623645.62 | AG3: 27.472687 | AH3: 54.893287 | AI3: 54.893287 | AJ3: 6388.3302 | AK3: 854.70085 | AL3: Nanofiltration | AM3: 4254.2298 | AN3: 363.96394 | AO3: 9331.8588 | AP3: 11861.225 | AQ3: 2529.3659 | AR3: 0.010243526 | AS3: 232.53387 | AT3: 154.85306 | AU3: 13.24821 | AV3: 339.67769 | AW3: 431.74607 | AX3: 92.068385 | AY3: 1.998104 | AZ3: =VLOOKUP(BA3,Sheet1!$A$1:$B$58,2,FALSE) -> 1,3-Butanediol (PW2) | BA3: 1-3-Butanediol-PW2 | BB3: C4H10O2 | BC3: 90.1192 | BD3: 5.5 | BE3: 207 | BF3: Acetaldehyde | BG3: 0.24231868 | BH3: 0.44482051 | BI3: 0.90999471 | BJ3: 90 | BK3: 527.16554 | BL3: 112.41626 | BM3: 2.197383 | BN3: 373.55511 | BO3: 153.61044
A4: 2 | B4: Acetaldehyde | C4: C2H4O | D4: 2 | E4: 4 | F4: 1 | G4: 44.05176 | H4: 10 | I4: Categories-Category_2 | J4: 1.176 | K4: 500 | L4: 100 | N4: FormicAcid/CO | O4: 0 | P4: 0.2 | Q4: 0.0325 | R4: 77.5 | S4: 170 | T4: 100 | U4: 1812.1302 | V4: 20 | W4: 0.95 | X4: 1 | Y4: 35449.564 | Z4: 1.7724782e+08 | AA4: 2.0844343e+08 | AB4: 208443.43 | AC4: 0 | AD4: 1837.0442 | AE4: 661335.9 | AF4: 661335.9 | AG4: 29.13301 | AH4: 58.210786 | AI4: 58.210786 | AJ4: 6774.4116 | AK4: 854.70085 | AL4: Nanofiltration | AM4: 4511.3359 | AN4: 385.96025 | AO4: 9895.8336 | AP4: 12526.409 | AQ4: 2630.575 | AR4: 0.010243526 | AS4: 232.53387 | AT4: 154.85306 | AU4: 13.24821 | AV4: 339.67769 | AW4: 429.97303 | AX4: 90.295338 | AY4: 1.998104 | AZ4: =VLOOKUP(BA4,Sheet1!$A$1:$B$58,2,FALSE) -> 1,3-Diaminopropane | BA4: 1-3-Diaminopropane | BB4: C3H12N2 | BC4: 76.13958 | BD4: 6 | BE4: 139.3 | BF4: Acetaldehyde | BG4: 0.59437932 | BH4: 0.49648649 | BI4: 0.85813308 | BJ4: 90 | BK4: 556.72927 | BL4: 116.91445 | BM4: 1.9927667 | BN4: 338.77034 | BO4: 217.95893
A5: 3 | B5: Acetaldehyde | C5: C2H4O | D5: 2 | E5: 4 | F5: 1 | G5: 44.05176 | H5: 10 | I5: Categories-Category_2 | J5: 1.176 | K5: 500 | L5: 100 | N5: FormicAcid/CO | O5: 0 | P5: 0.2 | Q5: 0.0325 | R5: 77.5 | S5: 170 | T5: 100 | U5: 1812.1302 | V5: 20 | W5: 0.95 | X5: 1 | Y5: 34471.821 | Z5: 1.723591e+08 | AA5: 2.0269431e+08 | AB5: 202694.31 | AC5: 0 | AD5: 1786.3762 | AE5: 643095.44 | AF5: 643095.44 | AG5: 28.329486 | AH5: 56.60526 | AI5: 56.60526 | AJ5: 6587.5649 | AK5: 854.70085 | AL5: Nanofiltration | AM5: 4386.9077 | AN5: 375.31499 | AO5: 9622.8943 | AP5: 12204.488 | AQ5: 2581.5942 | AR5: 0.010243526 | AS5: 232.53387 | AT5: 154.85306 | AU5: 13.24821 | AV5: 339.67769 | AW5: 430.80515 | AX5: 91.127464 | AY5: 1.998104 | AZ5: =VLOOKUP(BA5,Sheet1!$A$1:$B$58,2,FALSE) -> 1,3-Propanediol | BA5: 1-3-Propanediol | BB5: C3H8O2 | BC5: 76.09282 | BD5: 5.3333333 | BE5: 213 | BF5: Acetaldehyde | BG5: 0.5290927 | BH5: 0.51088235 | BI5: 0.88247278 | BJ5: 90 | BK5: 542.42171 | BL5: 114.73752 | BM5: 1.9866967 | BN5: 337.73843 | BO5: 204.68328
A6: 4 | B6: Acetaldehyde | C6: C2H4O | D6: 2 | E6: 4 | F6: 1 | G6: 44.05176 | H6: 10 | I6: Categories-Category_2 | J6: 1.176 | K6: 500 | L6: 100 | N6: FormicAcid/CO | O6: 0 | P6: 0.2 | Q6: 0.0325 | R6: 77.5 | S6: 170 | T6: 100 | U6: 1812.1302 | V6: 20 | W6: 0.95 | X6: 1 | Y6: 36811.212 | Z6: 1.8405606e+08 | AA6: 2.1644992e+08 | AB6: 216449.92 | AC6: 0 | AD6: 1907.6066 | AE6: 686738.38 | AF6: 686738.38 | AG6: 30.252034 | AH6: 60.446712 | AI6: 60.446712 | AJ6: 7034.6225 | AK6: 854.70085 | AL6: Nanofiltration | AM6: 4684.6202 | AN6: 400.78531 | AO6: 10275.941 | AP6: 12974.729 | AQ6: 2698.7879 | AR6: 0.010243526 | AS6: 232.53387 | AT6: 154.85306 | AU6: 13.24821 | AV6: 339.67769 | AW6: 428.88782 | AX6: 89.210128 | AY6: 1.998104 | AZ6: =VLOOKUP(BA6,Sheet1!$A$1:$B$58,2,FALSE) -> 1,4-Butanediol | BA6: 1-4-Butanediol | BB6: C4H10O2 | BC6: 90.1192 | BD6: 5.5 | BE6: 230 | BF6: Acetaldehyde | BG6: 0.46445567 | BH6: 0.40395349 | BI6: 0.82639071 | BJ6: 90 | BK6: 576.65462 | BL6: 119.94613 | BM6: 2.2220649 | BN6: 377.75103 | BO6: 198.90359
A7: 5 | B7: Acetaldehyde | C7: C2H4O | D7: 2 | E7: 4 | F7: 1 | G7: 44.05176 | H7: 10 | I7: Categories-Category_2 | J7: 1.176 | K7: 500 | L7: 100 | N7: FormicAcid/CO | O7: 0 | P7: 0.2 | Q7: 0.0325 | R7: 77.5 | S7: 170 | T7: 100 | U7: 1812.1302 | V7: 20 | W7: 0.95 | X7: 1 | Y7: 48043.559 | Z7: 2.4021779e+08 | AA7: 2.8249612e+08 | AB7: 282496.12 | AC7: 0 | AD7: 2489.682 | AE7: 896285.51 | AF7: 896285.51 | AG7: 39.482954 | AH7: 78.89105 | AI7: 78.89105 | AJ7: 9181.1241 | AK7: 854.70085 | AL7: Nanofiltration | AM7: 6114.0564 | AN7: 523.07848 | AO7: 13411.479 | AP7: 16672.96 | AQ7: 3261.4812 | AR7: 0.010243526 | AS7: 232.53387 | AT7: 154.85306 | AU7: 13.24821 | AV7: 339.67769 | AW7: 422.28248 | AX7: 82.604793 | AY7: 1.998104 | AZ7: =VLOOKUP(BA7,Sheet1!$A$1:$B$58,2,FALSE) -> 1-Propanol (PW1) | BA7: 1-Propanol-PW1 | BB7: C3H8O | BC7: 60.09382 | BD7: 6 | BE7: 97 | BF7: Acetaldehyde | BG7: 0.95857749 | BH7: 0.46415584 | BI7: 0.63318464 | BJ7: 90 | BK7: 741.02043 | BL7: 144.95472 | BM7: 2.5476914 | BN7: 433.10754 | BO7: 307.91289
A8: 6 | B8: Acetaldehyde | C8: C2H4O | D8: 2 | E8: 4 | F8: 1 | G8: 44.05176 | H8: 10 | I8: Categories-Category_2 | J8: 1.176 | K8: 500 | L8: 100 | N8: FormicAcid/CO | O8: 0 | P8: 0.2 | Q8: 0.0325 | R8: 77.5 | S8: 170 | T8: 100 | U8: 1812.1302 | V8: 20 | W8: 0.95 | X8: 1 | Y8: 51591.572 | Z8: 2.5795786e+08 | AA8: 3.0335845e+08 | AB8: 303358.45 | AC8: 0 | AD8: 2673.5448 | AE8: 962476.14 | AF8: 962476.14 | AG8: 42.398768 | AH8: 84.71715 | AI8: 84.71715 | AJ8: 9859.1495 | AK8: 854.70085 | AL8: Nanofiltration | AM8: 6565.5791 | AN8: 561.7078 | AO8: 14401.915 | AP8: 17841.137 | AQ8: 3439.2218 | AR8: 0.010243526 | AS8: 232.53387 | AT8: 154.85306 | AU8: 13.24821 | AV8: 339.67769 | AW8: 420.79377 | AX8: 81.116079 | AY8: 1.998104 | AZ8: =VLOOKUP(BA8,Sheet1!$A$1:$B$58,2,FALSE) -> 1-Propanol (PW2) | BA8: 1-Propanol-PW2 | BB8: C3H8O | BC8: 60.09382 | BD8: 6 | BE8: 97 | BF8: Acetaldehyde | BG8: 1.1916215 | BH8: 0.43223529 | BI8: 0.58963978 | BJ8: 90 | BK8: 792.93943 | BL8: 152.8543 | BM8: 2.5735852 | BN8: 437.50948 | BO8: 355.42995
A9: 7 | B9: Acetaldehyde | C9: C2H4O | D9: 2 | E9: 4 | F9: 1 | G9: 44.05176 | H9: 10 | I9: Categories-Category_2 | J9: 1.176 | K9: 500 | L9: 100 | N9: FormicAcid/CO | O9: 0 | P9: 0.2 | Q9: 0.0325 | R9: 77.5 | S9: 170 | T9: 100 | U9: 1812.1302 | V9: 20 | W9: 0.95 | X9: 1 | Y9: 34807.335 | Z9: 1.7403668e+08 | AA9: 2.0466713e+08 | AB9: 204667.13 | AC9: 0 | AD9: 1803.763 | AE9: 649354.69 | AF9: 649354.69 | AG9: 28.605217 | AH9: 57.1562 | AI9: 57.1562 | AJ9: 6651.6817 | AK9: 854.70085 | AL9: Nanofiltration | AM9: 4429.6055 | AN9: 378.96793 | AO9: 9716.5539 | AP9: 12314.956 | AQ9: 2598.4021 | AR9: 0.010243526 | AS9: 232.53387 | AT9: 154.85306 | AU9: 13.24821 | AV9: 339.67769 | AW9: 430.51434 | AX9: 90.83665 | AY9: 1.998104 | AZ9: =VLOOKUP(BA9,Sheet1!$A$1:$B$58,2,FALSE) -> 2,3-Butanediol | BA9: 2-3-Butanediol | BB9: C4H10O2 | BC9: 90.1192 | BD9: 5.5 | BE9: 177 | BF9: Acetaldehyde | BG9: 0.33283517 | BH9: 0.4272093 | BI9: 0.87396646 | BJ9: 90 | BK9: 547.33138 | BL9: 115.48454 | BM9: 2.2074404 | BN9: 375.26486 | BO9: 172.06652
A10: 8 | B10: Acetaldehyde | C10: C2H4O | D10: 2 | E10: 4 | F10: 1 | G10: 44.05176 | H10: 10 | I10: Categories-Category_2 | J10: 1.176 | K10: 500 | L10: 100 | N10: FormicAcid/CO | O10: 0 | P10: 0.2 | Q10: 0.0325 | R10: 77.5 | S10: 170 | T10: 100 | U10: 1812.1302 | V10: 20 | W10: 0.95 | X10: 1 | Y10: 55448.395 | Z10: 2.7724198e+08 | AA10: 3.2603656e+08 | AB10: 326036.56 | AC10: 0 | AD10: 2873.4106 | AE10: 1034427.8 | AF10: 1034427.8 | AG10: 45.568366 | AH10: 91.050336 | AI10: 91.050336 | AJ10: 10596.188 | AK10: 854.70085 | AL10: Nanofiltration | AM10: 7056.401 | AN10: 603.69929 | AO10: 15478.557 | AP10: 19110.99 | AQ10: 3632.4324 | AR10: 0.010243526 | AS10: 232.53387 | AT10: 154.85306 | AU10: 13.24821 | AV10: 339.67769 | AW10: 419.39159 | AX10: 79.713906 | AY10: 1.998104 | AZ10: =VLOOKUP(BA10,Sheet1!$A$1:$B$58,2,FALSE) -> 2-Methyl-1-Butanol | BA10: 2-Methyl-1-Butanol | BB10: C5H12O | BC10: 88.14658 | BD10: 6 | BE10: 129 | BF10: Acetaldehyde | BG10: 1.1456035 | BH10: 0.2741791 | BI10: 0.54862622 | BJ10: 90 | BK10: 849.37731 | BL10: 161.44144 | BM10: 2.9010781 | BN10: 493.18328 | BO10: 356.19403
A11: 9 | B11: Acetaldehyde | C11: C2H4O | D11: 2 | E11: 4 | F11: 1 | G11: 44.05176 | H11: 10 | I11: Categories-Category_2 | J11: 1.176 | K11: 500 | L11: 100 | N11: FormicAcid/CO | O11: 0 | P11: 0.2 | Q11: 0.0325 | R11: 77.5 | S11: 170 | T11: 100 | U11: 1812.1302 | V11: 20 | W11: 0.95 | X11: 1 | Y11: 23770.878 | Z11: 1.1885439e+08 | AA11: 1.3977276e+08 | AB11: 139772.76 | AC11: 0 | AD11: 1231.8389 | AE11: 443462.02 | AF11: 443462.02 | AG11: 19.535282 | AH11: 39.033527 | AI11: 39.033527 | AJ11: 4542.6148 | AK11: 1835.3365 | AL11: Distillation | AM11: 3025.0983 | AN11: 258.80753 | AO11: 6635.6996 | AP11: 9661.8572 | AQ11: 3026.1576 | AR11: 0.010243526 | AS11: 232.53387 | AT11: 154.85306 | AU11: 13.24821 | AV11: 339.67769 | AW11: 494.58498 | AX11: 154.90729 | AY11: 1.998104 | AZ11: =VLOOKUP(BA11,Sheet1!$A$1:$B$58,2,FALSE) -> 2-Pyrone-4,6-Dicarboxylate | BA11: 2-Pyrone-4-6-Dicarboxylate | BB11: C7H2O6 | BC11: 182.08458 | BD11: 2.5714286 | BE11: 355.5 | BF11: Acetaldehyde | BG11: -0.13056496 | BH11: 0.30960674 | BI11: 1.2797358 | BJ11: 90 | BK11: 429.41588 | BL11: 134.49589 | BM11: 1.8653884 | BN11: 317.11602 | BO11: 112.29985
A12: 10 | B12: Acetaldehyde | C12: C2H4O | D12: 2 | E12: 4 | F12: 1 | G12: 44.05176 | H12: 10 | I12: Categories-Category_2 | J12: 1.176 | K12: 500 | L12: 100 | N12: FormicAcid/CO | O12: 0 | P12: 0.2 | Q12: 0.0325 | R12: 77.5 | S12: 170 | T12: 100 | U12: 1812.1302 | V12: 20 | W12: 0.95 | X12: 1 | Y12: 57118.088 | Z12: 2.8559044e+08 | AA12: 3.3585436e+08 | AB12: 335854.36 | AC12: 0 | AD12: 2959.9363 | AE12: 1065577.1 | AF12: 1065577.1 | AG12: 46.940545 | AH12: 93.792093 | AI12: 93.792093 | AJ12: 10915.267 | AK12: 854.70085 | AL12: Nanofiltration | AM12: 7268.8872 | AN12: 621.87822 | AO12: 15944.656 | AP12: 19660.733 | AQ12: 3716.077 | AR12: 0.010243526 | AS12: 232.53387 | AT12: 154.85306 | AU12: 13.24821 | AV12: 339.67769 | AW12: 418.8433 | AX12: 79.165612 | AY12: 1.998104 | AZ12: =VLOOKUP(BA12,Sheet1!$A$1:$B$58,2,FALSE) -> 3-Methyl-1-Pentanol | BA12: 3-Methyl-1-Pentanol | BB12: C6H14O | BC12: 102.17296 | BD12: 6 | BE12: 153 | BF12: Acetaldehyde | BG12: 1.1672426 | BH12: 0.229625 | BI12: 0.53258862 | BJ12: 90 | BK12: 873.81035 | BL12: 165.15898 | BM12: 3.0012949 | BN12: 510.22013 | BO12: 363.59022
A13: 11 | B13: Acetaldehyde | C13: C2H4O | D13: 2 | E13: 4 | F13: 1 | G13: 44.05176 | H13: 10 | I13: Categories-Category_2 | J13: 1.176 | K13: 500 | L13: 100 | N13: FormicAcid/CO | O13: 0 | P13: 0.2 | Q13: 0.0325 | R13: 77.5 | S13: 170 | T13: 100 | U13: 1812.1302 | V13: 20 | W13: 0.95 | X13: 1 | Y13: 57275.744 | Z13: 2.8637872e+08 | AA13: 3.3678138e+08 | AB13: 336781.38 | AC13: 0 | AD13: 2968.1063 | AE13: 1068518.3 | AF13: 1068518.3 | AG13: 47.07011 | AH13: 94.050977 | AI13: 94.050977 | AJ13: 10945.395 | AK13: 854.70085 | AL13: Nanofiltration | AM13: 7288.9507 | AN13: 623.59471 | AO13: 15988.666 | AP13: 19712.641 | AQ13: 3723.9749 | AR13: 0.010243526 | AS13: 232.53387 | AT13: 154.85306 | AU13: 13.24821 | AV13: 339.67769 | AW13: 418.79318 | AX13: 79.115493 | AY13: 1.998104 | AZ13: =VLOOKUP(BA13,Sheet1!$A$1:$B$58,2,FALSE) -> 4-Hydroxystyrene | BA13: 4-Hydroxystyrene | BB13: C8H8O | BC13: 120.14732 | BD13: 4.75 | BE13: 229 | BF13: Acetaldehyde | BG13: 0.83163662 | BH13: 0.19473498 | BI13: 0.53112262 | BJ13: 90 | BK13: 876.11738 | BL13: 165.51 | BM13: 3.3484068 | BN13: 569.22915 | BO13: 306.88822
... A28: 26 | B28: Acetaldehyde | C28: C2H4O | D28: 2 | E28: 4 | F28: 1 | G28: 44.05176 | H28: 10 | I28: Categories-Category_2 | J28: 1.176 | K28: 500 | L28: 100 | N28: FormicAcid/CO | O28: 0 | P28: 0.2 | Q28: 0.0325 | R28: 77.5 | S28: 170 | T28: 100 | U28: 1812.1302 | V28: 20 | W28: 0.95 | X28: 1 | Y28: 33239.555 | Z28: 1.6619777e+08 | AA28: 1.9544858e+08 | AB28: 195448.58 | AC28: 0 | AD28: 1722.5185 | AE28: 620106.67 | AF28: 620106.67 | AG28: 27.31679 | AH28: 54.581789 | AI28: 54.581789 | AJ28: 6352.0789 | AK28: 854.70085 | AL28: Nanofiltration | AM28: 4230.0887 | AN28: 361.89858 | AO28: 9278.9042 | AP28: 11798.767 | AQ28: 2519.8629 | AR28: 0.010243526 | AS28: 232.53387 | AT28: 154.85306 | AU28: 13.24821 | AV28: 339.67769 | AW28: 431.92362 | AX28: 92.245935 | AY28: 1.998104 | AZ28: =VLOOKUP(BA28,Sheet1!$A$1:$B$58,2,FALSE) -> cis,cis-Muconate | BA28: ciscisMuconate | BB28: C6H4O4 | BC28: 140.09156 | BD28: 3.3333333 | BE28: 345.4 | BF28: Acetaldehyde | BG28: 0.29836145 | BH28: 0.28778068 | BI28: 0.91518805 | BJ28: 90 | BK28: 524.38965 | BL28: 111.9939 | BM28: 2.1274959 | BN28: 361.6743 | BO28: 162.71535
A29: 27 | B29: Acetaldehyde | C29: C2H4O | D29: 2 | E29: 4 | F29: 1 | G29: 44.05176 | H29: 10 | I29: Categories-Category_2 | J29: 1.176 | K29: 500 | L29: 100 | N29: FormicAcid/CO | O29: 0 | P29: 0.2 | Q29: 0.0325 | R29: 77.5 | S29: 170 | T29: 100 | U29: 1812.1302 | V29: 20 | W29: 0.95 | X29: 1 | Y29: 15829.453 | Z29: 79147265 | AA29: 93077184 | AB29: 93077.184 | AC29: 0 | AD29: 820.30359 | AE29: 295309.29 | AF29: 295309.29 | AG29: 13.008894 | AH29: 25.993124 | AI29: 25.993124 | AJ29: 3025.0085 | AK29: 854.70085 | AL29: Nanofiltration | AM29: 2014.4671 | AN29: 172.34457 | AO29: 4418.8311 | AP29: 6066.521 | AQ29: 1647.6899 | AR29: 0.010243526 | AS29: 232.53387 | AT29: 154.85306 | AU29: 13.24821 | AV29: 339.67769 | AW29: 466.33641 | AX29: 126.65872 | AY29: 1.998104 | AZ29: =VLOOKUP(BA29,Sheet1!$A$1:$B$58,2,FALSE) -> Citrate | BA29: Citrate | BB29: C6H5O7 | BC29: 189.0964 | BD29: 2.5 | BF29: Acetaldehyde | BG29: -0.35670564 | BH29: 0.44769231 | BI29: 1.9217621 | BJ29: 90 | BK29: 269.62316 | BL29: 73.230664 | BM29: 1.5119556 | BN29: 257.03245 | BO29: 12.590705
A30: 28 | B30: Acetaldehyde | C30: C2H4O | D30: 2 | E30: 4 | F30: 1 | G30: 44.05176 | H30: 10 | I30: Categories-Category_2 | J30: 1.176 | K30: 500 | L30: 100 | N30: FormicAcid/CO | O30: 0 | P30: 0.2 | Q30: 0.0325 | R30: 77.5 | S30: 170 | T30: 100 | U30: 1812.1302 | V30: 20 | W30: 0.95 | X30: 1 | Y30: 42403.18 | Z30: 2.120159e+08 | AA30: 2.493307e+08 | AB30: 249330.7 | AC30: 0 | AD30: 2197.39 | AE30: 791060.38 | AF30: 791060.38 | AG30: 34.847602 | AH30: 69.629135 | AI30: 69.629135 | AJ30: 8103.2477 | AK30: 854.70085 | AL30: Nanofiltration | AM30: 5396.258 | AN30: 461.66836 | AO30: 11836.953 | AP30: 14815.875 | AQ30: 2978.922 | AR30: 0.010243526 | AS30: 232.53387 | AT30: 154.85306 | AU30: 13.24821 | AV30: 339.67769 | AW30: 425.16196 | AX30: 85.484274 | AY30: 1.998104 | AZ30: =VLOOKUP(BA30,Sheet1!$A$1:$B$58,2,FALSE) -> Coumaric Acid | BA30: CoumaricAcid | BB30: C9H7O3 | BC30: 163.14818 | BD30: 4.1111111 | BE30: 346 | BF30: Acetaldehyde | BG30: 0.35737245 | BH30: 0.19370826 | BI30: 0.71740948 | BJ30: 90 | BK30: 658.48333 | BL30: 132.39653 | BM30: 2.7372558 | BN30: 465.33348 | BO30: 193.14985
A31: 29 | B31: Acetaldehyde | C31: C2H4O | D31: 2 | E31: 4 | F31: 1 | G31: 44.05176 | H31: 10 | I31: Categories-Category_2 | J31: 1.176 | K31: 500 | L31: 100 | N31: FormicAcid/CO | O31: 0 | P31: 0.2 | Q31: 0.0325 | R31: 77.5 | S31: 170 | T31: 100 | U31: 1812.1302 | V31: 20 | W31: 0.95 | X31: 1 | Y31: 31085.945 | Z31: 1.5542973e+08 | AA31: 1.8278536e+08 | AB31: 182785.36 | AC31: 0 | AD31: 1610.9156 | AE31: 579929.61 | AF31: 579929.61 | AG31: 25.54692 | AH31: 51.045404 | AI31: 51.045404 | AJ31: 5940.5241 | AK31: 854.70085 | AL31: Nanofiltration | AM31: 3956.0188 | AN31: 338.45097 | AO31: 8677.7187 | AP31: 11089.695 | AQ31: 2411.9761 | AR31: 0.010243526 | AS31: 232.53387 | AT31: 154.85306 | AU31: 13.24821 | AV31: 339.67769 | AW31: 434.09126 | AX31: 94.413576 | AY31: 1.998104 | AZ31: =VLOOKUP(BA31,Sheet1!$A$1:$B$58,2,FALSE) -> Ethyl Acetate | BA31: EthylAcetate | BB31: C4H8O2 | BC31: 88.10352 | BD31: 5 | BE31: 77.1 | BF31: Acetaldehyde | BG31: 0.043712121 | BH31: 0.48929577 | BI31: 0.97859155 | BJ31: 90 | BK31: 492.87532 | BL31: 107.19894 | BM31: 2.2249725 | BN31: 378.24533 | BO31: 114.63
A32: 30 | B32: Acetaldehyde | C32: C2H4O | D32: 2 | E32: 4 | F32: 1 | G32: 44.05176 | H32: 10 | I32: Categories-Category_2 | J32: 1.176 | K32: 500 | L32: 100 | N32: FormicAcid/CO | O32: 0 | P32: 0.2 | Q32: 0.0325 | R32: 77.5 | S32: 170 | T32: 100 | U32: 1812.1302 | V32: 20 | W32: 0.95 | X32: 1 | Y32: 63543.02 | Z32: 3.177151e+08 | AA32: 3.7363296e+08 | AB32: 373632.96 | AC32: 0 | AD32: 3292.885 | AE32: 1185438.6 | AF32: 1185438.6 | AG32: 52.220656 | AH32: 104.3423 | AI32: 104.3423 | AJ32: 12143.071 | AK32: 1835.3365 | AL32: Distillation | AM32: 8086.5286 | AN32: 691.83024 | AO32: 17738.192 | AP32: 22756.767 | AQ32: 5018.5748 | AR32: 0.010243526 | AS32: 232.53387 | AT32: 154.85306 | AU32: 13.24821 | AV32: 339.67769 | AW32: 435.78094 | AX32: 96.103251 | AY32: 1.998104 | AZ32: =VLOOKUP(BA32,Sheet1!$A$1:$B$58,2,FALSE) -> Farnesene | BA32: Farnesene | BB32: C15H24 | BC32: 204.34866 | BD32: 5.6 | BE32: 260 (A)/272 (B) | BF32: Acetaldehyde | BG32: 0.94318409 | BH32: 0.10320225 | BI32: 0.47873776 | BJ32: 90 | BK32: 1011.4118 | BL32: 223.04777 | BM32: 3.6942517 | BN32: 628.02278 | BO32: 383.38907
A33: 31 | B33: Acetaldehyde | C33: C2H4O | D33: 2 | E33: 4 | F33: 1 | G33: 44.05176 | H33: 10 | I33: Categories-Category_2 | J33: 1.176 | K33: 500 | L33: 100 | N33: FormicAcid/CO | O33: 0 | P33: 0.2 | Q33: 0.0325 | R33: 77.5 | S33: 170 | T33: 100 | U33: 1812.1302 | V33: 20 | W33: 0.95 | X33: 1 | Y33: 33752.556 | Z33: 1.6876278e+08 | AA33: 1.9846503e+08 | AB33: 198465.03 | AC33: 0 | AD33: 1749.1029 | AE33: 629677.05 | AF33: 629677.05 | AG33: 27.738382 | AH33: 55.424174 | AI33: 55.424174 | AJ33: 6450.1134 | AK33: 1835.3365 | AL33: Distillation | AM33: 4295.3735 | AN33: 367.48393 | AO33: 9422.1096 | AP33: 12948.307 | AQ33: 3526.1977 | AR33: 0.010243526 | AS33: 232.53387 | AT33: 154.85306 | AU33: 13.24821 | AV33: 339.67769 | AW33: 466.8011 | AX33: 127.12341 | AY33: 1.998104 | AZ33: =VLOOKUP(BA33,Sheet1!$A$1:$B$58,2,FALSE) -> Gamma Butyrolactone | BA33: GammaButyrolactone | BB33: C4H6O2 | BC33: 86.08784 | BD33: 4.5 | BE33: 204 | BF33: Acetaldehyde | BG33: 0.17207886 | BH33: 0.46119048 | BI33: 0.90127822 | BJ33: 90 | BK33: 575.48033 | BL33: 156.7199 | BM33: 2.2912178 | BN33: 389.50702 | BO33: 185.97331
A34: 32 | B34: Acetaldehyde | C34: C2H4O | D34: 2 | E34: 4 | F34: 1 | G34: 44.05176 | H34: 10 | I34: Categories-Category_2 | J34: 1.176 | K34: 500 | L34: 100 | N34: FormicAcid/CO | O34: 0 | P34: 0.2 | Q34: 0.0325 | R34: 77.5 | S34: 170 | T34: 100 | U34: 1812.1302 | V34: 20 | W34: 0.95 | X34: 1 | Y34: 19809.978 | Z34: 99049891 | AA34: 1.1648267e+08 | AB34: 116482.67 | AC34: 0 | AD34: 1026.5798 | AE34: 369568.72 | AF34: 369568.72 | AG34: 16.280152 | AH34: 32.529438 | AI34: 32.529438 | AJ34: 3785.6868 | AK34: 854.70085 | AL34: Nanofiltration | AM34: 2521.0315 | AN34: 215.68288 | AO34: 5530.0045 | AP34: 7377.1021 | AQ34: 1847.0975 | AR34: 0.010243526 | AS34: 232.53387 | AT34: 154.85306 | AU34: 13.24821 | AV34: 339.67769 | AW34: 453.1347 | AX34: 113.45702 | AY34: 1.998104 | AZ34: =VLOOKUP(BA34,Sheet1!$A$1:$B$58,2,FALSE) -> L-Glutamate | BA34: Glutamate_L | BB34: C5H8NO4 | BC34: 146.11892 | BD34: 3.4 | BE34: 333.8 | BF34: Acetaldehyde | BG34: -0.2047876 | BH34: 0.46295455 | BI34: 1.5356122 | BJ34: 90 | BK34: 327.8712 | BL34: 82.093223 | BM34: 1.6505404 | BN34: 280.59187 | BO34: 47.27933
A35: 33 | B35: Acetaldehyde | C35: C2H4O | D35: 2 | E35: 4 | F35: 1 | G35: 44.05176 | H35: 10 | I35: Categories-Category_2 | J35: 1.176 | K35: 500 | L35: 100 | N35: FormicAcid/CO | O35: 0 | P35: 0.2 | Q35: 0.0325 | R35: 77.5 | S35: 170 | T35: 100 | U35: 1812.1302 | V35: 20 | W35: 0.95 | X35: 1 | Y35: 31961.618 | Z35: 1.5980809e+08 | AA35: 1.8793431e+08 | AB35: 187934.31 | AC35: 0 | AD35: 1656.2941 | AE35: 596265.88 | AF35: 596265.88 | AG35: 26.266562 | AH35: 52.483323 | AI35: 52.483323 | AJ35: 6107.8652 | AK35: 854.70085 | AL35: Nanofiltration | AM35: 4067.4575 | AN35: 347.98493 | AO35: 8922.1649 | AP35: 11378.009 | AQ35: 2455.8436 | AR35: 0.010243526 | AS35: 232.53387 | AT35: 154.85306 | AU35: 13.24821 | AV35: 339.67769 | AW35: 433.17465 | AX35: 93.496957 | AY35: 1.998104 | AZ35: =VLOOKUP(BA35,Sheet1!$A$1:$B$58,2,FALSE) -> Glutarate | BA35: Glutarate | BB35: C5H6O4 | BC35: 130.09654 | BD35: 3.6 | BE35: 200 | BF35: Acetaldehyde | BG35: 0.4078967 | BH35: 0.3222807 | BI35: 0.95178046 | BJ35: 90 | BK35: 505.68927 | BL35: 109.1486 | BM35: 1.9246954 | BN35: 327.19822 | BO35: 178.49104
A36: 34 | B36: Acetaldehyde | C36: C2H4O | D36: 2 | E36: 4 | F36: 1 | G36: 44.05176 | H36: 10 | I36: Categories-Category_2 | J36: 1.176 | K36: 500 | L36: 100 | N36: FormicAcid/CO | O36: 0 | P36: 0.2 | Q36: 0.0325 | R36: 77.5 | S36: 170 | T36: 100 | U36: 1812.1302 | V36: 20 | W36: 0.95 | X36: 1 | Y36: 15128.873 | Z36: 75644363 | AA36: 88957771 | AB36: 88957.771 | AC36: 0 | AD36: 783.99857 | AE36: 282239.49 | AF36: 282239.49 | AG36: 12.433146 | AH36: 24.84272 | AI36: 24.84272 | AJ36: 2891.1276 | AK36: 854.70085 | AL36: Nanofiltration | AM36: 1925.3108 | AN36: 164.71693 | AO36: 4223.2623 | AP36: 5835.8561 | AQ36: 1612.5938 | AR36: 0.010243526 | AS36: 232.53387 | AT36: 154.85306 | AU36: 13.24821 | AV36: 339.67769 | AW36: 469.37887 | AX36: 129.70119 | AY36: 1.998104 | AZ36: =VLOOKUP(BA36,Sheet1!$A$1:$B$58,2,FALSE) -> Glycolate | BA36: Glycolate | BB36: C2H3O3 | BC36: 75.04192 | BD36: 2.5 | BE36: 112 | BF36: Acetaldehyde | BG36: -0.17923562 | BH36: 1.1803704 | BI36: 2.0107541 | BJ36: 90 | BK36: 259.37138 | BL36: 71.670835 | BM36: 1.2833565 | BN36: 218.1706 | BO36: 41.20078
A37: 35 | B37: Acetaldehyde | C37: C2H4O | D37: 2 | E37: 4 | F37: 1 | G37: 44.05176 | H37: 10 | I37: Categories-Category_2 | J37: 1.176 | K37: 500 | L37: 100 | N37: FormicAcid/CO | O37: 0 | P37: 0.2 | Q37: 0.0325 | R37: 77.5 | S37: 170 | T37: 100 | U37: 1812.1302 | V37: 20 | W37: 0.95 | X37: 1 | Y37: 62598.831 | Z37: 3.1299416e+08 | AA37: 3.6808113e+08 | AB37: 368081.13 | AC37: 0 | AD37: 3243.9558 | AE37: 1167824.1 | AF37: 1167824.1 | AG37: 51.444706 | AH37: 102.79188 | AI37: 102.79188 | AJ37: 11962.637 | AK37: 854.70085 | AL37: Nanofiltration | AM37: 7966.3704 | AN37: 681.55029 | AO37: 17474.619 | AP37: 21465.258 | AQ37: 3990.6392 | AR37: 0.010243526 | AS37: 232.53387 | AT37: 154.85306 | AU37: 13.24821 | AV37: 339.67769 | AW37: 417.24911 | AX37: 77.571425 | AY37: 1.998104 | AZ37: =VLOOKUP(BA37,Sheet1!$A$1:$B$58,2,FALSE) -> Heptane | BA37: Heptane | BB37: C7H16 | BC37: 100.20034 | BD37: 6.2857143 | BE37: 98 | BF37: Acetaldehyde | BG37: 1.0371346 | BH37: 0.21364532 | BI37: 0.48595865 | BJ37: 90 | BK37: 954.01147 | BL37: 177.36174 | BM37: 3.5313932 | BN37: 600.33685 | BO37: 353.67462
A38: 36 | B38: Acetaldehyde | C38: C2H4O | D38: 2 | E38: 4 | F38: 1 | G38: 44.05176 | H38: 10 | I38: Categories-Category_2 | J38: 1.176 | K38: 500 | L38: 100 | N38: FormicAcid/CO | O38: 0 | P38: 0.2 | Q38: 0.0325 | R38: 77.5 | S38: 170 | T38: 100 | U38: 1812.1302 | V38: 20 | W38: 0.95 | X38: 1 | Y38: 63564.009 | Z38: 3.1782005e+08 | AA38: 3.7375637e+08 | AB38: 373756.37 | AC38: 0 | AD38: 3293.9726 | AE38: 1185830.1 | AF38: 1185830.1 | AG38: 52.237905 | AH38: 104.37677 | AI38: 104.37677 | AJ38: 12147.082 | AK38: 854.70085 | AL38: Nanofiltration | AM38: 8089.1997 | AN38: 692.05876 | AO38: 17744.051 | AP38: 21783.041 | AQ38: 4038.9906 | AR38: 0.010243526 | AS38: 232.53387 | AT38: 154.85306 | AU38: 13.24821 | AV38: 339.67769 | AW38: 416.99684 | AX38: 77.319153 | AY38: 1.998104 | AZ38: =VLOOKUP(BA38,Sheet1!$A$1:$B$58,2,FALSE) -> Hexane | BA38: Hexane | BB38: C6H14 | BC38: 86.17396 | BD38: 6.3333333 | BE38: 69 | BF38: Acetaldehyde | BG38: 1.110804 | BH38: 0.24464789 | BI38: 0.47857968 | BJ38: 90 | BK38: 968.13518 | BL38: 179.51069 | BM38: 3.5281635 | BN38: 599.7878 | BO38: 368.34738
A39: 37 | B39: Acetaldehyde | C39: C2H4O | D39: 2 | E39: 4 | F39: 1 | G39: 44.05176 | H39: 10 | I39: Categories-Category_2 | J39: 1.176 | K39: 500 | L39: 100 | N39: FormicAcid/CO | O39: 0 | P39: 0.2 | Q39: 0.0325 | R39: 77.5 | S39: 170 | T39: 100 | U39: 1812.1302 | V39: 20 | W39: 0.95 | X39: 1 | Y39: 40230.393 | Z39: 2.0115196e+08 | AA39: 2.3655471e+08 | AB39: 236554.71 | AC39: 0 | AD39: 2084.7932 | AE39: 750525.54 | AF39: 750525.54 | AG39: 33.061971 | AH39: 66.061258 | AI39: 66.061258 | AJ39: 7688.028 | AK39: 854.70085 | AL39: Nanofiltration | AM39: 5119.7475 | AN39: 438.01195 | AO39: 11230.414 | AP39: 14100.488 | AQ39: 2870.0745 | AR39: 0.010243526 | AS39: 232.53387 | AT39: 154.85306 | AU39: 13.24821 | AV39: 339.67769 | AW39: 426.48662 | AX39: 86.808934 | AY39: 1.998104 | AZ39: =VLOOKUP(BA39,Sheet1!$A$1:$B$58,2,FALSE) -> Isobutanol | BA39: Isobutanol | BB39: C5H10O | BC39: 86.1309 | BD39: 5.6 | BE39: 108 | BF39: Acetaldehyde | BG39: 0.59858454 | BH39: 0.38673684 | BI39: 0.75615576 | BJ39: 90 | BK39: 626.68837 | BL39: 127.55886 | BM39: 2.3374714 | BN39: 397.37013 | BO39: 229.31824
A40: 38 | B40: Acetaldehyde | C40: C2H4O | D40: 2 | E40: 4 | F40: 1 | G40: 44.05176 | H40: 10 | I40: Categories-Category_2 | J40: 1.176 | K40: 500 | L40: 100 | N40: FormicAcid/CO | O40: 0 | P40: 0.2 | Q40: 0.0325 | R40: 77.5 | S40: 170 | T40: 100 | U40: 1812.1302 | V40: 20 | W40: 0.95 | X40: 1 | Y40: 33502.948 | Z40: 1.6751474e+08 | AA40: 1.9699733e+08 | AB40: 196997.33 | AC40: 0 | AD40: 1736.1679 | AE40: 625020.45 | AF40: 625020.45 | AG40: 27.533251 | AH40: 55.0143 | AI40: 55.0143 | AJ40: 6402.4134 | AK40: 854.70085 | AL40: Nanofiltration | AM40: 4263.6083 | AN40: 364.7663 | AO40: 9352.431 | AP40: 11885.489 | AQ40: 2533.0578 | AR40: 0.010243526 | AS40: 232.53387 | AT40: 154.85306 | AU40: 13.24821 | AV40: 339.67769 | AW40: 431.67764 | AX40: 91.999951 | AY40: 1.998104 | AZ40: =VLOOKUP(BA40,Sheet1!$A$1:$B$58,2,FALSE) -> Isobutyrate | BA40: Isobutyrate | BB40: C4H7O2 | BC40: 87.09568 | BD40: 4.75 | BE40: 155 | BF40: Acetaldehyde | BG40: 0.17934662 | BH40: 0.45925 | BI40: 0.90799303 | BJ40: 90 | BK40: 528.24395 | BL40: 112.58034 | BM40: 2.2657334 | BN40: 385.17468 | BO40: 143.06927
A41: 39 | B41: Acetaldehyde | C41: C2H4O | D41: 2 | E41: 4 | F41: 1 | G41: 44.05176 | H41: 10 | I41: Categories-Category_2 | J41: 1.176 | K41: 500 | L41: 100 | N41: FormicAcid/CO | O41: 0 | P41: 0.2 | Q41: 0.0325 | R41: 77.5 | S41: 170 | T41: 100 | U41: 1812.1302 | V41: 20 | W41: 0.95 | X41: 1 | Y41: 63721.512 | Z41: 3.1860756e+08 | AA41: 3.7468249e+08 | AB41: 374682.49 | AC41: 66773.504 | AD41: 3302.1346 | AE41: 1188768.5 | AF41: 1188768.5 | AG41: 52.367343 | AH41: 104.6354 | AI41: 104.6354 | AJ41: 12177.181 | AK41: 2170.1389 | AL41: PSA | AM41: 8109.2436 | AN41: 693.77358 | AO41: 17788.018 | AP41: 23150.337 | AQ41: 5362.3188 | AR41: 0.010243526 | AS41: 232.53387 | AT41: 154.85306 | AU41: 13.24821 | AV41: 339.67769 | AW41: 442.07583 | AX41: 102.39815 | AY41: 1.998104 | AZ41: =VLOOKUP(BA41,Sheet1!$A$1:$B$58,2,FALSE) -> Isoprene | BA41: Isoprene | BB41: C5H8 | BC41: 68.11622 | BD41: 5.6 | BE41: 34.07 | BF41: Acetaldehyde | BG41: 0.95490794 | BH41: 0.3087395 | BI41: 0.47739676 | BJ41: 90 | BK41: 1028.9039 | BL41: 238.32528 | BM41: 3.6955543 | BN41: 628.24423 | BO41: 400.65963
A42: 40 | B42: Acetaldehyde | C42: C2H4O | D42: 2 | E42: 4 | F42: 1 | G42: 44.05176 | H42: 10 | I42: Categories-Category_2 | J42: 1.176 | K42: 500 | L42: 100 | N42: FormicAcid/CO | O42: 0 | P42: 0.2 | Q42: 0.0325 | R42: 77.5 | S42: 170 | T42: 100 | U42: 1812.1302 | V42: 20 | W42: 0.95 | X42: 1 | Y42: 41982.489 | Z42: 2.0991244e+08 | AA42: 2.4685703e+08 | AB42: 246857.03 | AC42: 0 | AD42: 2175.5891 | AE42: 783212.09 | AF42: 783212.09 | AG42: 34.501871 | AH42: 68.938328 | AI42: 68.938328 | AJ42: 8022.8536 | AK42: 854.70085 | AL42: Nanofiltration | AM42: 5342.7204 | AN42: 457.08805 | AO42: 11719.516 | AP42: 14677.363 | AQ42: 2957.8471 | AR42: 0.010243526 | AS42: 232.53387 | AT42: 154.85306 | AU42: 13.24821 | AV42: 339.67769 | AW42: 425.40774 | AX42: 85.730049 | AY42: 1.998104 | AZ42: =VLOOKUP(BA42,Sheet1!$A$1:$B$58,2,FALSE) -> Isopropanol | BA42: Isopropanol | BB42: C3H8O | BC42: 60.09382 | BD42: 6 | BE42: 82.5 | BF42: Acetaldehyde | BG42: 0.56046861 | BH42: 0.53116667 | BI42: 0.72459838 | BJ42: 90 | BK42: 652.32724 | BL42: 131.45987 | BM42: 2.5034571 | BN42: 425.58771 | BO42: 226.73953
A43: 41 | B43: Acetaldehyde | C43: C2H4O | D43: 2 | E43: 4 | F43: 1 | G43: 44.05176 | H43: 10 | I43: Categories-Category_2 | J43: 1.176 | K43: 500 | L43: 100 | N43: FormicAcid/CO | O43: 0 | P43: 0.2 | Q43: 0.0325 | R43: 77.5 | S43: 170 | T43: 100 | U43: 1812.1302 | V43: 20 | W43: 0.95 | X43: 1 | Y43: 22599.884 | Z43: 1.1299942e+08 | AA43: 1.3288732e+08 | AB43: 132887.32 | AC43: 0 | AD43: 1171.1565 | AE43: 421616.33 | AF43: 421616.33 | AG43: 18.572941 | AH43: 37.110669 | AI43: 37.110669 | AJ43: 4318.8379 | AK43: 854.70085 | AL43: Nanofiltration | AM43: 2876.0769 | AN43: 246.05823 | AO43: 6308.8138 | AP43: 8295.6738 | AQ43: 1986.8601 | AR43: 0.010243526 | AS43: 232.53387 | AT43: 154.85306 | AU43: 13.24821 | AV43: 339.67769 | AW43: 446.65375 | AX43: 106.97606 | AY43: 1.998104 | AZ43: =VLOOKUP(BA43,Sheet1!$A$1:$B$58,2,FALSE) -> Itaconate | BA43: Itaconate | BB43: C5H4O4 | BC43: 128.08086 | BD43: 3.2 | BE43: 381 | BF43: Acetaldehyde | BG43: -0.23362853 | BH43: 0.46295455 | BI43: 1.3460442 | BJ43: 90 | BK43: 368.69661 | BL43: 88.304892 | BM43: 1.8829916 | BN43: 320.10857 | BO43: 48.588042
A44: 42 | B44: Acetaldehyde | C44: C2H4O | D44: 2 | E44: 4 | F44: 1 | G44: 44.05176 | H44: 10 | I44: Categories-Category_2 | J44: 1.176 | K44: 500 | L44: 100 | N44: FormicAcid/CO | O44: 0 | P44: 0.2 | Q44: 0.0325 | R44: 77.5 | S44: 170 | T44: 100 | U44: 1812.1302 | V44: 20 | W44: 0.95 | X44: 1 | Y44: 63453.775 | Z44: 3.1726887e+08 | AA44: 3.731082e+08 | AB44: 373108.2 | AC44: 0 | AD44: 3288.2601 | AE44: 1183773.6 | AF44: 1183773.6 | AG44: 52.147313 | AH44: 104.19576 | AI44: 104.19576 | AJ44: 12126.016 | AK44: 854.70085 | AL44: Nanofiltration | AM44: 8075.1711 | AN44: 690.85857 | AO44: 17713.279 | AP44: 21746.747 | AQ44: 4033.4683 | AR44: 0.010243526 | AS44: 232.53387 | AT44: 154.85306 | AU44: 13.24821 | AV44: 339.67769 | AW44: 417.02527 | AX44: 77.347577 | AY44: 1.998104 | AZ44: =VLOOKUP(BA44,Sheet1!$A$1:$B$58,2,FALSE) -> Limonene | BA44: Limonene | BB44: C10H16 | BC44: 136.23244 | BD44: 5.6 | BE44: 176 | BF44: Acetaldehyde | BG44: 0.93732216 | BH44: 0.1550211 | BI44: 0.47941109 | BJ44: 90 | BK44: 966.52208 | BL44: 179.26526 | BM44: 3.6936003 | BN44: 627.91206 | BO44: 338.61003
A45: 43 | B45: Acetaldehyde | C45: C2H4O | D45: 2 | E45: 4 | F45: 1 | G45: 44.05176 | H45: 10 | I45: Categories-Category_2 | J45: 1.176 | K45: 500 | L45: 100 | N45: FormicAcid/CO | O45: 0 | P45: 0.2 | Q45: 0.0325 | R45: 77.5 | S45: 170 | T45: 100 | U45: 1812.1302 | V45: 20 | W45: 0.95 | X45: 1 | Y45: 32214.045 | Z45: 1.6107022e+08 | AA45: 1.8941858e+08 | AB45: 189418.58 | AC45: 0 | AD45: 1669.3752 | AE45: 600975.08 | AF45: 600975.08 | AG45: 26.47401 | AH45: 52.897826 | AI45: 52.897826 | AJ45: 6156.1039 | AK45: 854.70085 | AL45: Nanofiltration | AM45: 4099.5815 | AN45: 350.73325 | AO45: 8992.6305 | AP45: 11461.12 | AQ45: 2468.4891 | AR45: 0.010243526 | AS45: 232.53387 | AT45: 154.85306 | AU45: 13.24821 | AV45: 339.67769 | AW45: 432.91967 | AX45: 93.24198 | AY45: 1.998104 | AZ45: =VLOOKUP(BA45,Sheet1!$A$1:$B$58,2,FALSE) -> L-Lysine | BA45: Lysine_L | BB45: C6H15N2O2 | BC45: 147.1932 | BD45: 4.8333333 | BF45: Acetaldehyde | BG45: 0.32194431 | BH45: 0.28261538 | BI45: 0.94432238 | BJ45: 90 | BK45: 509.38309 | BL45: 109.71063 | BM45: 2.0290702 | BN45: 344.94193 | BO45: 164.44116
A46: 44 | B46: Acetaldehyde | C46: C2H4O | D46: 2 | E46: 4 | F46: 1 | G46: 44.05176 | H46: 10 | I46: Categories-Category_2 | J46: 1.176 | K46: 500 | L46: 100 | N46: FormicAcid/CO | O46: 0 | P46: 0.2 | Q46: 0.0325 | R46: 77.5 | S46: 170 | T46: 100 | U46: 1812.1302 | V46: 20 | W46: 0.95 | X46: 1 | Y46: 15441.805 | Z46: 77209023 | AA46: 90797811 | AB46: 90797.811 | AC46: 0 | AD46: 800.21513 | AE46: 288077.45 | AF46: 288077.45 | AG46: 12.690319 | AH46: 25.356577 | AI46: 25.356577 | AJ46: 2950.9289 | AK46: 854.70085 | AL46: Nanofiltration | AM46: 1965.1347 | AN46: 168.12401 | AO46: 4310.6181 | AP46: 5938.8884 | AQ46: 1628.2704 | AR46: 0.010243526 | AS46: 232.53387 | AT46: 154.85306 | AU46: 13.24821 | AV46: 339.67769 | AW46: 467.98577 | AX46: 128.30808 | AY46: 1.998104 | AZ46: =VLOOKUP(BA46,Sheet1!$A$1:$B$58,2,FALSE) -> L-Malate | BA46: Malate_L | BB46: C4H4O5 | BC46: 132.06916 | BD46: 2.5 | BF46: Acetaldehyde | BG46: -0.31867491 | BH46: 0.65709677 | BI46: 1.9700057 | BJ46: 90 | BK46: 263.9506 | BL46: 72.367572 | BM46: 1.4456339 | BN46: 245.75776 | BO46: 18.192837
A47: 45 | B47: Acetaldehyde | C47: C2H4O | D47: 2 | E47: 4 | F47: 1 | G47: 44.05176 | H47: 10 | I47: Categories-Category_2 | J47: 1.176 | K47: 500 | L47: 100 | N47: FormicAcid/CO | O47: 0 | P47: 0.2 | Q47: 0.0325 | R47: 77.5 | S47: 170 | T47: 100 | U47: 1812.1302 | V47: 20 | W47: 0.95 | X47: 1 | Y47: 14237.441 | Z47: 71187205 | AA47: 83716153 | AB47: 83716.153 | AC47: 0 | AD47: 737.80339 | AE47: 265609.22 | AF47: 265609.22 | AG47: 11.700554 | AH47: 23.378923 | AI47: 23.378923 | AJ47: 2720.775 | AK47: 854.70085 | AL47: Nanofiltration | AM47: 1811.8666 | AN47: 155.0114 | AO47: 3974.417 | AP47: 5542.3538 | AQ47: 1567.9368 | AR47: 0.010243526 | AS47: 232.53387 | AT47: 154.85306 | AU47: 13.24821 | AV47: 339.67769 | AW47: 473.68304 | AX47: 134.00535 | AY47: 1.998104 | AZ47: =VLOOKUP(BA47,Sheet1!$A$1:$B$58,2,FALSE) -> Malonate | BA47: Malonate | BB47: C3H2O4 | BC47: 102.04378 | BD47: 2 | BE47: 199 | BF47: Acetaldehyde | BG47: -0.35869948 | BH47: 0.92238095 | BI47: 2.136651 | BJ47: 90 | BK47: 246.32684 | BL47: 69.686081 | BM47: 1.3977627 | BN47: 237.61967 | BO47: 8.7071687
A48: 46 | B48: Acetaldehyde | C48: C2H4O | D48: 2 | E48: 4 | F48: 1 | G48: 44.05176 | H48: 10 | I48: Categories-Category_2 | J48: 1.176 | K48: 500 | L48: 100 | N48: FormicAcid/CO | O48: 0 | P48: 0.2 | Q48: 0.0325 | R48: 77.5 | S48: 170 | T48: 100 | U48: 1812.1302 | V48: 20 | W48: 0.95 | X48: 1 | Y48: 61916.248 | Z48: 3.0958124e+08 | AA48: 3.6406754e+08 | AB48: 364067.54 | AC48: 0 | AD48: 3208.5834 | AE48: 1155090 | AF48: 1155090 | AG48: 50.883749 | AH48: 101.67103 | AI48: 101.67103 | AJ48: 11832.195 | AK48: 854.70085 | AL48: Nanofiltration | AM48: 7879.5045 | AN48: 674.11861 | AO48: 17284.074 | AP48: 21240.519 | AQ48: 3956.4447 | AR48: 0.010243526 | AS48: 232.53387 | AT48: 154.85306 | AU48: 13.24821 | AV48: 339.67769 | AW48: 417.43227 | AX48: 77.754583 | AY48: 1.998104 | AZ48: =VLOOKUP(BA48,Sheet1!$A$1:$B$58,2,FALSE) -> Nonane | BA48: Nonane | BB48: C9H20 | BC48: 128.2531 | BD48: 6.2222222 | BE48: 151 | BF48: Acetaldehyde | BG48: 0.97849461 | BH48: 0.16875486 | BI48: 0.491316 | BJ48: 90 | BK48: 944.02307 | BL48: 175.84199 | BM48: 3.5402176 | BN48: 601.837 | BO48: 342.18607
A49: 47 | B49: Acetaldehyde | C49: C2H4O | D49: 2 | E49: 4 | F49: 1 | G49: 44.05176 | H49: 10 | I49: Categories-Category_2 | J49: 1.176 | K49: 500 | L49: 100 | N49: FormicAcid/CO | O49: 0 | P49: 0.2 | Q49: 0.0325 | R49: 77.5 | S49: 170 | T49: 100 | U49: 1812.1302 | V49: 20 | W49: 0.95 | X49: 1 | Y49: 62474.532 | Z49: 3.1237266e+08 | AA49: 3.6735025e+08 | AB49: 367350.25 | AC49: 0 | AD49: 3237.5145 | AE49: 1165505.2 | AF49: 1165505.2 | AG49: 51.342555 | AH49: 102.58777 | AI49: 102.58777 | AJ49: 11938.883 | AK49: 854.70085 | AL49: Nanofiltration | AM49: 7950.552 | AN49: 680.19698 | AO49: 17439.921 | AP49: 21424.333 | AQ49: 3984.4123 | AR49: 0.010243526 | AS49: 232.53387 | AT49: 154.85306 | AU49: 13.24821 | AV49: 339.67769 | AW49: 417.28217 | AX49: 77.604481 | AY49: 1.998104 | AZ49: =VLOOKUP(BA49,Sheet1!$A$1:$B$58,2,FALSE) -> Octane | BA49: Octane | BB49: C8H18 | BC49: 114.22672 | BD49: 6.25 | BE49: 126 | BF49: Acetaldehyde | BG49: 1.0212196 | BH49: 0.18778378 | BI49: 0.48692551 | BJ49: 90 | BK49: 952.19257 | BL49: 177.08499 | BM49: 3.5382367 | BN49: 601.50024 | BO49: 350.69233
A50: 48 | B50: Acetaldehyde | C50: C2H4O | D50: 2 | E50: 4 | F50: 1 | G50: 44.05176 | H50: 10 | I50: Categories-Category_2 | J50: 1.176 | K50: 500 | L50: 100 | N50: FormicAcid/CO | O50: 0 | P50: 0.2 | Q50: 0.0325 | R50: 77.5 | S50: 170 | T50: 100 | U50: 1812.1302 | V50: 20 | W50: 0.95 | X50: 1 | Y50: 64026.359 | Z50: 3.2013179e+08 | AA50: 3.7647499e+08 | AB50: 376474.99 | AC50: 66773.504 | AD50: 3317.9322 | AE50: 1194455.6 | AF50: 1194455.6 | AG50: 52.617871 | AH50: 105.13598 | AI50: 105.13598 | AJ50: 12235.437 | AK50: 2170.1389 | AL50: PSA | AM50: 8148.0386 | AN50: 697.09263 | AO50: 17873.117 | AP50: 23250.707 | AQ50: 5377.5904 | AR50: 0.010243526 | AS50: 232.53387 | AT50: 154.85306 | AU50: 13.24821 | AV50: 339.67769 | AW50: 441.87852 | AX50: 102.20084 | AY50: 1.998104 | AZ50: =VLOOKUP(BA50,Sheet1!$A$1:$B$58,2,FALSE) -> Pentane | BA50: Pentane | BB50: C5H12 | BC50: 72.14758 | BD50: 6.4 | BE50: 36.1 | BF50: Acetaldehyde | BG50: 1.1554409 | BH50: 0.29010033 | BI50: 0.47512374 | BJ50: 90 | BK50: 1033.3648 | BL50: 239.00402 | BM50: 3.5172694 | BN50: 597.93579 | BO50: 435.42897
A51: 49 | B51: Acetaldehyde | C51: C2H4O | D51: 2 | E51: 4 | F51: 1 | G51: 44.05176 | H51: 10 | I51: Categories-Category_2 | J51: 1.176 | K51: 500 | L51: 100 | N51: FormicAcid/CO | O51: 0 | P51: 0.2 | Q51: 0.0325 | R51: 77.5 | S51: 170 | T51: 100 | U51: 1812.1302 | V51: 20 | W51: 0.95 | X51: 1 | Y51: 50896.661 | Z51: 2.5448331e+08 | AA51: 2.9927237e+08 | AB51: 299272.37 | AC51: 0 | AD51: 2637.5336 | AE51: 949512.1 | AF51: 949512.1 | AG51: 41.827679 | AH51: 83.576055 | AI51: 83.576055 | AJ51: 9726.352 | AK51: 854.70085 | AL51: Nanofiltration | AM51: 6477.1442 | AN51: 554.14189 | AO51: 14207.929 | AP51: 17612.339 | AQ51: 3404.4097 | AR51: 0.010243526 | AS51: 232.53387 | AT51: 154.85306 | AU51: 13.24821 | AV51: 339.67769 | AW51: 421.069 | AX51: 81.391313 | AY51: 1.998104 | AZ51: =VLOOKUP(BA51,Sheet1!$A$1:$B$58,2,FALSE) -> Pentanol (PW1) | BA51: Pentanol-PW1 | BB51: C5H12O | BC51: 88.14658 | BD51: 6 | BE51: 138 | BF51: Acetaldehyde | BG51: 0.84663223 | BH51: 0.29869919 | BI51: 0.59769035 | BJ51: 90 | BK51: 782.77062 | BL51: 151.3071 | BM51: 2.8678591 | BN51: 487.53605 | BO51: 295.23458
A52: 50 | B52: Acetaldehyde | C52: C2H4O | D52: 2 | E52: 4 | F52: 1 | G52: 44.05176 | H52: 10 | I52: Categories-Category_2 | J52: 1.176 | K52: 500 | L52: 100 | N52: FormicAcid/CO | O52: 0 | P52: 0.2 | Q52: 0.0325 | R52: 77.5 | S52: 170 | T52: 100 | U52: 1812.1302 | V52: 20 | W52: 0.95 | X52: 1 | Y52: 55601.765 | Z52: 2.7800883e+08 | AA52: 3.2693838e+08 | AB52: 326938.38 | AC52: 0 | AD52: 2881.3584 | AE52: 1037289 | AF52: 1037289 | AG52: 45.694407 | AH52: 91.302181 | AI52: 91.302181 | AJ52: 10625.497 | AK52: 854.70085 | AL52: Nanofiltration | AM52: 7075.919 | AN52: 605.36912 | AO52: 15521.371 | AP52: 19161.486 | AQ52: 3640.1156 | AR52: 0.010243526 | AS52: 232.53387 | AT52: 154.85306 | AU52: 13.24821 | AV52: 339.67769 | AW52: 419.33986 | AX52: 79.662169 | AY52: 1.998104 | AZ52: =VLOOKUP(BA52,Sheet1!$A$1:$B$58,2,FALSE) -> Pentanol (PW2) | BA52: Pentanol-PW2 | BB52: C5H12O | BC52: 88.14658 | BD52: 6 | BE52: 138 | BF52: Acetaldehyde | BG52: 1.1556773 | BH52: 0.27342282 | BI52: 0.5471129 | BJ52: 90 | BK52: 851.62161 | BL52: 161.78292 | BM52: 2.9021974 | BN52: 493.37356 | BO52: 358.24805
A53: 51 | B53: Acetaldehyde | C53: C2H4O | D53: 2 | E53: 4 | F53: 1 | G53: 44.05176 | H53: 10 | I53: Categories-Category_2 | J53: 1.176 | K53: 500 | L53: 100 | N53: FormicAcid/CO | O53: 0 | P53: 0.2 | Q53: 0.0325 | R53: 77.5 | S53: 170 | T53: 100 | U53: 1812.1302 | V53: 20 | W53: 0.95 | X53: 1 | Y53: 57619.087 | Z53: 2.8809544e+08 | AA53: 3.3880023e+08 | AB53: 338800.23 | AC53: 0 | AD53: 2985.8988 | AE53: 1074923.6 | AF53: 1074923.6 | AG53: 47.352274 | AH53: 94.614771 | AI53: 94.614771 | AJ53: 11011.008 | AK53: 854.70085 | AL53: Nanofiltration | AM53: 7332.6448 | AN53: 627.33289 | AO53: 16084.511 | AP53: 19825.686 | AQ53: 3741.175 | AR53: 0.010243526 | AS53: 232.53387 | AT53: 154.85306 | AU53: 13.24821 | AV53: 339.67769 | AW53: 418.68498 | AX53: 79.007292 | AY53: 1.998104 | AZ53: =VLOOKUP(BA53,Sheet1!$A$1:$B$58,2,FALSE) -> Phenol | BA53: Phenol | BB53: C6H6O | BC53: 94.11024 | BD53: 4.6666667 | BE53: 181.7 | BF53: Acetaldehyde | BG53: 0.97873253 | BH53: 0.24713004 | BI53: 0.52795774 | BJ53: 90 | BK53: 881.1416 | BL53: 166.27444 | BM53: 3.2263684 | BN53: 548.48263 | BO53: 332.65897
A54: 52 | B54: Acetaldehyde | C54: C2H4O | D54: 2 | E54: 4 | F54: 1 | G54: 44.05176 | H54: 10 | I54: Categories-Category_2 | J54: 1.176 | K54: 500 | L54: 100 | N54: FormicAcid/CO | O54: 0 | P54: 0.2 | Q54: 0.0325 | R54: 77.5 | S54: 170 | T54: 100 | U54: 1812.1302 | V54: 20 | W54: 0.95 | X54: 1 | Y54: 66919.884 | Z54: 3.3459942e+08 | AA54: 3.9348892e+08 | AB54: 393488.92 | AC54: 66773.504 | AD54: 3467.8786 | AE54: 1248436.3 | AF54: 1248436.3 | AG54: 54.995816 | AH54: 109.88736 | AI54: 109.88736 | AJ54: 12788.39 | AK54: 2170.1389 | AL54: PSA | AM54: 8516.2706 | AN54: 728.59614 | AO54: 18680.852 | AP54: 24203.395 | AQ54: 5522.5438 | AR54: 0.010243526 | AS54: 232.53387 | AT54: 154.85306 | AU54: 13.24821 | AV54: 339.67769 | AW54: 440.09522 | AX54: 100.41753 | AY54: 1.998104 | AZ54: =VLOOKUP(BA54,Sheet1!$A$1:$B$58,2,FALSE) -> Propane (PW1) | BA54: Propane-PW1 | BB54: C3H8 | BC54: 44.09482 | BD54: 6.6666667 | BE54: -42 | BF54: Acetaldehyde | BG54: 1.4012652 | BH54: 0.45413613 | BI54: 0.45458004 | BJ54: 90 | BK54: 1075.7065 | BL54: 245.44639 | BM54: 3.4826175 | BN54: 592.04498 | BO54: 483.66148
...

Sheet Sheet1
B1: BioProduct_Graph
A2: 1-3-Butanediol-PW1 | B2: 1,3-Butanediol (PW1)
A3: 1-3-Butanediol-PW2 | B3: 1,3-Butanediol (PW2)
A4: 1-3-Diaminopropane | B4: 1,3-Diaminopropane
A5: 1-3-Propanediol | B5: 1,3-Propanediol
A6: 1-4-Butanediol | B6: 1,4-Butanediol
A7: 1-Propanol-PW1 | B7: 1-Propanol (PW1)
A8: 1-Propanol-PW2 | B8: 1-Propanol (PW2)
A9: 2-3-Butanediol | B9: 2,3-Butanediol
A10: 2-Methyl-1-Butanol | B10: 2-Methyl-1-Butanol
A11: 2-Pyrone-4-6-Dicarboxylate | B11: 2-Pyrone-4,6-Dicarboxylate
A12: 3-Methyl-1-Pentanol | B12: 3-Methyl-1-Pentanol
A13: 4-Hydroxystyrene | B13: 4-Hydroxystyrene
... A58: Succinate | B58: Succinate
