Workbook

Sheet Overall-ECR-Bio
B1: Substrate | C1: Formula_S | D1: C_Sn | E1: H_Sn | F1: O_Sn | G1: MW_S | H1: N_electrons | I1: ParametersType | J1: CellVoltage | K1: CurrentDensity | L1: FaradaicEfficiency | M1: EnergyEfficiency | N1: ByProducts | O1: ByP_FE | P1: Xco2 | Q1: ElectricityPrice | R1: CO2Price | S1: CarbonTax | T1: Conversion | U1: ElectrolyzerPrice | V1: PlantLife | W1: StreamFactor | X1: ScalingFactor | Y1: ElectrodeArea | Z1: I | AA1: Power | AB1: kWh | AC1: kWh_sep | AD1: emol_curr | AE1: MaxProductionRate | AF1: ActualProductionRate | AG1: ActualProductionRate_mass | AH1: CO2rate_fed | AI1: CO2rate_conv | AJ1: Cost_elec_h | AK1: Cost_h_sep | AL1: Type_sep | AM1: Cost_CO2_h | AN1: Cost_electrolyzer_h | AO1: CT_savings_h | AP1: ProductionCost_hNOCT | AQ1: ProductionCost_h | AR1: Cost_elec_mol | AS1: Cost_elec_mass | AT1: Cost_CO2_mass | AU1: Cost_electrolyzer_mass | AV1: CT_savings_mass | AW1: ProductionCost_massNOCT | AX1: ProductionCost_mass | AY1: CO2_ECons_mass | AZ1: BioProduct | BA1: BioProduct_Graph | BB1: Formula_BP | BC1: MW_BP | BD1: Deg_RedBP | BE1: BoilP_degC | BF1: SubstratePathway | BG1: CO2_BProd_mass | BH1: YieldBP_Molar | BI1: YieldBP_Mass | BJ1: Bioconversion | BK1: BioproductionCost_massNOCT | BL1: BioproductionCost_mass1 | BM1: CO2_OverallCons_mass | BN1: CT_OverallSavings_mass | BO1: BioproductionCost_mass2
A2: 0 | B2: Acetaldehyde | C2: C2H4O | D2: 2 | E2: 4 | F2: 1 | G2: 44.05176 | H2: 10 | I2: Categories-Category_1 | J2: 2 | K2: 20 | L2: 60 | N2: FormicAcid/CO | O2: 40 | P2: 0.32 | Q2: 0.0325 | R2: 77.5 | S2: 170 | T2: 50 | U2: 1812.1302 | V2: 20 | W2: 0.95 | X2: 1 | Y2: 1416577.6 | Z2: 2.8331552e+08 | AA2: 5.6663104e+08 | AB2: 566631.04 | AC2: 0 | AD2: 2936.3584 | AE2: 1057089 | AF2: 634253.42 | AG2: 27.939979 | AH2: 297.74392 | AI2: 148.87196 | AJ2: 18415.509 | AK2: 854.70085 | AL2: Nanofiltration | AM2: 23075.154 | AN2: 15808.691 | AO2: 25308.234 | AP2: 58154.055 | AQ2: 32845.821 | AR2: 0.029034938 | AS2: 659.10961 | AT2: 825.88301 | AU2: 565.80898 | AV2: 905.80717 | AW2: 2081.3922 | AX2: 1175.585 | AY2: 5.3282775 | AZ2: 1-3-Butanediol-PW1 | BA2: =VLOOKUP($AZ2,Sheet1!$A$2:$B$58,2) -> 1,3-Butanediol (PW1) | BB2: C4H10O2 | BC2: 90.1192 | BD2: 5.5 | BE2: 207 | BF2: Acetaldehyde | BG2: 0.27966661 | BH2: 0.43738095 | BI2: 0.89477518 | BJ2: 80 | BK2: 2907.7027 | BL2: 1642.2911 | BM2: 7.1639315 | BN2: 1217.8684 | BO2: 1689.8344
A3: 1 | B3: Acetaldehyde | C3: C2H4O | D3: 2 | E3: 4 | F3: 1 | G3: 44.05176 | H3: 10 | I3: Categories-Category_1 | J3: 2 | K3: 20 | L3: 60 | N3: FormicAcid/CO | O3: 40 | P3: 0.32 | Q3: 0.0325 | R3: 77.5 | S3: 170 | T3: 50 | U3: 1812.1302 | V3: 20 | W3: 0.95 | X3: 1 | Y3: 1392885.5 | Z3: 2.7857711e+08 | AA3: 5.5715421e+08 | AB3: 557154.21 | AC3: 0 | AD3: 2887.2482 | AE3: 1039409.4 | AF3: 623645.62 | AG3: 27.472687 | AH3: 292.7642 | AI3: 146.3821 | AJ3: 18107.512 | AK3: 854.70085 | AL3: Nanofiltration | AM3: 22689.225 | AN3: 15544.293 | AO3: 24884.957 | AP3: 57195.731 | AQ3: 32310.774 | AR3: 0.029034938 | AS3: 659.10961 | AT3: 825.88301 | AU3: 565.80898 | AV3: 905.80717 | AW3: 2081.9125 | AX3: 1176.1054 | AY3: 5.3282775 | AZ3: 1-3-Butanediol-PW2 | BA3: =VLOOKUP($AZ3,Sheet1!$A$2:$B$58,2) -> 1,3-Butanediol (PW2) | BB3: C4H10O2 | BC3: 90.1192 | BD3: 5.5 | BE3: 207 | BF3: Acetaldehyde | BG3: 0.24231868 | BH3: 0.44482051 | BI3: 0.90999471 | BJ3: 80 | BK3: 2859.7866 | BL3: 1615.5387 | BM3: 7.0767863 | BN3: 1203.0537 | BO3: 1656.7329
A4: 2 | B4: Acetaldehyde | C4: C2H4O | D4: 2 | E4: 4 | F4: 1 | G4: 44.05176 | H4: 10 | I4: Categories-Category_1 | J4: 2 | K4: 20 | L4: 60 | N4: FormicAcid/CO | O4: 40 | P4: 0.32 | Q4: 0.0325 | R4: 77.5 | S4: 170 | T4: 50 | U4: 1812.1302 | V4: 20 | W4: 0.95 | X4: 1 | Y4: 1477065.2 | Z4: 2.9541303e+08 | AA4: 5.9082606e+08 | AB4: 590826.06 | AC4: 0 | AD4: 3061.7403 | AE4: 1102226.5 | AF4: 661335.9 | AG4: 29.13301 | AH4: 310.45753 | AI4: 155.22876 | AJ4: 19201.847 | AK4: 854.70085 | AL4: Nanofiltration | AM4: 24060.458 | AN4: 16483.719 | AO4: 26388.89 | AP4: 60600.725 | AQ4: 34211.835 | AR4: 0.029034938 | AS4: 659.10961 | AT4: 825.88301 | AU4: 565.80898 | AV4: 905.80717 | AW4: 2080.1395 | AX4: 1174.3323 | AY4: 5.3282775 | AZ4: 1-3-Diaminopropane | BA4: =VLOOKUP($AZ4,Sheet1!$A$2:$B$58,2) -> 1,3-Diaminopropane | BB4: C3H12N2 | BC4: 76.13958 | BD4: 6 | BE4: 139.3 | BF4: Acetaldehyde | BG4: 0.59437932 | BH4: 0.49648649 | BI4: 0.85813308 | BJ4: 80 | BK4: 3030.0363 | BL4: 1710.5918 | BM4: 7.1670588 | BN4: 1218.4 | BO4: 1811.6363
A5: 3 | B5: Acetaldehyde | C5: C2H4O | D5: 2 | E5: 4 | F5: 1 | G5: 44.05176 | H5: 10 | I5: Categories-Category_1 | J5: 2 | K5: 20 | L5: 60 | N5: FormicAcid/CO | O5: 40 | P5: 0.32 | Q5: 0.0325 | R5: 77.5 | S5: 170 | T5: 50 | U5: 1812.1302 | V5: 20 | W5: 0.95 | X5: 1 | Y5: 1436325.9 | Z5: 2.8726517e+08 | AA5: 5.7453035e+08 | AB5: 574530.35 | AC5: 0 | AD5: 2977.2937 | AE5: 1071825.7 | AF5: 643095.44 | AG5: 28.329486 | AH5: 301.89472 | AI5: 150.94736 | AJ5: 18672.236 | AK5: 854.70085 | AL5: Nanofiltration | AM5: 23396.841 | AN5: 16029.078 | AO5: 25661.051 | AP5: 58952.856 | AQ5: 33291.804 | AR5: 0.029034938 | AS5: 659.10961 | AT5: 825.88301 | AU5: 565.80898 | AV5: 905.80717 | AW5: 2080.9716 | AX5: 1175.1644 | AY5: 5.3282775 | AZ5: 1-3-Propanediol | BA5: =VLOOKUP($AZ5,Sheet1!$A$2:$B$58,2) -> 1,3-Propanediol | BB5: C3H8O2 | BC5: 76.09282 | BD5: 5.3333333 | BE5: 213 | BF5: Acetaldehyde | BG5: 0.5290927 | BH5: 0.51088235 | BI5: 0.88247278 | BJ5: 80 | BK5: 2947.6428 | BL5: 1664.5902 | BM5: 7.0182753 | BN5: 1193.1068 | BO5: 1754.536
A6: 4 | B6: Acetaldehyde | C6: C2H4O | D6: 2 | E6: 4 | F6: 1 | G6: 44.05176 | H6: 10 | I6: Categories-Category_1 | J6: 2 | K6: 20 | L6: 60 | N6: FormicAcid/CO | O6: 40 | P6: 0.32 | Q6: 0.0325 | R6: 77.5 | S6: 170 | T6: 50 | U6: 1812.1302 | V6: 20 | W6: 0.95 | X6: 1 | Y6: 1533800.5 | Z6: 3.067601e+08 | AA6: 6.1352019e+08 | AB6: 613520.19 | AC6: 0 | AD6: 3179.3443 | AE6: 1144564 | AF6: 686738.38 | AG6: 30.252034 | AH6: 322.38246 | AI6: 161.19123 | AJ6: 19939.406 | AK6: 854.70085 | AL6: Nanofiltration | AM6: 24984.641 | AN6: 17116.873 | AO6: 27402.509 | AP6: 62895.621 | AQ6: 35493.111 | AR6: 0.029034938 | AS6: 659.10961 | AT6: 825.88301 | AU6: 565.80898 | AV6: 905.80717 | AW6: 2079.0543 | AX6: 1173.2471 | AY6: 5.3282775 | AZ6: 1-4-Butanediol | BA6: =VLOOKUP($AZ6,Sheet1!$A$2:$B$58,2) -> 1,4-Butanediol | BB6: C4H10O2 | BC6: 90.1192 | BD6: 5.5 | BE6: 230 | BF6: Acetaldehyde | BG6: 0.46445567 | BH6: 0.40395349 | BI6: 0.82639071 | BJ6: 80 | BK6: 3144.781 | BL6: 1774.6556 | BM6: 7.5951059 | BN6: 1291.168 | BO6: 1853.613
A7: 5 | B7: Acetaldehyde | C7: C2H4O | D7: 2 | E7: 4 | F7: 1 | G7: 44.05176 | H7: 10 | I7: Categories-Category_1 | J7: 2 | K7: 20 | L7: 60 | N7: FormicAcid/CO | O7: 40 | P7: 0.32 | Q7: 0.0325 | R7: 77.5 | S7: 170 | T7: 50 | U7: 1812.1302 | V7: 20 | W7: 0.95 | X7: 1 | Y7: 2001814.9 | Z7: 4.0036299e+08 | AA7: 8.0072598e+08 | AB7: 800725.98 | AC7: 0 | AD7: 4149.4699 | AE7: 1493809.2 | AF7: 896285.51 | AG7: 39.482954 | AH7: 420.75227 | AI7: 210.37613 | AJ7: 26023.594 | AK7: 854.70085 | AL7: Nanofiltration | AM7: 32608.301 | AN7: 22339.81 | AO7: 35763.943 | AP7: 81826.406 | AQ7: 46062.463 | AR7: 0.029034938 | AS7: 659.10961 | AT7: 825.88301 | AU7: 565.80898 | AV7: 905.80717 | AW7: 2072.4489 | AX7: 1166.6418 | AY7: 5.3282775 | AZ7: 1-Propanol-PW1 | BA7: =VLOOKUP($AZ7,Sheet1!$A$2:$B$58,2) -> 1-Propanol (PW1) | BB7: C3H8O | BC7: 60.09382 | BD7: 6 | BE7: 97 | BF7: Acetaldehyde | BG7: 0.95857749 | BH7: 0.46415584 | BI7: 0.63318464 | BJ7: 80 | BK7: 4091.3203 | BL7: 2303.1232 | BM7: 9.5602292 | BN7: 1625.239 | BO7: 2466.0813
A8: 6 | B8: Acetaldehyde | C8: C2H4O | D8: 2 | E8: 4 | F8: 1 | G8: 44.05176 | H8: 10 | I8: Categories-Category_1 | J8: 2 | K8: 20 | L8: 60 | N8: FormicAcid/CO | O8: 40 | P8: 0.32 | Q8: 0.0325 | R8: 77.5 | S8: 170 | T8: 50 | U8: 1812.1302 | V8: 20 | W8: 0.95 | X8: 1 | Y8: 2149648.9 | Z8: 4.2992977e+08 | AA8: 8.5985954e+08 | AB8: 859859.54 | AC8: 0 | AD8: 4455.908 | AE8: 1604126.9 | AF8: 962476.14 | AG8: 42.398768 | AH8: 451.8248 | AI8: 225.9124 | AJ8: 27945.435 | AK8: 854.70085 | AL8: Nanofiltration | AM8: 35016.422 | AN8: 23989.604 | AO8: 38405.108 | AP8: 87806.162 | AQ8: 49401.054 | AR8: 0.029034938 | AS8: 659.10961 | AT8: 825.88301 | AU8: 565.80898 | AV8: 905.80717 | AW8: 2070.9602 | AX8: 1165.1531 | AY8: 5.3282775 | AZ8: 1-Propanol-PW2 | BA8: =VLOOKUP($AZ8,Sheet1!$A$2:$B$58,2) -> 1-Propanol (PW2) | BB8: C3H8O | BC8: 60.09382 | BD8: 6 | BE8: 97 | BF8: Acetaldehyde | BG8: 1.1916215 | BH8: 0.43223529 | BI8: 0.58963978 | BJ8: 80 | BK8: 4390.3081 | BL8: 2470.0527 | BM8: 10.103998 | BN8: 1717.6797 | BO8: 2672.6283
A9: 7 | B9: Acetaldehyde | C9: C2H4O | D9: 2 | E9: 4 | F9: 1 | G9: 44.05176 | H9: 10 | I9: Categories-Category_1 | J9: 2 | K9: 20 | L9: 60 | N9: FormicAcid/CO | O9: 40 | P9: 0.32 | Q9: 0.0325 | R9: 77.5 | S9: 170 | T9: 50 | U9: 1812.1302 | V9: 20 | W9: 0.95 | X9: 1 | Y9: 1450305.6 | Z9: 2.9006113e+08 | AA9: 5.8012225e+08 | AB9: 580122.25 | AC9: 0 | AD9: 3006.2717 | AE9: 1082257.8 | AF9: 649354.69 | AG9: 28.605217 | AH9: 304.83306 | AI9: 152.41653 | AJ9: 18853.973 | AK9: 854.70085 | AL9: Nanofiltration | AM9: 23624.563 | AN9: 16185.089 | AO9: 25910.81 | AP9: 59518.325 | AQ9: 33607.515 | AR9: 0.029034938 | AS9: 659.10961 | AT9: 825.88301 | AU9: 565.80898 | AV9: 905.80717 | AW9: 2080.6808 | AX9: 1174.8736 | AY9: 5.3282775 | AZ9: 2-3-Butanediol | BA9: =VLOOKUP($AZ9,Sheet1!$A$2:$B$58,2) -> 2,3-Butanediol | BB9: C4H10O2 | BC9: 90.1192 | BD9: 5.5 | BE9: 177 | BF9: Acetaldehyde | BG9: 0.33283517 | BH9: 0.4272093 | BI9: 0.87396646 | BJ9: 80 | BK9: 2975.9163 | BL9: 1680.3757 | BM9: 7.2879914 | BN9: 1238.9585 | BO9: 1736.9577
A10: 8 | B10: Acetaldehyde | C10: C2H4O | D10: 2 | E10: 4 | F10: 1 | G10: 44.05176 | H10: 10 | I10: Categories-Category_1 | J10: 2 | K10: 20 | L10: 60 | N10: FormicAcid/CO | O10: 40 | P10: 0.32 | Q10: 0.0325 | R10: 77.5 | S10: 170 | T10: 50 | U10: 1812.1302 | V10: 20 | W10: 0.95 | X10: 1 | Y10: 2310349.8 | Z10: 4.6206996e+08 | AA10: 9.2413992e+08 | AB10: 924139.92 | AC10: 0 | AD10: 4789.0176 | AE10: 1724046.4 | AF10: 1034427.8 | AG10: 45.568366 | AH10: 485.60179 | AI10: 242.8009 | AJ10: 30034.548 | AK10: 854.70085 | AL10: Nanofiltration | AM10: 37634.139 | AN10: 25782.991 | AO10: 41276.152 | AP10: 94306.378 | AQ10: 53030.226 | AR10: 0.029034938 | AS10: 659.10961 | AT10: 825.88301 | AU10: 565.80898 | AV10: 905.80717 | AW10: 2069.558 | AX10: 1163.7509 | AY10: 5.3282775 | AZ10: 2-Methyl-1-Butanol | BA10: =VLOOKUP($AZ10,Sheet1!$A$2:$B$58,2) -> 2-Methyl-1-Butanol | BB10: C5H12O | BC10: 88.14658 | BD10: 6 | BE10: 129 | BF10: Acetaldehyde | BG10: 1.1456035 | BH10: 0.2741791 | BI10: 0.54862622 | BJ10: 80 | BK10: 4715.3189 | BL10: 2651.5113 | BM10: 10.994441 | BN10: 1869.055 | BO10: 2846.2639
A11: 9 | B11: Acetaldehyde | C11: C2H4O | D11: 2 | E11: 4 | F11: 1 | G11: 44.05176 | H11: 10 | I11: Categories-Category_1 | J11: 2 | K11: 20 | L11: 60 | N11: FormicAcid/CO | O11: 40 | P11: 0.32 | Q11: 0.0325 | R11: 77.5 | S11: 170 | T11: 50 | U11: 1812.1302 | V11: 20 | W11: 0.95 | X11: 1 | Y11: 990453.26 | Z11: 1.9809065e+08 | AA11: 3.961813e+08 | AB11: 396181.3 | AC11: 0 | AD11: 2053.0649 | AE11: 739103.37 | AF11: 443462.02 | AG11: 19.535282 | AH11: 208.17881 | AI11: 104.08941 | AJ11: 12875.892 | AK11: 1835.3365 | AL11: Distillation | AM11: 16133.858 | AN11: 11053.238 | AO11: 17695.199 | AP11: 41898.325 | AQ11: 24203.126 | AR11: 0.029034938 | AS11: 659.10961 | AT11: 825.88301 | AU11: 565.80898 | AV11: 905.80717 | AW11: 2144.7514 | AX11: 1238.9443 | AY11: 5.3282775 | AZ11: 2-Pyrone-4-6-Dicarboxylate | BA11: =VLOOKUP($AZ11,Sheet1!$A$2:$B$58,2) -> 2-Pyrone-4,6-Dicarboxylate | BB11: C7H2O6 | BC11: 182.08458 | BD11: 2.5714286 | BE11: 355.5 | BF11: Acetaldehyde | BG11: -0.13056496 | BH11: 0.30960674 | BI11: 1.2797358 | BJ11: 80 | BK11: 2094.9163 | BL11: 1210.1563 | BM11: 5.3350352 | BN11: 906.95599 | BO11: 1187.9603
A12: 10 | B12: Acetaldehyde | C12: C2H4O | D12: 2 | E12: 4 | F12: 1 | G12: 44.05176 | H12: 10 | I12: Categories-Category_1 | J12: 2 | K12: 20 | L12: 60 | N12: FormicAcid/CO | O12: 40 | P12: 0.32 | Q12: 0.0325 | R12: 77.5 | S12: 170 | T12: 50 | U12: 1812.1302 | V12: 20 | W12: 0.95 | X12: 1 | Y12: 2379920.3 | Z12: 4.7598406e+08 | AA12: 9.5196813e+08 | AB12: 951968.13 | AC12: 0 | AD12: 4933.2271 | AE12: 1775961.8 | AF12: 1065577.1 | AG12: 46.940545 | AH12: 500.2245 | AI12: 250.11225 | AJ12: 30938.964 | AK12: 854.70085 | AL12: Nanofiltration | AM12: 38767.399 | AN12: 26559.382 | AO12: 42519.082 | AP12: 97120.446 | AQ12: 54601.363 | AR12: 0.029034938 | AS12: 659.10961 | AT12: 825.88301 | AU12: 565.80898 | AV12: 905.80717 | AW12: 2069.0098 | AX12: 1163.2026 | AY12: 5.3282775 | AZ12: 3-Methyl-1-Pentanol | BA12: =VLOOKUP($AZ12,Sheet1!$A$2:$B$58,2) -> 3-Methyl-1-Pentanol | BB12: C6H14O | BC12: 102.17296 | BD12: 6 | BE12: 153 | BF12: Acetaldehyde | BG12: 1.1672426 | BH12: 0.229625 | BI12: 0.53258862 | BJ12: 80 | BK12: 4856.0223 | BL12: 2730.0682 | BM12: 11.33837 | BN12: 1927.5229 | BO12: 2928.4994
A13: 11 | B13: Acetaldehyde | C13: C2H4O | D13: 2 | E13: 4 | F13: 1 | G13: 44.05176 | H13: 10 | I13: Categories-Category_1 | J13: 2 | K13: 20 | L13: 60 | N13: FormicAcid/CO | O13: 40 | P13: 0.32 | Q13: 0.0325 | R13: 77.5 | S13: 170 | T13: 50 | U13: 1812.1302 | V13: 20 | W13: 0.95 | X13: 1 | Y13: 2386489.3 | Z13: 4.7729787e+08 | AA13: 9.5459573e+08 | AB13: 954595.73 | AC13: 0 | AD13: 4946.8438 | AE13: 1780863.8 | AF13: 1068518.3 | AG13: 47.07011 | AH13: 501.60521 | AI13: 250.8026 | AJ13: 31024.361 | AK13: 854.70085 | AL13: Nanofiltration | AM13: 38874.404 | AN13: 26632.691 | AO13: 42636.443 | AP13: 97386.157 | AQ13: 54749.714 | AR13: 0.029034938 | AS13: 659.10961 | AT13: 825.88301 | AU13: 565.80898 | AV13: 905.80717 | AW13: 2068.9596 | AX13: 1163.1525 | AY13: 5.3282775 | AZ13: 4-Hydroxystyrene | BA13: =VLOOKUP($AZ13,Sheet1!$A$2:$B$58,2) -> 4-Hydroxystyrene | BB13: C8H8O | BC13: 120.14732 | BD13: 4.75 | BE13: 229 | BF13: Acetaldehyde | BG13: 0.83163662 | BH13: 0.19473498 | BI13: 0.53112262 | BJ13: 80 | BK13: 4869.3078 | BL13: 2737.4857 | BM13: 11.708494 | BN13: 1990.4439 | BO13: 2878.8639
... A28: 26 | B28: Acetaldehyde | C28: C2H4O | D28: 2 | E28: 4 | F28: 1 | G28: 44.05176 | H28: 10 | I28: Categories-Category_1 | J28: 2 | K28: 20 | L28: 60 | N28: FormicAcid/CO | O28: 40 | P28: 0.32 | Q28: 0.0325 | R28: 77.5 | S28: 170 | T28: 50 | U28: 1812.1302 | V28: 20 | W28: 0.95 | X28: 1 | Y28: 1384981.5 | Z28: 2.7699629e+08 | AA28: 5.5399258e+08 | AB28: 553992.58 | AC28: 0 | AD28: 2870.8642 | AE28: 1033511.1 | AF28: 620106.67 | AG28: 27.31679 | AH28: 291.10288 | AI28: 145.55144 | AJ28: 18004.759 | AK28: 854.70085 | AL28: Nanofiltration | AM28: 22560.473 | AN28: 15456.085 | AO28: 24743.744 | AP28: 56876.018 | AQ28: 32132.274 | AR28: 0.029034938 | AS28: 659.10961 | AT28: 825.88301 | AU28: 565.80898 | AV28: 905.80717 | AW28: 2082.0901 | AX28: 1176.2829 | AY28: 5.3282775 | AZ28: ciscisMuconate | BA28: =VLOOKUP($AZ28,Sheet1!$A$2:$B$58,2) -> cis,cis-Muconate | BB28: C6H4O4 | BC28: 140.09156 | BD28: 3.3333333 | BE28: 345.4 | BF28: Acetaldehyde | BG28: 0.29836145 | BH28: 0.28778068 | BI28: 0.91518805 | BJ28: 80 | BK28: 2843.8009 | BL28: 1606.6137 | BM28: 6.9792105 | BN28: 1186.4658 | BO28: 1657.3351
A29: 27 | B29: Acetaldehyde | C29: C2H4O | D29: 2 | E29: 4 | F29: 1 | G29: 44.05176 | H29: 10 | I29: Categories-Category_1 | J29: 2 | K29: 20 | L29: 60 | N29: FormicAcid/CO | O29: 40 | P29: 0.32 | Q29: 0.0325 | R29: 77.5 | S29: 170 | T29: 50 | U29: 1812.1302 | V29: 20 | W29: 0.95 | X29: 1 | Y29: 659560.55 | Z29: 1.3191211e+08 | AA29: 2.6382422e+08 | AB29: 263824.22 | AC29: 0 | AD29: 1367.1727 | AE29: 492182.16 | AF29: 295309.29 | AG29: 13.008894 | AH29: 138.63 | AI29: 69.314998 | AJ29: 8574.2871 | AK29: 854.70085 | AL29: Nanofiltration | AM29: 10743.825 | AN29: 7360.5492 | AO29: 11783.55 | AP29: 27533.362 | AQ29: 15749.812 | AR29: 0.029034938 | AS29: 659.10961 | AT29: 825.88301 | AU29: 565.80898 | AV29: 905.80717 | AW29: 2116.5029 | AX29: 1210.6957 | AY29: 5.3282775 | AZ29: Citrate | BA29: =VLOOKUP($AZ29,Sheet1!$A$2:$B$58,2) -> Citrate | BB29: C6H5O7 | BC29: 189.0964 | BD29: 2.5 | BF29: Acetaldehyde | BG29: -0.35670564 | BH29: 0.44769231 | BI29: 1.9217621 | BJ29: 80 | BK29: 1376.6681 | BL29: 787.49061 | BM29: 3.8224555 | BN29: 649.81744 | BO29: 726.85065
A30: 28 | B30: Acetaldehyde | C30: C2H4O | D30: 2 | E30: 4 | F30: 1 | G30: 44.05176 | H30: 10 | I30: Categories-Category_1 | J30: 2 | K30: 20 | L30: 60 | N30: FormicAcid/CO | O30: 40 | P30: 0.32 | Q30: 0.0325 | R30: 77.5 | S30: 170 | T30: 50 | U30: 1812.1302 | V30: 20 | W30: 0.95 | X30: 1 | Y30: 1766799.2 | Z30: 3.5335984e+08 | AA30: 7.0671967e+08 | AB30: 706719.67 | AC30: 0 | AD30: 3662.3166 | AE30: 1318434 | AF30: 791060.38 | AG30: 34.847602 | AH30: 371.35539 | AI30: 185.67769 | AJ30: 22968.389 | AK30: 854.70085 | AL30: Nanofiltration | AM30: 28780.042 | AN30: 19717.086 | AO30: 31565.208 | AP30: 72320.219 | AQ30: 40755.011 | AR30: 0.029034938 | AS30: 659.10961 | AT30: 825.88301 | AU30: 565.80898 | AV30: 905.80717 | AW30: 2075.3284 | AX30: 1169.5212 | AY30: 5.3282775 | AZ30: CoumaricAcid | BA30: =VLOOKUP($AZ30,Sheet1!$A$2:$B$58,2) -> Coumaric Acid | BB30: C9H7O3 | BC30: 163.14818 | BD30: 4.1111111 | BE30: 346 | BF30: Acetaldehyde | BG30: 0.35737245 | BH30: 0.19370826 | BI30: 0.71740948 | BJ30: 80 | BK30: 3616.0109 | BL30: 2037.7506 | BM30: 8.9265122 | BN30: 1517.5071 | BO30: 2098.5039
A31: 29 | B31: Acetaldehyde | C31: C2H4O | D31: 2 | E31: 4 | F31: 1 | G31: 44.05176 | H31: 10 | I31: Categories-Category_1 | J31: 2 | K31: 20 | L31: 60 | N31: FormicAcid/CO | O31: 40 | P31: 0.32 | Q31: 0.0325 | R31: 77.5 | S31: 170 | T31: 50 | U31: 1812.1302 | V31: 20 | W31: 0.95 | X31: 1 | Y31: 1295247.7 | Z31: 2.5904954e+08 | AA31: 5.1809909e+08 | AB31: 518099.09 | AC31: 0 | AD31: 2684.8593 | AE31: 966549.35 | AF31: 579929.61 | AG31: 25.54692 | AH31: 272.24216 | AI31: 136.12108 | AJ31: 16838.22 | AK31: 854.70085 | AL31: Nanofiltration | AM31: 21098.767 | AN31: 14454.677 | AO31: 23140.583 | AP31: 53246.365 | AQ31: 30105.782 | AR31: 0.029034938 | AS31: 659.10961 | AT31: 825.88301 | AU31: 565.80898 | AV31: 905.80717 | AW31: 2084.2577 | AX31: 1178.4505 | AY31: 5.3282775 | AZ31: EthylAcetate | BA31: =VLOOKUP($AZ31,Sheet1!$A$2:$B$58,2) -> Ethyl Acetate | BB31: C4H8O2 | BC31: 88.10352 | BD31: 5 | BE31: 77.1 | BF31: Acetaldehyde | BG31: 0.043712121 | BH31: 0.48929577 | BI31: 0.97859155 | BJ31: 80 | BK31: 2662.3183 | BL31: 1505.2891 | BM31: 6.7623418 | BN31: 1149.5981 | BO31: 1512.7202
A32: 30 | B32: Acetaldehyde | C32: C2H4O | D32: 2 | E32: 4 | F32: 1 | G32: 44.05176 | H32: 10 | I32: Categories-Category_1 | J32: 2 | K32: 20 | L32: 60 | N32: FormicAcid/CO | O32: 40 | P32: 0.32 | Q32: 0.0325 | R32: 77.5 | S32: 170 | T32: 50 | U32: 1812.1302 | V32: 20 | W32: 0.95 | X32: 1 | Y32: 2647625.9 | Z32: 5.2952517e+08 | AA32: 1.0590503e+09 | AB32: 1059050.3 | AC32: 0 | AD32: 5488.1416 | AE32: 1975731 | AF32: 1185438.6 | AG32: 52.220656 | AH32: 556.49229 | AI32: 278.24615 | AJ32: 34419.136 | AK32: 1835.3365 | AL32: Distillation | AM32: 43128.153 | AN32: 29546.916 | AO32: 47301.845 | AP32: 108929.54 | AQ32: 61627.697 | AR32: 0.029034938 | AS32: 659.10961 | AT32: 825.88301 | AU32: 565.80898 | AV32: 905.80717 | AW32: 2085.9474 | AX32: 1180.1402 | AY32: 5.3282775 | AZ32: Farnesene | BA32: =VLOOKUP($AZ32,Sheet1!$A$2:$B$58,2) -> Farnesene | BB32: C15H24 | BC32: 204.34866 | BD32: 5.6 | BE32: 260 (A)/272 (B) | BF32: Acetaldehyde | BG32: 0.94318409 | BH32: 0.10320225 | BI32: 0.47873776 | BJ32: 80 | BK32: 5446.4771 | BL32: 3081.3848 | BM32: 12.969123 | BN32: 2204.7509 | BO32: 3241.7261
A33: 31 | B33: Acetaldehyde | C33: C2H4O | D33: 2 | E33: 4 | F33: 1 | G33: 44.05176 | H33: 10 | I33: Categories-Category_1 | J33: 2 | K33: 20 | L33: 60 | N33: FormicAcid/CO | O33: 40 | P33: 0.32 | Q33: 0.0325 | R33: 77.5 | S33: 170 | T33: 50 | U33: 1812.1302 | V33: 20 | W33: 0.95 | X33: 1 | Y33: 1406356.5 | Z33: 2.812713e+08 | AA33: 5.6254259e+08 | AB33: 562542.59 | AC33: 0 | AD33: 2915.1715 | AE33: 1049461.8 | AF33: 629677.05 | AG33: 27.738382 | AH33: 295.5956 | AI33: 147.7978 | AJ33: 18282.634 | AK33: 1835.3365 | AL33: Distillation | AM33: 22908.659 | AN33: 15694.626 | AO33: 25125.626 | AP33: 58721.256 | AQ33: 33595.63 | AR33: 0.029034938 | AS33: 659.10961 | AT33: 825.88301 | AU33: 565.80898 | AV33: 905.80717 | AW33: 2116.9676 | AX33: 1211.1604 | AY33: 5.3282775 | AZ33: GammaButyrolactone | BA33: =VLOOKUP($AZ33,Sheet1!$A$2:$B$58,2) -> Gamma Butyrolactone | BB33: C4H6O2 | BC33: 86.08784 | BD33: 4.5 | BE33: 204 | BF33: Acetaldehyde | BG33: 0.17207886 | BH33: 0.46119048 | BI33: 0.90127822 | BJ33: 80 | BK33: 2936.0628 | BL33: 1679.7815 | BM33: 7.217811 | BN33: 1227.0279 | BO33: 1709.0349
A34: 32 | B34: Acetaldehyde | C34: C2H4O | D34: 2 | E34: 4 | F34: 1 | G34: 44.05176 | H34: 10 | I34: Categories-Category_1 | J34: 2 | K34: 20 | L34: 60 | N34: FormicAcid/CO | O34: 40 | P34: 0.32 | Q34: 0.0325 | R34: 77.5 | S34: 170 | T34: 50 | U34: 1812.1302 | V34: 20 | W34: 0.95 | X34: 1 | Y34: 825415.76 | Z34: 1.6508315e+08 | AA34: 3.301663e+08 | AB34: 330166.3 | AC34: 0 | AD34: 1710.9663 | AE34: 615947.86 | AF34: 369568.72 | AG34: 16.280152 | AH34: 173.49034 | AI34: 86.745169 | AJ34: 10730.405 | AK34: 854.70085 | AL34: Nanofiltration | AM34: 13445.501 | AN34: 9211.4565 | AO34: 14746.679 | AP34: 34242.063 | AQ34: 19495.385 | AR34: 0.029034938 | AS34: 659.10961 | AT34: 825.88301 | AU34: 565.80898 | AV34: 905.80717 | AW34: 2103.3012 | AX34: 1197.494 | AY34: 5.3282775 | AZ34: Glutamate_L | BA34: =VLOOKUP($AZ34,Sheet1!$A$2:$B$58,2) -> L-Glutamate | BB34: C5H8NO4 | BC34: 146.11892 | BD34: 3.4 | BE34: 333.8 | BF34: Acetaldehyde | BG34: -0.2047876 | BH34: 0.46295455 | BI34: 1.5356122 | BJ34: 80 | BK34: 1712.1032 | BL34: 974.76923 | BM34: 4.5420461 | BN34: 772.14783 | BO34: 939.95534
A35: 33 | B35: Acetaldehyde | C35: C2H4O | D35: 2 | E35: 4 | F35: 1 | G35: 44.05176 | H35: 10 | I35: Categories-Category_1 | J35: 2 | K35: 20 | L35: 60 | N35: FormicAcid/CO | O35: 40 | P35: 0.32 | Q35: 0.0325 | R35: 77.5 | S35: 170 | T35: 50 | U35: 1812.1302 | V35: 20 | W35: 0.95 | X35: 1 | Y35: 1331734.1 | Z35: 2.6634682e+08 | AA35: 5.3269363e+08 | AB35: 532693.63 | AC35: 0 | AD35: 2760.4902 | AE35: 993776.47 | AF35: 596265.88 | AG35: 26.266562 | AH35: 279.91106 | AI35: 139.95553 | AJ35: 17312.543 | AK35: 854.70085 | AL35: Nanofiltration | AM35: 21693.107 | AN35: 14861.857 | AO35: 23792.44 | AP35: 54722.207 | AQ35: 30929.768 | AR35: 0.029034938 | AS35: 659.10961 | AT35: 825.88301 | AU35: 565.80898 | AV35: 905.80717 | AW35: 2083.3411 | AX35: 1177.5339 | AY35: 5.3282775 | AZ35: Glutarate | BA35: =VLOOKUP($AZ35,Sheet1!$A$2:$B$58,2) -> Glutarate | BB35: C5H6O4 | BC35: 130.09654 | BD35: 3.6 | BE35: 200 | BF35: Acetaldehyde | BG35: 0.4078967 | BH35: 0.3222807 | BI35: 0.95178046 | BJ35: 80 | BK35: 2736.1104 | BL35: 1546.4884 | BM35: 6.5898797 | BN35: 1120.2796 | BO35: 1615.8308
A36: 34 | B36: Acetaldehyde | C36: C2H4O | D36: 2 | E36: 4 | F36: 1 | G36: 44.05176 | H36: 10 | I36: Categories-Category_1 | J36: 2 | K36: 20 | L36: 60 | N36: FormicAcid/CO | O36: 40 | P36: 0.32 | Q36: 0.0325 | R36: 77.5 | S36: 170 | T36: 50 | U36: 1812.1302 | V36: 20 | W36: 0.95 | X36: 1 | Y36: 630369.69 | Z36: 1.2607394e+08 | AA36: 2.5214788e+08 | AB36: 252147.88 | AC36: 0 | AD36: 1306.6643 | AE36: 470399.14 | AF36: 282239.49 | AG36: 12.433146 | AH36: 132.4945 | AI36: 66.247252 | AJ36: 8194.806 | AK36: 854.70085 | AL36: Nanofiltration | AM36: 10268.324 | AN36: 7034.7858 | AO36: 11262.033 | AP36: 26352.617 | AQ36: 15090.584 | AR36: 0.029034938 | AS36: 659.10961 | AT36: 825.88301 | AU36: 565.80898 | AV36: 905.80717 | AW36: 2119.5453 | AX36: 1213.7382 | AY36: 5.3282775 | AZ36: Glycolate | BA36: =VLOOKUP($AZ36,Sheet1!$A$2:$B$58,2) -> Glycolate | BB36: C2H3O3 | BC36: 75.04192 | BD36: 2.5 | BE36: 112 | BF36: Acetaldehyde | BG36: -0.17923562 | BH36: 1.1803704 | BI36: 2.0107541 | BJ36: 80 | BK36: 1317.6308 | BL36: 754.52919 | BM36: 3.4915982 | BN36: 593.5717 | BO36: 724.05914
A37: 35 | B37: Acetaldehyde | C37: C2H4O | D37: 2 | E37: 4 | F37: 1 | G37: 44.05176 | H37: 10 | I37: Categories-Category_1 | J37: 2 | K37: 20 | L37: 60 | N37: FormicAcid/CO | O37: 40 | P37: 0.32 | Q37: 0.0325 | R37: 77.5 | S37: 170 | T37: 50 | U37: 1812.1302 | V37: 20 | W37: 0.95 | X37: 1 | Y37: 2608284.6 | Z37: 5.2165693e+08 | AA37: 1.0433139e+09 | AB37: 1043313.9 | AC37: 0 | AD37: 5406.593 | AE37: 1946373.5 | AF37: 1167824.1 | AG37: 51.444706 | AH37: 548.22334 | AI37: 274.11167 | AJ37: 33907.7 | AK37: 854.70085 | AL37: Nanofiltration | AM37: 42487.309 | AN37: 29107.877 | AO37: 46598.984 | AP37: 106357.59 | AQ37: 59758.603 | AR37: 0.029034938 | AS37: 659.10961 | AT37: 825.88301 | AU37: 565.80898 | AV37: 905.80717 | AW37: 2067.4156 | AX37: 1161.6084 | AY37: 5.3282775 | AZ37: Heptane | BA37: =VLOOKUP($AZ37,Sheet1!$A$2:$B$58,2) -> Heptane | BB37: C7H16 | BC37: 100.20034 | BD37: 6.2857143 | BE37: 98 | BF37: Acetaldehyde | BG37: 1.0371346 | BH37: 0.21364532 | BI37: 0.48595865 | BJ37: 80 | BK37: 5317.8794 | BL37: 2987.9302 | BM37: 12.668449 | BN37: 2153.6363 | BO37: 3164.243
A38: 36 | B38: Acetaldehyde | C38: C2H4O | D38: 2 | E38: 4 | F38: 1 | G38: 44.05176 | H38: 10 | I38: Categories-Category_1 | J38: 2 | K38: 20 | L38: 60 | N38: FormicAcid/CO | O38: 40 | P38: 0.32 | Q38: 0.0325 | R38: 77.5 | S38: 170 | T38: 50 | U38: 1812.1302 | V38: 20 | W38: 0.95 | X38: 1 | Y38: 2648500.4 | Z38: 5.2970008e+08 | AA38: 1.0594002e+09 | AB38: 1059400.2 | AC38: 0 | AD38: 5489.9544 | AE38: 1976383.6 | AF38: 1185830.1 | AG38: 52.237905 | AH38: 556.67611 | AI38: 278.33805 | AJ38: 34430.505 | AK38: 854.70085 | AL38: Nanofiltration | AM38: 43142.398 | AN38: 29556.676 | AO38: 47317.469 | AP38: 107984.28 | AQ38: 60666.811 | AR38: 0.029034938 | AS38: 659.10961 | AT38: 825.88301 | AU38: 565.80898 | AV38: 905.80717 | AW38: 2067.1633 | AX38: 1161.3561 | AY38: 5.3282775 | AZ38: Hexane | BA38: =VLOOKUP($AZ38,Sheet1!$A$2:$B$58,2) -> Hexane | BB38: C6H14 | BC38: 86.17396 | BD38: 6.3333333 | BE38: 69 | BF38: Acetaldehyde | BG38: 1.110804 | BH38: 0.24464789 | BI38: 0.47857968 | BJ38: 80 | BK38: 5399.214 | BL38: 3033.3406 | BM38: 12.806099 | BN38: 2177.0368 | BO38: 3222.1772
A39: 37 | B39: Acetaldehyde | C39: C2H4O | D39: 2 | E39: 4 | F39: 1 | G39: 44.05176 | H39: 10 | I39: Categories-Category_1 | J39: 2 | K39: 20 | L39: 60 | N39: FormicAcid/CO | O39: 40 | P39: 0.32 | Q39: 0.0325 | R39: 77.5 | S39: 170 | T39: 50 | U39: 1812.1302 | V39: 20 | W39: 0.95 | X39: 1 | Y39: 1676266.4 | Z39: 3.3525327e+08 | AA39: 6.7050654e+08 | AB39: 670506.54 | AC39: 0 | AD39: 3474.6553 | AE39: 1250875.9 | AF39: 750525.54 | AG39: 33.061971 | AH39: 352.32671 | AI39: 176.16336 | AJ39: 21791.463 | AK39: 854.70085 | AL39: Nanofiltration | AM39: 27305.32 | AN39: 18706.76 | AO39: 29947.77 | AP39: 68658.244 | AQ39: 38710.473 | AR39: 0.029034938 | AS39: 659.10961 | AT39: 825.88301 | AU39: 565.80898 | AV39: 905.80717 | AW39: 2076.6531 | AX39: 1170.8459 | AY39: 5.3282775 | AZ39: Isobutanol | BA39: =VLOOKUP($AZ39,Sheet1!$A$2:$B$58,2) -> Isobutanol | BB39: C5H10O | BC39: 86.1309 | BD39: 5.6 | BE39: 108 | BF39: Acetaldehyde | BG39: 0.59858454 | BH39: 0.38673684 | BI39: 0.75615576 | BJ39: 80 | BK39: 3432.9122 | BL39: 1935.5237 | BM39: 8.2095832 | BN39: 1395.6291 | BO39: 2037.283
A40: 38 | B40: Acetaldehyde | C40: C2H4O | D40: 2 | E40: 4 | F40: 1 | G40: 44.05176 | H40: 10 | I40: Categories-Category_1 | J40: 2 | K40: 20 | L40: 60 | N40: FormicAcid/CO | O40: 40 | P40: 0.32 | Q40: 0.0325 | R40: 77.5 | S40: 170 | T40: 50 | U40: 1812.1302 | V40: 20 | W40: 0.95 | X40: 1 | Y40: 1395956.2 | Z40: 2.7919123e+08 | AA40: 5.5838247e+08 | AB40: 558382.47 | AC40: 0 | AD40: 2893.6132 | AE40: 1041700.8 | AF40: 625020.45 | AG40: 27.533251 | AH40: 293.4096 | AI40: 146.7048 | AJ40: 18147.43 | AK40: 854.70085 | AL40: Nanofiltration | AM40: 22739.244 | AN40: 15578.561 | AO40: 24939.816 | AP40: 57319.936 | AQ40: 32380.12 | AR40: 0.029034938 | AS40: 659.10961 | AT40: 825.88301 | AU40: 565.80898 | AV40: 905.80717 | AW40: 2081.8441 | AX40: 1176.0369 | AY40: 5.3282775 | AZ40: Isobutyrate | BA40: =VLOOKUP($AZ40,Sheet1!$A$2:$B$58,2) -> Isobutyrate | BB40: C4H7O2 | BC40: 87.09568 | BD40: 4.75 | BE40: 155 | BF40: Acetaldehyde | BG40: 0.17934662 | BH40: 0.45925 | BI40: 0.90799303 | BJ40: 80 | BK40: 2865.9968 | BL40: 1619.006 | BM40: 7.1558934 | BN40: 1216.5019 | BO40: 1649.4949
A41: 39 | B41: Acetaldehyde | C41: C2H4O | D41: 2 | E41: 4 | F41: 1 | G41: 44.05176 | H41: 10 | I41: Categories-Category_1 | J41: 2 | K41: 20 | L41: 60 | N41: FormicAcid/CO | O41: 40 | P41: 0.32 | Q41: 0.0325 | R41: 77.5 | S41: 170 | T41: 50 | U41: 1812.1302 | V41: 20 | W41: 0.95 | X41: 1 | Y41: 2655063 | Z41: 5.310126e+08 | AA41: 1.0620252e+09 | AB41: 1062025.2 | AC41: 66773.504 | AD41: 5503.5577 | AE41: 1981280.8 | AF41: 1188768.5 | AG41: 52.367343 | AH41: 558.05547 | AI41: 279.02774 | AJ41: 34515.819 | AK41: 2170.1389 | AL41: PSA | AM41: 43249.299 | AN41: 29629.913 | AO41: 47434.715 | AP41: 109565.17 | AQ41: 62130.455 | AR41: 0.029034938 | AS41: 659.10961 | AT41: 825.88301 | AU41: 565.80898 | AV41: 905.80717 | AW41: 2092.2423 | AX41: 1186.4351 | AY41: 5.3282775 | AZ41: Isoprene | BA41: =VLOOKUP($AZ41,Sheet1!$A$2:$B$58,2) -> Isoprene | BB41: C5H8 | BC41: 68.11622 | BD41: 5.6 | BE41: 34.07 | BF41: Acetaldehyde | BG41: 0.95490794 | BH41: 0.3087395 | BI41: 0.47739676 | BJ41: 80 | BK41: 5478.2585 | BL41: 3106.5228 | BM41: 12.996479 | BN41: 2209.4014 | BO41: 3268.8571
A42: 40 | B42: Acetaldehyde | C42: C2H4O | D42: 2 | E42: 4 | F42: 1 | G42: 44.05176 | H42: 10 | I42: Categories-Category_1 | J42: 2 | K42: 20 | L42: 60 | N42: FormicAcid/CO | O42: 40 | P42: 0.32 | Q42: 0.0325 | R42: 77.5 | S42: 170 | T42: 50 | U42: 1812.1302 | V42: 20 | W42: 0.95 | X42: 1 | Y42: 1749270.4 | Z42: 3.4985407e+08 | AA42: 6.9970814e+08 | AB42: 699708.14 | AC42: 0 | AD42: 3625.9819 | AE42: 1305353.5 | AF42: 783212.09 | AG42: 34.501871 | AH42: 367.67108 | AI42: 183.83554 | AJ42: 22740.515 | AK42: 854.70085 | AL42: Nanofiltration | AM42: 28494.509 | AN42: 19521.469 | AO42: 31252.042 | AP42: 71611.193 | AQ42: 40359.151 | AR42: 0.029034938 | AS42: 659.10961 | AT42: 825.88301 | AU42: 565.80898 | AV42: 905.80717 | AW42: 2075.5742 | AX42: 1169.767 | AY42: 5.3282775 | AZ42: Isopropanol | BA42: =VLOOKUP($AZ42,Sheet1!$A$2:$B$58,2) -> Isopropanol | BB42: C3H8O | BC42: 60.09382 | BD42: 6 | BE42: 82.5 | BF42: Acetaldehyde | BG42: 0.56046861 | BH42: 0.53116667 | BI42: 0.72459838 | BJ42: 80 | BK42: 3580.5597 | BL42: 2017.9576 | BM42: 8.6313085 | BN42: 1467.3224 | BO42: 2113.2372
A43: 41 | B43: Acetaldehyde | C43: C2H4O | D43: 2 | E43: 4 | F43: 1 | G43: 44.05176 | H43: 10 | I43: Categories-Category_1 | J43: 2 | K43: 20 | L43: 60 | N43: FormicAcid/CO | O43: 40 | P43: 0.32 | Q43: 0.0325 | R43: 77.5 | S43: 170 | T43: 50 | U43: 1812.1302 | V43: 20 | W43: 0.95 | X43: 1 | Y43: 941661.85 | Z43: 1.8833237e+08 | AA43: 3.7666474e+08 | AB43: 376664.74 | AC43: 0 | AD43: 1951.9274 | AE43: 702693.88 | AF43: 421616.33 | AG43: 18.572941 | AH43: 197.92357 | AI43: 98.961784 | AJ43: 12241.604 | AK43: 854.70085 | AL43: Nanofiltration | AM43: 15339.077 | AN43: 10508.737 | AO43: 16823.503 | AP43: 38944.118 | AQ43: 22120.615 | AR43: 0.029034938 | AS43: 659.10961 | AT43: 825.88301 | AU43: 565.80898 | AV43: 905.80717 | AW43: 2096.8202 | AX43: 1191.013 | AY43: 5.3282775 | AZ43: Itaconate | BA43: =VLOOKUP($AZ43,Sheet1!$A$2:$B$58,2) -> Itaconate | BB43: C5H4O4 | BC43: 128.08086 | BD43: 3.2 | BE43: 381 | BF43: Acetaldehyde | BG43: -0.23362853 | BH43: 0.46295455 | BI43: 1.3460442 | BJ43: 80 | BK43: 1947.2059 | BL43: 1106.0308 | BM43: 5.1817178 | BN43: 880.89202 | BO43: 1066.3139
A44: 42 | B44: Acetaldehyde | C44: C2H4O | D44: 2 | E44: 4 | F44: 1 | G44: 44.05176 | H44: 10 | I44: Categories-Category_1 | J44: 2 | K44: 20 | L44: 60 | N44: FormicAcid/CO | O44: 40 | P44: 0.32 | Q44: 0.0325 | R44: 77.5 | S44: 170 | T44: 50 | U44: 1812.1302 | V44: 20 | W44: 0.95 | X44: 1 | Y44: 2643907.3 | Z44: 5.2878146e+08 | AA44: 1.0575629e+09 | AB44: 1057562.9 | AC44: 0 | AD44: 5480.4336 | AE44: 1972956.1 | AF44: 1183773.6 | AG44: 52.147313 | AH44: 555.7107 | AI44: 277.85535 | AJ44: 34370.795 | AK44: 854.70085 | AL44: Nanofiltration | AM44: 43067.579 | AN44: 29505.418 | AO44: 47235.41 | AP44: 107798.49 | AQ44: 60563.083 | AR44: 0.029034938 | AS44: 659.10961 | AT44: 825.88301 | AU44: 565.80898 | AV44: 905.80717 | AW44: 2067.1917 | AX44: 1161.3846 | AY44: 5.3282775 | AZ44: Limonene | BA44: =VLOOKUP($AZ44,Sheet1!$A$2:$B$58,2) -> Limonene | BB44: C10H16 | BC44: 136.23244 | BD44: 5.6 | BE44: 176 | BF44: Acetaldehyde | BG44: 0.93732216 | BH44: 0.1550211 | BI44: 0.47941109 | BJ44: 80 | BK44: 5389.9246 | BL44: 3028.1542 | BM44: 12.955445 | BN44: 2202.4257 | BO44: 3187.4989
A45: 43 | B45: Acetaldehyde | C45: C2H4O | D45: 2 | E45: 4 | F45: 1 | G45: 44.05176 | H45: 10 | I45: Categories-Category_1 | J45: 2 | K45: 20 | L45: 60 | N45: FormicAcid/CO | O45: 40 | P45: 0.32 | Q45: 0.0325 | R45: 77.5 | S45: 170 | T45: 50 | U45: 1812.1302 | V45: 20 | W45: 0.95 | X45: 1 | Y45: 1342251.9 | Z45: 2.6845037e+08 | AA45: 5.3690074e+08 | AB45: 536900.74 | AC45: 0 | AD45: 2782.292 | AE45: 1001625.1 | AF45: 600975.08 | AG45: 26.47401 | AH45: 282.12174 | AI45: 141.06087 | AJ45: 17449.274 | AK45: 854.70085 | AL45: Nanofiltration | AM45: 21864.435 | AN45: 14979.233 | AO45: 23980.348 | AP45: 55147.643 | AQ45: 31167.295 | AR45: 0.029034938 | AS45: 659.10961 | AT45: 825.88301 | AU45: 565.80898 | AV45: 905.80717 | AW45: 2083.0861 | AX45: 1177.279 | AY45: 5.3282775 | AZ45: Lysine_L | BA45: =VLOOKUP($AZ45,Sheet1!$A$2:$B$58,2) -> L-Lysine | BB45: C6H15N2O2 | BC45: 147.1932 | BD45: 4.8333333 | BF45: Acetaldehyde | BG45: 0.32194431 | BH45: 0.28261538 | BI45: 0.94432238 | BJ45: 80 | BK45: 2757.3821 | BL45: 1558.3647 | BM45: 6.7310992 | BN45: 1144.2869 | BO45: 1613.0953
A46: 44 | B46: Acetaldehyde | C46: C2H4O | D46: 2 | E46: 4 | F46: 1 | G46: 44.05176 | H46: 10 | I46: Categories-Category_1 | J46: 2 | K46: 20 | L46: 60 | N46: FormicAcid/CO | O46: 40 | P46: 0.32 | Q46: 0.0325 | R46: 77.5 | S46: 170 | T46: 50 | U46: 1812.1302 | V46: 20 | W46: 0.95 | X46: 1 | Y46: 643408.52 | Z46: 1.286817e+08 | AA46: 2.5736341e+08 | AB46: 257363.41 | AC46: 0 | AD46: 1333.6919 | AE46: 480129.08 | AF46: 288077.45 | AG46: 12.690319 | AH46: 135.23508 | AI46: 67.617538 | AJ46: 8364.3108 | AK46: 854.70085 | AL46: Nanofiltration | AM46: 10480.718 | AN46: 7180.2962 | AO46: 11494.981 | AP46: 26880.026 | AQ46: 15385.045 | AR46: 0.029034938 | AS46: 659.10961 | AT46: 825.88301 | AU46: 565.80898 | AV46: 905.80717 | AW46: 2118.1522 | AX46: 1212.3451 | AY46: 5.3282775 | AZ46: Malate_L | BA46: =VLOOKUP($AZ46,Sheet1!$A$2:$B$58,2) -> L-Malate | BB46: C4H4O5 | BC46: 132.06916 | BD46: 2.5 | BF46: Acetaldehyde | BG46: -0.31867491 | BH46: 0.65709677 | BI46: 1.9700057 | BJ46: 80 | BK46: 1344.0013 | BL46: 769.25224 | BM46: 3.6995518 | BN46: 628.92381 | BO46: 715.07751
A47: 45 | B47: Acetaldehyde | C47: C2H4O | D47: 2 | E47: 4 | F47: 1 | G47: 44.05176 | H47: 10 | I47: Categories-Category_1 | J47: 2 | K47: 20 | L47: 60 | N47: FormicAcid/CO | O47: 40 | P47: 0.32 | Q47: 0.0325 | R47: 77.5 | S47: 170 | T47: 50 | U47: 1812.1302 | V47: 20 | W47: 0.95 | X47: 1 | Y47: 593226.71 | Z47: 1.1864534e+08 | AA47: 2.3729068e+08 | AB47: 237290.68 | AC47: 0 | AD47: 1229.6723 | AE47: 442682.03 | AF47: 265609.22 | AG47: 11.700554 | AH47: 124.68759 | AI47: 62.343796 | AJ47: 7711.9472 | AK47: 854.70085 | AL47: Nanofiltration | AM47: 9663.2884 | AN47: 6620.2783 | AO47: 10598.445 | AP47: 24850.215 | AQ47: 14251.769 | AR47: 0.029034938 | AS47: 659.10961 | AT47: 825.88301 | AU47: 565.80898 | AV47: 905.80717 | AW47: 2123.8495 | AX47: 1218.0423 | AY47: 5.3282775 | AZ47: Malonate | BA47: =VLOOKUP($AZ47,Sheet1!$A$2:$B$58,2) -> Malonate | BB47: C3H2O4 | BC47: 102.04378 | BD47: 2 | BE47: 199 | BF47: Acetaldehyde | BG47: -0.35869948 | BH47: 0.92238095 | BI47: 2.136651 | BJ47: 80 | BK47: 1242.5107 | BL47: 712.58847 | BM47: 3.4758893 | BN47: 590.90118 | BO47: 651.60956
A48: 46 | B48: Acetaldehyde | C48: C2H4O | D48: 2 | E48: 4 | F48: 1 | G48: 44.05176 | H48: 10 | I48: Categories-Category_1 | J48: 2 | K48: 20 | L48: 60 | N48: FormicAcid/CO | O48: 40 | P48: 0.32 | Q48: 0.0325 | R48: 77.5 | S48: 170 | T48: 50 | U48: 1812.1302 | V48: 20 | W48: 0.95 | X48: 1 | Y48: 2579843.7 | Z48: 5.1596874e+08 | AA48: 1.0319375e+09 | AB48: 1031937.5 | AC48: 0 | AD48: 5347.6391 | AE48: 1925150.1 | AF48: 1155090 | AG48: 50.883749 | AH48: 542.24547 | AI48: 271.12273 | AJ48: 33537.968 | AK48: 854.70085 | AL48: Nanofiltration | AM48: 42024.024 | AN48: 28790.482 | AO48: 46090.865 | AP48: 105207.17 | AQ48: 59116.31 | AR48: 0.029034938 | AS48: 659.10961 | AT48: 825.88301 | AU48: 565.80898 | AV48: 905.80717 | AW48: 2067.5987 | AX48: 1161.7916 | AY48: 5.3282775 | AZ48: Nonane | BA48: =VLOOKUP($AZ48,Sheet1!$A$2:$B$58,2) -> Nonane | BB48: C9H20 | BC48: 128.2531 | BD48: 6.2222222 | BE48: 151 | BF48: Acetaldehyde | BG48: 0.97849461 | BH48: 0.16875486 | BI48: 0.491316 | BJ48: 80 | BK48: 5260.3587 | BL48: 2955.8155 | BM48: 12.577642 | BN48: 2138.1992 | BO48: 3122.1596
A49: 47 | B49: Acetaldehyde | C49: C2H4O | D49: 2 | E49: 4 | F49: 1 | G49: 44.05176 | H49: 10 | I49: Categories-Category_1 | J49: 2 | K49: 20 | L49: 60 | N49: FormicAcid/CO | O49: 40 | P49: 0.32 | Q49: 0.0325 | R49: 77.5 | S49: 170 | T49: 50 | U49: 1812.1302 | V49: 20 | W49: 0.95 | X49: 1 | Y49: 2603105.5 | Z49: 5.206211e+08 | AA49: 1.0412422e+09 | AB49: 1041242.2 | AC49: 0 | AD49: 5395.8574 | AE49: 1942508.7 | AF49: 1165505.2 | AG49: 51.342555 | AH49: 547.13476 | AI49: 273.56738 | AJ49: 33840.371 | AK49: 854.70085 | AL49: Nanofiltration | AM49: 42402.944 | AN49: 29050.079 | AO49: 46506.455 | AP49: 106148.1 | AQ49: 59641.641 | AR49: 0.029034938 | AS49: 659.10961 | AT49: 825.88301 | AU49: 565.80898 | AV49: 905.80717 | AW49: 2067.4486 | AX49: 1161.6415 | AY49: 5.3282775 | AZ49: Octane | BA49: =VLOOKUP($AZ49,Sheet1!$A$2:$B$58,2) -> Octane | BB49: C8H18 | BC49: 114.22672 | BD49: 6.25 | BE49: 126 | BF49: Acetaldehyde | BG49: 1.0212196 | BH49: 0.18778378 | BI49: 0.48692551 | BJ49: 80 | BK49: 5307.4048 | BL49: 2982.082 | BM49: 12.657149 | BN49: 2151.7154 | BO49: 3155.6894
A50: 48 | B50: Acetaldehyde | C50: C2H4O | D50: 2 | E50: 4 | F50: 1 | G50: 44.05176 | H50: 10 | I50: Categories-Category_1 | J50: 2 | K50: 20 | L50: 60 | N50: FormicAcid/CO | O50: 40 | P50: 0.32 | Q50: 0.0325 | R50: 77.5 | S50: 170 | T50: 50 | U50: 1812.1302 | V50: 20 | W50: 0.95 | X50: 1 | Y50: 2667765 | Z50: 5.3355299e+08 | AA50: 1.067106e+09 | AB50: 1067106 | AC50: 66773.504 | AD50: 5529.887 | AE50: 1990759.3 | AF50: 1194455.6 | AG50: 52.617871 | AH50: 560.72524 | AI50: 280.36262 | AJ50: 34680.944 | AK50: 2170.1389 | AL50: PSA | AM50: 43456.206 | AN50: 29771.664 | AO50: 47661.645 | AP50: 110078.95 | AQ50: 62417.308 | AR50: 0.029034938 | AS50: 659.10961 | AT50: 825.88301 | AU50: 565.80898 | AV50: 905.80717 | AW50: 2092.045 | AX50: 1186.2378 | AY50: 5.3282775 | AZ50: Pentane | BA50: =VLOOKUP($AZ50,Sheet1!$A$2:$B$58,2) -> Pentane | BB50: C5H12 | BC50: 72.14758 | BD50: 6.4 | BE50: 36.1 | BF50: Acetaldehyde | BG50: 1.1554409 | BH50: 0.29010033 | BI50: 0.47512374 | BJ50: 80 | BK50: 5503.9477 | BL50: 3120.8654 | BM50: 12.86269 | BN50: 2186.6573 | BO50: 3317.2904
A51: 49 | B51: Acetaldehyde | C51: C2H4O | D51: 2 | E51: 4 | F51: 1 | G51: 44.05176 | H51: 10 | I51: Categories-Category_1 | J51: 2 | K51: 20 | L51: 60 | N51: FormicAcid/CO | O51: 40 | P51: 0.32 | Q51: 0.0325 | R51: 77.5 | S51: 170 | T51: 50 | U51: 1812.1302 | V51: 20 | W51: 0.95 | X51: 1 | Y51: 2120694.2 | Z51: 4.2413885e+08 | AA51: 8.4827769e+08 | AB51: 848277.69 | AC51: 0 | AD51: 4395.8893 | AE51: 1582520.2 | AF51: 949512.1 | AG51: 41.827679 | AH51: 445.73896 | AI51: 222.86948 | AJ51: 27569.025 | AK51: 854.70085 | AL51: Nanofiltration | AM51: 34544.769 | AN51: 23666.477 | AO51: 37887.811 | AP51: 86634.972 | AQ51: 48747.16 | AR51: 0.029034938 | AS51: 659.10961 | AT51: 825.88301 | AU51: 565.80898 | AV51: 905.80717 | AW51: 2071.2355 | AX51: 1165.4283 | AY51: 5.3282775 | AZ51: Pentanol-PW1 | BA51: =VLOOKUP($AZ51,Sheet1!$A$2:$B$58,2) -> Pentanol (PW1) | BB51: C5H12O | BC51: 88.14658 | BD51: 6 | BE51: 138 | BF51: Acetaldehyde | BG51: 0.84663223 | BH51: 0.29869919 | BI51: 0.59769035 | BJ51: 80 | BK51: 4331.7486 | BL51: 2437.358 | BM51: 10.296842 | BN51: 1750.4631 | BO51: 2581.2855
A52: 50 | B52: Acetaldehyde | C52: C2H4O | D52: 2 | E52: 4 | F52: 1 | G52: 44.05176 | H52: 10 | I52: Categories-Category_1 | J52: 2 | K52: 20 | L52: 60 | N52: FormicAcid/CO | O52: 40 | P52: 0.32 | Q52: 0.0325 | R52: 77.5 | S52: 170 | T52: 50 | U52: 1812.1302 | V52: 20 | W52: 0.95 | X52: 1 | Y52: 2316740.2 | Z52: 4.6334804e+08 | AA52: 9.2669609e+08 | AB52: 926696.09 | AC52: 0 | AD52: 4802.264 | AE52: 1728815.1 | AF52: 1037289 | AG52: 45.694407 | AH52: 486.94496 | AI52: 243.47248 | AJ52: 30117.623 | AK52: 854.70085 | AL52: Nanofiltration | AM52: 37738.235 | AN52: 25854.306 | AO52: 41390.322 | AP52: 94564.865 | AQ52: 53174.543 | AR52: 0.029034938 | AS52: 659.10961 | AT52: 825.88301 | AU52: 565.80898 | AV52: 905.80717 | AW52: 2069.5063 | AX52: 1163.6991 | AY52: 5.3282775 | AZ52: Pentanol-PW2 | BA52: =VLOOKUP($AZ52,Sheet1!$A$2:$B$58,2) -> Pentanol (PW2) | BB52: C5H12O | BC52: 88.14658 | BD52: 6 | BE52: 138 | BF52: Acetaldehyde | BG52: 1.1556773 | BH52: 0.27342282 | BI52: 0.5471129 | BJ52: 80 | BK52: 4728.2432 | BL52: 2658.7271 | BM52: 11.017947 | BN52: 1873.051 | BO52: 2855.1923
A53: 51 | B53: Acetaldehyde | C53: C2H4O | D53: 2 | E53: 4 | F53: 1 | G53: 44.05176 | H53: 10 | I53: Categories-Category_1 | J53: 2 | K53: 20 | L53: 60 | N53: FormicAcid/CO | O53: 40 | P53: 0.32 | Q53: 0.0325 | R53: 77.5 | S53: 170 | T53: 50 | U53: 1812.1302 | V53: 20 | W53: 0.95 | X53: 1 | Y53: 2400795.3 | Z53: 4.8015906e+08 | AA53: 9.6031812e+08 | AB53: 960318.12 | AC53: 0 | AD53: 4976.4979 | AE53: 1791539.3 | AF53: 1074923.6 | AG53: 47.352274 | AH53: 504.61211 | AI53: 252.30606 | AJ53: 31210.339 | AK53: 854.70085 | AL53: Nanofiltration | AM53: 39107.439 | AN53: 26792.342 | AO53: 42892.03 | AP53: 97964.821 | AQ53: 55072.791 | AR53: 0.029034938 | AS53: 659.10961 | AT53: 825.88301 | AU53: 565.80898 | AV53: 905.80717 | AW53: 2068.8514 | AX53: 1163.0443 | AY53: 5.3282775 | AZ53: Phenol | BA53: =VLOOKUP($AZ53,Sheet1!$A$2:$B$58,2) -> Phenol | BB53: C6H6O | BC53: 94.11024 | BD53: 4.6666667 | BE53: 181.7 | BF53: Acetaldehyde | BG53: 0.97873253 | BH53: 0.24713004 | BI53: 0.52795774 | BJ53: 80 | BK53: 4898.241 | BL53: 2753.6396 | BM53: 11.63657 | BN53: 1978.217 | BO53: 2920.0241
A54: 52 | B54: Acetaldehyde | C54: C2H4O | D54: 2 | E54: 4 | F54: 1 | G54: 44.05176 | H54: 10 | I54: Categories-Category_1 | J54: 2 | K54: 20 | L54: 60 | N54: FormicAcid/CO | O54: 40 | P54: 0.32 | Q54: 0.0325 | R54: 77.5 | S54: 170 | T54: 50 | U54: 1812.1302 | V54: 20 | W54: 0.95 | X54: 1 | Y54: 2788328.5 | Z54: 5.576657e+08 | AA54: 1.1153314e+09 | AB54: 1115331.4 | AC54: 66773.504 | AD54: 5779.7976 | AE54: 2080727.1 | AF54: 1248436.3 | AG54: 54.995816 | AH54: 586.06593 | AI54: 293.03297 | AJ54: 36248.27 | AK54: 2170.1389 | AL54: PSA | AM54: 45420.11 | AN54: 31117.127 | AO54: 49815.604 | AP54: 114955.65 | AQ54: 65140.041 | AR54: 0.029034938 | AS54: 659.10961 | AT54: 825.88301 | AU54: 565.80898 | AV54: 905.80717 | AW54: 2090.2617 | AX54: 1184.4545 | AY54: 5.3282775 | AZ54: Propane-PW1 | BA54: =VLOOKUP($AZ54,Sheet1!$A$2:$B$58,2) -> Propane (PW1) | BB54: C3H8 | BC54: 44.09482 | BD54: 6.6666667 | BE54: -42 | BF54: Acetaldehyde | BG54: 1.4012652 | BH54: 0.45413613 | BI54: 0.45458004 | BJ54: 80 | BK54: 5747.7823 | BL54: 3257.0021 | BM54: 13.250383 | BN54: 2252.5651 | BO54: 3495.2172
...

Sheet Sheet1
B1: BioProduct_Graph
A2: 1-3-Butanediol-PW1 | B2: 1,3-Butanediol (PW1)
A3: 1-3-Butanediol-PW2 | B3: 1,3-Butanediol (PW2)
A4: 1-3-Diaminopropane | B4: 1,3-Diaminopropane
A5: 1-3-Propanediol | B5: 1,3-Propanediol
A6: 1-4-Butanediol | B6: 1,4-Butanediol
A7: 1-Propanol-PW1 | B7: 1-Propanol (PW1)
A8: 1-Propanol-PW2 | B8: 1-Propanol (PW2)
A9: 2-3-Butanediol | B9: 2,3-Butanediol
A10: 2-Methyl-1-Butanol | B10: 2-Methyl-1-Butanol
A11: 2-Pyrone-4-6-Dicarboxylate | B11: 2-Pyrone-4,6-Dicarboxylate
A12: 3-Methyl-1-Pentanol | B12: 3-Methyl-1-Pentanol
A13: 4-Hydroxystyrene | B13: 4-Hydroxystyrene
... A58: Succinate | B58: Succinate
