Workbook

Sheet Overall-ECR-Bio
B1: Substrate | C1: Formula_S | D1: C_Sn | E1: H_Sn | F1: O_Sn | G1: MW_S | H1: N_electrons | I1: ParametersType | J1: CellVoltage | K1: CurrentDensity | L1: FaradaicEfficiency | M1: EnergyEfficiency | N1: ByProducts | O1: ByP_FE | P1: Xco2 | Q1: ElectricityPrice | R1: CO2Price | S1: CarbonTax | T1: Conversion | U1: ElectrolyzerPrice | V1: PlantLife | W1: StreamFactor | X1: ScalingFactor | Y1: ElectrodeArea | Z1: I | AA1: Power | AB1: kWh | AC1: kWh_sep | AD1: emol_curr | AE1: MaxProductionRate | AF1: ActualProductionRate | AG1: ActualProductionRate_mass | AH1: CO2rate_fed | AI1: CO2rate_conv | AJ1: Cost_elec_h | AK1: Cost_h_sep | AL1: Type_sep | AM1: Cost_CO2_h | AN1: Cost_electrolyzer_h | AO1: CT_savings_h | AP1: ProductionCost_hNOCT | AQ1: ProductionCost_h | AR1: Cost_elec_mol | AS1: Cost_elec_mass | AT1: Cost_CO2_mass | AU1: Cost_electrolyzer_mass | AV1: CT_savings_mass | AW1: ProductionCost_massNOCT | AX1: ProductionCost_mass | AY1: CO2_ECons_mass | AZ1: BioProduct | BA1: BioProduct_Graph | BB1: Formula_BP | BC1: Carbons in Product | BD1: Lower Heating Value | BE1: Lower Heating Value of Product | BF1: MW_BP | BG1: Deg_RedBP | BH1: BoilP_degC | BI1: SubstratePathway | BJ1: CO2_BProd_mass | BK1: YieldBP_Molar | BL1: YieldBP_Mass | BM1: Bioconversion | BN1: O2_BProd_mass | BO1: BioproductionCost_massNOCT | BP1: BioproductionCost_mass1 | BQ1: CO2_OverallCons_mass | BR1: CT_OverallSavings_mass | BS1: BioproductionCost_mass2 | BT1: Carbon_Efficiency | BU1: Additional_CO2_Intake | BV1: Energy_Input | BW1: LHV_Ratio | BX1: Maximum_Recycle | BY1: Recycle_Cost | BZ1: Carbon_capture_SP | CA1: CCSP_COInput | CB1: CCSP_COBio | CC1: CCSP_GasRec | CD1: CCSP_ECR | CE1: Flue_gas_SP | CF1: Bioreactor_SP | CG1: BioSP_COInput | CH1: BioSP_COBio | CI1: BioSP_GasRec | CJ1: BioSP_ECR | CK1: Carbon_capture_rec | CL1: CCRec_COInput | CM1: CCRec_COBio | CN1: CCRec_Rec | CO1: CCRec_ECR | CP1: Flue_gas_rec | CQ1: Bioreactor_rec | CR1: BioRec_COInput | CS1: BioRec_COBio | CT1: BioRec_Rec | CU1: BioRec_ECR | CV1: BioproductionCost_mass2_alt
A2: 562 | B2: CarbonMonoxide | C2: CO | D2: 1 | E2: 0 | F2: 1 | G2: 28.0097 | H2: 2 | I2: Categories-Category_2 | J2: 1.333 | K2: 500 | L2: 100 | N2: FormicAcid | O2: 0 | P2: 0.5 | Q2: 0.0325 | R2: 77.5 | S2: 170 | T2: 100 | U2: 1812.1302 | V2: 20 | W2: 0.95 | X2: 1 | Y2: 11040.274 | Z2: 55201371 | AA2: 73583428 | AB2: 73583.428 | AC2: 0 | AD2: 572.12189 | AE2: 1029819.4 | AF2: 1029819.4 | AG2: 28.844933 | AH2: 45.322352 | AI2: 45.322352 | AJ2: 2391.4614 | AK2: 854.70085 | AL2: Nanofiltration | AM2: 3512.4823 | AN2: 123.20701 | AO2: 7704.7998 | AP2: 6881.8515 | AQ2: -822.94829 | AR2: 0.0023222144 | AS2: 82.907505 | AT2: 121.77121 | AU2: 4.2713571 | AV2: 267.11104 | AW2: 238.58095 | AX2: -28.530082 | AY2: 1.5712414 | AZ2: Isobutanol | BA2: =VLOOKUP($AZ2,Sheet1!$A$2:$B$58,2,FALSE) -> Isobutanol | BB2: C4H10O | BC2: 4 | BD2: 14.748421 | BE2: 32.959 | BF2: 74.1202 | BG2: =VLOOKUP($AZ2,Sheet1!$A$2:$C$58,3,FALSE) -> 5.602 | BH2: 108 | BI2: Flue_Gas | BJ2: 0 | BK2: 0.25 | BL2: 0.86670336 | BM2: 100 | BN2: 0 | BO2: 275.27406 | BP2: -32.917932 | BQ2: 1.8128941 | BR2: 308.19199 | BS2: -32.917932 | BT2: 1 | BU2: 0 | BV2: 17.016689 | BW2: 1.9368633 | BX2: 0 | BY2: 1.102311 | BZ2: 37.000419 | CA2: 19.983731 | CB2: 0 | CC2: 0 | CD2: 17.016689 | CE2: 24.010994 | CF2: 19.015062 | CG2: 1.9983731 | CH2: 0 | CI2: 0 | CJ2: 17.016689 | CK2: 37.000419 | CL2: 19.983731 | CM2: 0 | CN2: 0 | CO2: 17.016689 | CP2: 24.010994 | CQ2: 19.015062 | CR2: 1.9983731 | CS2: 0 | CT2: 0 | CU2: 17.016689 | CV2: =IF(BS2<0,1.1,BS2) -> 1.1
A3: 337 | B3: Methanol | C3: CH3OH | D3: 1 | E3: 4 | F3: 1 | G3: 32.04106 | H3: 6 | I3: Categories-Category_2 | J3: 1.213 | K3: 500 | L3: 100 | N3: FormicAcid/CO | O3: 0 | P3: 0.125 | Q3: 0.0325 | R3: 77.5 | S3: 170 | T3: 100 | U3: 1812.1302 | V3: 20 | W3: 0.95 | X3: 1 | Y3: 37340.58 | Z3: 1.867029e+08 | AA3: 2.2647062e+08 | AB3: 226470.62 | AC3: 0 | AD3: 1935.0392 | AE3: 1161023.5 | AF3: 1161023.5 | AG3: 37.200424 | AH3: 38.322484 | AI3: 38.322484 | AJ3: 7360.2951 | AK3: 854.70085 | AL3: Nanofiltration | AM3: 2969.9925 | AN3: 416.71258 | AO3: 6514.8222 | AP3: 11601.701 | AQ3: 5086.8788 | AR3: 0.0063394884 | AS3: 197.85514 | AT3: 79.837597 | AU3: 11.201823 | AV3: 175.12763 | AW3: 311.87013 | AX3: 136.74249 | AY3: 1.0301625 | AZ3: Isobutanol | BA3: =VLOOKUP($AZ3,Sheet1!$A$2:$B$58,2,FALSE) -> Isobutanol | BB3: C4H10O | BC3: 4 | BD3: 19.93 | BE3: 32.959 | BF3: 74.1202 | BG3: =VLOOKUP($AZ3,Sheet1!$A$2:$C$58,3,FALSE) -> 5.602 | BH3: 108 | BI3: Methanol_MethylTransferase_0 | BJ3: 0 | BK3: 0.25 | BL3: 0.67203535 | BM3: 100 | BN3: 0 | BO3: 464.06804 | BP3: 203.47515 | BQ3: 1.5328993 | BR3: 260.59289 | BS3: 203.47515 | BT3: 1 | BU3: 0 | BV3: 29.656178 | BW3: 1.1113705 | BX3: 0 | BY3: 1.102311 | BZ3: 46.553496 | CA3: 16.897318 | CB3: 0 | CC3: 0 | CD3: 29.656178 | CE3: 35.570239 | CF3: 31.34591 | CG3: 1.6897318 | CH3: 0 | CI3: 0 | CJ3: 29.656178 | CK3: 46.553496 | CL3: 16.897318 | CM3: 0 | CN3: 0 | CO3: 29.656178 | CP3: 35.570239 | CQ3: 31.34591 | CR3: 1.6897318 | CS3: 0 | CT3: 0 | CU3: 29.656178 | CV3: =IF(BS3<0,1.1,BS3) -> 203.47515
A4: 281 | B4: Methanol | C4: CH3OH | D4: 1 | E4: 4 | F4: 1 | G4: 32.04106 | H4: 6 | I4: Categories-Category_2 | J4: 1.213 | K4: 500 | L4: 100 | N4: FormicAcid/CO | O4: 0 | P4: 0.125 | Q4: 0.0325 | R4: 77.5 | S4: 170 | T4: 100 | U4: 1812.1302 | V4: 20 | W4: 0.95 | X4: 1 | Y4: 37340.58 | Z4: 1.867029e+08 | AA4: 2.2647062e+08 | AB4: 226470.62 | AC4: 0 | AD4: 1935.0392 | AE4: 1161023.5 | AF4: 1161023.5 | AG4: 37.200424 | AH4: 38.322484 | AI4: 38.322484 | AJ4: 7360.2951 | AK4: 854.70085 | AL4: Nanofiltration | AM4: 2969.9925 | AN4: 416.71258 | AO4: 6514.8222 | AP4: 11601.701 | AQ4: 5086.8788 | AR4: 0.0063394884 | AS4: 197.85514 | AT4: 79.837597 | AU4: 11.201823 | AV4: 175.12763 | AW4: 311.87013 | AX4: 136.74249 | AY4: 1.0301625 | AZ4: Isobutanol | BA4: =VLOOKUP($AZ4,Sheet1!$A$2:$B$58,2,FALSE) -> Isobutanol | BB4: C4H10O | BC4: 4 | BD4: 19.93 | BE4: 32.959 | BF4: 74.1202 | BG4: =VLOOKUP($AZ4,Sheet1!$A$2:$C$58,3,FALSE) -> 5.602 | BH4: 108 | BI4: Methanol_MethylTransferase_0.1 | BJ4: 0 | BK4: 0.25 | BL4: 0.67203535 | BM4: 100 | BN4: 0 | BO4: 464.06804 | BP4: 203.47515 | BQ4: 1.5328993 | BR4: 260.59289 | BS4: 203.47515 | BT4: 1 | BU4: 0 | BV4: 29.656178 | BW4: 1.1113705 | BX4: 0 | BY4: 1.102311 | BZ4: 46.553496 | CA4: 16.897318 | CB4: 0 | CC4: 0 | CD4: 29.656178 | CE4: 35.570239 | CF4: 31.34591 | CG4: 1.6897318 | CH4: 0 | CI4: 0 | CJ4: 29.656178 | CK4: 46.553496 | CL4: 16.897318 | CM4: 0 | CN4: 0 | CO4: 29.656178 | CP4: 35.570239 | CQ4: 31.34591 | CR4: 1.6897318 | CS4: 0 | CT4: 0 | CU4: 29.656178 | CV4: =IF(BS4<0,1.1,BS4) -> 203.47515
A5: 1039 | B5: CarbonMonoxide_1 | C5: CO | D5: 1 | E5: 0 | F5: 1 | G5: 28.0097 | H5: 2 | I5: Categories-Category_2 | J5: 1.333 | K5: 500 | L5: 50 | N5: Hydrogen | O5: 50 | P5: 0.25 | Q5: 0.0325 | R5: 77.5 | S5: 170 | T5: 100 | U5: 1812.1302 | V5: 20 | W5: 0.95 | X5: 1 | Y5: 28564.919 | Z5: 1.428246e+08 | AA5: 1.9038519e+08 | AB5: 190385.19 | AC5: 0 | AD5: 1480.2726 | AE5: 2664490.7 | AF5: 1332245.3 | AG5: 37.315792 | AH5: 58.632118 | AI5: 58.632118 | AJ5: 6187.5185 | AK5: 854.70085 | AL5: Nanofiltration | AM5: 4543.9891 | AN5: 318.77815 | AO5: 9967.46 | AP5: 11904.987 | AQ5: 1937.5266 | AR5: 0.0046444287 | AS5: 154.66118 | AT5: 113.58006 | AU5: 7.9680737 | AV5: 249.14335 | AW5: 297.57313 | AX5: 48.429778 | AY5: 1.5712414 | AZ5: Succinate | BA5: =VLOOKUP($AZ5,Sheet1!$A$2:$B$58,2,FALSE) -> Succinate | BB5: C4H4O4 | BC5: 4 | BD5: 17.478546 | BE5: 0 | BF5: 116.07016 | BG5: =VLOOKUP($AZ5,Sheet1!$A$2:$C$58,3,FALSE) -> 3 | BH5: 235 | BI5: CO_1:H2_1 | BJ5: 0 | BK5: 0.17333333 | BL5: 0.66995763 | BM5: 100 | BN5: 0 | BO5: 444.16708 | BP5: 72.287822 | BQ5: 2.3452847 | BR5: 398.6984 | BS5: 45.468681 | BT5: 0.69333333 | BU5: 0 | BV5: 26.089033 | BW5: 0 | BX5: 0 | BY5: 1.102311 | BZ5: 51.941364 | CA5: 25.852331 | CB5: 0 | CC5: 0 | CD5: 26.089033 | CE5: 35.137348 | CF5: 28.674266 | CG5: 2.5852331 | CH5: 0 | CI5: 0 | CJ5: 26.089033 | CK5: 51.941364 | CL5: 25.852331 | CM5: 0 | CN5: 0 | CO5: 26.089033 | CP5: 35.137348 | CQ5: 28.674266 | CR5: 2.5852331 | CS5: 0 | CT5: 0 | CU5: 26.089033 | CV5: =IF(BS5<0,1.1,BS5) -> 45.468681
A6: 1040 | B6: CarbonMonoxide_1 | C6: CO | D6: 1 | E6: 0 | F6: 1 | G6: 28.0097 | H6: 2 | I6: Categories-Category_2 | J6: 1.333 | K6: 500 | L6: 50 | N6: Hydrogen | O6: 50 | P6: 0.25 | Q6: 0.0325 | R6: 77.5 | S6: 170 | T6: 100 | U6: 1812.1302 | V6: 20 | W6: 0.95 | X6: 1 | Y6: 28690.896 | Z6: 1.4345448e+08 | AA6: 1.9122482e+08 | AB6: 191224.82 | AC6: 0 | AD6: 1486.8009 | AE6: 2676241.6 | AF6: 1338120.8 | AG6: 37.480363 | AH6: 58.890697 | AI6: 58.890697 | AJ6: 6214.8067 | AK6: 854.70085 | AL6: Nanofiltration | AM6: 4564.029 | AN6: 320.18403 | AO6: 10011.418 | AP6: 11953.721 | AQ6: 1942.3021 | AR6: 0.0046444287 | AS6: 154.66118 | AT6: 113.58006 | AU6: 7.9680737 | AV6: 249.14335 | AW6: 297.47932 | AX6: 48.335973 | AY6: 1.5712414 | AZ6: Malate_L | BA6: =VLOOKUP($AZ6,Sheet1!$A$2:$B$58,2,FALSE) -> L-Malate | BB6: C4H4O5 | BC6: 4 | BD6: 17.478546 | BE6: 0 | BF6: 132.06916 | BG6: =VLOOKUP($AZ6,Sheet1!$A$2:$C$58,3,FALSE) -> 2.5 | BI6: CO_1:H2_1 | BJ6: 0 | BK6: 0.15166667 | BL6: 0.66701596 | BM6: 100 | BN6: 0 | BO6: 445.98531 | BP6: 72.465992 | BQ6: 2.3556279 | BR6: 400.45674 | BS6: 45.528573 | BT6: 0.60666667 | BU6: 0 | BV6: 26.20409 | BW6: 0 | BX6: 0 | BY6: 1.102311 | BZ6: 52.170436 | CA6: 25.966345 | CB6: 0 | CC6: 0 | CD6: 26.20409 | CE6: 35.292311 | CF6: 28.800725 | CG6: 2.5966345 | CH6: 0 | CI6: 0 | CJ6: 26.20409 | CK6: 52.170436 | CL6: 25.966345 | CM6: 0 | CN6: 0 | CO6: 26.20409 | CP6: 35.292311 | CQ6: 28.800725 | CR6: 2.5966345 | CS6: 0 | CT6: 0 | CU6: 26.20409 | CV6: =IF(BS6<0,1.1,BS6) -> 45.528573
A7: 1041 | B7: CarbonMonoxide_1 | C7: CO | D7: 1 | E7: 0 | F7: 1 | G7: 28.0097 | H7: 2 | I7: Categories-Category_2 | J7: 1.333 | K7: 500 | L7: 50 | N7: Hydrogen | O7: 50 | P7: 0.25 | Q7: 0.0325 | R7: 77.5 | S7: 170 | T7: 100 | U7: 1812.1302 | V7: 20 | W7: 0.95 | X7: 1 | Y7: 30057.546 | Z7: 1.5028773e+08 | AA7: 2.0033355e+08 | AB7: 200333.55 | AC7: 0 | AD7: 1557.6226 | AE7: 2803720.6 | AF7: 1401860.3 | AG7: 39.265687 | AH7: 61.695872 | AI7: 61.695872 | AJ7: 6510.8403 | AK7: 854.70085 | AL7: Nanofiltration | AM7: 4781.4301 | AN7: 335.43554 | AO7: 10488.298 | AP7: 12482.407 | AQ7: 1994.1085 | AR7: 0.0046444287 | AS7: 154.66118 | AT7: 113.58006 | AU7: 7.9680737 | AV7: 249.14335 | AW7: 296.51222 | AX7: 47.368872 | AY7: 1.5712414 | AZ7: Citrate | BA7: =VLOOKUP($AZ7,Sheet1!$A$2:$B$58,2,FALSE) -> Citrate | BB7: C6H5O7 | BC7: 6 | BD7: 17.478546 | BE7: 0 | BF7: 189.0964 | BG7: =VLOOKUP($AZ7,Sheet1!$A$2:$C$58,3,FALSE) -> 2.5 | BI7: CO_1:H2_1 | BJ7: 0 | BK7: 0.10111111 | BL7: 0.63668822 | BM7: 100 | BN7: 0 | BO7: 465.71024 | BP7: 74.398852 | BQ7: 2.4678349 | BR7: 419.53193 | BS7: 46.178307 | BT7: 0.60666667 | BU7: 0 | BV7: 27.452285 | BW7: 0 | BX7: 0 | BY7: 1.102311 | BZ7: 54.655501 | CA7: 27.203215 | CB7: 0 | CC7: 0 | CD7: 27.452285 | CE7: 36.973411 | CF7: 30.172607 | CG7: 2.7203215 | CH7: 0 | CI7: 0 | CJ7: 27.452285 | CK7: 54.655501 | CL7: 27.203215 | CM7: 0 | CN7: 0 | CO7: 27.452285 | CP7: 36.973411 | CQ7: 30.172607 | CR7: 2.7203215 | CS7: 0 | CT7: 0 | CU7: 27.452285 | CV7: =IF(BS7<0,1.1,BS7) -> 46.178307
A8: 823 | B8: CarbonMonoxide_2 | C8: CO | D8: 1 | E8: 0 | F8: 1 | G8: 28.0097 | H8: 2 | I8: Categories-Category_2 | J8: 1.333 | K8: 500 | L8: 33.333333 | N8: Hydrogen | O8: 66.666667 | P8: 0.16666667 | Q8: 0.0325 | R8: 77.5 | S8: 170 | T8: 100 | U8: 1812.1302 | V8: 20 | W8: 0.95 | X8: 1 | Y8: 35510.434 | Z8: 1.7755217e+08 | AA8: 2.3667704e+08 | AB8: 236677.04 | AC8: 0 | AD8: 1840.1985 | AE8: 3312357.4 | AF8: 1104119.1 | AG8: 30.926045 | AH8: 48.592282 | AI8: 48.592282 | AJ8: 7692.0038 | AK8: 854.70085 | AL8: Nanofiltration | AM8: 3765.9019 | AN8: 396.28855 | AO8: 8260.688 | AP8: 12708.895 | AQ8: 4448.2071 | AR8: 0.0069666431 | AS8: 217.36999 | AT8: 106.42143 | AU8: 11.198804 | AV8: 233.44056 | AW8: 359.1434 | AX8: 125.70284 | AY8: 1.5712414 | AZ8: 1-3-Propanediol | BA8: =VLOOKUP($AZ8,Sheet1!$A$2:$B$58,2,FALSE) -> 1,3-Propanediol | BB8: C3H8O2 | BC8: 3 | BD8: 23.925551 | BE8: 0 | BF8: 76.09282 | BG8: =VLOOKUP($AZ8,Sheet1!$A$2:$C$58,3,FALSE) -> 5.3333333 | BH8: 213 | BI8: CO_1:H2_2 | BJ8: 0 | BK8: 0.33333333 | BL8: 0.80838011 | BM8: 100 | BN8: 0 | BO8: 444.27541 | BP8: 155.49967 | BQ8: 1.9436913 | BR8: 330.42752 | BS8: 113.84789 | BT8: 1 | BU8: 0 | BV8: 29.596906 | BW8: 0 | BX8: 0 | BY8: 1.102311 | BZ8: 51.022429 | CA8: 21.425523 | CB8: 0 | CC8: 0 | CD8: 29.596906 | CE8: 37.095839 | CF8: 31.739459 | CG8: 2.1425523 | CH8: 0 | CI8: 0 | CJ8: 29.596906 | CK8: 51.022429 | CL8: 21.425523 | CM8: 0 | CN8: 0 | CO8: 29.596906 | CP8: 37.095839 | CQ8: 31.739459 | CR8: 2.1425523 | CS8: 0 | CT8: 0 | CU8: 29.596906 | CV8: =IF(BS8<0,1.1,BS8) -> 113.84789
A9: 1044 | B9: CarbonMonoxide_1 | C9: CO | D9: 1 | E9: 0 | F9: 1 | G9: 28.0097 | H9: 2 | I9: Categories-Category_2 | J9: 1.333 | K9: 500 | L9: 50 | N9: Hydrogen | O9: 50 | P9: 0.25 | Q9: 0.0325 | R9: 77.5 | S9: 170 | T9: 100 | U9: 1812.1302 | V9: 20 | W9: 0.95 | X9: 1 | Y9: 32491.297 | Z9: 1.6245648e+08 | AA9: 2.1655449e+08 | AB9: 216554.49 | AC9: 0 | AD9: 1683.7428 | AE9: 3030737 | AF9: 1515368.5 | AG9: 42.445017 | AH9: 66.691368 | AI9: 66.691368 | AJ9: 7038.021 | AK9: 854.70085 | AL9: Nanofiltration | AM9: 5168.581 | AN9: 362.59565 | AO9: 11337.533 | AP9: 13423.899 | AQ9: 2086.366 | AR9: 0.0046444287 | AS9: 154.66118 | AT9: 113.58006 | AU9: 7.9680737 | AV9: 249.14335 | AW9: 294.99144 | AX9: 45.848089 | AY9: 1.5712414 | AZ9: Malonate | BA9: =VLOOKUP($AZ9,Sheet1!$A$2:$B$58,2,FALSE) -> Malonate | BB9: C3H2O4 | BC9: 3 | BD9: 17.478546 | BE9: 0 | BF9: 102.04378 | BG9: =VLOOKUP($AZ9,Sheet1!$A$2:$C$58,3,FALSE) -> 2 | BH9: 199 | BI9: CO_1:H2_1 | BJ9: 0 | BK9: 0.17333333 | BL9: 0.58899729 | BM9: 100 | BN9: 0 | BO9: 500.83667 | BP9: 77.840917 | BQ9: 2.6676547 | BR9: 453.5013 | BS9: 47.335363 | BT9: 0.52 | BU9: 0 | BV9: 29.675088 | BW9: 0 | BX9: 0 | BY9: 1.102311 | BZ9: 59.08094 | CA9: 29.405851 | CB9: 0 | CC9: 0 | CD9: 29.675088 | CE9: 39.967136 | CF9: 32.615673 | CG9: 2.9405851 | CH9: 0 | CI9: 0 | CJ9: 29.675088 | CK9: 59.08094 | CL9: 29.405851 | CM9: 0 | CN9: 0 | CO9: 29.675088 | CP9: 39.967136 | CQ9: 32.615673 | CR9: 2.9405851 | CS9: 0 | CT9: 0 | CU9: 29.675088 | CV9: =IF(BS9<0,1.1,BS9) -> 47.335363
A10: 1048 | B10: CarbonMonoxide_1 | C10: CO | D10: 1 | E10: 0 | F10: 1 | G10: 28.0097 | H10: 2 | I10: Categories-Category_2 | J10: 1.333 | K10: 500 | L10: 50 | N10: Hydrogen | O10: 50 | P10: 0.25 | Q10: 0.0325 | R10: 77.5 | S10: 170 | T10: 100 | U10: 1812.1302 | V10: 20 | W10: 0.95 | X10: 1 | Y10: 33495.736 | Z10: 1.6747868e+08 | AA10: 2.2324908e+08 | AB10: 223249.08 | AC10: 0 | AD10: 1735.7942 | AE10: 3124429.5 | AF10: 1562214.8 | AG10: 43.757167 | AH10: 68.753072 | AI10: 68.753072 | AJ10: 7255.5951 | AK10: 854.70085 | AL10: Nanofiltration | AM10: 5328.3631 | AN10: 373.80497 | AO10: 11688.022 | AP10: 13812.464 | AQ10: 2124.4418 | AR10: 0.0046444287 | AS10: 154.66118 | AT10: 113.58006 | AU10: 7.9680737 | AV10: 249.14335 | AW10: 294.42822 | AX10: 45.284868 | AY10: 1.5712414 | AZ10: Glutamate_L | BA10: =VLOOKUP($AZ10,Sheet1!$A$2:$B$58,2,FALSE) -> L-Glutamate | BB10: C5H8NO4 | BC10: 5 | BD10: 17.478546 | BE10: 0 | BF10: 146.11892 | BG10: =VLOOKUP($AZ10,Sheet1!$A$2:$C$58,3,FALSE) -> 3.4 | BH10: 333.8 | BI10: CO_1:H2_1 | BJ10: 0 | BK10: 0.11741935 | BL10: 0.57133498 | BM10: 100 | BN10: 0 | BO10: 515.33379 | BP10: 79.261501 | BQ10: 2.7501229 | BR10: 467.52089 | BS10: 47.812895 | BT10: 0.58709677 | BU10: 0 | BV10: 30.592467 | BW10: 0 | BX10: 0 | BY10: 1.102311 | BZ10: 60.907374 | CA10: 30.314907 | CB10: 0 | CC10: 0 | CD10: 30.592467 | CE10: 41.202685 | CF10: 33.623958 | CG10: 3.0314907 | CH10: 0 | CI10: 0 | CJ10: 30.592467 | CK10: 60.907374 | CL10: 30.314907 | CM10: 0 | CN10: 0 | CO10: 30.592467 | CP10: 41.202685 | CQ10: 33.623958 | CR10: 3.0314907 | CS10: 0 | CT10: 0 | CU10: 30.592467 | CV10: =IF(BS10<0,1.1,BS10) -> 47.812895
A11: 1052 | B11: CarbonMonoxide_1 | C11: CO | D11: 1 | E11: 0 | F11: 1 | G11: 28.0097 | H11: 2 | I11: Categories-Category_2 | J11: 1.333 | K11: 500 | L11: 50 | N11: Hydrogen | O11: 50 | P11: 0.25 | Q11: 0.0325 | R11: 77.5 | S11: 170 | T11: 100 | U11: 1812.1302 | V11: 20 | W11: 0.95 | X11: 1 | Y11: 35747.695 | Z11: 1.7873848e+08 | AA11: 2.3825839e+08 | AB11: 238258.39 | AC11: 0 | AD11: 1852.4938 | AE11: 3334488.8 | AF11: 1667244.4 | AG11: 46.699015 | AH11: 73.375425 | AI11: 73.375425 | AJ11: 7743.3977 | AK11: 854.70085 | AL11: Nanofiltration | AM11: 5686.5955 | AN11: 398.93634 | AO11: 12473.822 | AP11: 14683.63 | AQ11: 2209.808 | AR11: 0.0046444287 | AS11: 154.66118 | AT11: 113.58006 | AU11: 7.9680737 | AV11: 249.14335 | AW11: 293.2805 | AX11: 44.13715 | AY11: 1.5712414 | AZ11: Itaconate | BA11: =VLOOKUP($AZ11,Sheet1!$A$2:$B$58,2,FALSE) -> Itaconate | BB11: C5H4O4 | BC11: 5 | BD11: 17.478546 | BE11: 0 | BF11: 128.08086 | BG11: =VLOOKUP($AZ11,Sheet1!$A$2:$C$58,3,FALSE) -> 3.2 | BH11: 381 | BI11: CO_1:H2_1 | BJ11: 0 | BK11: 0.12551724 | BL11: 0.5353432 | BM11: 100 | BN11: 0 | BO11: 547.83642 | BP11: 82.446458 | BQ11: 2.935017 | BR11: 498.95289 | BS11: 48.883524 | BT11: 0.62758621 | BU11: 0 | BV11: 32.649236 | BW11: 0 | BX11: 0 | BY11: 1.102311 | BZ11: 65.002251 | CA11: 32.353015 | CB11: 0 | CC11: 0 | CD11: 32.649236 | CE11: 43.972791 | CF11: 35.884538 | CG11: 3.2353015 | CH11: 0 | CI11: 0 | CJ11: 32.649236 | CK11: 65.002251 | CL11: 32.353015 | CM11: 0 | CN11: 0 | CO11: 32.649236 | CP11: 43.972791 | CQ11: 35.884538 | CR11: 3.2353015 | CS11: 0 | CT11: 0 | CU11: 32.649236 | CV11: =IF(BS11<0,1.1,BS11) -> 48.883524
A12: 817 | B12: CarbonMonoxide_2 | C12: CO | D12: 1 | E12: 0 | F12: 1 | G12: 28.0097 | H12: 2 | I12: Categories-Category_2 | J12: 1.333 | K12: 500 | L12: 33.333333 | N12: Hydrogen | O12: 66.666667 | P12: 0.16666667 | Q12: 0.0325 | R12: 77.5 | S12: 170 | T12: 100 | U12: 1812.1302 | V12: 20 | W12: 0.95 | X12: 1 | Y12: 39932.558 | Z12: 1.9966279e+08 | AA12: 2.661505e+08 | AB12: 266150.5 | AC12: 0 | AD12: 2069.359 | AE12: 3724846.1 | AF12: 1241615.4 | AG12: 34.777274 | AH12: 54.643493 | AI12: 54.643493 | AJ12: 8649.8912 | AK12: 854.70085 | AL12: Nanofiltration | AM12: 4234.8707 | AN12: 445.63848 | AO12: 9289.3938 | AP12: 14185.101 | AQ12: 4895.7074 | AR12: 0.0069666431 | AS12: 217.36999 | AT12: 106.42143 | AU12: 11.198804 | AV12: 233.44056 | AW12: 356.46869 | AX12: 123.02812 | AY12: 1.5712414 | AZ12: Ethanol | BA12: =VLOOKUP($AZ12,Sheet1!$A$2:$B$58,2,FALSE) -> #N/A | BB12: C2H6O | BC12: 2 | BD12: 23.925551 | BE12: 0 | BF12: 46.06744 | BG12: =VLOOKUP($AZ12,Sheet1!$A$2:$C$58,3,FALSE) -> #N/A | BH12: 78.37 | BI12: CO_1:H2_2 | BJ12: 0 | BK12: 0.5 | BL12: 0.71886025 | BM12: 100 | BN12: 0 | BO12: 495.88037 | BP12: 171.14331 | BQ12: 2.1857397 | BR12: 371.57575 | BS12: 124.30462 | BT12: 1 | BU12: 0 | BV12: 33.282617 | BW12: 0 | BX12: 0 | BY12: 1.102311 | BZ12: 57.376267 | CA12: 24.093649 | CB12: 0 | CC12: 0 | CD12: 33.282617 | CE12: 41.715395 | CF12: 35.691982 | CG12: 2.4093649 | CH12: 0 | CI12: 0 | CJ12: 33.282617 | CK12: 57.376267 | CL12: 24.093649 | CM12: 0 | CN12: 0 | CO12: 33.282617 | CP12: 41.715395 | CQ12: 35.691982 | CR12: 2.4093649 | CS12: 0 | CT12: 0 | CU12: 33.282617 | CV12: =IF(BS12<0,1.1,BS12) -> 124.30462
A13: 824 | B13: CarbonMonoxide_2 | C13: CO | D13: 1 | E13: 0 | F13: 1 | G13: 28.0097 | H13: 2 | I13: Categories-Category_2 | J13: 1.333 | K13: 500 | L13: 33.333333 | N13: Hydrogen | O13: 66.666667 | P13: 0.16666667 | Q13: 0.0325 | R13: 77.5 | S13: 170 | T13: 100 | U13: 1812.1302 | V13: 20 | W13: 0.95 | X13: 1 | Y13: 40192.479 | Z13: 2.0096239e+08 | AA13: 2.6788287e+08 | AB13: 267882.87 | AC13: 0 | AD13: 2082.8284 | AE13: 3749091.2 | AF13: 1249697.1 | AG13: 35.00364 | AH13: 54.999167 | AI13: 54.999167 | AJ13: 8706.1933 | AK13: 854.70085 | AL13: Nanofiltration | AM13: 4262.4355 | AN13: 448.53914 | AO13: 9349.8585 | AP13: 14271.869 | AQ13: 4922.0103 | AR13: 0.0069666431 | AS13: 217.36999 | AT13: 106.42143 | AU13: 11.198804 | AV13: 233.44056 | AW13: 356.32979 | AX13: 122.88922 | AY13: 1.5712414 | AZ13: 1-3-Butanediol-PW1 | BA13: =VLOOKUP($AZ13,Sheet1!$A$2:$B$58,2,FALSE) -> 1,3-Butanediol (PW1) | BB13: C4H10O2 | BC13: 4 | BD13: 23.925551 | BE13: 25.35 | BF13: 90.1192 | BG13: =VLOOKUP($AZ13,Sheet1!$A$2:$C$58,3,FALSE) -> 5.5 | BH13: 207 | BI13: CO_1:H2_2 | BJ13: 0 | BK13: 0.25 | BL13: 0.71421144 | BM13: 100 | BN13: 0 | BO13: 498.91358 | BP13: 172.06281 | BQ13: 2.1999667 | BR13: 373.99434 | BS13: 124.91924 | BT13: 1 | BU13: 0 | BV13: 33.499254 | BW13: 0.75673327 | BX13: 0 | BY13: 1.102311 | BZ13: 57.749729 | CA13: 24.250475 | CB13: 0 | CC13: 0 | CD13: 33.499254 | CE13: 41.98692 | CF13: 35.924301 | CG13: 2.4250475 | CH13: 0 | CI13: 0 | CJ13: 33.499254 | CK13: 57.749729 | CL13: 24.250475 | CM13: 0 | CN13: 0 | CO13: 33.499254 | CP13: 41.98692 | CQ13: 35.924301 | CR13: 2.4250475 | CS13: 0 | CT13: 0 | CU13: 33.499254 | CV13: =IF(BS13<0,1.1,BS13) -> 124.91924
A14: 825 | B14: CarbonMonoxide_2 | C14: CO | D14: 1 | E14: 0 | F14: 1 | G14: 28.0097 | H14: 2 | I14: Categories-Category_2 | J14: 1.333 | K14: 500 | L14: 33.333333 | N14: Hydrogen | O14: 66.666667 | P14: 0.16666667 | Q14: 0.0325 | R14: 77.5 | S14: 170 | T14: 100 | U14: 1812.1302 | V14: 20 | W14: 0.95 | X14: 1 | Y14: 40192.479 | Z14: 2.0096239e+08 | AA14: 2.6788287e+08 | AB14: 267882.87 | AC14: 0 | AD14: 2082.8284 | AE14: 3749091.2 | AF14: 1249697.1 | AG14: 35.00364 | AH14: 54.999167 | AI14: 54.999167 | AJ14: 8706.1933 | AK14: 854.70085 | AL14: Nanofiltration | AM14: 4262.4355 | AN14: 448.53914 | AO14: 9349.8585 | AP14: 14271.869 | AQ14: 4922.0103 | AR14: 0.0069666431 | AS14: 217.36999 | AT14: 106.42143 | AU14: 11.198804 | AV14: 233.44056 | AW14: 356.32979 | AX14: 122.88922 | AY14: 1.5712414 | AZ14: 1-3-Butanediol-PW2 | BA14: =VLOOKUP($AZ14,Sheet1!$A$2:$B$58,2,FALSE) -> 1,3-Butanediol (PW2) | BB14: C4H10O2 | BC14: 4 | BD14: 23.925551 | BE14: 25.35 | BF14: 90.1192 | BG14: =VLOOKUP($AZ14,Sheet1!$A$2:$C$58,3,FALSE) -> 5.5 | BH14: 207 | BI14: CO_1:H2_2 | BJ14: 0 | BK14: 0.25 | BL14: 0.71421144 | BM14: 100 | BN14: 0 | BO14: 498.91358 | BP14: 172.06281 | BQ14: 2.1999667 | BR14: 373.99434 | BS14: 124.91924 | BT14: 1 | BU14: 0 | BV14: 33.499254 | BW14: 0.75673327 | BX14: 0 | BY14: 1.102311 | BZ14: 57.749729 | CA14: 24.250475 | CB14: 0 | CC14: 0 | CD14: 33.499254 | CE14: 41.98692 | CF14: 35.924301 | CG14: 2.4250475 | CH14: 0 | CI14: 0 | CJ14: 33.499254 | CK14: 57.749729 | CL14: 24.250475 | CM14: 0 | CN14: 0 | CO14: 33.499254 | CP14: 41.98692 | CQ14: 35.924301 | CR14: 2.4250475 | CS14: 0 | CT14: 0 | CU14: 33.499254 | CV14: =IF(BS14<0,1.1,BS14) -> 124.91924
A15: 826 | B15: CarbonMonoxide_2 | C15: CO | D15: 1 | E15: 0 | F15: 1 | G15: 28.0097 | H15: 2 | I15: Categories-Category_2 | J15: 1.333 | K15: 500 | L15: 33.333333 | N15: Hydrogen | O15: 66.666667 | P15: 0.16666667 | Q15: 0.0325 | R15: 77.5 | S15: 170 | T15: 100 | U15: 1812.1302 | V15: 20 | W15: 0.95 | X15: 1 | Y15: 40192.479 | Z15: 2.0096239e+08 | AA15: 2.6788287e+08 | AB15: 267882.87 | AC15: 0 | AD15: 2082.8284 | AE15: 3749091.2 | AF15: 1249697.1 | AG15: 35.00364 | AH15: 54.999167 | AI15: 54.999167 | AJ15: 8706.1933 | AK15: 854.70085 | AL15: Nanofiltration | AM15: 4262.4355 | AN15: 448.53914 | AO15: 9349.8585 | AP15: 14271.869 | AQ15: 4922.0103 | AR15: 0.0069666431 | AS15: 217.36999 | AT15: 106.42143 | AU15: 11.198804 | AV15: 233.44056 | AW15: 356.32979 | AX15: 122.88922 | AY15: 1.5712414 | AZ15: 2-3-Butanediol | BA15: =VLOOKUP($AZ15,Sheet1!$A$2:$B$58,2,FALSE) -> 2,3-Butanediol | BB15: C4H10O2 | BC15: 4 | BD15: 23.925551 | BE15: 0 | BF15: 90.1192 | BG15: =VLOOKUP($AZ15,Sheet1!$A$2:$C$58,3,FALSE) -> 5.5 | BH15: 177 | BI15: CO_1:H2_2 | BJ15: 0 | BK15: 0.25 | BL15: 0.71421144 | BM15: 100 | BN15: 0 | BO15: 498.91358 | BP15: 172.06281 | BQ15: 2.1999667 | BR15: 373.99434 | BS15: 124.91924 | BT15: 1 | BU15: 0 | BV15: 33.499254 | BW15: 0 | BX15: 0 | BY15: 1.102311 | BZ15: 57.749729 | CA15: 24.250475 | CB15: 0 | CC15: 0 | CD15: 33.499254 | CE15: 41.98692 | CF15: 35.924301 | CG15: 2.4250475 | CH15: 0 | CI15: 0 | CJ15: 33.499254 | CK15: 57.749729 | CL15: 24.250475 | CM15: 0 | CN15: 0 | CO15: 33.499254 | CP15: 41.98692 | CQ15: 35.924301 | CR15: 2.4250475 | CS15: 0 | CT15: 0 | CU15: 33.499254 | CV15: =IF(BS15<0,1.1,BS15) -> 124.91924
A16: 827 | B16: CarbonMonoxide_2 | C16: CO | D16: 1 | E16: 0 | F16: 1 | G16: 28.0097 | H16: 2 | I16: Categories-Category_2 | J16: 1.333 | K16: 500 | L16: 33.333333 | N16: Hydrogen | O16: 66.666667 | P16: 0.16666667 | Q16: 0.0325 | R16: 77.5 | S16: 170 | T16: 100 | U16: 1812.1302 | V16: 20 | W16: 0.95 | X16: 1 | Y16: 40453.867 | Z16: 2.0226933e+08 | AA16: 2.6962502e+08 | AB16: 269625.02 | AC16: 0 | AD16: 2096.3739 | AE16: 3773473 | AF16: 1257824.3 | AG16: 35.231282 | AH16: 55.356849 | AI16: 55.356849 | AJ16: 8762.8132 | AK16: 854.70085 | AL16: Nanofiltration | AM16: 4290.1558 | AN16: 451.45617 | AO16: 9410.6644 | AP16: 14359.126 | AQ16: 4948.4617 | AR16: 0.0069666431 | AS16: 217.36999 | AT16: 106.42143 | AU16: 11.198804 | AV16: 233.44056 | AW16: 356.1919 | AX16: 122.75134 | AY16: 1.5712414 | AZ16: EthylAcetate | BA16: =VLOOKUP($AZ16,Sheet1!$A$2:$B$58,2,FALSE) -> Ethyl Acetate | BB16: C4H8O2 | BC16: 4 | BD16: 23.925551 | BE16: 0 | BF16: 88.10352 | BG16: =VLOOKUP($AZ16,Sheet1!$A$2:$C$58,3,FALSE) -> 5 | BH16: 77.1 | BI16: CO_1:H2_2 | BJ16: 0 | BK16: 0.25 | BL16: 0.70959665 | BM16: 100 | BN16: 0 | BO16: 501.9639 | BP16: 172.98749 | BQ16: 2.214274 | BR16: 376.42658 | BS16: 125.53733 | BT16: 1 | BU16: 0 | BV16: 33.717113 | BW16: 0 | BX16: 0 | BY16: 1.102311 | BZ16: 58.125299 | CA16: 24.408185 | CB16: 0 | CC16: 0 | CD16: 33.717113 | CE16: 42.259978 | CF16: 36.157932 | CG16: 2.4408185 | CH16: 0 | CI16: 0 | CJ16: 33.717113 | CK16: 58.125299 | CL16: 24.408185 | CM16: 0 | CN16: 0 | CO16: 33.717113 | CP16: 42.259978 | CQ16: 36.157932 | CR16: 2.4408185 | CS16: 0 | CT16: 0 | CU16: 33.717113 | CV16: =IF(BS16<0,1.1,BS16) -> 125.53733
A17: 828 | B17: CarbonMonoxide_2 | C17: CO | D17: 1 | E17: 0 | F17: 1 | G17: 28.0097 | H17: 2 | I17: Categories-Category_2 | J17: 1.333 | K17: 500 | L17: 33.333333 | N17: Hydrogen | O17: 66.666667 | P17: 0.16666667 | Q17: 0.0325 | R17: 77.5 | S17: 170 | T17: 100 | U17: 1812.1302 | V17: 20 | W17: 0.95 | X17: 1 | Y17: 40921.984 | Z17: 2.0460992e+08 | AA17: 2.7274503e+08 | AB17: 272745.03 | AC17: 0 | AD17: 2120.6324 | AE17: 3817138.3 | AF17: 1272379.4 | AG17: 35.638966 | AH17: 55.997419 | AI17: 55.997419 | AJ17: 8864.2134 | AK17: 854.70085 | AL17: Nanofiltration | AM17: 4339.8 | AN17: 456.68026 | AO17: 9519.5612 | AP17: 14515.394 | AQ17: 4995.8332 | AR17: 0.0069666431 | AS17: 217.36999 | AT17: 106.42143 | AU17: 11.198804 | AV17: 233.44056 | AW17: 355.94937 | AX17: 122.50881 | AY17: 1.5712414 | AZ17: Butyrate | BA17: =VLOOKUP($AZ17,Sheet1!$A$2:$B$58,2,FALSE) -> Butyrate | BB17: C4H7O2 | BC17: 4 | BD17: 23.925551 | BE17: 0 | BF17: 87.09568 | BG17: =VLOOKUP($AZ17,Sheet1!$A$2:$C$58,3,FALSE) -> 4.75 | BH17: 163.5 | BI17: CO_1:H2_2 | BJ17: 0 | BK17: 0.25 | BL17: 0.70147938 | BM17: 100 | BN17: 0 | BO17: 507.42671 | BP17: 174.64349 | BQ17: 2.2398968 | BR17: 380.78245 | BS17: 126.64426 | BT17: 1 | BU17: 0 | BV17: 34.107276 | BW17: 0 | BX17: 0 | BY17: 1.102311 | BZ17: 58.797904 | CA17: 24.690628 | CB17: 0 | CC17: 0 | CD17: 34.107276 | CE17: 42.748995 | CF17: 36.576338 | CG17: 2.4690628 | CH17: 0 | CI17: 0 | CJ17: 34.107276 | CK17: 58.797904 | CL17: 24.690628 | CM17: 0 | CN17: 0 | CO17: 34.107276 | CP17: 42.748995 | CQ17: 36.576338 | CR17: 2.4690628 | CS17: 0 | CT17: 0 | CU17: 34.107276 | CV17: =IF(BS17<0,1.1,BS17) -> 126.64426
A18: 829 | B18: CarbonMonoxide_2 | C18: CO | D18: 1 | E18: 0 | F18: 1 | G18: 28.0097 | H18: 2 | I18: Categories-Category_2 | J18: 1.333 | K18: 500 | L18: 33.333333 | N18: Hydrogen | O18: 66.666667 | P18: 0.16666667 | Q18: 0.0325 | R18: 77.5 | S18: 170 | T18: 100 | U18: 1812.1302 | V18: 20 | W18: 0.95 | X18: 1 | Y18: 40921.984 | Z18: 2.0460992e+08 | AA18: 2.7274503e+08 | AB18: 272745.03 | AC18: 0 | AD18: 2120.6324 | AE18: 3817138.3 | AF18: 1272379.4 | AG18: 35.638966 | AH18: 55.997419 | AI18: 55.997419 | AJ18: 8864.2134 | AK18: 854.70085 | AL18: Nanofiltration | AM18: 4339.8 | AN18: 456.68026 | AO18: 9519.5612 | AP18: 14515.394 | AQ18: 4995.8332 | AR18: 0.0069666431 | AS18: 217.36999 | AT18: 106.42143 | AU18: 11.198804 | AV18: 233.44056 | AW18: 355.94937 | AX18: 122.50881 | AY18: 1.5712414 | AZ18: Isobutyrate | BA18: =VLOOKUP($AZ18,Sheet1!$A$2:$B$58,2,FALSE) -> Isobutyrate | BB18: C4H7O2 | BC18: 4 | BD18: 23.925551 | BE18: 0 | BF18: 87.09568 | BG18: =VLOOKUP($AZ18,Sheet1!$A$2:$C$58,3,FALSE) -> 4.75 | BH18: 155 | BI18: CO_1:H2_2 | BJ18: 0 | BK18: 0.25 | BL18: 0.70147938 | BM18: 100 | BN18: 0 | BO18: 507.42671 | BP18: 174.64349 | BQ18: 2.2398968 | BR18: 380.78245 | BS18: 126.64426 | BT18: 1 | BU18: 0 | BV18: 34.107276 | BW18: 0 | BX18: 0 | BY18: 1.102311 | BZ18: 58.797904 | CA18: 24.690628 | CB18: 0 | CC18: 0 | CD18: 34.107276 | CE18: 42.748995 | CF18: 36.576338 | CG18: 2.4690628 | CH18: 0 | CI18: 0 | CJ18: 34.107276 | CK18: 58.797904 | CL18: 24.690628 | CM18: 0 | CN18: 0 | CO18: 34.107276 | CP18: 42.748995 | CQ18: 36.576338 | CR18: 2.4690628 | CS18: 0 | CT18: 0 | CU18: 34.107276 | CV18: =IF(BS18<0,1.1,BS18) -> 126.64426
A19: 1054 | B19: CarbonMonoxide_1 | C19: CO | D19: 1 | E19: 0 | F19: 1 | G19: 28.0097 | H19: 2 | I19: Categories-Category_2 | J19: 1.333 | K19: 500 | L19: 50 | N19: Hydrogen | O19: 50 | P19: 0.25 | Q19: 0.0325 | R19: 77.5 | S19: 170 | T19: 100 | U19: 1812.1302 | V19: 20 | W19: 0.95 | X19: 1 | Y19: 37774.35 | Z19: 1.8887175e+08 | AA19: 2.5176604e+08 | AB19: 251766.04 | AC19: 0 | AD19: 1957.5177 | AE19: 3523531.9 | AF19: 1761766 | AG19: 49.346536 | AH19: 77.53532 | AI19: 77.53532 | AJ19: 8182.3964 | AK19: 854.70085 | AL19: Nanofiltration | AM19: 6008.9873 | AN19: 421.55335 | AO19: 13181.004 | AP19: 15467.638 | AQ19: 2286.6335 | AR19: 0.0046444287 | AS19: 154.66118 | AT19: 113.58006 | AU19: 7.9680737 | AV19: 249.14335 | AW19: 292.3646 | AX19: 43.221253 | AY19: 1.5712414 | AZ19: Acrylate-PW2 | BA19: =VLOOKUP($AZ19,Sheet1!$A$2:$B$58,2,FALSE) -> Acrylate (PW2) | BB19: C3H3O2 | BC19: 3 | BD19: 17.478546 | BE19: 0 | BF19: 71.05362 | BG19: =VLOOKUP($AZ19,Sheet1!$A$2:$C$58,3,FALSE) -> 3.6666667 | BH19: 80 | BI19: CO_1:H2_1 | BJ19: 0 | BK19: 0.21411765 | BL19: 0.50662118 | BM19: 100 | BN19: 0 | BO19: 577.08721 | BP19: 85.312765 | BQ19: 3.1014128 | BR19: 527.24017 | BS19: 49.847038 | BT19: 0.64235294 | BU19: 0 | BV19: 34.500229 | BW19: 0 | BX19: 0 | BY19: 1.102311 | BZ19: 68.687443 | CA19: 34.187214 | CB19: 0 | CC19: 0 | CD19: 34.500229 | CE19: 46.465754 | CF19: 37.91895 | CG19: 3.4187214 | CH19: 0 | CI19: 0 | CJ19: 34.500229 | CK19: 68.687443 | CL19: 34.187214 | CM19: 0 | CN19: 0 | CO19: 34.500229 | CP19: 46.465754 | CQ19: 37.91895 | CR19: 3.4187214 | CS19: 0 | CT19: 0 | CU19: 34.500229 | CV19: =IF(BS19<0,1.1,BS19) -> 49.847038
A20: 830 | B20: CarbonMonoxide_2 | C20: CO | D20: 1 | E20: 0 | F20: 1 | G20: 28.0097 | H20: 2 | I20: Categories-Category_2 | J20: 1.333 | K20: 500 | L20: 33.333333 | N20: Hydrogen | O20: 66.666667 | P20: 0.16666667 | Q20: 0.0325 | R20: 77.5 | S20: 170 | T20: 100 | U20: 1812.1302 | V20: 20 | W20: 0.95 | X20: 1 | Y20: 41917.601 | Z20: 2.09588e+08 | AA20: 2.7938081e+08 | AB20: 279380.81 | AC20: 0 | AD20: 2172.2266 | AE20: 3910007.8 | AF20: 1303335.9 | AG20: 36.506049 | AH20: 57.359815 | AI20: 57.359815 | AJ20: 9079.8763 | AK20: 854.70085 | AL20: Nanofiltration | AM20: 4445.3857 | AN20: 467.79112 | AO20: 9751.1685 | AP20: 14847.754 | AQ20: 5096.5854 | AR20: 0.0069666431 | AS20: 217.36999 | AT20: 106.42143 | AU20: 11.198804 | AV20: 233.44056 | AW20: 355.45156 | AX20: 122.01099 | AY20: 1.5712414 | AZ20: Succinate | BA20: =VLOOKUP($AZ20,Sheet1!$A$2:$B$58,2,FALSE) -> Succinate | BB20: C4H4O4 | BC20: 4 | BD20: 23.925551 | BE20: 0 | BF20: 116.07016 | BG20: =VLOOKUP($AZ20,Sheet1!$A$2:$C$58,3,FALSE) -> 3 | BH20: 235 | BI20: CO_1:H2_2 | BJ20: 0 | BK20: 0.17846154 | BL20: 0.68481802 | BM20: 100 | BN20: 0 | BO20: 519.04528 | BP20: 178.16557 | BQ20: 2.2943926 | BR20: 390.04674 | BS20: 128.99853 | BT20: 0.71384615 | BU20: 0 | BV20: 34.937093 | BW20: 0 | BX20: 0 | BY20: 1.102311 | BZ20: 60.228435 | CA20: 25.291342 | CB20: 0 | CC20: 0 | CD20: 34.937093 | CE20: 43.789062 | CF20: 37.466227 | CG20: 2.5291342 | CH20: 0 | CI20: 0 | CJ20: 34.937093 | CK20: 60.228435 | CL20: 25.291342 | CM20: 0 | CN20: 0 | CO20: 34.937093 | CP20: 43.789062 | CQ20: 37.466227 | CR20: 2.5291342 | CS20: 0 | CT20: 0 | CU20: 34.937093 | CV20: =IF(BS20<0,1.1,BS20) -> 128.99853
A21: 831 | B21: CarbonMonoxide_2 | C21: CO | D21: 1 | E21: 0 | F21: 1 | G21: 28.0097 | H21: 2 | I21: Categories-Category_2 | J21: 1.333 | K21: 500 | L21: 33.333333 | N21: Hydrogen | O21: 66.666667 | P21: 0.16666667 | Q21: 0.0325 | R21: 77.5 | S21: 170 | T21: 100 | U21: 1812.1302 | V21: 20 | W21: 0.95 | X21: 1 | Y21: 42405.976 | Z21: 2.1202988e+08 | AA21: 2.8263583e+08 | AB21: 282635.83 | AC21: 0 | AD21: 2197.5348 | AE21: 3955562.7 | AF21: 1318520.9 | AG21: 36.931375 | AH21: 58.028105 | AI21: 58.028105 | AJ21: 9185.6645 | AK21: 854.70085 | AL21: Nanofiltration | AM21: 4497.1782 | AN21: 473.24128 | AO21: 9864.7779 | AP21: 15010.785 | AQ21: 5146.0069 | AR21: 0.0069666431 | AS21: 217.36999 | AT21: 106.42143 | AU21: 11.198804 | AV21: 233.44056 | AW21: 355.21591 | AX21: 121.77535 | AY21: 1.5712414 | AZ21: Malate_L | BA21: =VLOOKUP($AZ21,Sheet1!$A$2:$B$58,2,FALSE) -> L-Malate | BB21: C4H4O5 | BC21: 4 | BD21: 23.925551 | BE21: 0 | BF21: 132.06916 | BG21: =VLOOKUP($AZ21,Sheet1!$A$2:$C$58,3,FALSE) -> 2.5 | BI21: CO_1:H2_2 | BJ21: 0 | BK21: 0.15466667 | BL21: 0.6769312 | BM21: 100 | BN21: 0 | BO21: 524.74448 | BP21: 179.89324 | BQ21: 2.3211242 | BR21: 394.59112 | BS21: 130.15337 | BT21: 0.61866667 | BU21: 0 | BV21: 35.344139 | BW21: 0 | BX21: 0 | BY21: 1.102311 | BZ21: 60.930147 | CA21: 25.586007 | CB21: 0 | CC21: 0 | CD21: 35.344139 | CE21: 44.299242 | CF21: 37.90274 | CG21: 2.5586007 | CH21: 0 | CI21: 0 | CJ21: 35.344139 | CK21: 60.930147 | CL21: 25.586007 | CM21: 0 | CN21: 0 | CO21: 35.344139 | CP21: 44.299242 | CQ21: 37.90274 | CR21: 2.5586007 | CS21: 0 | CT21: 0 | CU21: 35.344139 | CV21: =IF(BS21<0,1.1,BS21) -> 130.15337
A22: 818 | B22: CarbonMonoxide_2 | C22: CO | D22: 1 | E22: 0 | F22: 1 | G22: 28.0097 | H22: 2 | I22: Categories-Category_2 | J22: 1.333 | K22: 500 | L22: 33.333333 | N22: Hydrogen | O22: 66.666667 | P22: 0.16666667 | Q22: 0.0325 | R22: 77.5 | S22: 170 | T22: 100 | U22: 1812.1302 | V22: 20 | W22: 0.95 | X22: 1 | Y22: 42726.826 | Z22: 2.1363413e+08 | AA22: 2.847743e+08 | AB22: 284774.3 | AC22: 0 | AD22: 2214.1617 | AE22: 3985491.1 | AF22: 1328497 | AG22: 37.210804 | AH22: 58.467155 | AI22: 58.467155 | AJ22: 9255.1647 | AK22: 854.70085 | AL22: Nanofiltration | AM22: 4531.2045 | AN22: 476.82189 | AO22: 9939.4163 | AP22: 15117.892 | AQ22: 5178.4756 | AR22: 0.0069666431 | AS22: 217.36999 | AT22: 106.42143 | AU22: 11.198804 | AV22: 233.44056 | AW22: 355.06403 | AX22: 121.62347 | AY22: 1.5712414 | AZ22: Isobutanol | BA22: =VLOOKUP($AZ22,Sheet1!$A$2:$B$58,2,FALSE) -> Isobutanol | BB22: C4H10O | BC22: 4 | BD22: 23.925551 | BE22: 32.959 | BF22: 74.1202 | BG22: =VLOOKUP($AZ22,Sheet1!$A$2:$C$58,3,FALSE) -> 5.602 | BH22: 108 | BI22: CO_1:H2_2 | BJ22: 0 | BK22: 0.25 | BL22: 0.67184789 | BM22: 100 | BN22: 0 | BO22: 528.48871 | BP22: 181.02828 | BQ22: 2.3386862 | BR22: 397.57665 | BS22: 130.91206 | BT22: 1 | BU22: 0 | BV22: 35.611558 | BW22: 0.92551412 | BX22: 0 | BY22: 1.102311 | BZ22: 61.391153 | CA22: 25.779595 | CB22: 0 | CC22: 0 | CD22: 35.611558 | CE22: 44.634417 | CF22: 38.189518 | CG22: 2.5779595 | CH22: 0 | CI22: 0 | CJ22: 35.611558 | CK22: 61.391153 | CL22: 25.779595 | CM22: 0 | CN22: 0 | CO22: 35.611558 | CP22: 44.634417 | CQ22: 38.189518 | CR22: 2.5779595 | CS22: 0 | CT22: 0 | CU22: 35.611558 | CV22: =IF(BS22<0,1.1,BS22) -> 130.91206
A23: 832 | B23: CarbonMonoxide_2 | C23: CO | D23: 1 | E23: 0 | F23: 1 | G23: 28.0097 | H23: 2 | I23: Categories-Category_2 | J23: 1.333 | K23: 500 | L23: 33.333333 | N23: Hydrogen | O23: 66.666667 | P23: 0.16666667 | Q23: 0.0325 | R23: 77.5 | S23: 170 | T23: 100 | U23: 1812.1302 | V23: 20 | W23: 0.95 | X23: 1 | Y23: 44425.925 | Z23: 2.2212963e+08 | AA23: 2.9609879e+08 | AB23: 296098.79 | AC23: 0 | AD23: 2302.2113 | AE23: 4143980.4 | AF23: 1381326.8 | AG23: 38.690549 | AH23: 60.792192 | AI23: 60.792192 | AJ23: 9623.2107 | AK23: 854.70085 | AL23: Nanofiltration | AM23: 4711.3949 | AN23: 495.78346 | AO23: 10334.673 | AP23: 15685.09 | AQ23: 5350.4172 | AR23: 0.0069666431 | AS23: 217.36999 | AT23: 106.42143 | AU23: 11.198804 | AV23: 233.44056 | AW23: 354.29629 | AX23: 120.85573 | AY23: 1.5712414 | AZ23: Citrate | BA23: =VLOOKUP($AZ23,Sheet1!$A$2:$B$58,2,FALSE) -> Citrate | BB23: C6H5O7 | BC23: 6 | BD23: 23.925551 | BE23: 0 | BF23: 189.0964 | BG23: =VLOOKUP($AZ23,Sheet1!$A$2:$C$58,3,FALSE) -> 2.5 | BI23: CO_1:H2_2 | BJ23: 0 | BK23: 0.10311111 | BL23: 0.64615263 | BM23: 100 | BN23: 0 | BO23: 548.31672 | BP23: 187.03898 | BQ23: 2.4316877 | BR23: 413.38691 | BS23: 134.92982 | BT23: 0.61866667 | BU23: 0 | BV23: 37.027707 | BW23: 0 | BX23: 0 | BY23: 1.102311 | BZ23: 63.832468 | CA23: 26.804761 | CB23: 0 | CC23: 0 | CD23: 37.027707 | CE23: 46.409374 | CF23: 39.708183 | CG23: 2.6804761 | CH23: 0 | CI23: 0 | CJ23: 37.027707 | CK23: 63.832468 | CL23: 26.804761 | CM23: 0 | CN23: 0 | CO23: 37.027707 | CP23: 46.409374 | CQ23: 39.708183 | CR23: 2.6804761 | CS23: 0 | CT23: 0 | CU23: 37.027707 | CV23: =IF(BS23<0,1.1,BS23) -> 134.92982
A24: 819 | B24: CarbonMonoxide_2 | C24: CO | D24: 1 | E24: 0 | F24: 1 | G24: 28.0097 | H24: 2 | I24: Categories-Category_2 | J24: 1.333 | K24: 500 | L24: 33.333333 | N24: Hydrogen | O24: 66.666667 | P24: 0.16666667 | Q24: 0.0325 | R24: 77.5 | S24: 170 | T24: 100 | U24: 1812.1302 | V24: 20 | W24: 0.95 | X24: 1 | Y24: 45929.432 | Z24: 2.2964716e+08 | AA24: 3.0611966e+08 | AB24: 306119.66 | AC24: 0 | AD24: 2380.1251 | AE24: 4284225.1 | AF24: 1428075 | AG24: 39.999953 | AH24: 62.849582 | AI24: 62.849582 | AJ24: 9948.8891 | AK24: 854.70085 | AL24: Nanofiltration | AM24: 4870.8426 | AN24: 512.56226 | AO24: 10684.429 | AP24: 16186.995 | AQ24: 5502.5658 | AR24: 0.0069666431 | AS24: 217.36999 | AT24: 106.42143 | AU24: 11.198804 | AV24: 233.44056 | AW24: 353.66431 | AX24: 120.22374 | AY24: 1.5712414 | AZ24: Isopropanol | BA24: =VLOOKUP($AZ24,Sheet1!$A$2:$B$58,2,FALSE) -> Isopropanol | BB24: C3H8O | BC24: 3 | BD24: 23.925551 | BE24: 30.447 | BF24: 60.09382 | BG24: =VLOOKUP($AZ24,Sheet1!$A$2:$C$58,3,FALSE) -> 6.04 | BH24: 82.5 | BI24: CO_1:H2_2 | BJ24: 0 | BK24: 0.33333333 | BL24: 0.62500073 | BM24: 100 | BN24: 0 | BO24: 565.86223 | BP24: 192.35777 | BQ24: 2.5139833 | BR24: 427.37716 | BS24: 138.48507 | BT24: 1 | BU24: 0 | BV24: 38.280836 | BW24: 0.7953588 | BX24: 0 | BY24: 1.102311 | BZ24: 65.992751 | CA24: 27.711914 | CB24: 0 | CC24: 0 | CD24: 38.280836 | CE24: 47.980006 | CF24: 41.052028 | CG24: 2.7711914 | CH24: 0 | CI24: 0 | CJ24: 38.280836 | CK24: 65.992751 | CL24: 27.711914 | CM24: 0 | CN24: 0 | CO24: 38.280836 | CP24: 47.980006 | CQ24: 41.052028 | CR24: 2.7711914 | CS24: 0 | CT24: 0 | CU24: 38.280836 | CV24: =IF(BS24<0,1.1,BS24) -> 138.48507
A25: 833 | B25: CarbonMonoxide_2 | C25: CO | D25: 1 | E25: 0 | F25: 1 | G25: 28.0097 | H25: 2 | I25: Categories-Category_2 | J25: 1.333 | K25: 500 | L25: 33.333333 | N25: Hydrogen | O25: 66.666667 | P25: 0.16666667 | Q25: 0.0325 | R25: 77.5 | S25: 170 | T25: 100 | U25: 1812.1302 | V25: 20 | W25: 0.95 | X25: 1 | Y25: 46525.061 | Z25: 2.3262531e+08 | AA25: 3.1008953e+08 | AB25: 310089.53 | AC25: 0 | AD25: 2410.9914 | AE25: 4339784.5 | AF25: 1446594.8 | AG25: 40.518687 | AH25: 63.664639 | AI25: 63.664639 | AJ25: 10077.91 | AK25: 854.70085 | AL25: Nanofiltration | AM25: 4934.0095 | AN25: 519.20935 | AO25: 10822.989 | AP25: 16385.83 | AQ25: 5562.841 | AR25: 0.0069666431 | AS25: 217.36999 | AT25: 106.42143 | AU25: 11.198804 | AV25: 233.44056 | AW25: 353.42523 | AX25: 119.98467 | AY25: 1.5712414 | AZ25: Acetone | BA25: =VLOOKUP($AZ25,Sheet1!$A$2:$B$58,2,FALSE) -> Acetone | BB25: C3H6O | BC25: 3 | BD25: 23.925551 | BE25: 0 | BF25: 58.07814 | BG25: =VLOOKUP($AZ25,Sheet1!$A$2:$C$58,3,FALSE) -> 5.3333333 | BH25: 56 | BI25: CO_1:H2_2 | BJ25: 0 | BK25: 0.33333333 | BL25: 0.61699926 | BM25: 100 | BN25: 0 | BO25: 572.81306 | BP25: 194.46486 | BQ25: 2.5465856 | BR25: 432.91954 | BS25: 139.89352 | BT25: 1 | BU25: 0 | BV25: 38.777276 | BW25: 0 | BX25: 0 | BY25: 1.102311 | BZ25: 66.848569 | CA25: 28.071293 | CB25: 0 | CC25: 0 | CD25: 38.777276 | CE25: 48.602229 | CF25: 41.584405 | CG25: 2.8071293 | CH25: 0 | CI25: 0 | CJ25: 38.777276 | CK25: 66.848569 | CL25: 28.071293 | CM25: 0 | CN25: 0 | CO25: 38.777276 | CP25: 48.602229 | CQ25: 41.584405 | CR25: 2.8071293 | CS25: 0 | CT25: 0 | CU25: 38.777276 | CV25: =IF(BS25<0,1.1,BS25) -> 139.89352
A26: 834 | B26: CarbonMonoxide_2 | C26: CO | D26: 1 | E26: 0 | F26: 1 | G26: 28.0097 | H26: 2 | I26: Categories-Category_2 | J26: 1.333 | K26: 500 | L26: 33.333333 | N26: Hydrogen | O26: 66.666667 | P26: 0.16666667 | Q26: 0.0325 | R26: 77.5 | S26: 170 | T26: 100 | U26: 1812.1302 | V26: 20 | W26: 0.95 | X26: 1 | Y26: 47679.365 | Z26: 2.3839683e+08 | AA26: 3.1778297e+08 | AB26: 317782.97 | AC26: 0 | AD26: 2470.809 | AE26: 4447456.1 | AF26: 1482485.4 | AG26: 41.523971 | AH26: 65.244182 | AI26: 65.244182 | AJ26: 10327.946 | AK26: 854.70085 | AL26: Nanofiltration | AM26: 5056.4241 | AN26: 532.09112 | AO26: 11091.511 | AP26: 16771.163 | AQ26: 5679.6517 | AR26: 0.0069666431 | AS26: 217.36999 | AT26: 106.42143 | AU26: 11.198804 | AV26: 233.44056 | AW26: 352.97893 | AX26: 119.53837 | AY26: 1.5712414 | AZ26: Malonate | BA26: =VLOOKUP($AZ26,Sheet1!$A$2:$B$58,2,FALSE) -> Malonate | BB26: C3H2O4 | BC26: 3 | BD26: 23.925551 | BE26: 0 | BF26: 102.04378 | BG26: =VLOOKUP($AZ26,Sheet1!$A$2:$C$58,3,FALSE) -> 2 | BH26: 199 | BI26: CO_1:H2_2 | BJ26: 0 | BK26: 0.17846154 | BL26: 0.60206188 | BM26: 100 | BN26: 0 | BO26: 586.28347 | BP26: 198.5483 | BQ26: 2.6097673 | BR26: 443.66043 | BS26: 142.62303 | BT26: 0.53538462 | BU26: 0 | BV26: 39.739354 | BW26: 0 | BX26: 0 | BY26: 1.102311 | BZ26: 68.507106 | CA26: 28.767751 | CB26: 0 | CC26: 0 | CD26: 39.739354 | CE26: 49.808067 | CF26: 42.61613 | CG26: 2.8767751 | CH26: 0 | CI26: 0 | CJ26: 39.739354 | CK26: 68.507106 | CL26: 28.767751 | CM26: 0 | CN26: 0 | CO26: 39.739354 | CP26: 49.808067 | CQ26: 42.61613 | CR26: 2.8767751 | CS26: 0 | CT26: 0 | CU26: 39.739354 | CV26: =IF(BS26<0,1.1,BS26) -> 142.62303
A27: 1141 | B27: FormicAcid_2 | C27: CHOOH | D27: 1 | E27: 1 | F27: 2 | G27: 45.01654 | H27: 2 | I27: Categories-Category_2 | J27: 1.4 | K27: 500 | L27: 33.333333 | N27: Hydrogen | O27: 66.666667 | P27: 0.16666667 | Q27: 0.0325 | R27: 77.5 | S27: 170 | T27: 100 | U27: 1812.1302 | V27: 20 | W27: 0.95 | X27: 1 | Y27: 41532.353 | Z27: 2.0766177e+08 | AA27: 2.9072647e+08 | AB27: 290726.47 | AC27: 0 | AD27: 2152.2625 | AE27: 3874072.5 | AF27: 1291357.5 | AG27: 58.132447 | AH27: 56.832644 | AI27: 56.832644 | AJ27: 9448.6104 | AK27: 854.70085 | AL27: Nanofiltration | AM27: 4404.5299 | AN27: 463.49184 | AO27: 9661.5495 | AP27: 15171.333 | AQ27: 5509.7835 | AR27: 0.0073168044 | AS27: 149.15044 | AT27: 69.527427 | AU27: 7.3164209 | AV27: 152.51178 | AW27: 239.48611 | AX27: 86.974336 | AY27: 0.97764066 | AZ27: Isobutanol | BA27: =VLOOKUP($AZ27,Sheet1!$A$2:$B$58,2,FALSE) -> Isobutanol | BB27: C4H10O | BC27: 4 | BD27: 15.03836 | BE27: 32.959 | BF27: 74.1202 | BG27: =VLOOKUP($AZ27,Sheet1!$A$2:$C$58,3,FALSE) -> 5.602 | BH27: 108 | BI27: FOR_1:H2_2 | BJ27: 0 | BK27: 0.25 | BL27: 0.43005243 | BM27: 100 | BN27: 0 | BO27: 556.87655 | BP27: 202.24124 | BQ27: 2.2733058 | BR27: 386.46198 | BS27: 170.41457 | BT27: 1 | BU27: 0 | BV27: 34.968668 | BW27: 0.94252947 | BX27: 0 | BY27: 1.102311 | BZ27: 60.027567 | CA27: 25.058899 | CB27: 0 | CC27: 0 | CD27: 34.968668 | CE27: 43.739283 | CF27: 37.474558 | CG27: 2.5058899 | CH27: 0 | CI27: 0 | CJ27: 34.968668 | CK27: 60.027567 | CL27: 25.058899 | CM27: 0 | CN27: 0 | CO27: 34.968668 | CP27: 43.739283 | CQ27: 37.474558 | CR27: 2.5058899 | CS27: 0 | CT27: 0 | CU27: 34.968668 | CV27: =IF(BS27<0,1.1,BS27) -> 170.41457
A28: 835 | B28: CarbonMonoxide_2 | C28: CO | D28: 1 | E28: 0 | F28: 1 | G28: 28.0097 | H28: 2 | I28: Categories-Category_2 | J28: 1.333 | K28: 500 | L28: 33.333333 | N28: Hydrogen | O28: 66.666667 | P28: 0.16666667 | Q28: 0.0325 | R28: 77.5 | S28: 170 | T28: 100 | U28: 1812.1302 | V28: 20 | W28: 0.95 | X28: 1 | Y28: 47827.416 | Z28: 2.3913708e+08 | AA28: 3.1876973e+08 | AB28: 318769.73 | AC28: 0 | AD28: 2478.4812 | AE28: 4461266.1 | AF28: 1487088.7 | AG28: 41.652909 | AH28: 65.446774 | AI28: 65.446774 | AJ28: 10360.016 | AK28: 854.70085 | AL28: Nanofiltration | AM28: 5072.125 | AN28: 533.74334 | AO28: 11125.952 | AP28: 16820.585 | AQ28: 5694.6338 | AR28: 0.0069666431 | AS28: 217.36999 | AT28: 106.42143 | AU28: 11.198804 | AV28: 233.44056 | AW28: 352.92324 | AX28: 119.48268 | AY28: 1.5712414 | AZ28: Glutamate_L | BA28: =VLOOKUP($AZ28,Sheet1!$A$2:$B$58,2,FALSE) -> L-Glutamate | BB28: C5H8NO4 | BC28: 5 | BD28: 23.925551 | BE28: 0 | BF28: 146.11892 | BG28: =VLOOKUP($AZ28,Sheet1!$A$2:$C$58,3,FALSE) -> 3.4 | BH28: 333.8 | BI28: CO_1:H2_2 | BJ28: 0 | BK28: 0.12540541 | BL28: 0.60019818 | BM28: 100 | BN28: 0 | BO28: 588.01118 | BP28: 199.07205 | BQ28: 2.617871 | BR28: 445.03806 | BS28: 142.97312 | BT28: 0.62702703 | BU28: 0 | BV28: 39.862751 | BW28: 0 | BX28: 0 | BY28: 1.102311 | BZ28: 68.71983 | CA28: 28.857079 | CB28: 0 | CC28: 0 | CD28: 39.862751 | CE28: 49.962729 | CF28: 42.748459 | CG28: 2.8857079 | CH28: 0 | CI28: 0 | CJ28: 39.862751 | CK28: 68.71983 | CL28: 28.857079 | CM28: 0 | CN28: 0 | CO28: 39.862751 | CP28: 49.962729 | CQ28: 42.748459 | CR28: 2.8857079 | CS28: 0 | CT28: 0 | CU28: 39.862751 | CV28: =IF(BS28<0,1.1,BS28) -> 142.97312
A29: 820 | B29: CarbonMonoxide_2 | C29: CO | D29: 1 | E29: 0 | F29: 1 | G29: 28.0097 | H29: 2 | I29: Categories-Category_2 | J29: 1.333 | K29: 500 | L29: 33.333333 | N29: Hydrogen | O29: 66.666667 | P29: 0.16666667 | Q29: 0.0325 | R29: 77.5 | S29: 170 | T29: 100 | U29: 1812.1302 | V29: 20 | W29: 0.95 | X29: 1 | Y29: 49492.922 | Z29: 2.4746461e+08 | AA29: 3.2987033e+08 | AB29: 329870.33 | AC29: 0 | AD29: 2564.7899 | AE29: 4616621.9 | AF29: 1538874 | AG29: 43.103398 | AH29: 67.725843 | AI29: 67.725843 | AJ29: 10720.786 | AK29: 854.70085 | AL29: Nanofiltration | AM29: 5248.7528 | AN29: 552.33002 | AO29: 11513.393 | AP29: 17376.569 | AQ29: 5863.176 | AR29: 0.0069666431 | AS29: 217.36999 | AT29: 106.42143 | AU29: 11.198804 | AV29: 233.44056 | AW29: 352.31977 | AX29: 118.87921 | AY29: 1.5712414 | AZ29: 1-Propanol-PW2 | BA29: =VLOOKUP($AZ29,Sheet1!$A$2:$B$58,2,FALSE) -> 1-Propanol (PW2) | BB29: C3H8O | BC29: 3 | BD29: 23.925551 | BE29: 30.68 | BF29: 60.09382 | BG29: =VLOOKUP($AZ29,Sheet1!$A$2:$C$58,3,FALSE) -> 6.01 | BH29: 97 | BI29: CO_1:H2_2 | BJ29: 0 | BK29: 0.30933333 | BL29: 0.58000068 | BM29: 100 | BN29: 0 | BO29: 607.44718 | BP29: 204.96392 | BQ29: 2.7090337 | BR29: 460.53573 | BS29: 146.91144 | BT29: 0.928 | BU29: 0 | BV29: 41.250901 | BW29: 0.74374133 | BX29: 0 | BY29: 1.102311 | BZ29: 71.112878 | CA29: 29.861977 | CB29: 0 | CC29: 0 | CD29: 41.250901 | CE29: 51.702593 | CF29: 44.237099 | CG29: 2.9861977 | CH29: 0 | CI29: 0 | CJ29: 41.250901 | CK29: 71.112878 | CL29: 29.861977 | CM29: 0 | CN29: 0 | CO29: 41.250901 | CP29: 51.702593 | CQ29: 44.237099 | CR29: 2.9861977 | CS29: 0 | CT29: 0 | CU29: 41.250901 | CV29: =IF(BS29<0,1.1,BS29) -> 146.91144
A30: 822 | B30: CarbonMonoxide_2 | C30: CO | D30: 1 | E30: 0 | F30: 1 | G30: 28.0097 | H30: 2 | I30: Categories-Category_2 | J30: 1.333 | K30: 500 | L30: 33.333333 | N30: Hydrogen | O30: 66.666667 | P30: 0.16666667 | Q30: 0.0325 | R30: 77.5 | S30: 170 | T30: 100 | U30: 1812.1302 | V30: 20 | W30: 0.95 | X30: 1 | Y30: 49650.433 | Z30: 2.4825216e+08 | AA30: 3.3092013e+08 | AB30: 330920.13 | AC30: 0 | AD30: 2572.9524 | AE30: 4631314.2 | AF30: 1543771.4 | AG30: 43.240574 | AH30: 67.94138 | AI30: 67.94138 | AJ30: 10754.904 | AK30: 854.70085 | AL30: Nanofiltration | AM30: 5265.4569 | AN30: 554.0878 | AO30: 11550.035 | AP30: 17429.15 | AQ30: 5879.1154 | AR30: 0.0069666431 | AS30: 217.36999 | AT30: 106.42143 | AU30: 11.198804 | AV30: 233.44056 | AW30: 352.2648 | AX30: 118.82423 | AY30: 1.5712414 | AZ30: Butanol-PW2 | BA30: =VLOOKUP($AZ30,Sheet1!$A$2:$B$58,2,FALSE) -> Butanol (PW2) | BB30: C4H10O | BC30: 4 | BD30: 23.925551 | BE30: 33.075 | BF30: 74.1202 | BG30: =VLOOKUP($AZ30,Sheet1!$A$2:$C$58,3,FALSE) -> 6.03 | BH30: 117.7 | BI30: CO_1:H2_2 | BJ30: 0 | BK30: 0.25 | BL30: 0.57816069 | BM30: 100 | BN30: 0 | BO30: 609.28528 | BP30: 205.52112 | BQ30: 2.7176552 | BR30: 462.00138 | BS30: 147.2839 | BT30: 1 | BU30: 0 | BV30: 41.382182 | BW30: 0.79925704 | BX30: 0 | BY30: 1.102311 | BZ30: 71.339194 | CA30: 29.957012 | CB30: 0 | CC30: 0 | CD30: 41.382182 | CE30: 51.867136 | CF30: 44.377883 | CG30: 2.9957012 | CH30: 0 | CI30: 0 | CJ30: 41.382182 | CK30: 71.339194 | CL30: 29.957012 | CM30: 0 | CN30: 0 | CO30: 41.382182 | CP30: 51.867136 | CQ30: 44.377883 | CR30: 2.9957012 | CS30: 0 | CT30: 0 | CU30: 41.382182 | CV30: =IF(BS30<0,1.1,BS30) -> 147.2839
A31: 821 | B31: CarbonMonoxide_2 | C31: CO | D31: 1 | E31: 0 | F31: 1 | G31: 28.0097 | H31: 2 | I31: Categories-Category_2 | J31: 1.333 | K31: 500 | L31: 33.333333 | N31: Hydrogen | O31: 66.666667 | P31: 0.16666667 | Q31: 0.0325 | R31: 77.5 | S31: 170 | T31: 100 | U31: 1812.1302 | V31: 20 | W31: 0.95 | X31: 1 | Y31: 49650.433 | Z31: 2.4825216e+08 | AA31: 3.3092013e+08 | AB31: 330920.13 | AC31: 0 | AD31: 2572.9524 | AE31: 4631314.2 | AF31: 1543771.4 | AG31: 43.240574 | AH31: 67.94138 | AI31: 67.94138 | AJ31: 10754.904 | AK31: 854.70085 | AL31: Nanofiltration | AM31: 5265.4569 | AN31: 554.0878 | AO31: 11550.035 | AP31: 17429.15 | AQ31: 5879.1154 | AR31: 0.0069666431 | AS31: 217.36999 | AT31: 106.42143 | AU31: 11.198804 | AV31: 233.44056 | AW31: 352.2648 | AX31: 118.82423 | AY31: 1.5712414 | AZ31: Butanol-PW1 | BA31: =VLOOKUP($AZ31,Sheet1!$A$2:$B$58,2,FALSE) -> Butanol (PW1) | BB31: C4H10O | BC31: 4 | BD31: 23.925551 | BE31: 33.075 | BF31: 74.1202 | BG31: =VLOOKUP($AZ31,Sheet1!$A$2:$C$58,3,FALSE) -> 6.03 | BH31: 117.7 | BI31: CO_1:H2_2 | BJ31: -1.4083968e-15 | BK31: 0.25 | BL31: 0.57816069 | BM31: 100 | BN31: 0 | BO31: 609.28528 | BP31: 205.52112 | BQ31: 2.7176552 | BR31: 462.00138 | BS31: 147.2839 | BT31: 1 | BU31: 3.5209919e-14 | BV31: 41.382182 | BW31: 0.79925704 | BX31: 0 | BY31: 1.102311 | BZ31: 71.339194 | CA31: 29.957012 | CB31: 1.4083968e-14 | CC31: 0 | CD31: 41.382182 | CE31: 51.867136 | CF31: 44.377883 | CG31: 2.9957012 | CH31: 1.4083968e-15 | CI31: 0 | CJ31: 41.382182 | CK31: 71.339194 | CL31: 29.957012 | CM31: 1.4083968e-14 | CN31: 0 | CO31: 41.382182 | CP31: 51.867136 | CQ31: 44.377883 | CR31: 2.9957012 | CS31: 1.4083968e-15 | CT31: 0 | CU31: 41.382182 | CV31: =IF(BS31<0,1.1,BS31) -> 147.2839
A32: 837 | B32: CarbonMonoxide_2 | C32: CO | D32: 1 | E32: 0 | F32: 1 | G32: 28.0097 | H32: 2 | I32: Categories-Category_2 | J32: 1.333 | K32: 500 | L32: 33.333333 | N32: Hydrogen | O32: 66.666667 | P32: 0.16666667 | Q32: 0.0325 | R32: 77.5 | S32: 170 | T32: 100 | U32: 1812.1302 | V32: 20 | W32: 0.95 | X32: 1 | Y32: 51466.924 | Z32: 2.5733462e+08 | AA32: 3.4302705e+08 | AB32: 343027.05 | AC32: 0 | AD32: 2667.0854 | AE32: 4800753.7 | AF32: 1600251.2 | AG32: 44.822557 | AH32: 70.427057 | AI32: 70.427057 | AJ32: 11148.379 | AK32: 854.70085 | AL32: Nanofiltration | AM32: 5458.0969 | AN32: 574.35944 | AO32: 11972.6 | AP32: 18035.536 | AQ32: 6062.9367 | AR32: 0.0069666431 | AS32: 217.36999 | AT32: 106.42143 | AU32: 11.198804 | AV32: 233.44056 | AW32: 351.6551 | AX32: 118.21454 | AY32: 1.5712414 | AZ32: Itaconate | BA32: =VLOOKUP($AZ32,Sheet1!$A$2:$B$58,2,FALSE) -> Itaconate | BB32: C5H4O4 | BC32: 5 | BD32: 23.925551 | BE32: 0 | BF32: 128.08086 | BG32: =VLOOKUP($AZ32,Sheet1!$A$2:$C$58,3,FALSE) -> 3.2 | BH32: 381 | BI32: CO_1:H2_2 | BJ32: 0 | BK32: 0.13257143 | BL32: 0.55775488 | BM32: 100 | BN32: 0 | BO32: 630.48323 | BP32: 211.94712 | BQ32: 2.8170823 | BR32: 478.90399 | BS32: 151.57925 | BT32: 0.66285714 | BU32: 0 | BV32: 42.896174 | BW32: 0 | BX32: 0 | BY32: 1.102311 | BZ32: 73.949182 | CA32: 31.053008 | CB32: 0 | CC32: 0 | CD32: 42.896174 | CE32: 53.764727 | CF32: 46.001475 | CG32: 3.1053008 | CH32: 0 | CI32: 0 | CJ32: 42.896174 | CK32: 73.949182 | CL32: 31.053008 | CM32: 0 | CN32: 0 | CO32: 42.896174 | CP32: 53.764727 | CQ32: 46.001475 | CR32: 3.1053008 | CS32: 0 | CT32: 0 | CU32: 42.896174 | CV32: =IF(BS32<0,1.1,BS32) -> 151.57925
A33: 838 | B33: CarbonMonoxide_2 | C33: CO | D33: 1 | E33: 0 | F33: 1 | G33: 28.0097 | H33: 2 | I33: Categories-Category_2 | J33: 1.333 | K33: 500 | L33: 33.333333 | N33: Hydrogen | O33: 66.666667 | P33: 0.16666667 | Q33: 0.0325 | R33: 77.5 | S33: 170 | T33: 100 | U33: 1812.1302 | V33: 20 | W33: 0.95 | X33: 1 | Y33: 53363.461 | Z33: 2.6681731e+08 | AA33: 3.5566747e+08 | AB33: 355667.47 | AC33: 0 | AD33: 2765.3665 | AE33: 4977659.7 | AF33: 1659219.9 | AG33: 46.474251 | AH33: 73.022267 | AI33: 73.022267 | AJ33: 11559.193 | AK33: 854.70085 | AL33: Nanofiltration | AM33: 5659.2257 | AN33: 595.52437 | AO33: 12413.785 | AP33: 18668.644 | AQ33: 6254.8582 | AR33: 0.0069666431 | AS33: 217.36999 | AT33: 106.42143 | AU33: 11.198804 | AV33: 233.44056 | AW33: 351.06283 | AX33: 117.62227 | AY33: 1.5712414 | AZ33: Acrylate-PW2 | BA33: =VLOOKUP($AZ33,Sheet1!$A$2:$B$58,2,FALSE) -> Acrylate (PW2) | BB33: C3H3O2 | BC33: 3 | BD33: 23.925551 | BE33: 0 | BF33: 71.05362 | BG33: =VLOOKUP($AZ33,Sheet1!$A$2:$C$58,3,FALSE) -> 3.6666667 | BH33: 80 | BI33: CO_1:H2_2 | BJ33: 0 | BK33: 0.232 | BL33: 0.53793228 | BM33: 100 | BN33: 0 | BO33: 652.61529 | BP33: 218.65628 | BQ33: 2.9208907 | BR33: 496.55142 | BS33: 156.06387 | BT33: 0.696 | BU33: 0 | BV33: 44.476882 | BW33: 0 | BX33: 0 | BY33: 1.102311 | BZ33: 76.674181 | CA33: 32.197299 | CB33: 0 | CC33: 0 | CD33: 44.476882 | CE33: 55.745937 | CF33: 47.696612 | CG33: 3.2197299 | CH33: 0 | CI33: 0 | CJ33: 44.476882 | CK33: 76.674181 | CL33: 32.197299 | CM33: 0 | CN33: 0 | CO33: 44.476882 | CP33: 55.745937 | CQ33: 47.696612 | CR33: 3.2197299 | CS33: 0 | CT33: 0 | CU33: 44.476882 | CV33: =IF(BS33<0,1.1,BS33) -> 156.06387
A34: 839 | B34: CarbonMonoxide_2 | C34: CO | D34: 1 | E34: 0 | F34: 1 | G34: 28.0097 | H34: 2 | I34: Categories-Category_2 | J34: 1.333 | K34: 500 | L34: 33.333333 | N34: Hydrogen | O34: 66.666667 | P34: 0.16666667 | Q34: 0.0325 | R34: 77.5 | S34: 170 | T34: 100 | U34: 1812.1302 | V34: 20 | W34: 0.95 | X34: 1 | Y34: 55001.648 | Z34: 2.7500824e+08 | AA34: 3.6658599e+08 | AB34: 366585.99 | AC34: 0 | AD34: 2850.2596 | AE34: 5130467.2 | AF34: 1710155.7 | AG34: 47.900949 | AH34: 75.263954 | AI34: 75.263954 | AJ34: 11914.045 | AK34: 854.70085 | AL34: Nanofiltration | AM34: 5832.9564 | AN34: 613.80618 | AO34: 12794.872 | AP34: 19215.508 | AQ34: 6420.6359 | AR34: 0.0069666431 | AS34: 217.36999 | AT34: 106.42143 | AU34: 11.198804 | AV34: 233.44056 | AW34: 350.58412 | AX34: 117.14356 | AY34: 1.5712414 | AZ34: Lysine_L | BA34: =VLOOKUP($AZ34,Sheet1!$A$2:$B$58,2,FALSE) -> L-Lysine | BB34: C6H15N2O2 | BC34: 6 | BD34: 23.925551 | BE34: 0 | BF34: 147.1932 | BG34: =VLOOKUP($AZ34,Sheet1!$A$2:$C$58,3,FALSE) -> 4.8333333 | BI34: CO_1:H2_2 | BJ34: 0 | BK34: 0.11047619 | BL34: 0.52191033 | BM34: 100 | BN34: 0 | BO34: 671.73248 | BP34: 224.4515 | BQ34: 3.0105581 | BR34: 511.79489 | BS34: 159.9376 | BT34: 0.66285714 | BU34: 0 | BV34: 45.842263 | BW34: 0 | BX34: 0 | BY34: 1.102311 | BZ34: 79.027977 | CA34: 33.185713 | CB34: 0 | CC34: 0 | CD34: 45.842263 | CE34: 57.457263 | CF34: 49.160834 | CG34: 3.3185713 | CH34: 0 | CI34: 0 | CJ34: 45.842263 | CK34: 79.027977 | CL34: 33.185713 | CM34: 0 | CN34: 0 | CO34: 45.842263 | CP34: 57.457263 | CQ34: 49.160834 | CR34: 3.3185713 | CS34: 0 | CT34: 0 | CU34: 45.842263 | CV34: =IF(BS34<0,1.1,BS34) -> 159.9376
A35: 836 | B35: CarbonMonoxide_2 | C35: CO | D35: 1 | E35: 0 | F35: 1 | G35: 28.0097 | H35: 2 | I35: Categories-Category_2 | J35: 1.333 | K35: 500 | L35: 33.333333 | N35: Hydrogen | O35: 66.666667 | P35: 0.16666667 | Q35: 0.0325 | R35: 77.5 | S35: 170 | T35: 100 | U35: 1812.1302 | V35: 20 | W35: 0.95 | X35: 1 | Y35: 56236.229 | Z35: 2.8118115e+08 | AA35: 3.7481447e+08 | AB35: 374814.47 | AC35: 0 | AD35: 2914.2372 | AE35: 5245626.9 | AF35: 1748542.3 | AG35: 48.976146 | AH35: 76.953347 | AI35: 76.953347 | AJ35: 12181.47 | AK35: 854.70085 | AL35: Nanofiltration | AM35: 5963.8844 | AN35: 627.58383 | AO35: 13082.069 | AP35: 19627.639 | AQ35: 6545.5702 | AR35: 0.0069666431 | AS35: 217.36999 | AT35: 106.42143 | AU35: 11.198804 | AV35: 233.44056 | AW35: 350.24178 | AX35: 116.80122 | AY35: 1.5712414 | AZ35: 2-Methyl-1-Butanol | BA35: =VLOOKUP($AZ35,Sheet1!$A$2:$B$58,2,FALSE) -> 2-Methyl-1-Butanol | BB35: C5H12O | BC35: 5 | BD35: 23.925551 | BE35: 34.96 | BF35: 88.14658 | BG35: =VLOOKUP($AZ35,Sheet1!$A$2:$C$58,3,FALSE) -> 6.02 | BH35: 129 | BI35: CO_1:H2_2 | BJ35: 0 | BK35: 0.1856 | BL35: 0.51045258 | BM35: 100 | BN35: 0 | BO35: 686.1397 | BP35: 228.81894 | BQ35: 3.0781339 | BR35: 523.28276 | BS35: 162.85694 | BT35: 0.928 | BU35: 0 | BV35: 46.87125 | BW35: 0.745873 | BX35: 0 | BY35: 1.102311 | BZ35: 80.801858 | CA35: 33.930608 | CB35: 0 | CC35: 0 | CD35: 46.87125 | CE35: 58.746963 | CF35: 50.264311 | CG35: 3.3930608 | CH35: 0 | CI35: 0 | CJ35: 46.87125 | CK35: 80.801858 | CL35: 33.930608 | CM35: 0 | CN35: 0 | CO35: 46.87125 | CP35: 58.746963 | CQ35: 50.264311 | CR35: 3.3930608 | CS35: 0 | CT35: 0 | CU35: 46.87125 | CV35: =IF(BS35<0,1.1,BS35) -> 162.85694
A36: 840 | B36: CarbonMonoxide_2 | C36: CO | D36: 1 | E36: 0 | F36: 1 | G36: 28.0097 | H36: 2 | I36: Categories-Category_2 | J36: 1.333 | K36: 500 | L36: 33.333333 | N36: Hydrogen | O36: 66.666667 | P36: 0.16666667 | Q36: 0.0325 | R36: 77.5 | S36: 170 | T36: 100 | U36: 1812.1302 | V36: 20 | W36: 0.95 | X36: 1 | Y36: 66947.132 | Z36: 3.3473566e+08 | AA36: 4.4620264e+08 | AB36: 446202.64 | AC36: 0 | AD36: 3469.2906 | AE36: 6244723.1 | AF36: 2081574.4 | AG36: 58.304274 | AH36: 91.610089 | AI36: 91.610089 | AJ36: 14501.586 | AK36: 854.70085 | AL36: Nanofiltration | AM36: 7099.7819 | AN36: 747.11513 | AO36: 15573.715 | AP36: 23203.184 | AQ36: 7629.4685 | AR36: 0.0069666431 | AS36: 217.36999 | AT36: 106.42143 | AU36: 11.198804 | AV36: 233.44056 | AW36: 347.80168 | AX36: 114.36112 | AY36: 1.5712414 | AZ36: 1-3-Diaminopropane | BA36: =VLOOKUP($AZ36,Sheet1!$A$2:$B$58,2,FALSE) -> 1,3-Diaminopropane | BB36: C3H12N2 | BC36: 3 | BD36: 23.925551 | BE36: 35.1 | BF36: 76.13958 | BG36: =VLOOKUP($AZ36,Sheet1!$A$2:$C$58,3,FALSE) -> 6.05 | BH36: 139.3 | BI36: CO_1:H2_2 | BJ36: 0 | BK36: 0.17846154 | BL36: 0.42878503 | BM36: 100 | BN36: 0 | BO36: 811.13297 | BP36: 266.70967 | BQ36: 3.6644035 | BR36: 622.9486 | BS36: 188.18437 | BT36: 0.53538462 | BU36: 0 | BV36: 55.798474 | BW36: 0.62904946 | BX36: 0 | BY36: 1.102311 | BZ36: 96.191597 | CA36: 40.393123 | CB36: 0 | CC36: 0 | CD36: 55.798474 | CE36: 69.936067 | CF36: 59.837786 | CG36: 4.0393123 | CH36: 0 | CI36: 0 | CJ36: 55.798474 | CK36: 96.191597 | CL36: 40.393123 | CM36: 0 | CN36: 0 | CO36: 55.798474 | CP36: 69.936067 | CQ36: 59.837786 | CR36: 4.0393123 | CS36: 0 | CT36: 0 | CU36: 55.798474 | CV36: =IF(BS36<0,1.1,BS36) -> 188.18437
