Workbook
Name _FilterDatabase_0: 'Overall Results'!$A$1:$AH$882
Name _FilterDatabase_0_0: 'Overall Results'!$A$1:$AH$770

Sheet Overall Results
A1: Date | B1: BaseModel | C1: Substrate | D1: Substrate_Type | E1: Product | F1: Objective | G1: S_ExchangeLB | H1: O2_ExchangeLB | I1: H2_ExchangeLB | J1: ATPM_LB | K1: S_Flux | L1: O2_Flux | M1: H2_Flux | N1: CO2_Flux | O1: Obj_Flux | P1: By-Products | Q1: Yield_Molar | R1: Yield_Mass | S1: ProductName | T1: ProductName_Graph | U1: Model_Author | V1: Formula_P | W1: C_P | X1: H_P | Y1: O_P | Z1: N_P | AA1: Charge_P | AB1: Deg_Red_P | AC1: MW_g/mol_P | AD1: BP_degC_P | AE1: MoleculeType_P | AF1: CCM_Feeder_P | AG1: Transport_P | AH1: MetID_P | AI1: isLiq | AJ1: isGas | AK1: Conc | AL1: LH | AM1: Carbons | AN1: LHVMolar | AO1: LHVMass | AP1: DoR_S | AQ1: Cn_S | AR1: CE
A2: 2021-05-11 | B2: iJO1366 | C2: Formate_SerineCycle | D2: ECR-C1a | E2: Propane-PW2 | F2: EX_propane_e | G2: -10 | H2: -20 | I2: NA | J2: 3.15 | K2: -10 | L2: -4.3134415 | M2: NA | N2: 9.5880649 | O2: 0.1373117 | Q2: 0.01373117 | R2: 0.013154003 | S2: =VLOOKUP($E2,'Product Naming'!$A$1:$P$58,2,FALSE) -> Propane-PW2 | T2: =VLOOKUP($E2,'Product Naming'!$A$1:$P$58,3,FALSE) -> Propane (PW2) | U2: =VLOOKUP($E2,'Product Naming'!$A$1:$P$58,4,FALSE) -> E | V2: =VLOOKUP($E2,'Product Naming'!$A$1:$P$58,5,FALSE) -> C3H8 | W2: =VLOOKUP($E2,'Product Naming'!$A$1:$P$58,6,FALSE) -> 3 | X2: =VLOOKUP($E2,'Product Naming'!$A$1:$P$58,7,FALSE) -> 8 | Y2: =VLOOKUP($E2,'Product Naming'!$A$1:$P$58,8,FALSE) -> 0 | Z2: =VLOOKUP($E2,'Product Naming'!$A$1:$P$58,9,FALSE) -> 0 | AA2: =VLOOKUP($E2,'Product Naming'!$A$1:$P$58,10,FALSE) -> 0 | AB2: =VLOOKUP($E2,'Product Naming'!$A$1:$P$58,11,FALSE) -> 6.6666667 | AC2: =VLOOKUP($E2,'Product Naming'!$A$1:$P$58,12,FALSE) -> 44.09482 | AD2: =VLOOKUP($E2,'Product Naming'!$A$1:$P$58,13,FALSE) -> -42 | AE2: =VLOOKUP($E2,'Product Naming'!$A$1:$P$58,14,FALSE) -> Hydrocarbon | AF2: =VLOOKUP($E2,'Product Naming'!$A$1:$P$58,15,FALSE) -> Oxaloacetate | AG2: =VLOOKUP($E2,'Product Naming'!$A$1:$P$58,16,FALSE) -> Diffusion | AH2: =VLOOKUP($E2,'Product Naming'!$A$1:$Q$58,17,FALSE) -> prop_c | AI2: =VLOOKUP($E2,'Product Parameters'!$A$2:$D$59,2,FALSE) -> 0 | AJ2: =VLOOKUP($E2,'Product Parameters'!$A$2:$D$59,3,FALSE) -> 1 | AK2: =VLOOKUP($E2,'Product Parameters'!$A$2:$D$59,4,FALSE) -> 0.12 | AL2: =VLOOKUP($E2,'Product Parameters'!$A$2:$E$59,5,FALSE) -> 0 | AM2: =VLOOKUP($E2,'Product Parameters'!$A$2:$F$59,6,FALSE) -> 3 | AN2: =VLOOKUP($C2,'Substrate Heating'!$A$2:$C$33,3,FALSE) -> 247.59097 | AO2: =VLOOKUP($C2,'Substrate Heating'!$A$2:$B$33,2,FALSE) -> 5.5 | AP2: =VLOOKUP($C2,'Substrate Heating'!$A$2:$M$33,13,FALSE) -> 1 | AQ2: =VLOOKUP($C2,'Substrate Heating'!$A$2:$M$33,8,FALSE) -> 1 | AR2: =Q2*W2/AQ2 -> 0.041193511
A3: 2021-05-11 | B3: iJO1366 | C3: Formate_SerineCycle | D3: ECR-C1a | E3: Propane-PW1 | F3: EX_propane_e | G3: -10 | H3: -20 | I3: NA | J3: 3.15 | K3: -10 | L3: -4.172486 | M3: NA | N3: 9.5034916 | O3: 0.16550279 | Q3: 0.016550279 | R3: 0.015854615 | S3: =VLOOKUP($E3,'Product Naming'!$A$1:$P$58,2,FALSE) -> Propane-PW1 | T3: =VLOOKUP($E3,'Product Naming'!$A$1:$P$58,3,FALSE) -> Propane (PW1) | U3: =VLOOKUP($E3,'Product Naming'!$A$1:$P$58,4,FALSE) -> E | V3: =VLOOKUP($E3,'Product Naming'!$A$1:$P$58,5,FALSE) -> C3H8 | W3: =VLOOKUP($E3,'Product Naming'!$A$1:$P$58,6,FALSE) -> 3 | X3: =VLOOKUP($E3,'Product Naming'!$A$1:$P$58,7,FALSE) -> 8 | Y3: =VLOOKUP($E3,'Product Naming'!$A$1:$P$58,8,FALSE) -> 0 | Z3: =VLOOKUP($E3,'Product Naming'!$A$1:$P$58,9,FALSE) -> 0 | AA3: =VLOOKUP($E3,'Product Naming'!$A$1:$P$58,10,FALSE) -> 0 | AB3: =VLOOKUP($E3,'Product Naming'!$A$1:$P$58,11,FALSE) -> 6.6666667 | AC3: =VLOOKUP($E3,'Product Naming'!$A$1:$P$58,12,FALSE) -> 44.09482 | AD3: =VLOOKUP($E3,'Product Naming'!$A$1:$P$58,13,FALSE) -> -42 | AE3: =VLOOKUP($E3,'Product Naming'!$A$1:$P$58,14,FALSE) -> Hydrocarbon | AF3: =VLOOKUP($E3,'Product Naming'!$A$1:$P$58,15,FALSE) -> Acetyl-CoA | AG3: =VLOOKUP($E3,'Product Naming'!$A$1:$P$58,16,FALSE) -> Diffusion | AH3: =VLOOKUP($E3,'Product Naming'!$A$1:$Q$58,17,FALSE) -> prop_c | AI3: =VLOOKUP($E3,'Product Parameters'!$A$2:$D$59,2,FALSE) -> 0 | AJ3: =VLOOKUP($E3,'Product Parameters'!$A$2:$D$59,3,FALSE) -> 1 | AK3: =VLOOKUP($E3,'Product Parameters'!$A$2:$D$59,4,FALSE) -> 0.12 | AL3: =VLOOKUP($E3,'Product Parameters'!$A$2:$E$59,5,FALSE) -> 0 | AM3: =VLOOKUP($E3,'Product Parameters'!$A$2:$F$59,6,FALSE) -> 3 | AN3: =VLOOKUP($C3,'Substrate Heating'!$A$2:$C$33,3,FALSE) -> 247.59097 | AO3: =VLOOKUP($C3,'Substrate Heating'!$A$2:$B$33,2,FALSE) -> 5.5 | AP3: =VLOOKUP($C3,'Substrate Heating'!$A$2:$M$33,13,FALSE) -> 1 | AQ3: =VLOOKUP($C3,'Substrate Heating'!$A$2:$M$33,8,FALSE) -> 1 | AR3: =Q3*W3/AQ3 -> 0.049650838
A4: 2021-05-11 | B4: iJO1366 | C4: Formate_SerineCycle | D4: ECR-C1a | E4: Butane | F4: EX_butane_e | G4: -10 | H4: -20 | I4: NA | J4: 3.15 | K4: -10 | L4: -4.1535714 | M4: NA | N4: 9.4791209 | O4: 0.13021978 | Q4: 0.013021978 | R4: 0.016442745 | S4: =VLOOKUP($E4,'Product Naming'!$A$1:$P$58,2,FALSE) -> Butane | T4: =VLOOKUP($E4,'Product Naming'!$A$1:$P$58,3,FALSE) -> Butane | U4: =VLOOKUP($E4,'Product Naming'!$A$1:$P$58,4,FALSE) -> E | V4: =VLOOKUP($E4,'Product Naming'!$A$1:$P$58,5,FALSE) -> C4H10 | W4: =VLOOKUP($E4,'Product Naming'!$A$1:$P$58,6,FALSE) -> 4 | X4: =VLOOKUP($E4,'Product Naming'!$A$1:$P$58,7,FALSE) -> 10 | Y4: =VLOOKUP($E4,'Product Naming'!$A$1:$P$58,8,FALSE) -> 0 | Z4: =VLOOKUP($E4,'Product Naming'!$A$1:$P$58,9,FALSE) -> 0 | AA4: =VLOOKUP($E4,'Product Naming'!$A$1:$P$58,10,FALSE) -> 0 | AB4: =VLOOKUP($E4,'Product Naming'!$A$1:$P$58,11,FALSE) -> 6.5 | AC4: =VLOOKUP($E4,'Product Naming'!$A$1:$P$58,12,FALSE) -> 58.1212 | AD4: =VLOOKUP($E4,'Product Naming'!$A$1:$P$58,13,FALSE) -> -1 | AE4: =VLOOKUP($E4,'Product Naming'!$A$1:$P$58,14,FALSE) -> Hydrocarbon (alkane) | AF4: =VLOOKUP($E4,'Product Naming'!$A$1:$P$58,15,FALSE) -> Acetyl-CoA + Succinyl-CoA | AG4: =VLOOKUP($E4,'Product Naming'!$A$1:$P$58,16,FALSE) -> Diffusion | AH4: =VLOOKUP($E4,'Product Naming'!$A$1:$Q$58,17,FALSE) -> butn_c | AI4: =VLOOKUP($E4,'Product Parameters'!$A$2:$D$59,2,FALSE) -> 0 | AJ4: =VLOOKUP($E4,'Product Parameters'!$A$2:$D$59,3,FALSE) -> 1 | AK4: =VLOOKUP($E4,'Product Parameters'!$A$2:$D$59,4,FALSE) -> 0.12 | AL4: =VLOOKUP($E4,'Product Parameters'!$A$2:$E$59,5,FALSE) -> 0 | AM4: =VLOOKUP($E4,'Product Parameters'!$A$2:$F$59,6,FALSE) -> 4 | AN4: =VLOOKUP($C4,'Substrate Heating'!$A$2:$C$33,3,FALSE) -> 247.59097 | AO4: =VLOOKUP($C4,'Substrate Heating'!$A$2:$B$33,2,FALSE) -> 5.5 | AP4: =VLOOKUP($C4,'Substrate Heating'!$A$2:$M$33,13,FALSE) -> 1 | AQ4: =VLOOKUP($C4,'Substrate Heating'!$A$2:$M$33,8,FALSE) -> 1 | AR4: =Q4*W4/AQ4 -> 0.052087912
A5: 2021-05-11 | B5: iJO1366 | C5: Formate_SerineCycle | D5: ECR-C1a | E5: Pentane | F5: EX_pentane_e | G5: -10 | H5: -20 | I5: NA | J5: 3.15 | K5: -10 | L5: -4.1512981 | M5: NA | N5: 9.4695613 | O5: 0.10608774 | Q5: 0.010608774 | R5: 0.016628372 | S5: =VLOOKUP($E5,'Product Naming'!$A$1:$P$58,2,FALSE) -> Pentane | T5: =VLOOKUP($E5,'Product Naming'!$A$1:$P$58,3,FALSE) -> Pentane | U5: =VLOOKUP($E5,'Product Naming'!$A$1:$P$58,4,FALSE) -> E | V5: =VLOOKUP($E5,'Product Naming'!$A$1:$P$58,5,FALSE) -> C5H12 | W5: =VLOOKUP($E5,'Product Naming'!$A$1:$P$58,6,FALSE) -> 5 | X5: =VLOOKUP($E5,'Product Naming'!$A$1:$P$58,7,FALSE) -> 12 | Y5: =VLOOKUP($E5,'Product Naming'!$A$1:$P$58,8,FALSE) -> 0 | Z5: =VLOOKUP($E5,'Product Naming'!$A$1:$P$58,9,FALSE) -> 0 | AA5: =VLOOKUP($E5,'Product Naming'!$A$1:$P$58,10,FALSE) -> 0 | AB5: =VLOOKUP($E5,'Product Naming'!$A$1:$P$58,11,FALSE) -> 6.4 | AC5: =VLOOKUP($E5,'Product Naming'!$A$1:$P$58,12,FALSE) -> 72.14758 | AD5: =VLOOKUP($E5,'Product Naming'!$A$1:$P$58,13,FALSE) -> 36.1 | AE5: =VLOOKUP($E5,'Product Naming'!$A$1:$P$58,14,FALSE) -> Hydrocarbon (alkane) | AF5: =VLOOKUP($E5,'Product Naming'!$A$1:$P$58,15,FALSE) -> Acetyl-CoA | AG5: =VLOOKUP($E5,'Product Naming'!$A$1:$P$58,16,FALSE) -> Diffusion | AH5: =VLOOKUP($E5,'Product Naming'!$A$1:$Q$58,17,FALSE) -> pent_c | AI5: =VLOOKUP($E5,'Product Parameters'!$A$2:$D$59,2,FALSE) -> 0 | AJ5: =VLOOKUP($E5,'Product Parameters'!$A$2:$D$59,3,FALSE) -> 1 | AK5: =VLOOKUP($E5,'Product Parameters'!$A$2:$D$59,4,FALSE) -> 0.12 | AL5: =VLOOKUP($E5,'Product Parameters'!$A$2:$E$59,5,FALSE) -> 26.5 | AM5: =VLOOKUP($E5,'Product Parameters'!$A$2:$F$59,6,FALSE) -> 5 | AN5: =VLOOKUP($C5,'Substrate Heating'!$A$2:$C$33,3,FALSE) -> 247.59097 | AO5: =VLOOKUP($C5,'Substrate Heating'!$A$2:$B$33,2,FALSE) -> 5.5 | AP5: =VLOOKUP($C5,'Substrate Heating'!$A$2:$M$33,13,FALSE) -> 1 | AQ5: =VLOOKUP($C5,'Substrate Heating'!$A$2:$M$33,8,FALSE) -> 1 | AR5: =Q5*W5/AQ5 -> 0.053043868
A6: 2021-05-25 | B6: iJO1366 | C6: Formate_SerineCycle | D6: ECR-C1a | E6: Heptane | F6: EX_heptane_e | G6: -10 | H6: -20 | I6: NA | J6: 3.15 | K6: -10 | L6: -4.1398878 | M6: NA | N6: 9.4526559 | O6: 0.078192016 | Q6: 0.0078192016 | R6: 0.017021366 | S6: =VLOOKUP($E6,'Product Naming'!$A$1:$P$58,2,FALSE) -> Heptane | T6: =VLOOKUP($E6,'Product Naming'!$A$1:$P$58,3,FALSE) -> Heptane | U6: =VLOOKUP($E6,'Product Naming'!$A$1:$P$58,4,FALSE) -> E | V6: =VLOOKUP($E6,'Product Naming'!$A$1:$P$58,5,FALSE) -> C7H16 | W6: =VLOOKUP($E6,'Product Naming'!$A$1:$P$58,6,FALSE) -> 7 | X6: =VLOOKUP($E6,'Product Naming'!$A$1:$P$58,7,FALSE) -> 16 | Y6: =VLOOKUP($E6,'Product Naming'!$A$1:$P$58,8,FALSE) -> 0 | Z6: =VLOOKUP($E6,'Product Naming'!$A$1:$P$58,9,FALSE) -> 0 | AA6: =VLOOKUP($E6,'Product Naming'!$A$1:$P$58,10,FALSE) -> 0 | AB6: =VLOOKUP($E6,'Product Naming'!$A$1:$P$58,11,FALSE) -> 6.2857143 | AC6: =VLOOKUP($E6,'Product Naming'!$A$1:$P$58,12,FALSE) -> 100.20034 | AD6: =VLOOKUP($E6,'Product Naming'!$A$1:$P$58,13,FALSE) -> 98 | AE6: =VLOOKUP($E6,'Product Naming'!$A$1:$P$58,14,FALSE) -> Hydrocarbon (alkane) | AF6: =VLOOKUP($E6,'Product Naming'!$A$1:$P$58,15,FALSE) -> Acetyl-CoA | AG6: =VLOOKUP($E6,'Product Naming'!$A$1:$P$58,16,FALSE) -> Proton symporter | AH6: =VLOOKUP($E6,'Product Naming'!$A$1:$Q$58,17,FALSE) -> hept_c | AI6: =VLOOKUP($E6,'Product Parameters'!$A$2:$D$59,2,FALSE) -> 1 | AJ6: =VLOOKUP($E6,'Product Parameters'!$A$2:$D$59,3,FALSE) -> 0 | AK6: =VLOOKUP($E6,'Product Parameters'!$A$2:$D$59,4,FALSE) -> 0.12 | AL6: =VLOOKUP($E6,'Product Parameters'!$A$2:$E$59,5,FALSE) -> 36 | AM6: =VLOOKUP($E6,'Product Parameters'!$A$2:$F$59,6,FALSE) -> 7 | AN6: =VLOOKUP($C6,'Substrate Heating'!$A$2:$C$33,3,FALSE) -> 247.59097 | AO6: =VLOOKUP($C6,'Substrate Heating'!$A$2:$B$33,2,FALSE) -> 5.5 | AP6: =VLOOKUP($C6,'Substrate Heating'!$A$2:$M$33,13,FALSE) -> 1 | AQ6: =VLOOKUP($C6,'Substrate Heating'!$A$2:$M$33,8,FALSE) -> 1 | AR6: =Q6*W6/AQ6 -> 0.054734411
A7: 2021-05-25 | B7: iJO1366 | C7: Formate_SerineCycle | D7: ECR-C1a | E7: Hexane | F7: EX_hexane_e | G7: -10 | H7: -20 | I7: NA | J7: 3.15 | K7: -10 | L7: -4.1323699 | M7: NA | N7: 9.4520231 | O7: 0.09132948 | Q7: 0.009132948 | R7: 0.017098178 | S7: =VLOOKUP($E7,'Product Naming'!$A$1:$P$58,2,FALSE) -> Hexane | T7: =VLOOKUP($E7,'Product Naming'!$A$1:$P$58,3,FALSE) -> Hexane | U7: =VLOOKUP($E7,'Product Naming'!$A$1:$P$58,4,FALSE) -> E | V7: =VLOOKUP($E7,'Product Naming'!$A$1:$P$58,5,FALSE) -> C6H14 | W7: =VLOOKUP($E7,'Product Naming'!$A$1:$P$58,6,FALSE) -> 6 | X7: =VLOOKUP($E7,'Product Naming'!$A$1:$P$58,7,FALSE) -> 14 | Y7: =VLOOKUP($E7,'Product Naming'!$A$1:$P$58,8,FALSE) -> 0 | Z7: =VLOOKUP($E7,'Product Naming'!$A$1:$P$58,9,FALSE) -> 0 | AA7: =VLOOKUP($E7,'Product Naming'!$A$1:$P$58,10,FALSE) -> 0 | AB7: =VLOOKUP($E7,'Product Naming'!$A$1:$P$58,11,FALSE) -> 6.3333333 | AC7: =VLOOKUP($E7,'Product Naming'!$A$1:$P$58,12,FALSE) -> 86.17396 | AD7: =VLOOKUP($E7,'Product Naming'!$A$1:$P$58,13,FALSE) -> 69 | AE7: =VLOOKUP($E7,'Product Naming'!$A$1:$P$58,14,FALSE) -> Hydrocarbon (alkane) | AF7: =VLOOKUP($E7,'Product Naming'!$A$1:$P$58,15,FALSE) -> Acetyl-CoA + Succinyl-CoA | AG7: =VLOOKUP($E7,'Product Naming'!$A$1:$P$58,16,FALSE) -> Proton symporter | AH7: =VLOOKUP($E7,'Product Naming'!$A$1:$Q$58,17,FALSE) -> hex_c | AI7: =VLOOKUP($E7,'Product Parameters'!$A$2:$D$59,2,FALSE) -> 1 | AJ7: =VLOOKUP($E7,'Product Parameters'!$A$2:$D$59,3,FALSE) -> 0 | AK7: =VLOOKUP($E7,'Product Parameters'!$A$2:$D$59,4,FALSE) -> 0.12 | AL7: =VLOOKUP($E7,'Product Parameters'!$A$2:$E$59,5,FALSE) -> 31 | AM7: =VLOOKUP($E7,'Product Parameters'!$A$2:$F$59,6,FALSE) -> 6 | AN7: =VLOOKUP($C7,'Substrate Heating'!$A$2:$C$33,3,FALSE) -> 247.59097 | AO7: =VLOOKUP($C7,'Substrate Heating'!$A$2:$B$33,2,FALSE) -> 5.5 | AP7: =VLOOKUP($C7,'Substrate Heating'!$A$2:$M$33,13,FALSE) -> 1 | AQ7: =VLOOKUP($C7,'Substrate Heating'!$A$2:$M$33,8,FALSE) -> 1 | AR7: =Q7*W7/AQ7 -> 0.054797688
A8: 2021-05-25 | B8: iJO1366 | C8: Formate_SerineCycle | D8: ECR-C1a | E8: Nonane | F8: EX_nonane_e | G8: -10 | H8: -20 | I8: NA | J8: 3.15 | K8: -10 | L8: -4.1343595 | M8: NA | N8: 9.4435168 | O8: 0.061831464 | Q8: 0.0061831464 | R8: 0.017228212 | S8: =VLOOKUP($E8,'Product Naming'!$A$1:$P$58,2,FALSE) -> Nonane | T8: =VLOOKUP($E8,'Product Naming'!$A$1:$P$58,3,FALSE) -> Nonane | U8: =VLOOKUP($E8,'Product Naming'!$A$1:$P$58,4,FALSE) -> E | V8: =VLOOKUP($E8,'Product Naming'!$A$1:$P$58,5,FALSE) -> C9H20 | W8: =VLOOKUP($E8,'Product Naming'!$A$1:$P$58,6,FALSE) -> 9 | X8: =VLOOKUP($E8,'Product Naming'!$A$1:$P$58,7,FALSE) -> 20 | Y8: =VLOOKUP($E8,'Product Naming'!$A$1:$P$58,8,FALSE) -> 0 | Z8: =VLOOKUP($E8,'Product Naming'!$A$1:$P$58,9,FALSE) -> 0 | AA8: =VLOOKUP($E8,'Product Naming'!$A$1:$P$58,10,FALSE) -> 0 | AB8: =VLOOKUP($E8,'Product Naming'!$A$1:$P$58,11,FALSE) -> 6.2222222 | AC8: =VLOOKUP($E8,'Product Naming'!$A$1:$P$58,12,FALSE) -> 128.2531 | AD8: =VLOOKUP($E8,'Product Naming'!$A$1:$P$58,13,FALSE) -> 151 | AE8: =VLOOKUP($E8,'Product Naming'!$A$1:$P$58,14,FALSE) -> Hydrocarbon (alkane) | AF8: =VLOOKUP($E8,'Product Naming'!$A$1:$P$58,15,FALSE) -> Acetyl-CoA | AG8: =VLOOKUP($E8,'Product Naming'!$A$1:$P$58,16,FALSE) -> Proton symporter | AH8: =VLOOKUP($E8,'Product Naming'!$A$1:$Q$58,17,FALSE) -> nonan_c | AI8: =VLOOKUP($E8,'Product Parameters'!$A$2:$D$59,2,FALSE) -> 1 | AJ8: =VLOOKUP($E8,'Product Parameters'!$A$2:$D$59,3,FALSE) -> 0 | AK8: =VLOOKUP($E8,'Product Parameters'!$A$2:$D$59,4,FALSE) -> 0.12 | AL8: =VLOOKUP($E8,'Product Parameters'!$A$2:$E$59,5,FALSE) -> 46.5 | AM8: =VLOOKUP($E8,'Product Parameters'!$A$2:$F$59,6,FALSE) -> 9 | AN8: =VLOOKUP($C8,'Substrate Heating'!$A$2:$C$33,3,FALSE) -> 247.59097 | AO8: =VLOOKUP($C8,'Substrate Heating'!$A$2:$B$33,2,FALSE) -> 5.5 | AP8: =VLOOKUP($C8,'Substrate Heating'!$A$2:$M$33,13,FALSE) -> 1 | AQ8: =VLOOKUP($C8,'Substrate Heating'!$A$2:$M$33,8,FALSE) -> 1 | AR8: =Q8*W8/AQ8 -> 0.055648317
A9: 2021-05-25 | B9: iJO1366 | C9: Formate_SerineCycle | D9: ECR-C1a | E9: Octane | F9: EX_octane_e | G9: -10 | H9: -20 | I9: NA | J9: 3.15 | K9: -10 | L9: -4.127907 | M9: NA | N9: 9.4418605 | O9: 0.069767442 | Q9: 0.0069767442 | R9: 0.017313438 | S9: =VLOOKUP($E9,'Product Naming'!$A$1:$P$58,2,FALSE) -> Octane | T9: =VLOOKUP($E9,'Product Naming'!$A$1:$P$58,3,FALSE) -> Octane | U9: =VLOOKUP($E9,'Product Naming'!$A$1:$P$58,4,FALSE) -> E | V9: =VLOOKUP($E9,'Product Naming'!$A$1:$P$58,5,FALSE) -> C8H18 | W9: =VLOOKUP($E9,'Product Naming'!$A$1:$P$58,6,FALSE) -> 8 | X9: =VLOOKUP($E9,'Product Naming'!$A$1:$P$58,7,FALSE) -> 18 | Y9: =VLOOKUP($E9,'Product Naming'!$A$1:$P$58,8,FALSE) -> 0 | Z9: =VLOOKUP($E9,'Product Naming'!$A$1:$P$58,9,FALSE) -> 0 | AA9: =VLOOKUP($E9,'Product Naming'!$A$1:$P$58,10,FALSE) -> 0 | AB9: =VLOOKUP($E9,'Product Naming'!$A$1:$P$58,11,FALSE) -> 6.25 | AC9: =VLOOKUP($E9,'Product Naming'!$A$1:$P$58,12,FALSE) -> 114.22672 | AD9: =VLOOKUP($E9,'Product Naming'!$A$1:$P$58,13,FALSE) -> 126 | AE9: =VLOOKUP($E9,'Product Naming'!$A$1:$P$58,14,FALSE) -> Hydrocarbon (alkane) | AF9: =VLOOKUP($E9,'Product Naming'!$A$1:$P$58,15,FALSE) -> Acetyl-CoA + Succinyl-CoA | AG9: =VLOOKUP($E9,'Product Naming'!$A$1:$P$58,16,FALSE) -> Proton symporter | AH9: =VLOOKUP($E9,'Product Naming'!$A$1:$Q$58,17,FALSE) -> octn_c | AI9: =VLOOKUP($E9,'Product Parameters'!$A$2:$D$59,2,FALSE) -> 1 | AJ9: =VLOOKUP($E9,'Product Parameters'!$A$2:$D$59,3,FALSE) -> 0 | AK9: =VLOOKUP($E9,'Product Parameters'!$A$2:$D$59,4,FALSE) -> 0.12 | AL9: =VLOOKUP($E9,'Product Parameters'!$A$2:$E$59,5,FALSE) -> 41 | AM9: =VLOOKUP($E9,'Product Parameters'!$A$2:$F$59,6,FALSE) -> 8 | AN9: =VLOOKUP($C9,'Substrate Heating'!$A$2:$C$33,3,FALSE) -> 247.59097 | AO9: =VLOOKUP($C9,'Substrate Heating'!$A$2:$B$33,2,FALSE) -> 5.5 | AP9: =VLOOKUP($C9,'Substrate Heating'!$A$2:$M$33,13,FALSE) -> 1 | AQ9: =VLOOKUP($C9,'Substrate Heating'!$A$2:$M$33,8,FALSE) -> 1 | AR9: =Q9*W9/AQ9 -> 0.055813953
A10: 2021-05-11 | B10: iJO1366 | C10: Formate_SerineCycle | D10: ECR-C1a | E10: BetaCarotene | F10: EX_caro_e | G10: -10 | H10: -20 | I10: NA | J10: 3.15 | K10: -10 | L10: -4.1604566 | M10: NA | N10: 9.378116 | O10: 0.0155471 | Q10: 0.00155471 | R10: 0.018133388 | S10: =VLOOKUP($E10,'Product Naming'!$A$1:$P$58,2,FALSE) -> BetaCarotene | T10: =VLOOKUP($E10,'Product Naming'!$A$1:$P$58,3,FALSE) -> Beta carotene | U10: =VLOOKUP($E10,'Product Naming'!$A$1:$P$58,4,FALSE) -> A | V10: =VLOOKUP($E10,'Product Naming'!$A$1:$P$58,5,FALSE) -> C40H56 | W10: =VLOOKUP($E10,'Product Naming'!$A$1:$P$58,6,FALSE) -> 40 | X10: =VLOOKUP($E10,'Product Naming'!$A$1:$P$58,7,FALSE) -> 56 | Y10: =VLOOKUP($E10,'Product Naming'!$A$1:$P$58,8,FALSE) -> 0 | Z10: =VLOOKUP($E10,'Product Naming'!$A$1:$P$58,9,FALSE) -> 0 | AA10: =VLOOKUP($E10,'Product Naming'!$A$1:$P$58,10,FALSE) -> 0 | AB10: =VLOOKUP($E10,'Product Naming'!$A$1:$P$58,11,FALSE) -> 5.4 | AC10: =VLOOKUP($E10,'Product Naming'!$A$1:$P$58,12,FALSE) -> 536.86704 | AD10: =VLOOKUP($E10,'Product Naming'!$A$1:$P$58,13,FALSE) -> 633 | AE10: =VLOOKUP($E10,'Product Naming'!$A$1:$P$58,14,FALSE) -> Hydrocarbon | AF10: =VLOOKUP($E10,'Product Naming'!$A$1:$P$58,15,FALSE) -> Acetyl-CoA | AG10: =VLOOKUP($E10,'Product Naming'!$A$1:$P$58,16,FALSE) -> ABC Transporter | AH10: =VLOOKUP($E10,'Product Naming'!$A$1:$Q$58,17,FALSE) -> caro_c | AI10: =VLOOKUP($E10,'Product Parameters'!$A$2:$D$59,2,FALSE) -> 1 | AJ10: =VLOOKUP($E10,'Product Parameters'!$A$2:$D$59,3,FALSE) -> 0 | AK10: =VLOOKUP($E10,'Product Parameters'!$A$2:$D$59,4,FALSE) -> 0.12 | AL10: =VLOOKUP($E10,'Product Parameters'!$A$2:$E$59,5,FALSE) -> 40.65 | AM10: =VLOOKUP($E10,'Product Parameters'!$A$2:$F$59,6,FALSE) -> 40 | AN10: =VLOOKUP($C10,'Substrate Heating'!$A$2:$C$33,3,FALSE) -> 247.59097 | AO10: =VLOOKUP($C10,'Substrate Heating'!$A$2:$B$33,2,FALSE) -> 5.5 | AP10: =VLOOKUP($C10,'Substrate Heating'!$A$2:$M$33,13,FALSE) -> 1 | AQ10: =VLOOKUP($C10,'Substrate Heating'!$A$2:$M$33,8,FALSE) -> 1 | AR10: =Q10*W10/AQ10 -> 0.062188402
A11: 2021-05-11 | B11: iJO1366 | C11: Formate_SerineCycle | D11: ECR-C1a | E11: Isoprene | F11: EX_iprene_e | G11: -10 | H11: -20 | I11: NA | J11: 3.15 | K11: -10 | L11: -4.118491 | M11: NA | N11: 9.3703507 | O11: 0.12592986 | Q11: 0.012592986 | R11: 0.018635544 | S11: =VLOOKUP($E11,'Product Naming'!$A$1:$P$58,2,FALSE) -> Isoprene | T11: =VLOOKUP($E11,'Product Naming'!$A$1:$P$58,3,FALSE) -> Isoprene | U11: =VLOOKUP($E11,'Product Naming'!$A$1:$P$58,4,FALSE) -> E | V11: =VLOOKUP($E11,'Product Naming'!$A$1:$P$58,5,FALSE) -> C5H8 | W11: =VLOOKUP($E11,'Product Naming'!$A$1:$P$58,6,FALSE) -> 5 | X11: =VLOOKUP($E11,'Product Naming'!$A$1:$P$58,7,FALSE) -> 8 | Y11: =VLOOKUP($E11,'Product Naming'!$A$1:$P$58,8,FALSE) -> 0 | Z11: =VLOOKUP($E11,'Product Naming'!$A$1:$P$58,9,FALSE) -> 0 | AA11: =VLOOKUP($E11,'Product Naming'!$A$1:$P$58,10,FALSE) -> 0 | AB11: =VLOOKUP($E11,'Product Naming'!$A$1:$P$58,11,FALSE) -> 5.6 | AC11: =VLOOKUP($E11,'Product Naming'!$A$1:$P$58,12,FALSE) -> 68.11622 | AD11: =VLOOKUP($E11,'Product Naming'!$A$1:$P$58,13,FALSE) -> 34.07 | AE11: =VLOOKUP($E11,'Product Naming'!$A$1:$P$58,14,FALSE) -> Hydrocarbon | AF11: =VLOOKUP($E11,'Product Naming'!$A$1:$P$58,15,FALSE) -> Acetyl-CoA | AG11: =VLOOKUP($E11,'Product Naming'!$A$1:$P$58,16,FALSE) -> Diffusion | AH11: =VLOOKUP($E11,'Product Naming'!$A$1:$Q$58,17,FALSE) -> iprene_c | AI11: =VLOOKUP($E11,'Product Parameters'!$A$2:$D$59,2,FALSE) -> 0 | AJ11: =VLOOKUP($E11,'Product Parameters'!$A$2:$D$59,3,FALSE) -> 1 | AK11: =VLOOKUP($E11,'Product Parameters'!$A$2:$D$59,4,FALSE) -> 0.12 | AL11: =VLOOKUP($E11,'Product Parameters'!$A$2:$E$59,5,FALSE) -> 26.4 | AM11: =VLOOKUP($E11,'Product Parameters'!$A$2:$F$59,6,FALSE) -> 5 | AN11: =VLOOKUP($C11,'Substrate Heating'!$A$2:$C$33,3,FALSE) -> 247.59097 | AO11: =VLOOKUP($C11,'Substrate Heating'!$A$2:$B$33,2,FALSE) -> 5.5 | AP11: =VLOOKUP($C11,'Substrate Heating'!$A$2:$M$33,13,FALSE) -> 1 | AQ11: =VLOOKUP($C11,'Substrate Heating'!$A$2:$M$33,8,FALSE) -> 1 | AR11: =Q11*W11/AQ11 -> 0.062964931
A12: 2021-05-11 | B12: iJO1366 | C12: Formate_SerineCycle | D12: ECR-C1a | E12: Farnesene | F12: EX_frene_e | G12: -10 | H12: -20 | I12: NA | J12: 3.15 | K12: -10 | L12: -4.1177096 | M12: NA | N12: 9.3697926 | O12: 0.042013827 | Q12: 0.0042013827 | R12: 0.018652062 | S12: =VLOOKUP($E12,'Product Naming'!$A$1:$P$58,2,FALSE) -> Farnesene | T12: =VLOOKUP($E12,'Product Naming'!$A$1:$P$58,3,FALSE) -> Farnesene | U12: =VLOOKUP($E12,'Product Naming'!$A$1:$P$58,4,FALSE) -> A | V12: =VLOOKUP($E12,'Product Naming'!$A$1:$P$58,5,FALSE) -> C15H24 | W12: =VLOOKUP($E12,'Product Naming'!$A$1:$P$58,6,FALSE) -> 15 | X12: =VLOOKUP($E12,'Product Naming'!$A$1:$P$58,7,FALSE) -> 24 | Y12: =VLOOKUP($E12,'Product Naming'!$A$1:$P$58,8,FALSE) -> 0 | Z12: =VLOOKUP($E12,'Product Naming'!$A$1:$P$58,9,FALSE) -> 0 | AA12: =VLOOKUP($E12,'Product Naming'!$A$1:$P$58,10,FALSE) -> 0 | AB12: =VLOOKUP($E12,'Product Naming'!$A$1:$P$58,11,FALSE) -> 5.6 | AC12: =VLOOKUP($E12,'Product Naming'!$A$1:$P$58,12,FALSE) -> 204.34866 | AD12: =VLOOKUP($E12,'Product Naming'!$A$1:$P$58,13,FALSE) -> 260 (A)/272 (B) | AE12: =VLOOKUP($E12,'Product Naming'!$A$1:$P$58,14,FALSE) -> Hydrocarbon | AF12: =VLOOKUP($E12,'Product Naming'!$A$1:$P$58,15,FALSE) -> Acetyl-CoA | AG12: =VLOOKUP($E12,'Product Naming'!$A$1:$P$58,16,FALSE) -> Proton symporter | AH12: =VLOOKUP($E12,'Product Naming'!$A$1:$Q$58,17,FALSE) -> frene_c | AI12: =VLOOKUP($E12,'Product Parameters'!$A$2:$D$59,2,FALSE) -> 1 | AJ12: =VLOOKUP($E12,'Product Parameters'!$A$2:$D$59,3,FALSE) -> 0 | AK12: =VLOOKUP($E12,'Product Parameters'!$A$2:$D$59,4,FALSE) -> 0.12 | AL12: =VLOOKUP($E12,'Product Parameters'!$A$2:$E$59,5,FALSE) -> 0 | AM12: =VLOOKUP($E12,'Product Parameters'!$A$2:$F$59,6,FALSE) -> 15 | AN12: =VLOOKUP($C12,'Substrate Heating'!$A$2:$C$33,3,FALSE) -> 247.59097 | AO12: =VLOOKUP($C12,'Substrate Heating'!$A$2:$B$33,2,FALSE) -> 5.5 | AP12: =VLOOKUP($C12,'Substrate Heating'!$A$2:$M$33,13,FALSE) -> 1 | AQ12: =VLOOKUP($C12,'Substrate Heating'!$A$2:$M$33,8,FALSE) -> 1 | AR12: =Q12*W12/AQ12 -> 0.063020741
A13: 2021-05-17 | B13: iJO1366 | C13: Formate_SerineCycle | D13: ECR-C1a | E13: Limonene | F13: EX_limnen_e | G13: -10 | H13: -20 | I13: NA | J13: 3.15 | K13: -10 | L13: -4.1173184 | M13: NA | N13: 9.3695132 | O13: 0.063048683 | Q13: 0.0063048683 | R13: 0.018660331 | S13: =VLOOKUP($E13,'Product Naming'!$A$1:$P$58,2,FALSE) -> Limonene | T13: =VLOOKUP($E13,'Product Naming'!$A$1:$P$58,3,FALSE) -> Limonene | U13: =VLOOKUP($E13,'Product Naming'!$A$1:$P$58,4,FALSE) -> E | V13: =VLOOKUP($E13,'Product Naming'!$A$1:$P$58,5,FALSE) -> C10H16 | W13: =VLOOKUP($E13,'Product Naming'!$A$1:$P$58,6,FALSE) -> 10 | X13: =VLOOKUP($E13,'Product Naming'!$A$1:$P$58,7,FALSE) -> 16 | Y13: =VLOOKUP($E13,'Product Naming'!$A$1:$P$58,8,FALSE) -> 0 | Z13: =VLOOKUP($E13,'Product Naming'!$A$1:$P$58,9,FALSE) -> 0 | AA13: =VLOOKUP($E13,'Product Naming'!$A$1:$P$58,10,FALSE) -> 0 | AB13: =VLOOKUP($E13,'Product Naming'!$A$1:$P$58,11,FALSE) -> 5.6 | AC13: =VLOOKUP($E13,'Product Naming'!$A$1:$P$58,12,FALSE) -> 136.23244 | AD13: =VLOOKUP($E13,'Product Naming'!$A$1:$P$58,13,FALSE) -> 176 | AE13: =VLOOKUP($E13,'Product Naming'!$A$1:$P$58,14,FALSE) -> Isoprenoid; Aromatic (Cycloalkane) | AF13: =VLOOKUP($E13,'Product Naming'!$A$1:$P$58,15,FALSE) -> Acetyl-CoA | AG13: =VLOOKUP($E13,'Product Naming'!$A$1:$P$58,16,FALSE) -> Proton symporter | AH13: =VLOOKUP($E13,'Product Naming'!$A$1:$Q$58,17,FALSE) -> limnen_c | AI13: =VLOOKUP($E13,'Product Parameters'!$A$2:$D$59,2,FALSE) -> 1 | AJ13: =VLOOKUP($E13,'Product Parameters'!$A$2:$D$59,3,FALSE) -> 0 | AK13: =VLOOKUP($E13,'Product Parameters'!$A$2:$D$59,4,FALSE) -> 0.12 | AL13: =VLOOKUP($E13,'Product Parameters'!$A$2:$E$59,5,FALSE) -> 49.5 | AM13: =VLOOKUP($E13,'Product Parameters'!$A$2:$F$59,6,FALSE) -> 10 | AN13: =VLOOKUP($C13,'Substrate Heating'!$A$2:$C$33,3,FALSE) -> 247.59097 | AO13: =VLOOKUP($C13,'Substrate Heating'!$A$2:$B$33,2,FALSE) -> 5.5 | AP13: =VLOOKUP($C13,'Substrate Heating'!$A$2:$M$33,13,FALSE) -> 1 | AQ13: =VLOOKUP($C13,'Substrate Heating'!$A$2:$M$33,8,FALSE) -> 1 | AR13: =Q13*W13/AQ13 -> 0.063048683
... A68: 2021-05-11 | B68: iJO1366 | C68: Formate_RGP-Serine | D68: ECR-C1a | E68: Pentanol-PW2 | F68: EX_pentoh_e | G68: -10 | H68: -20 | I68: NA | J68: 3.15 | K68: -10 | L68: -3.2313433 | M68: NA | N68: 8.8208955 | O68: 0.2358209 | Q68: 0.02358209 | R68: 0.045159648 | S68: =VLOOKUP($E68,'Product Naming'!$A$1:$P$58,2,FALSE) -> Pentanol-PW2 | T68: =VLOOKUP($E68,'Product Naming'!$A$1:$P$58,3,FALSE) -> Pentanol (PW2) | U68: =VLOOKUP($E68,'Product Naming'!$A$1:$P$58,4,FALSE) -> E | V68: =VLOOKUP($E68,'Product Naming'!$A$1:$P$58,5,FALSE) -> C5H12O | W68: =VLOOKUP($E68,'Product Naming'!$A$1:$P$58,6,FALSE) -> 5 | X68: =VLOOKUP($E68,'Product Naming'!$A$1:$P$58,7,FALSE) -> 12 | Y68: =VLOOKUP($E68,'Product Naming'!$A$1:$P$58,8,FALSE) -> 1 | Z68: =VLOOKUP($E68,'Product Naming'!$A$1:$P$58,9,FALSE) -> 0 | AA68: =VLOOKUP($E68,'Product Naming'!$A$1:$P$58,10,FALSE) -> 0 | AB68: =VLOOKUP($E68,'Product Naming'!$A$1:$P$58,11,FALSE) -> 6 | AC68: =VLOOKUP($E68,'Product Naming'!$A$1:$P$58,12,FALSE) -> 88.14658 | AD68: =VLOOKUP($E68,'Product Naming'!$A$1:$P$58,13,FALSE) -> 138 | AE68: =VLOOKUP($E68,'Product Naming'!$A$1:$P$58,14,FALSE) -> Alcohol | AF68: =VLOOKUP($E68,'Product Naming'!$A$1:$P$58,15,FALSE) -> Oxaloacetate | AG68: =VLOOKUP($E68,'Product Naming'!$A$1:$P$58,16,FALSE) -> Proton symporter | AH68: =VLOOKUP($E68,'Product Naming'!$A$1:$Q$58,17,FALSE) -> pentoh_c | AI68: =VLOOKUP($E68,'Product Parameters'!$A$2:$D$59,2,FALSE) -> 1 | AJ68: =VLOOKUP($E68,'Product Parameters'!$A$2:$D$59,3,FALSE) -> 0 | AK68: =VLOOKUP($E68,'Product Parameters'!$A$2:$D$59,4,FALSE) -> 0.12 | AL68: =VLOOKUP($E68,'Product Parameters'!$A$2:$E$59,5,FALSE) -> 57 | AM68: =VLOOKUP($E68,'Product Parameters'!$A$2:$F$59,6,FALSE) -> 5 | AN68: =VLOOKUP($C68,'Substrate Heating'!$A$2:$C$33,3,FALSE) -> 247.59097 | AO68: =VLOOKUP($C68,'Substrate Heating'!$A$2:$B$33,2,FALSE) -> 5.5 | AP68: =VLOOKUP($C68,'Substrate Heating'!$A$2:$M$33,13,FALSE) -> 1 | AQ68: =VLOOKUP($C68,'Substrate Heating'!$A$2:$M$33,8,FALSE) -> 1 | AR68: =Q68*W68/AQ68 -> 0.11791045
A69: 2021-05-27 | B69: iHN637 | C69: FOR_1:H2_0 | D69: ECR-C1b | E69: Phenol | F69: EX_phenol_e | G69: -10 | H69: 0 | I69: 0 | J69: 0.45 | K69: -10 | L69: 0 | M69: 0 | N69: 5.2252632 | O69: 0.22526316 | Q69: 0.022526316 | R69: 0.046056385 | S69: =VLOOKUP($E69,'Product Naming'!$A$1:$P$58,2,FALSE) -> Phenol | T69: =VLOOKUP($E69,'Product Naming'!$A$1:$P$58,3,FALSE) -> Phenol | U69: =VLOOKUP($E69,'Product Naming'!$A$1:$P$58,4,FALSE) -> E-S | V69: =VLOOKUP($E69,'Product Naming'!$A$1:$P$58,5,FALSE) -> C6H6O | W69: =VLOOKUP($E69,'Product Naming'!$A$1:$P$58,6,FALSE) -> 6 | X69: =VLOOKUP($E69,'Product Naming'!$A$1:$P$58,7,FALSE) -> 6 | Y69: =VLOOKUP($E69,'Product Naming'!$A$1:$P$58,8,FALSE) -> 1 | Z69: =VLOOKUP($E69,'Product Naming'!$A$1:$P$58,9,FALSE) -> 0 | AA69: =VLOOKUP($E69,'Product Naming'!$A$1:$P$58,10,FALSE) -> 0 | AB69: =VLOOKUP($E69,'Product Naming'!$A$1:$P$58,11,FALSE) -> 4.6666667 | AC69: =VLOOKUP($E69,'Product Naming'!$A$1:$P$58,12,FALSE) -> 94.11024 | AD69: =VLOOKUP($E69,'Product Naming'!$A$1:$P$58,13,FALSE) -> 181.7 | AE69: =VLOOKUP($E69,'Product Naming'!$A$1:$P$58,14,FALSE) -> Aromatic + Alcohol | AF69: =VLOOKUP($E69,'Product Naming'!$A$1:$P$58,15,FALSE) -> E4P + L-glutamate | AG69: =VLOOKUP($E69,'Product Naming'!$A$1:$P$58,16,FALSE) -> Proton symporter | AH69: =VLOOKUP($E69,'Product Naming'!$A$1:$Q$58,17,FALSE) -> phenol_c | AI69: =VLOOKUP($E69,'Product Parameters'!$A$2:$D$59,2,FALSE) -> 1 | AJ69: =VLOOKUP($E69,'Product Parameters'!$A$2:$D$59,3,FALSE) -> 0 | AK69: =VLOOKUP($E69,'Product Parameters'!$A$2:$D$59,4,FALSE) -> 0.12 | AL69: =VLOOKUP($E69,'Product Parameters'!$A$2:$E$59,5,FALSE) -> 58.8 | AM69: =VLOOKUP($E69,'Product Parameters'!$A$2:$F$59,6,FALSE) -> 6 | AN69: =VLOOKUP($C69,'Substrate Heating'!$A$2:$C$33,3,FALSE) -> 247.59097 | AO69: =VLOOKUP($C69,'Substrate Heating'!$A$2:$B$33,2,FALSE) -> 5.5 | AP69: =VLOOKUP($C69,'Substrate Heating'!$A$2:$M$33,13,FALSE) -> 1 | AQ69: =VLOOKUP($C69,'Substrate Heating'!$A$2:$M$33,8,FALSE) -> 1 | AR69: =Q69*W69/AQ69 -> 0.13515789
A70: 2021-05-11 | B70: iJO1366 | C70: Formate_RGP-Serine | D70: ECR-C1a | E70: Butanol-PW2 | F70: EX_btoh_e | G70: -10 | H70: -20 | I70: NA | J70: 3.15 | K70: -10 | L70: -3.2763636 | M70: NA | N70: 8.8509091 | O70: 0.28727273 | Q70: 0.028727273 | R70: 0.046258738 | S70: =VLOOKUP($E70,'Product Naming'!$A$1:$P$58,2,FALSE) -> Butanol-PW2 | T70: =VLOOKUP($E70,'Product Naming'!$A$1:$P$58,3,FALSE) -> Butanol (PW2) | U70: =VLOOKUP($E70,'Product Naming'!$A$1:$P$58,4,FALSE) -> E | V70: =VLOOKUP($E70,'Product Naming'!$A$1:$P$58,5,FALSE) -> C4H10O | W70: =VLOOKUP($E70,'Product Naming'!$A$1:$P$58,6,FALSE) -> 4 | X70: =VLOOKUP($E70,'Product Naming'!$A$1:$P$58,7,FALSE) -> 10 | Y70: =VLOOKUP($E70,'Product Naming'!$A$1:$P$58,8,FALSE) -> 1 | Z70: =VLOOKUP($E70,'Product Naming'!$A$1:$P$58,9,FALSE) -> 0 | AA70: =VLOOKUP($E70,'Product Naming'!$A$1:$P$58,10,FALSE) -> 0 | AB70: =VLOOKUP($E70,'Product Naming'!$A$1:$P$58,11,FALSE) -> 6 | AC70: =VLOOKUP($E70,'Product Naming'!$A$1:$P$58,12,FALSE) -> 74.1202 | AD70: =VLOOKUP($E70,'Product Naming'!$A$1:$P$58,13,FALSE) -> 117.7 | AE70: =VLOOKUP($E70,'Product Naming'!$A$1:$P$58,14,FALSE) -> Alcohol | AF70: =VLOOKUP($E70,'Product Naming'!$A$1:$P$58,15,FALSE) -> Oxaloacetate | AG70: =VLOOKUP($E70,'Product Naming'!$A$1:$P$58,16,FALSE) -> Proton symporter | AH70: =VLOOKUP($E70,'Product Naming'!$A$1:$Q$58,17,FALSE) -> btoh_c | AI70: =VLOOKUP($E70,'Product Parameters'!$A$2:$D$59,2,FALSE) -> 1 | AJ70: =VLOOKUP($E70,'Product Parameters'!$A$2:$D$59,3,FALSE) -> 0 | AK70: =VLOOKUP($E70,'Product Parameters'!$A$2:$D$59,4,FALSE) -> 0.12 | AL70: =VLOOKUP($E70,'Product Parameters'!$A$2:$E$59,5,FALSE) -> 52 | AM70: =VLOOKUP($E70,'Product Parameters'!$A$2:$F$59,6,FALSE) -> 4 | AN70: =VLOOKUP($C70,'Substrate Heating'!$A$2:$C$33,3,FALSE) -> 247.59097 | AO70: =VLOOKUP($C70,'Substrate Heating'!$A$2:$B$33,2,FALSE) -> 5.5 | AP70: =VLOOKUP($C70,'Substrate Heating'!$A$2:$M$33,13,FALSE) -> 1 | AQ70: =VLOOKUP($C70,'Substrate Heating'!$A$2:$M$33,8,FALSE) -> 1 | AR70: =Q70*W70/AQ70 -> 0.11490909
A71: 2021-05-11 | B71: iJO1366 | C71: Formate_RGP-Serine | D71: ECR-C1a | E71: 4-Hydroxystyrene | F71: EX_hxst_e | G71: -10 | H71: -20 | I71: NA | J71: 3.15 | K71: -10 | L71: -3.3134831 | M71: NA | N71: 8.5797753 | O71: 0.17752809 | Q71: 0.017752809 | R71: 0.046338713 | S71: =VLOOKUP($E71,'Product Naming'!$A$1:$P$58,2,FALSE) -> 4-Hydroxystyrene | T71: =VLOOKUP($E71,'Product Naming'!$A$1:$P$58,3,FALSE) -> 4-Hydroxystyrene | U71: =VLOOKUP($E71,'Product Naming'!$A$1:$P$58,4,FALSE) -> E | V71: =VLOOKUP($E71,'Product Naming'!$A$1:$P$58,5,FALSE) -> C8H8O | W71: =VLOOKUP($E71,'Product Naming'!$A$1:$P$58,6,FALSE) -> 8 | X71: =VLOOKUP($E71,'Product Naming'!$A$1:$P$58,7,FALSE) -> 8 | Y71: =VLOOKUP($E71,'Product Naming'!$A$1:$P$58,8,FALSE) -> 1 | Z71: =VLOOKUP($E71,'Product Naming'!$A$1:$P$58,9,FALSE) -> 0 | AA71: =VLOOKUP($E71,'Product Naming'!$A$1:$P$58,10,FALSE) -> 0 | AB71: =VLOOKUP($E71,'Product Naming'!$A$1:$P$58,11,FALSE) -> 4.75 | AC71: =VLOOKUP($E71,'Product Naming'!$A$1:$P$58,12,FALSE) -> 120.14732 | AD71: =VLOOKUP($E71,'Product Naming'!$A$1:$P$58,13,FALSE) -> 229 | AE71: =VLOOKUP($E71,'Product Naming'!$A$1:$P$58,14,FALSE) -> Aromatic + Alcohol | AF71: =VLOOKUP($E71,'Product Naming'!$A$1:$P$58,15,FALSE) -> E4P + L-glutamate | AG71: =VLOOKUP($E71,'Product Naming'!$A$1:$P$58,16,FALSE) -> Proton symporter | AH71: =VLOOKUP($E71,'Product Naming'!$A$1:$Q$58,17,FALSE) -> 4hxst_c | AI71: =VLOOKUP($E71,'Product Parameters'!$A$2:$D$59,2,FALSE) -> 1 | AJ71: =VLOOKUP($E71,'Product Parameters'!$A$2:$D$59,3,FALSE) -> 0 | AK71: =VLOOKUP($E71,'Product Parameters'!$A$2:$D$59,4,FALSE) -> 0.12 | AL71: =VLOOKUP($E71,'Product Parameters'!$A$2:$E$59,5,FALSE) -> 40.65 | AM71: =VLOOKUP($E71,'Product Parameters'!$A$2:$F$59,6,FALSE) -> 8 | AN71: =VLOOKUP($C71,'Substrate Heating'!$A$2:$C$33,3,FALSE) -> 247.59097 | AO71: =VLOOKUP($C71,'Substrate Heating'!$A$2:$B$33,2,FALSE) -> 5.5 | AP71: =VLOOKUP($C71,'Substrate Heating'!$A$2:$M$33,13,FALSE) -> 1 | AQ71: =VLOOKUP($C71,'Substrate Heating'!$A$2:$M$33,8,FALSE) -> 1 | AR71: =Q71*W71/AQ71 -> 0.14202247
A72: 2021-05-27 | B72: iHN637 | C72: FOR_1:H2_0 | D72: ECR-C1b | E72: Styrene | F72: EX_styr_e | G72: -10 | H72: 0 | I72: 0 | J72: 0.45 | K72: -10 | L72: 0 | M72: 0 | N72: 5.4115385 | O72: 0.20576923 | Q72: 0.020576923 | R72: 0.046558127 | S72: =VLOOKUP($E72,'Product Naming'!$A$1:$P$58,2,FALSE) -> Styrene | T72: =VLOOKUP($E72,'Product Naming'!$A$1:$P$58,3,FALSE) -> Styrene | U72: =VLOOKUP($E72,'Product Naming'!$A$1:$P$58,4,FALSE) -> E-S | V72: =VLOOKUP($E72,'Product Naming'!$A$1:$P$58,5,FALSE) -> C8H8 | W72: =VLOOKUP($E72,'Product Naming'!$A$1:$P$58,6,FALSE) -> 8 | X72: =VLOOKUP($E72,'Product Naming'!$A$1:$P$58,7,FALSE) -> 8 | Y72: =VLOOKUP($E72,'Product Naming'!$A$1:$P$58,8,FALSE) -> 0 | Z72: =VLOOKUP($E72,'Product Naming'!$A$1:$P$58,9,FALSE) -> 0 | AA72: =VLOOKUP($E72,'Product Naming'!$A$1:$P$58,10,FALSE) -> 0 | AB72: =VLOOKUP($E72,'Product Naming'!$A$1:$P$58,11,FALSE) -> 5 | AC72: =VLOOKUP($E72,'Product Naming'!$A$1:$P$58,12,FALSE) -> 104.14832 | AD72: =VLOOKUP($E72,'Product Naming'!$A$1:$P$58,13,FALSE) -> 145 | AE72: =VLOOKUP($E72,'Product Naming'!$A$1:$P$58,14,FALSE) -> Cycloalkane | AF72: =VLOOKUP($E72,'Product Naming'!$A$1:$P$58,15,FALSE) -> E4P | AG72: =VLOOKUP($E72,'Product Naming'!$A$1:$P$58,16,FALSE) -> Proton symporter | AH72: =VLOOKUP($E72,'Product Naming'!$A$1:$Q$58,17,FALSE) -> styr_c | AI72: =VLOOKUP($E72,'Product Parameters'!$A$2:$D$59,2,FALSE) -> 1 | AJ72: =VLOOKUP($E72,'Product Parameters'!$A$2:$D$59,3,FALSE) -> 0 | AK72: =VLOOKUP($E72,'Product Parameters'!$A$2:$D$59,4,FALSE) -> 0.12 | AL72: =VLOOKUP($E72,'Product Parameters'!$A$2:$E$59,5,FALSE) -> 43.9 | AM72: =VLOOKUP($E72,'Product Parameters'!$A$2:$F$59,6,FALSE) -> 8 | AN72: =VLOOKUP($C72,'Substrate Heating'!$A$2:$C$33,3,FALSE) -> 247.59097 | AO72: =VLOOKUP($C72,'Substrate Heating'!$A$2:$B$33,2,FALSE) -> 5.5 | AP72: =VLOOKUP($C72,'Substrate Heating'!$A$2:$M$33,13,FALSE) -> 1 | AQ72: =VLOOKUP($C72,'Substrate Heating'!$A$2:$M$33,8,FALSE) -> 1 | AR72: =Q72*W72/AQ72 -> 0.16461538
A73: 2021-05-11 | B73: iJO1366 | C73: Formate_RGP-Serine | D73: ECR-C1a | E73: Phenol | F73: EX_phenol_e | G73: -10 | H73: -20 | I73: NA | J73: 3.15 | K73: -10 | L73: -3.3971014 | M73: NA | N73: 8.626087 | O73: 0.22898551 | Q73: 0.022898551 | R73: 0.046817441 | S73: =VLOOKUP($E73,'Product Naming'!$A$1:$P$58,2,FALSE) -> Phenol | T73: =VLOOKUP($E73,'Product Naming'!$A$1:$P$58,3,FALSE) -> Phenol | U73: =VLOOKUP($E73,'Product Naming'!$A$1:$P$58,4,FALSE) -> E-S | V73: =VLOOKUP($E73,'Product Naming'!$A$1:$P$58,5,FALSE) -> C6H6O | W73: =VLOOKUP($E73,'Product Naming'!$A$1:$P$58,6,FALSE) -> 6 | X73: =VLOOKUP($E73,'Product Naming'!$A$1:$P$58,7,FALSE) -> 6 | Y73: =VLOOKUP($E73,'Product Naming'!$A$1:$P$58,8,FALSE) -> 1 | Z73: =VLOOKUP($E73,'Product Naming'!$A$1:$P$58,9,FALSE) -> 0 | AA73: =VLOOKUP($E73,'Product Naming'!$A$1:$P$58,10,FALSE) -> 0 | AB73: =VLOOKUP($E73,'Product Naming'!$A$1:$P$58,11,FALSE) -> 4.6666667 | AC73: =VLOOKUP($E73,'Product Naming'!$A$1:$P$58,12,FALSE) -> 94.11024 | AD73: =VLOOKUP($E73,'Product Naming'!$A$1:$P$58,13,FALSE) -> 181.7 | AE73: =VLOOKUP($E73,'Product Naming'!$A$1:$P$58,14,FALSE) -> Aromatic + Alcohol | AF73: =VLOOKUP($E73,'Product Naming'!$A$1:$P$58,15,FALSE) -> E4P + L-glutamate | AG73: =VLOOKUP($E73,'Product Naming'!$A$1:$P$58,16,FALSE) -> Proton symporter | AH73: =VLOOKUP($E73,'Product Naming'!$A$1:$Q$58,17,FALSE) -> phenol_c | AI73: =VLOOKUP($E73,'Product Parameters'!$A$2:$D$59,2,FALSE) -> 1 | AJ73: =VLOOKUP($E73,'Product Parameters'!$A$2:$D$59,3,FALSE) -> 0 | AK73: =VLOOKUP($E73,'Product Parameters'!$A$2:$D$59,4,FALSE) -> 0.12 | AL73: =VLOOKUP($E73,'Product Parameters'!$A$2:$E$59,5,FALSE) -> 58.8 | AM73: =VLOOKUP($E73,'Product Parameters'!$A$2:$F$59,6,FALSE) -> 6 | AN73: =VLOOKUP($C73,'Substrate Heating'!$A$2:$C$33,3,FALSE) -> 247.59097 | AO73: =VLOOKUP($C73,'Substrate Heating'!$A$2:$B$33,2,FALSE) -> 5.5 | AP73: =VLOOKUP($C73,'Substrate Heating'!$A$2:$M$33,13,FALSE) -> 1 | AQ73: =VLOOKUP($C73,'Substrate Heating'!$A$2:$M$33,8,FALSE) -> 1 | AR73: =Q73*W73/AQ73 -> 0.1373913
A74: 2023-11-29 | B74: iHN637 | C74: Methanol_MethylTransferase_1 | D74: ECR-C1a | E74: Phenol | F74: EX_phenol_e | G74: -10 | H74: 0 | I74: 0 | J74: 0.45 | K74: -10 | L74: 0 | M74: 0.64313725 | N74: 0 | O74: 0.16078431372549318 | Q74: 0.016078431 | R74: 0.047417063 | S74: =VLOOKUP($E74,'Product Naming'!$A$1:$P$58,2,FALSE) -> Phenol | T74: =VLOOKUP($E74,'Product Naming'!$A$1:$P$58,3,FALSE) -> Phenol | U74: =VLOOKUP($E74,'Product Naming'!$A$1:$P$58,4,FALSE) -> E-S | V74: =VLOOKUP($E74,'Product Naming'!$A$1:$P$58,5,FALSE) -> C6H6O | W74: =VLOOKUP($E74,'Product Naming'!$A$1:$P$58,6,FALSE) -> 6 | X74: =VLOOKUP($E74,'Product Naming'!$A$1:$P$58,7,FALSE) -> 6 | Y74: =VLOOKUP($E74,'Product Naming'!$A$1:$P$58,8,FALSE) -> 1 | Z74: =VLOOKUP($E74,'Product Naming'!$A$1:$P$58,9,FALSE) -> 0 | AA74: =VLOOKUP($E74,'Product Naming'!$A$1:$P$58,10,FALSE) -> 0 | AB74: =VLOOKUP($E74,'Product Naming'!$A$1:$P$58,11,FALSE) -> 4.6666667 | AC74: =VLOOKUP($E74,'Product Naming'!$A$1:$P$58,12,FALSE) -> 94.11024 | AD74: =VLOOKUP($E74,'Product Naming'!$A$1:$P$58,13,FALSE) -> 181.7 | AE74: =VLOOKUP($E74,'Product Naming'!$A$1:$P$58,14,FALSE) -> Aromatic + Alcohol | AF74: =VLOOKUP($E74,'Product Naming'!$A$1:$P$58,15,FALSE) -> E4P + L-glutamate | AG74: =VLOOKUP($E74,'Product Naming'!$A$1:$P$58,16,FALSE) -> Proton symporter | AH74: =VLOOKUP($E74,'Product Naming'!$A$1:$Q$58,17,FALSE) -> phenol_c | AI74: =VLOOKUP($E74,'Product Parameters'!$A$2:$D$59,2,FALSE) -> 1 | AJ74: =VLOOKUP($E74,'Product Parameters'!$A$2:$D$59,3,FALSE) -> 0 | AK74: =VLOOKUP($E74,'Product Parameters'!$A$2:$D$59,4,FALSE) -> 0.12 | AL74: =VLOOKUP($E74,'Product Parameters'!$A$2:$E$59,5,FALSE) -> 58.8 | AM74: =VLOOKUP($E74,'Product Parameters'!$A$2:$F$59,6,FALSE) -> 6 | AN74: =VLOOKUP($C74,'Substrate Heating'!$A$2:$C$33,3,FALSE) -> 638.57833 | AO74: =VLOOKUP($C74,'Substrate Heating'!$A$2:$B$33,2,FALSE) -> 19.93 | AP74: =VLOOKUP($C74,'Substrate Heating'!$A$2:$M$33,13,FALSE) -> 6 | AQ74: =VLOOKUP($C74,'Substrate Heating'!$A$2:$M$33,8,FALSE) -> 1 | AR74: =Q74*W74/AQ74 -> 0.096470588
A75: 2021-05-11 | B75: iJO1366 | C75: Formate_Formolase | D75: ECR-C1a | E75: Butane | F75: EX_butane_e | G75: -10 | H75: -20 | I75: NA | J75: 3.15 | K75: -10 | L75: -2.5352 | M75: NA | N75: 8.4832 | O75: 0.3792 | Q75: 0.03792 | R75: 0.047881274 | S75: =VLOOKUP($E75,'Product Naming'!$A$1:$P$58,2,FALSE) -> Butane | T75: =VLOOKUP($E75,'Product Naming'!$A$1:$P$58,3,FALSE) -> Butane | U75: =VLOOKUP($E75,'Product Naming'!$A$1:$P$58,4,FALSE) -> E | V75: =VLOOKUP($E75,'Product Naming'!$A$1:$P$58,5,FALSE) -> C4H10 | W75: =VLOOKUP($E75,'Product Naming'!$A$1:$P$58,6,FALSE) -> 4 | X75: =VLOOKUP($E75,'Product Naming'!$A$1:$P$58,7,FALSE) -> 10 | Y75: =VLOOKUP($E75,'Product Naming'!$A$1:$P$58,8,FALSE) -> 0 | Z75: =VLOOKUP($E75,'Product Naming'!$A$1:$P$58,9,FALSE) -> 0 | AA75: =VLOOKUP($E75,'Product Naming'!$A$1:$P$58,10,FALSE) -> 0 | AB75: =VLOOKUP($E75,'Product Naming'!$A$1:$P$58,11,FALSE) -> 6.5 | AC75: =VLOOKUP($E75,'Product Naming'!$A$1:$P$58,12,FALSE) -> 58.1212 | AD75: =VLOOKUP($E75,'Product Naming'!$A$1:$P$58,13,FALSE) -> -1 | AE75: =VLOOKUP($E75,'Product Naming'!$A$1:$P$58,14,FALSE) -> Hydrocarbon (alkane) | AF75: =VLOOKUP($E75,'Product Naming'!$A$1:$P$58,15,FALSE) -> Acetyl-CoA + Succinyl-CoA | AG75: =VLOOKUP($E75,'Product Naming'!$A$1:$P$58,16,FALSE) -> Diffusion | AH75: =VLOOKUP($E75,'Product Naming'!$A$1:$Q$58,17,FALSE) -> butn_c | AI75: =VLOOKUP($E75,'Product Parameters'!$A$2:$D$59,2,FALSE) -> 0 | AJ75: =VLOOKUP($E75,'Product Parameters'!$A$2:$D$59,3,FALSE) -> 1 | AK75: =VLOOKUP($E75,'Product Parameters'!$A$2:$D$59,4,FALSE) -> 0.12 | AL75: =VLOOKUP($E75,'Product Parameters'!$A$2:$E$59,5,FALSE) -> 0 | AM75: =VLOOKUP($E75,'Product Parameters'!$A$2:$F$59,6,FALSE) -> 4 | AN75: =VLOOKUP($C75,'Substrate Heating'!$A$2:$C$33,3,FALSE) -> 247.59097 | AO75: =VLOOKUP($C75,'Substrate Heating'!$A$2:$B$33,2,FALSE) -> 5.5 | AP75: =VLOOKUP($C75,'Substrate Heating'!$A$2:$M$33,13,FALSE) -> 1 | AQ75: =VLOOKUP($C75,'Substrate Heating'!$A$2:$M$33,8,FALSE) -> 1 | AR75: =Q75*W75/AQ75 -> 0.15168
A76: 2021-05-11 | B76: iJO1366 | C76: Formate_RGP-Serine | D76: ECR-C1a | E76: 1-Propanol-PW2 | F76: EX_ppoh_e | G76: -10 | H76: -20 | I76: NA | J76: 3.15 | K76: -10 | L76: -3.3465116 | M76: NA | N76: 8.8976744 | O76: 0.36744186 | Q76: 0.036744186 | R76: 0.047971273 | S76: =VLOOKUP($E76,'Product Naming'!$A$1:$P$58,2,FALSE) -> 1-propanol-PW2 | T76: =VLOOKUP($E76,'Product Naming'!$A$1:$P$58,3,FALSE) -> 1-Propanol (PW2) | U76: =VLOOKUP($E76,'Product Naming'!$A$1:$P$58,4,FALSE) -> E-S | V76: =VLOOKUP($E76,'Product Naming'!$A$1:$P$58,5,FALSE) -> C3H8O | W76: =VLOOKUP($E76,'Product Naming'!$A$1:$P$58,6,FALSE) -> 3 | X76: =VLOOKUP($E76,'Product Naming'!$A$1:$P$58,7,FALSE) -> 8 | Y76: =VLOOKUP($E76,'Product Naming'!$A$1:$P$58,8,FALSE) -> 1 | Z76: =VLOOKUP($E76,'Product Naming'!$A$1:$P$58,9,FALSE) -> 0 | AA76: =VLOOKUP($E76,'Product Naming'!$A$1:$P$58,10,FALSE) -> 0 | AB76: =VLOOKUP($E76,'Product Naming'!$A$1:$P$58,11,FALSE) -> 6 | AC76: =VLOOKUP($E76,'Product Naming'!$A$1:$P$58,12,FALSE) -> 60.09382 | AD76: =VLOOKUP($E76,'Product Naming'!$A$1:$P$58,13,FALSE) -> 97 | AE76: =VLOOKUP($E76,'Product Naming'!$A$1:$P$58,14,FALSE) -> Alcohol | AF76: =VLOOKUP($E76,'Product Naming'!$A$1:$P$58,15,FALSE) -> Oxaloacetate | AG76: =VLOOKUP($E76,'Product Naming'!$A$1:$P$58,16,FALSE) -> Proton symporter | AH76: =VLOOKUP($E76,'Product Naming'!$A$1:$Q$58,17,FALSE) -> ppoh_c | AI76: =VLOOKUP($E76,'Product Parameters'!$A$2:$D$59,2,FALSE) -> 1 | AJ76: =VLOOKUP($E76,'Product Parameters'!$A$2:$D$59,3,FALSE) -> 0 | AK76: =VLOOKUP($E76,'Product Parameters'!$A$2:$D$59,4,FALSE) -> 0.12 | AL76: =VLOOKUP($E76,'Product Parameters'!$A$2:$E$59,5,FALSE) -> 47 | AM76: =VLOOKUP($E76,'Product Parameters'!$A$2:$F$59,6,FALSE) -> 3 | AN76: =VLOOKUP($C76,'Substrate Heating'!$A$2:$C$33,3,FALSE) -> 247.59097 | AO76: =VLOOKUP($C76,'Substrate Heating'!$A$2:$B$33,2,FALSE) -> 5.5 | AP76: =VLOOKUP($C76,'Substrate Heating'!$A$2:$M$33,13,FALSE) -> 1 | AQ76: =VLOOKUP($C76,'Substrate Heating'!$A$2:$M$33,8,FALSE) -> 1 | AR76: =Q76*W76/AQ76 -> 0.11023256
A77: 2021-05-11 | B77: iJO1366 | C77: Formate_RGP-Serine | D77: ECR-C1a | E77: Pentanol-PW1 | F77: EX_pentoh_e | G77: -10 | H77: -20 | I77: NA | J77: 3.15 | K77: -10 | L77: -3.1190476 | M77: NA | N77: 8.7460317 | O77: 0.25079365 | Q77: 0.025079365 | R77: 0.048026927 | S77: =VLOOKUP($E77,'Product Naming'!$A$1:$P$58,2,FALSE) -> Pentanol-PW1 | T77: =VLOOKUP($E77,'Product Naming'!$A$1:$P$58,3,FALSE) -> Pentanol (PW1) | U77: =VLOOKUP($E77,'Product Naming'!$A$1:$P$58,4,FALSE) -> E | V77: =VLOOKUP($E77,'Product Naming'!$A$1:$P$58,5,FALSE) -> C5H12O | W77: =VLOOKUP($E77,'Product Naming'!$A$1:$P$58,6,FALSE) -> 5 | X77: =VLOOKUP($E77,'Product Naming'!$A$1:$P$58,7,FALSE) -> 12 | Y77: =VLOOKUP($E77,'Product Naming'!$A$1:$P$58,8,FALSE) -> 1 | Z77: =VLOOKUP($E77,'Product Naming'!$A$1:$P$58,9,FALSE) -> 0 | AA77: =VLOOKUP($E77,'Product Naming'!$A$1:$P$58,10,FALSE) -> 0 | AB77: =VLOOKUP($E77,'Product Naming'!$A$1:$P$58,11,FALSE) -> 6 | AC77: =VLOOKUP($E77,'Product Naming'!$A$1:$P$58,12,FALSE) -> 88.14658 | AD77: =VLOOKUP($E77,'Product Naming'!$A$1:$P$58,13,FALSE) -> 138 | AE77: =VLOOKUP($E77,'Product Naming'!$A$1:$P$58,14,FALSE) -> Alcohol | AF77: =VLOOKUP($E77,'Product Naming'!$A$1:$P$58,15,FALSE) -> Acetyl-CoA + Succinyl-CoA | AG77: =VLOOKUP($E77,'Product Naming'!$A$1:$P$58,16,FALSE) -> Proton symporter | AH77: =VLOOKUP($E77,'Product Naming'!$A$1:$Q$58,17,FALSE) -> pentoh_c | AI77: =VLOOKUP($E77,'Product Parameters'!$A$2:$D$59,2,FALSE) -> 1 | AJ77: =VLOOKUP($E77,'Product Parameters'!$A$2:$D$59,3,FALSE) -> 0 | AK77: =VLOOKUP($E77,'Product Parameters'!$A$2:$D$59,4,FALSE) -> 0.12 | AL77: =VLOOKUP($E77,'Product Parameters'!$A$2:$E$59,5,FALSE) -> 57 | AM77: =VLOOKUP($E77,'Product Parameters'!$A$2:$F$59,6,FALSE) -> 5 | AN77: =VLOOKUP($C77,'Substrate Heating'!$A$2:$C$33,3,FALSE) -> 247.59097 | AO77: =VLOOKUP($C77,'Substrate Heating'!$A$2:$B$33,2,FALSE) -> 5.5 | AP77: =VLOOKUP($C77,'Substrate Heating'!$A$2:$M$33,13,FALSE) -> 1 | AQ77: =VLOOKUP($C77,'Substrate Heating'!$A$2:$M$33,8,FALSE) -> 1 | AR77: =Q77*W77/AQ77 -> 0.12539683
A78: 2021-05-27 | B78: iHN637 | C78: FOR_1:H2_0 | D78: ECR-C1b | E78: Benzoate-PW2 | F78: EX_bz_e | G78: -10 | H78: 0 | I78: 0 | J78: 0.45 | K78: -10 | L78: 0 | M78: 0 | N78: 5.0926407 | O78: 0.18528139 | Q78: 0.018528139 | R78: 0.048750842 | S78: =VLOOKUP($E78,'Product Naming'!$A$1:$P$58,2,FALSE) -> Benzoate-PW2 | T78: =VLOOKUP($E78,'Product Naming'!$A$1:$P$58,3,FALSE) -> Benzoate (PW2) | U78: =VLOOKUP($E78,'Product Naming'!$A$1:$P$58,4,FALSE) -> A | V78: =VLOOKUP($E78,'Product Naming'!$A$1:$P$58,5,FALSE) -> C7H5O2 | W78: =VLOOKUP($E78,'Product Naming'!$A$1:$P$58,6,FALSE) -> 7 | X78: =VLOOKUP($E78,'Product Naming'!$A$1:$P$58,7,FALSE) -> 5 | Y78: =VLOOKUP($E78,'Product Naming'!$A$1:$P$58,8,FALSE) -> 2 | Z78: =VLOOKUP($E78,'Product Naming'!$A$1:$P$58,9,FALSE) -> 0 | AA78: =VLOOKUP($E78,'Product Naming'!$A$1:$P$58,10,FALSE) -> -1 | AB78: =VLOOKUP($E78,'Product Naming'!$A$1:$P$58,11,FALSE) -> 4.1428571 | AC78: =VLOOKUP($E78,'Product Naming'!$A$1:$P$58,12,FALSE) -> 121.1121 | AD78: =VLOOKUP($E78,'Product Naming'!$A$1:$P$58,13,FALSE) -> 249.2 | AE78: =VLOOKUP($E78,'Product Naming'!$A$1:$P$58,14,FALSE) -> Aromatic + Carboxylate | AF78: =VLOOKUP($E78,'Product Naming'!$A$1:$P$58,15,FALSE) -> E4P + aKG | AG78: =VLOOKUP($E78,'Product Naming'!$A$1:$P$58,16,FALSE) -> Proton symporter | AH78: =VLOOKUP($E78,'Product Naming'!$A$1:$Q$58,17,FALSE) -> bz_c | AI78: =VLOOKUP($E78,'Product Parameters'!$A$2:$D$59,2,FALSE) -> 1 | AJ78: =VLOOKUP($E78,'Product Parameters'!$A$2:$D$59,3,FALSE) -> 0 | AK78: =VLOOKUP($E78,'Product Parameters'!$A$2:$D$59,4,FALSE) -> 0.12 | AL78: =VLOOKUP($E78,'Product Parameters'!$A$2:$E$59,5,FALSE) -> 40.65 | AM78: =VLOOKUP($E78,'Product Parameters'!$A$2:$F$59,6,FALSE) -> 7 | AN78: =VLOOKUP($C78,'Substrate Heating'!$A$2:$C$33,3,FALSE) -> 247.59097 | AO78: =VLOOKUP($C78,'Substrate Heating'!$A$2:$B$33,2,FALSE) -> 5.5 | AP78: =VLOOKUP($C78,'Substrate Heating'!$A$2:$M$33,13,FALSE) -> 1 | AQ78: =VLOOKUP($C78,'Substrate Heating'!$A$2:$M$33,8,FALSE) -> 1 | AR78: =Q78*W78/AQ78 -> 0.12969697
A79: 2021-05-11 | B79: iJO1366 | C79: Formate_Formolase | D79: ECR-C1a | E79: Propane-PW1 | F79: EX_propane_e | G79: -10 | H79: -20 | I79: NA | J79: 3.15 | K79: -10 | L79: -2.3956044 | M79: NA | N79: 8.4373626 | O79: 0.52087912 | Q79: 0.052087912 | R79: 0.049898481 | S79: =VLOOKUP($E79,'Product Naming'!$A$1:$P$58,2,FALSE) -> Propane-PW1 | T79: =VLOOKUP($E79,'Product Naming'!$A$1:$P$58,3,FALSE) -> Propane (PW1) | U79: =VLOOKUP($E79,'Product Naming'!$A$1:$P$58,4,FALSE) -> E | V79: =VLOOKUP($E79,'Product Naming'!$A$1:$P$58,5,FALSE) -> C3H8 | W79: =VLOOKUP($E79,'Product Naming'!$A$1:$P$58,6,FALSE) -> 3 | X79: =VLOOKUP($E79,'Product Naming'!$A$1:$P$58,7,FALSE) -> 8 | Y79: =VLOOKUP($E79,'Product Naming'!$A$1:$P$58,8,FALSE) -> 0 | Z79: =VLOOKUP($E79,'Product Naming'!$A$1:$P$58,9,FALSE) -> 0 | AA79: =VLOOKUP($E79,'Product Naming'!$A$1:$P$58,10,FALSE) -> 0 | AB79: =VLOOKUP($E79,'Product Naming'!$A$1:$P$58,11,FALSE) -> 6.6666667 | AC79: =VLOOKUP($E79,'Product Naming'!$A$1:$P$58,12,FALSE) -> 44.09482 | AD79: =VLOOKUP($E79,'Product Naming'!$A$1:$P$58,13,FALSE) -> -42 | AE79: =VLOOKUP($E79,'Product Naming'!$A$1:$P$58,14,FALSE) -> Hydrocarbon | AF79: =VLOOKUP($E79,'Product Naming'!$A$1:$P$58,15,FALSE) -> Acetyl-CoA | AG79: =VLOOKUP($E79,'Product Naming'!$A$1:$P$58,16,FALSE) -> Diffusion | AH79: =VLOOKUP($E79,'Product Naming'!$A$1:$Q$58,17,FALSE) -> prop_c | AI79: =VLOOKUP($E79,'Product Parameters'!$A$2:$D$59,2,FALSE) -> 0 | AJ79: =VLOOKUP($E79,'Product Parameters'!$A$2:$D$59,3,FALSE) -> 1 | AK79: =VLOOKUP($E79,'Product Parameters'!$A$2:$D$59,4,FALSE) -> 0.12 | AL79: =VLOOKUP($E79,'Product Parameters'!$A$2:$E$59,5,FALSE) -> 0 | AM79: =VLOOKUP($E79,'Product Parameters'!$A$2:$F$59,6,FALSE) -> 3 | AN79: =VLOOKUP($C79,'Substrate Heating'!$A$2:$C$33,3,FALSE) -> 247.59097 | AO79: =VLOOKUP($C79,'Substrate Heating'!$A$2:$B$33,2,FALSE) -> 5.5 | AP79: =VLOOKUP($C79,'Substrate Heating'!$A$2:$M$33,13,FALSE) -> 1 | AQ79: =VLOOKUP($C79,'Substrate Heating'!$A$2:$M$33,8,FALSE) -> 1 | AR79: =Q79*W79/AQ79 -> 0.15626374
A80: 2021-05-11 | B80: iJO1366 | C80: Formate_Formolase | D80: ECR-C1a | E80: BetaCarotene | F80: EX_caro_e | G80: -10 | H80: -20 | I80: NA | J80: 3.15 | K80: -10 | L80: -2.63 | M80: NA | N80: 8.2444444 | O80: 0.043888889 | Q80: 0.0043888889 | R80: 0.051189882 | S80: =VLOOKUP($E80,'Product Naming'!$A$1:$P$58,2,FALSE) -> BetaCarotene | T80: =VLOOKUP($E80,'Product Naming'!$A$1:$P$58,3,FALSE) -> Beta carotene | U80: =VLOOKUP($E80,'Product Naming'!$A$1:$P$58,4,FALSE) -> A | V80: =VLOOKUP($E80,'Product Naming'!$A$1:$P$58,5,FALSE) -> C40H56 | W80: =VLOOKUP($E80,'Product Naming'!$A$1:$P$58,6,FALSE) -> 40 | X80: =VLOOKUP($E80,'Product Naming'!$A$1:$P$58,7,FALSE) -> 56 | Y80: =VLOOKUP($E80,'Product Naming'!$A$1:$P$58,8,FALSE) -> 0 | Z80: =VLOOKUP($E80,'Product Naming'!$A$1:$P$58,9,FALSE) -> 0 | AA80: =VLOOKUP($E80,'Product Naming'!$A$1:$P$58,10,FALSE) -> 0 | AB80: =VLOOKUP($E80,'Product Naming'!$A$1:$P$58,11,FALSE) -> 5.4 | AC80: =VLOOKUP($E80,'Product Naming'!$A$1:$P$58,12,FALSE) -> 536.86704 | AD80: =VLOOKUP($E80,'Product Naming'!$A$1:$P$58,13,FALSE) -> 633 | AE80: =VLOOKUP($E80,'Product Naming'!$A$1:$P$58,14,FALSE) -> Hydrocarbon | AF80: =VLOOKUP($E80,'Product Naming'!$A$1:$P$58,15,FALSE) -> Acetyl-CoA | AG80: =VLOOKUP($E80,'Product Naming'!$A$1:$P$58,16,FALSE) -> ABC Transporter | AH80: =VLOOKUP($E80,'Product Naming'!$A$1:$Q$58,17,FALSE) -> caro_c | AI80: =VLOOKUP($E80,'Product Parameters'!$A$2:$D$59,2,FALSE) -> 1 | AJ80: =VLOOKUP($E80,'Product Parameters'!$A$2:$D$59,3,FALSE) -> 0 | AK80: =VLOOKUP($E80,'Product Parameters'!$A$2:$D$59,4,FALSE) -> 0.12 | AL80: =VLOOKUP($E80,'Product Parameters'!$A$2:$E$59,5,FALSE) -> 40.65 | AM80: =VLOOKUP($E80,'Product Parameters'!$A$2:$F$59,6,FALSE) -> 40 | AN80: =VLOOKUP($C80,'Substrate Heating'!$A$2:$C$33,3,FALSE) -> 247.59097 | AO80: =VLOOKUP($C80,'Substrate Heating'!$A$2:$B$33,2,FALSE) -> 5.5 | AP80: =VLOOKUP($C80,'Substrate Heating'!$A$2:$M$33,13,FALSE) -> 1 | AQ80: =VLOOKUP($C80,'Substrate Heating'!$A$2:$M$33,8,FALSE) -> 1 | AR80: =Q80*W80/AQ80 -> 0.17555556
A81: 2021-05-25 | B81: iJO1366 | C81: Formate_Formolase | D81: ECR-C1a | E81: Hexane | F81: EX_hexane_e | G81: -10 | H81: -20 | I81: NA | J81: 3.15 | K81: -10 | L81: -2.3971098 | M81: NA | N81: 8.3560694 | O81: 0.27398844 | Q81: 0.027398844 | R81: 0.051294534 | S81: =VLOOKUP($E81,'Product Naming'!$A$1:$P$58,2,FALSE) -> Hexane | T81: =VLOOKUP($E81,'Product Naming'!$A$1:$P$58,3,FALSE) -> Hexane | U81: =VLOOKUP($E81,'Product Naming'!$A$1:$P$58,4,FALSE) -> E | V81: =VLOOKUP($E81,'Product Naming'!$A$1:$P$58,5,FALSE) -> C6H14 | W81: =VLOOKUP($E81,'Product Naming'!$A$1:$P$58,6,FALSE) -> 6 | X81: =VLOOKUP($E81,'Product Naming'!$A$1:$P$58,7,FALSE) -> 14 | Y81: =VLOOKUP($E81,'Product Naming'!$A$1:$P$58,8,FALSE) -> 0 | Z81: =VLOOKUP($E81,'Product Naming'!$A$1:$P$58,9,FALSE) -> 0 | AA81: =VLOOKUP($E81,'Product Naming'!$A$1:$P$58,10,FALSE) -> 0 | AB81: =VLOOKUP($E81,'Product Naming'!$A$1:$P$58,11,FALSE) -> 6.3333333 | AC81: =VLOOKUP($E81,'Product Naming'!$A$1:$P$58,12,FALSE) -> 86.17396 | AD81: =VLOOKUP($E81,'Product Naming'!$A$1:$P$58,13,FALSE) -> 69 | AE81: =VLOOKUP($E81,'Product Naming'!$A$1:$P$58,14,FALSE) -> Hydrocarbon (alkane) | AF81: =VLOOKUP($E81,'Product Naming'!$A$1:$P$58,15,FALSE) -> Acetyl-CoA + Succinyl-CoA | AG81: =VLOOKUP($E81,'Product Naming'!$A$1:$P$58,16,FALSE) -> Proton symporter | AH81: =VLOOKUP($E81,'Product Naming'!$A$1:$Q$58,17,FALSE) -> hex_c | AI81: =VLOOKUP($E81,'Product Parameters'!$A$2:$D$59,2,FALSE) -> 1 | AJ81: =VLOOKUP($E81,'Product Parameters'!$A$2:$D$59,3,FALSE) -> 0 | AK81: =VLOOKUP($E81,'Product Parameters'!$A$2:$D$59,4,FALSE) -> 0.12 | AL81: =VLOOKUP($E81,'Product Parameters'!$A$2:$E$59,5,FALSE) -> 31 | AM81: =VLOOKUP($E81,'Product Parameters'!$A$2:$F$59,6,FALSE) -> 6 | AN81: =VLOOKUP($C81,'Substrate Heating'!$A$2:$C$33,3,FALSE) -> 247.59097 | AO81: =VLOOKUP($C81,'Substrate Heating'!$A$2:$B$33,2,FALSE) -> 5.5 | AP81: =VLOOKUP($C81,'Substrate Heating'!$A$2:$M$33,13,FALSE) -> 1 | AQ81: =VLOOKUP($C81,'Substrate Heating'!$A$2:$M$33,8,FALSE) -> 1 | AR81: =Q81*W81/AQ81 -> 0.16439306
A82: 2021-05-11 | B82: iJO1366 | C82: Formate_Formolase | D82: ECR-C1a | E82: Pentane | F82: EX_pentane_e | G82: -10 | H82: -20 | I82: NA | J82: 3.15 | K82: -10 | L82: -2.3666667 | M82: NA | N82: 8.3541667 | O82: 0.32916667 | Q82: 0.032916667 | R82: 0.051594145 | S82: =VLOOKUP($E82,'Product Naming'!$A$1:$P$58,2,FALSE) -> Pentane | T82: =VLOOKUP($E82,'Product Naming'!$A$1:$P$58,3,FALSE) -> Pentane | U82: =VLOOKUP($E82,'Product Naming'!$A$1:$P$58,4,FALSE) -> E | V82: =VLOOKUP($E82,'Product Naming'!$A$1:$P$58,5,FALSE) -> C5H12 | W82: =VLOOKUP($E82,'Product Naming'!$A$1:$P$58,6,FALSE) -> 5 | X82: =VLOOKUP($E82,'Product Naming'!$A$1:$P$58,7,FALSE) -> 12 | Y82: =VLOOKUP($E82,'Product Naming'!$A$1:$P$58,8,FALSE) -> 0 | Z82: =VLOOKUP($E82,'Product Naming'!$A$1:$P$58,9,FALSE) -> 0 | AA82: =VLOOKUP($E82,'Product Naming'!$A$1:$P$58,10,FALSE) -> 0 | AB82: =VLOOKUP($E82,'Product Naming'!$A$1:$P$58,11,FALSE) -> 6.4 | AC82: =VLOOKUP($E82,'Product Naming'!$A$1:$P$58,12,FALSE) -> 72.14758 | AD82: =VLOOKUP($E82,'Product Naming'!$A$1:$P$58,13,FALSE) -> 36.1 | AE82: =VLOOKUP($E82,'Product Naming'!$A$1:$P$58,14,FALSE) -> Hydrocarbon (alkane) | AF82: =VLOOKUP($E82,'Product Naming'!$A$1:$P$58,15,FALSE) -> Acetyl-CoA | AG82: =VLOOKUP($E82,'Product Naming'!$A$1:$P$58,16,FALSE) -> Diffusion | AH82: =VLOOKUP($E82,'Product Naming'!$A$1:$Q$58,17,FALSE) -> pent_c | AI82: =VLOOKUP($E82,'Product Parameters'!$A$2:$D$59,2,FALSE) -> 0 | AJ82: =VLOOKUP($E82,'Product Parameters'!$A$2:$D$59,3,FALSE) -> 1 | AK82: =VLOOKUP($E82,'Product Parameters'!$A$2:$D$59,4,FALSE) -> 0.12 | AL82: =VLOOKUP($E82,'Product Parameters'!$A$2:$E$59,5,FALSE) -> 26.5 | AM82: =VLOOKUP($E82,'Product Parameters'!$A$2:$F$59,6,FALSE) -> 5 | AN82: =VLOOKUP($C82,'Substrate Heating'!$A$2:$C$33,3,FALSE) -> 247.59097 | AO82: =VLOOKUP($C82,'Substrate Heating'!$A$2:$B$33,2,FALSE) -> 5.5 | AP82: =VLOOKUP($C82,'Substrate Heating'!$A$2:$M$33,13,FALSE) -> 1 | AQ82: =VLOOKUP($C82,'Substrate Heating'!$A$2:$M$33,8,FALSE) -> 1 | AR82: =Q82*W82/AQ82 -> 0.16458333
A83: 2023-11-29 | B83: iHN637 | C83: Methanol_MethylTransferase_1 | D83: ECR-C1a | E83: Benzoate-PW1 | F83: EX_bz_e | G83: -10 | H83: 0 | I83: 0 | J83: 0.45 | K83: -10 | L83: 0 | M83: 0.8200000000000109 | N83: 0 | O83: 0.13666666666666671 | Q83: 0.013666667 | R83: 0.051926584 | S83: =VLOOKUP($E83,'Product Naming'!$A$1:$P$58,2,FALSE) -> Benzoate-PW1 | T83: =VLOOKUP($E83,'Product Naming'!$A$1:$P$58,3,FALSE) -> Benzoate (PW1) | U83: =VLOOKUP($E83,'Product Naming'!$A$1:$P$58,4,FALSE) -> A | V83: =VLOOKUP($E83,'Product Naming'!$A$1:$P$58,5,FALSE) -> C7H5O2 | W83: =VLOOKUP($E83,'Product Naming'!$A$1:$P$58,6,FALSE) -> 7 | X83: =VLOOKUP($E83,'Product Naming'!$A$1:$P$58,7,FALSE) -> 5 | Y83: =VLOOKUP($E83,'Product Naming'!$A$1:$P$58,8,FALSE) -> 2 | Z83: =VLOOKUP($E83,'Product Naming'!$A$1:$P$58,9,FALSE) -> 0 | AA83: =VLOOKUP($E83,'Product Naming'!$A$1:$P$58,10,FALSE) -> -1 | AB83: =VLOOKUP($E83,'Product Naming'!$A$1:$P$58,11,FALSE) -> 4.1428571 | AC83: =VLOOKUP($E83,'Product Naming'!$A$1:$P$58,12,FALSE) -> 121.1121 | AD83: =VLOOKUP($E83,'Product Naming'!$A$1:$P$58,13,FALSE) -> 249.2 | AE83: =VLOOKUP($E83,'Product Naming'!$A$1:$P$58,14,FALSE) -> Aromatic + Carboxylate | AF83: =VLOOKUP($E83,'Product Naming'!$A$1:$P$58,15,FALSE) -> E4P + aKG | AG83: =VLOOKUP($E83,'Product Naming'!$A$1:$P$58,16,FALSE) -> Proton symporter | AH83: =VLOOKUP($E83,'Product Naming'!$A$1:$Q$58,17,FALSE) -> bz_c | AI83: =VLOOKUP($E83,'Product Parameters'!$A$2:$D$59,2,FALSE) -> 1 | AJ83: =VLOOKUP($E83,'Product Parameters'!$A$2:$D$59,3,FALSE) -> 0 | AK83: =VLOOKUP($E83,'Product Parameters'!$A$2:$D$59,4,FALSE) -> 0.12 | AL83: =VLOOKUP($E83,'Product Parameters'!$A$2:$E$59,5,FALSE) -> 40.65 | AM83: =VLOOKUP($E83,'Product Parameters'!$A$2:$F$59,6,FALSE) -> 7 | AN83: =VLOOKUP($C83,'Substrate Heating'!$A$2:$C$33,3,FALSE) -> 638.57833 | AO83: =VLOOKUP($C83,'Substrate Heating'!$A$2:$B$33,2,FALSE) -> 19.93 | AP83: =VLOOKUP($C83,'Substrate Heating'!$A$2:$M$33,13,FALSE) -> 6 | AQ83: =VLOOKUP($C83,'Substrate Heating'!$A$2:$M$33,8,FALSE) -> 1 | AR83: =Q83*W83/AQ83 -> 0.095666667
A84: 2021-05-25 | B84: iJO1366 | C84: Formate_Formolase | D84: ECR-C1a | E84: Octane | F84: EX_octane_e | G84: -10 | H84: -20 | I84: NA | J84: 3.15 | K84: -10 | L84: -2.3783186 | M84: NA | N84: 8.3221239 | O84: 0.20973451 | Q84: 0.020973451 | R84: 0.052047564 | S84: =VLOOKUP($E84,'Product Naming'!$A$1:$P$58,2,FALSE) -> Octane | T84: =VLOOKUP($E84,'Product Naming'!$A$1:$P$58,3,FALSE) -> Octane | U84: =VLOOKUP($E84,'Product Naming'!$A$1:$P$58,4,FALSE) -> E | V84: =VLOOKUP($E84,'Product Naming'!$A$1:$P$58,5,FALSE) -> C8H18 | W84: =VLOOKUP($E84,'Product Naming'!$A$1:$P$58,6,FALSE) -> 8 | X84: =VLOOKUP($E84,'Product Naming'!$A$1:$P$58,7,FALSE) -> 18 | Y84: =VLOOKUP($E84,'Product Naming'!$A$1:$P$58,8,FALSE) -> 0 | Z84: =VLOOKUP($E84,'Product Naming'!$A$1:$P$58,9,FALSE) -> 0 | AA84: =VLOOKUP($E84,'Product Naming'!$A$1:$P$58,10,FALSE) -> 0 | AB84: =VLOOKUP($E84,'Product Naming'!$A$1:$P$58,11,FALSE) -> 6.25 | AC84: =VLOOKUP($E84,'Product Naming'!$A$1:$P$58,12,FALSE) -> 114.22672 | AD84: =VLOOKUP($E84,'Product Naming'!$A$1:$P$58,13,FALSE) -> 126 | AE84: =VLOOKUP($E84,'Product Naming'!$A$1:$P$58,14,FALSE) -> Hydrocarbon (alkane) | AF84: =VLOOKUP($E84,'Product Naming'!$A$1:$P$58,15,FALSE) -> Acetyl-CoA + Succinyl-CoA | AG84: =VLOOKUP($E84,'Product Naming'!$A$1:$P$58,16,FALSE) -> Proton symporter | AH84: =VLOOKUP($E84,'Product Naming'!$A$1:$Q$58,17,FALSE) -> octn_c | AI84: =VLOOKUP($E84,'Product Parameters'!$A$2:$D$59,2,FALSE) -> 1 | AJ84: =VLOOKUP($E84,'Product Parameters'!$A$2:$D$59,3,FALSE) -> 0 | AK84: =VLOOKUP($E84,'Product Parameters'!$A$2:$D$59,4,FALSE) -> 0.12 | AL84: =VLOOKUP($E84,'Product Parameters'!$A$2:$E$59,5,FALSE) -> 41 | AM84: =VLOOKUP($E84,'Product Parameters'!$A$2:$F$59,6,FALSE) -> 8 | AN84: =VLOOKUP($C84,'Substrate Heating'!$A$2:$C$33,3,FALSE) -> 247.59097 | AO84: =VLOOKUP($C84,'Substrate Heating'!$A$2:$B$33,2,FALSE) -> 5.5 | AP84: =VLOOKUP($C84,'Substrate Heating'!$A$2:$M$33,13,FALSE) -> 1 | AQ84: =VLOOKUP($C84,'Substrate Heating'!$A$2:$M$33,8,FALSE) -> 1 | AR84: =Q84*W84/AQ84 -> 0.16778761
